{
    "report": {
        "environment": {
            "Python": "3.8.11",
            "Platform": "Windows-10-10.0.19042-SP0"
        },
        "tests": [
            {
                "name": "modin/pandas/test/dataframe/test_iter.py::test_items_iteritems_iterrows[items]",
                "duration": 71.75144850000001,
                "run_index": 0,
                "setup": {
                    "name": "setup",
                    "duration": 5.017262400000001,
                    "outcome": "passed"
                },
                "call": {
                    "name": "call",
                    "duration": 61.7159472,
                    "outcome": "passed"
                },
                "teardown": {
                    "name": "teardown",
                    "duration": 0.0009765000000072632,
                    "outcome": "passed"
                },
                "outcome": "passed"
            },
            {
                "name": "modin/pandas/test/dataframe/test_iter.py::test_items_iteritems_iterrows[iteritems]",
                "duration": 25.85526430000003,
                "run_index": 1,
                "setup": {
                    "name": "setup",
                    "duration": 0.0006088000000090688,
                    "outcome": "passed"
                },
                "call": {
                    "name": "call",
                    "duration": 25.853528600000004,
                    "outcome": "passed"
                },
                "teardown": {
                    "name": "teardown",
                    "duration": 0.0005181000000078484,
                    "outcome": "passed"
                },
                "outcome": "passed"
            },
            {
                "name": "modin/pandas/test/dataframe/test_iter.py::test_items_iteritems_iterrows[iterrows]",
                "duration": 28.749450200000027,
                "run_index": 2,
                "setup": {
                    "name": "setup",
                    "duration": 0.0009647000000114758,
                    "outcome": "passed"
                },
                "call": {
                    "name": "call",
                    "duration": 28.746984400000002,
                    "outcome": "passed"
                },
                "teardown": {
                    "name": "teardown",
                    "duration": 0.0005364000000014357,
                    "outcome": "passed"
                },
                "outcome": "passed"
            },
            {
                "name": "modin/pandas/test/dataframe/test_iter.py::test_itertuples_name[None]",
                "duration": 21.267543400000022,
                "run_index": 3,
                "setup": {
                    "name": "setup",
                    "duration": 0.0006621999999936179,
                    "outcome": "passed"
                },
                "call": {
                    "name": "call",
                    "duration": 21.26536390000001,
                    "outcome": "failed",
                    "longrepr": "modin\\pandas\\test\\dataframe\\test_iter.py:62: in test_itertuples_name\n    np.testing.assert_equal(modin_row, pandas_row)\nC:\\Users\\alozovsk\\Anaconda3\\envs\\modin\\lib\\site-packages\\numpy\\__init__.py:307: in __getattr__\n    import numpy.testing as testing\nmodin\\experimental\\pandas\\numpy_wrap.py:164: in __getattr__\n    obj = getattr(self.__get_numpy(), name)\nC:\\Users\\alozovsk\\Anaconda3\\envs\\modin\\lib\\site-packages\\numpy\\__init__.py:307: in __getattr__\n    import numpy.testing as testing\nE   RecursionError: maximum recursion depth exceeded\n!!! Recursion detected (same locals & position)"
                },
                "teardown": {
                    "name": "teardown",
                    "duration": 0.0008551000000238673,
                    "outcome": "passed"
                },
                "outcome": "failed"
            },
            {
                "name": "modin/pandas/test/dataframe/test_iter.py::test_itertuples_name[NotPandas]",
                "duration": 21.604773999999992,
                "run_index": 4,
                "setup": {
                    "name": "setup",
                    "duration": 0.0007464999999911015,
                    "outcome": "passed"
                },
                "call": {
                    "name": "call",
                    "duration": 21.6025827,
                    "outcome": "failed",
                    "longrepr": "modin\\pandas\\test\\dataframe\\test_iter.py:62: in test_itertuples_name\n    np.testing.assert_equal(modin_row, pandas_row)\nC:\\Users\\alozovsk\\Anaconda3\\envs\\modin\\lib\\site-packages\\numpy\\__init__.py:307: in __getattr__\n    import numpy.testing as testing\nmodin\\experimental\\pandas\\numpy_wrap.py:164: in __getattr__\n    obj = getattr(self.__get_numpy(), name)\nC:\\Users\\alozovsk\\Anaconda3\\envs\\modin\\lib\\site-packages\\numpy\\__init__.py:307: in __getattr__\n    import numpy.testing as testing\nE   RecursionError: maximum recursion depth exceeded\n!!! Recursion detected (same locals & position)"
                },
                "teardown": {
                    "name": "teardown",
                    "duration": 0.0006983000000104767,
                    "outcome": "passed"
                },
                "outcome": "failed"
            },
            {
                "name": "modin/pandas/test/dataframe/test_iter.py::test_itertuples_multiindex",
                "duration": 2.6664737999999772,
                "run_index": 5,
                "setup": {
                    "name": "setup",
                    "duration": 0.0005628999999771622,
                    "outcome": "passed"
                },
                "call": {
                    "name": "call",
                    "duration": 2.664849800000013,
                    "outcome": "failed",
                    "longrepr": "modin\\pandas\\test\\dataframe\\test_iter.py:67: in test_itertuples_multiindex\n    modin_df, pandas_df = pd.DataFrame(data), pandas.DataFrame(data)\nmodin\\experimental\\cloud\\meta_magic.py:155: in __new__\n    return cls.__real_cls__(*a, **kw)\nmodin\\experimental\\cloud\\rpyc_proxy.py:431: in __init__\n    __remote_end__ = remote_cls(*a, **kw)\nC:\\Users\\alozovsk\\Anaconda3\\envs\\modin\\lib\\site-packages\\rpyc\\core\\netref.py:253: in __call__\n    return syncreq(_self, consts.HANDLE_CALL, args, kwargs)\nC:\\Users\\alozovsk\\Anaconda3\\envs\\modin\\lib\\site-packages\\rpyc\\core\\netref.py:76: in syncreq\n    return conn.sync_request(handler, proxy, *args)\nmodin\\experimental\\cloud\\rpyc_proxy.py:165: in sync_request\n    return super().sync_request(handler, *args)\nC:\\Users\\alozovsk\\Anaconda3\\envs\\modin\\lib\\site-packages\\rpyc\\core\\protocol.py:481: in sync_request\n    return self.async_request(handler, *args, timeout=timeout).value\nC:\\Users\\alozovsk\\Anaconda3\\envs\\modin\\lib\\site-packages\\rpyc\\core\\async_.py:102: in value\n    raise self._obj\nE   _get_exception_class.<locals>.Derived: Cannot interpret 'dtype('int32')' as a data type\nE   \nE   ========= Remote Traceback (1) =========\nE   Traceback (most recent call last):\nE     File \"C:\\Users\\alozovsk\\Anaconda3\\envs\\modin\\lib\\site-packages\\rpyc\\core\\protocol.py\", line 327, in _dispatch_request\nE       res = self._HANDLERS[handler](self, *args)\nE     File \"C:\\Users\\alozovsk\\Anaconda3\\envs\\modin\\lib\\site-packages\\rpyc\\core\\protocol.py\", line 608, in _handle_call\nE       return obj(*args, **dict(kwargs))\nE     File \"C:\\prog\\modin\\modin\\pandas\\dataframe.py\", line 171, in __init__\nE       pandas_df = pandas.DataFrame(\nE     File \"C:\\Users\\alozovsk\\Anaconda3\\envs\\modin\\lib\\site-packages\\pandas\\core\\frame.py\", line 614, in __init__\nE       mgr = dict_to_mgr(data, index, columns, dtype=dtype, copy=copy, typ=manager)\nE     File \"C:\\Users\\alozovsk\\Anaconda3\\envs\\modin\\lib\\site-packages\\pandas\\core\\internals\\construction.py\", line 464, in dict_to_mgr\nE       return arrays_to_mgr(\nE     File \"C:\\Users\\alozovsk\\Anaconda3\\envs\\modin\\lib\\site-packages\\pandas\\core\\internals\\construction.py\", line 135, in arrays_to_mgr\nE       return create_block_manager_from_arrays(\nE     File \"C:\\Users\\alozovsk\\Anaconda3\\envs\\modin\\lib\\site-packages\\pandas\\core\\internals\\managers.py\", line 1773, in create_block_manager_from_arrays\nE       blocks = _form_blocks(arrays, names, axes, consolidate)\nE     File \"C:\\Users\\alozovsk\\Anaconda3\\envs\\modin\\lib\\site-packages\\pandas\\core\\internals\\managers.py\", line 1838, in _form_blocks\nE       numeric_blocks = _multi_blockify(\nE     File \"C:\\Users\\alozovsk\\Anaconda3\\envs\\modin\\lib\\site-packages\\pandas\\core\\internals\\managers.py\", line 1928, in _multi_blockify\nE       values, placement = _stack_arrays(\nE     File \"C:\\Users\\alozovsk\\Anaconda3\\envs\\modin\\lib\\site-packages\\pandas\\core\\internals\\managers.py\", line 1957, in _stack_arrays\nE       stacked = np.empty(shape, dtype=dtype)\nE   TypeError: Cannot interpret 'dtype('int32')' as a data type"
                },
                "teardown": {
                    "name": "teardown",
                    "duration": 0.0004982000000097742,
                    "outcome": "passed"
                },
                "outcome": "failed"
            },
            {
                "name": "modin/pandas/test/dataframe/test_iter.py::test___iter__",
                "duration": 3.551585000000017,
                "run_index": 6,
                "setup": {
                    "name": "setup",
                    "duration": 0.0005610000000046966,
                    "outcome": "passed"
                },
                "call": {
                    "name": "call",
                    "duration": 3.549988500000012,
                    "outcome": "failed",
                    "longrepr": "modin\\pandas\\test\\dataframe\\test_iter.py:81: in test___iter__\n    modin_df = pd.DataFrame(test_data_values[0])\nmodin\\experimental\\cloud\\meta_magic.py:155: in __new__\n    return cls.__real_cls__(*a, **kw)\nmodin\\experimental\\cloud\\rpyc_proxy.py:431: in __init__\n    __remote_end__ = remote_cls(*a, **kw)\nC:\\Users\\alozovsk\\Anaconda3\\envs\\modin\\lib\\site-packages\\rpyc\\core\\netref.py:253: in __call__\n    return syncreq(_self, consts.HANDLE_CALL, args, kwargs)\nC:\\Users\\alozovsk\\Anaconda3\\envs\\modin\\lib\\site-packages\\rpyc\\core\\netref.py:76: in syncreq\n    return conn.sync_request(handler, proxy, *args)\nmodin\\experimental\\cloud\\rpyc_proxy.py:165: in sync_request\n    return super().sync_request(handler, *args)\nC:\\Users\\alozovsk\\Anaconda3\\envs\\modin\\lib\\site-packages\\rpyc\\core\\protocol.py:481: in sync_request\n    return self.async_request(handler, *args, timeout=timeout).value\nC:\\Users\\alozovsk\\Anaconda3\\envs\\modin\\lib\\site-packages\\rpyc\\core\\async_.py:102: in value\n    raise self._obj\nE   _get_exception_class.<locals>.Derived: Cannot interpret 'dtype('int32')' as a data type\nE   \nE   ========= Remote Traceback (1) =========\nE   Traceback (most recent call last):\nE     File \"C:\\Users\\alozovsk\\Anaconda3\\envs\\modin\\lib\\site-packages\\rpyc\\core\\protocol.py\", line 327, in _dispatch_request\nE       res = self._HANDLERS[handler](self, *args)\nE     File \"C:\\Users\\alozovsk\\Anaconda3\\envs\\modin\\lib\\site-packages\\rpyc\\core\\protocol.py\", line 608, in _handle_call\nE       return obj(*args, **dict(kwargs))\nE     File \"C:\\prog\\modin\\modin\\pandas\\dataframe.py\", line 171, in __init__\nE       pandas_df = pandas.DataFrame(\nE     File \"C:\\Users\\alozovsk\\Anaconda3\\envs\\modin\\lib\\site-packages\\pandas\\core\\frame.py\", line 614, in __init__\nE       mgr = dict_to_mgr(data, index, columns, dtype=dtype, copy=copy, typ=manager)\nE     File \"C:\\Users\\alozovsk\\Anaconda3\\envs\\modin\\lib\\site-packages\\pandas\\core\\internals\\construction.py\", line 464, in dict_to_mgr\nE       return arrays_to_mgr(\nE     File \"C:\\Users\\alozovsk\\Anaconda3\\envs\\modin\\lib\\site-packages\\pandas\\core\\internals\\construction.py\", line 135, in arrays_to_mgr\nE       return create_block_manager_from_arrays(\nE     File \"C:\\Users\\alozovsk\\Anaconda3\\envs\\modin\\lib\\site-packages\\pandas\\core\\internals\\managers.py\", line 1773, in create_block_manager_from_arrays\nE       blocks = _form_blocks(arrays, names, axes, consolidate)\nE     File \"C:\\Users\\alozovsk\\Anaconda3\\envs\\modin\\lib\\site-packages\\pandas\\core\\internals\\managers.py\", line 1838, in _form_blocks\nE       numeric_blocks = _multi_blockify(\nE     File \"C:\\Users\\alozovsk\\Anaconda3\\envs\\modin\\lib\\site-packages\\pandas\\core\\internals\\managers.py\", line 1928, in _multi_blockify\nE       values, placement = _stack_arrays(\nE     File \"C:\\Users\\alozovsk\\Anaconda3\\envs\\modin\\lib\\site-packages\\pandas\\core\\internals\\managers.py\", line 1957, in _stack_arrays\nE       stacked = np.empty(shape, dtype=dtype)\nE   TypeError: Cannot interpret 'dtype('int32')' as a data type"
                },
                "teardown": {
                    "name": "teardown",
                    "duration": 0.00047449999999571446,
                    "outcome": "passed"
                },
                "outcome": "failed"
            },
            {
                "name": "modin/pandas/test/dataframe/test_iter.py::test___contains__[int_data]",
                "duration": 1.9995873999999958,
                "run_index": 7,
                "setup": {
                    "name": "setup",
                    "duration": 0.0006454999999903066,
                    "outcome": "passed"
                },
                "call": {
                    "name": "call",
                    "duration": 1.997602900000004,
                    "outcome": "failed",
                    "longrepr": "modin\\pandas\\test\\dataframe\\test_iter.py:96: in test___contains__\n    modin_df = pd.DataFrame(data)\nmodin\\experimental\\cloud\\meta_magic.py:155: in __new__\n    return cls.__real_cls__(*a, **kw)\nmodin\\experimental\\cloud\\rpyc_proxy.py:431: in __init__\n    __remote_end__ = remote_cls(*a, **kw)\nC:\\Users\\alozovsk\\Anaconda3\\envs\\modin\\lib\\site-packages\\rpyc\\core\\netref.py:253: in __call__\n    return syncreq(_self, consts.HANDLE_CALL, args, kwargs)\nC:\\Users\\alozovsk\\Anaconda3\\envs\\modin\\lib\\site-packages\\rpyc\\core\\netref.py:76: in syncreq\n    return conn.sync_request(handler, proxy, *args)\nmodin\\experimental\\cloud\\rpyc_proxy.py:165: in sync_request\n    return super().sync_request(handler, *args)\nC:\\Users\\alozovsk\\Anaconda3\\envs\\modin\\lib\\site-packages\\rpyc\\core\\protocol.py:481: in sync_request\n    return self.async_request(handler, *args, timeout=timeout).value\nC:\\Users\\alozovsk\\Anaconda3\\envs\\modin\\lib\\site-packages\\rpyc\\core\\async_.py:102: in value\n    raise self._obj\nE   _get_exception_class.<locals>.Derived: Cannot interpret 'dtype('int32')' as a data type\nE   \nE   ========= Remote Traceback (1) =========\nE   Traceback (most recent call last):\nE     File \"C:\\Users\\alozovsk\\Anaconda3\\envs\\modin\\lib\\site-packages\\rpyc\\core\\protocol.py\", line 327, in _dispatch_request\nE       res = self._HANDLERS[handler](self, *args)\nE     File \"C:\\Users\\alozovsk\\Anaconda3\\envs\\modin\\lib\\site-packages\\rpyc\\core\\protocol.py\", line 608, in _handle_call\nE       return obj(*args, **dict(kwargs))\nE     File \"C:\\prog\\modin\\modin\\pandas\\dataframe.py\", line 171, in __init__\nE       pandas_df = pandas.DataFrame(\nE     File \"C:\\Users\\alozovsk\\Anaconda3\\envs\\modin\\lib\\site-packages\\pandas\\core\\frame.py\", line 614, in __init__\nE       mgr = dict_to_mgr(data, index, columns, dtype=dtype, copy=copy, typ=manager)\nE     File \"C:\\Users\\alozovsk\\Anaconda3\\envs\\modin\\lib\\site-packages\\pandas\\core\\internals\\construction.py\", line 464, in dict_to_mgr\nE       return arrays_to_mgr(\nE     File \"C:\\Users\\alozovsk\\Anaconda3\\envs\\modin\\lib\\site-packages\\pandas\\core\\internals\\construction.py\", line 135, in arrays_to_mgr\nE       return create_block_manager_from_arrays(\nE     File \"C:\\Users\\alozovsk\\Anaconda3\\envs\\modin\\lib\\site-packages\\pandas\\core\\internals\\managers.py\", line 1773, in create_block_manager_from_arrays\nE       blocks = _form_blocks(arrays, names, axes, consolidate)\nE     File \"C:\\Users\\alozovsk\\Anaconda3\\envs\\modin\\lib\\site-packages\\pandas\\core\\internals\\managers.py\", line 1838, in _form_blocks\nE       numeric_blocks = _multi_blockify(\nE     File \"C:\\Users\\alozovsk\\Anaconda3\\envs\\modin\\lib\\site-packages\\pandas\\core\\internals\\managers.py\", line 1928, in _multi_blockify\nE       values, placement = _stack_arrays(\nE     File \"C:\\Users\\alozovsk\\Anaconda3\\envs\\modin\\lib\\site-packages\\pandas\\core\\internals\\managers.py\", line 1957, in _stack_arrays\nE       stacked = np.empty(shape, dtype=dtype)\nE   TypeError: Cannot interpret 'dtype('int32')' as a data type"
                },
                "teardown": {
                    "name": "teardown",
                    "duration": 0.0006935000000112268,
                    "outcome": "passed"
                },
                "outcome": "failed"
            },
            {
                "name": "modin/pandas/test/dataframe/test_iter.py::test___contains__[float_nan_data]",
                "duration": 56.340682199999975,
                "run_index": 8,
                "setup": {
                    "name": "setup",
                    "duration": 0.0007072999999877538,
                    "outcome": "passed"
                },
                "call": {
                    "name": "call",
                    "duration": 56.3386323,
                    "outcome": "passed"
                },
                "teardown": {
                    "name": "teardown",
                    "duration": 0.0006352999999990061,
                    "outcome": "passed"
                },
                "outcome": "passed"
            },
            {
                "name": "modin/pandas/test/dataframe/test_iter.py::test__options_display",
                "duration": 6.085673299999968,
                "run_index": 9,
                "setup": {
                    "name": "setup",
                    "duration": 0.0005728999999803364,
                    "outcome": "passed"
                },
                "call": {
                    "name": "call",
                    "duration": 6.084036700000013,
                    "outcome": "failed",
                    "longrepr": "modin\\pandas\\test\\dataframe\\test_iter.py:114: in test__options_display\n    modin_df = pd.DataFrame(frame_data)\nmodin\\experimental\\cloud\\meta_magic.py:155: in __new__\n    return cls.__real_cls__(*a, **kw)\nmodin\\experimental\\cloud\\rpyc_proxy.py:431: in __init__\n    __remote_end__ = remote_cls(*a, **kw)\nC:\\Users\\alozovsk\\Anaconda3\\envs\\modin\\lib\\site-packages\\rpyc\\core\\netref.py:253: in __call__\n    return syncreq(_self, consts.HANDLE_CALL, args, kwargs)\nC:\\Users\\alozovsk\\Anaconda3\\envs\\modin\\lib\\site-packages\\rpyc\\core\\netref.py:76: in syncreq\n    return conn.sync_request(handler, proxy, *args)\nmodin\\experimental\\cloud\\rpyc_proxy.py:165: in sync_request\n    return super().sync_request(handler, *args)\nC:\\Users\\alozovsk\\Anaconda3\\envs\\modin\\lib\\site-packages\\rpyc\\core\\protocol.py:481: in sync_request\n    return self.async_request(handler, *args, timeout=timeout).value\nC:\\Users\\alozovsk\\Anaconda3\\envs\\modin\\lib\\site-packages\\rpyc\\core\\async_.py:102: in value\n    raise self._obj\nE   _get_exception_class.<locals>.Derived: Cannot interpret 'dtype('int32')' as a data type\nE   \nE   ========= Remote Traceback (1) =========\nE   Traceback (most recent call last):\nE     File \"C:\\Users\\alozovsk\\Anaconda3\\envs\\modin\\lib\\site-packages\\rpyc\\core\\protocol.py\", line 327, in _dispatch_request\nE       res = self._HANDLERS[handler](self, *args)\nE     File \"C:\\Users\\alozovsk\\Anaconda3\\envs\\modin\\lib\\site-packages\\rpyc\\core\\protocol.py\", line 608, in _handle_call\nE       return obj(*args, **dict(kwargs))\nE     File \"C:\\prog\\modin\\modin\\pandas\\dataframe.py\", line 158, in __init__\nE       data = np.array(values, dtype=old_dtype)\nE   TypeError: Cannot interpret 'dtype('int32')' as a data type"
                },
                "teardown": {
                    "name": "teardown",
                    "duration": 0.0004907999999943513,
                    "outcome": "passed"
                },
                "outcome": "failed"
            },
            {
                "name": "modin/pandas/test/dataframe/test_iter.py::test___finalize__",
                "duration": 2.0909414999999854,
                "run_index": 10,
                "setup": {
                    "name": "setup",
                    "duration": 0.0010867000000018834,
                    "outcome": "passed"
                },
                "call": {
                    "name": "call",
                    "duration": 2.0882507999999973,
                    "outcome": "failed",
                    "longrepr": "modin\\pandas\\test\\dataframe\\test_iter.py:141: in test___finalize__\n    pd.DataFrame(data).__finalize__(None)\nmodin\\experimental\\cloud\\meta_magic.py:155: in __new__\n    return cls.__real_cls__(*a, **kw)\nmodin\\experimental\\cloud\\rpyc_proxy.py:431: in __init__\n    __remote_end__ = remote_cls(*a, **kw)\nC:\\Users\\alozovsk\\Anaconda3\\envs\\modin\\lib\\site-packages\\rpyc\\core\\netref.py:253: in __call__\n    return syncreq(_self, consts.HANDLE_CALL, args, kwargs)\nC:\\Users\\alozovsk\\Anaconda3\\envs\\modin\\lib\\site-packages\\rpyc\\core\\netref.py:76: in syncreq\n    return conn.sync_request(handler, proxy, *args)\nmodin\\experimental\\cloud\\rpyc_proxy.py:165: in sync_request\n    return super().sync_request(handler, *args)\nC:\\Users\\alozovsk\\Anaconda3\\envs\\modin\\lib\\site-packages\\rpyc\\core\\protocol.py:481: in sync_request\n    return self.async_request(handler, *args, timeout=timeout).value\nC:\\Users\\alozovsk\\Anaconda3\\envs\\modin\\lib\\site-packages\\rpyc\\core\\async_.py:102: in value\n    raise self._obj\nE   _get_exception_class.<locals>.Derived: Cannot interpret 'dtype('int32')' as a data type\nE   \nE   ========= Remote Traceback (1) =========\nE   Traceback (most recent call last):\nE     File \"C:\\Users\\alozovsk\\Anaconda3\\envs\\modin\\lib\\site-packages\\rpyc\\core\\protocol.py\", line 327, in _dispatch_request\nE       res = self._HANDLERS[handler](self, *args)\nE     File \"C:\\Users\\alozovsk\\Anaconda3\\envs\\modin\\lib\\site-packages\\rpyc\\core\\protocol.py\", line 608, in _handle_call\nE       return obj(*args, **dict(kwargs))\nE     File \"C:\\prog\\modin\\modin\\pandas\\dataframe.py\", line 171, in __init__\nE       pandas_df = pandas.DataFrame(\nE     File \"C:\\Users\\alozovsk\\Anaconda3\\envs\\modin\\lib\\site-packages\\pandas\\core\\frame.py\", line 614, in __init__\nE       mgr = dict_to_mgr(data, index, columns, dtype=dtype, copy=copy, typ=manager)\nE     File \"C:\\Users\\alozovsk\\Anaconda3\\envs\\modin\\lib\\site-packages\\pandas\\core\\internals\\construction.py\", line 464, in dict_to_mgr\nE       return arrays_to_mgr(\nE     File \"C:\\Users\\alozovsk\\Anaconda3\\envs\\modin\\lib\\site-packages\\pandas\\core\\internals\\construction.py\", line 135, in arrays_to_mgr\nE       return create_block_manager_from_arrays(\nE     File \"C:\\Users\\alozovsk\\Anaconda3\\envs\\modin\\lib\\site-packages\\pandas\\core\\internals\\managers.py\", line 1773, in create_block_manager_from_arrays\nE       blocks = _form_blocks(arrays, names, axes, consolidate)\nE     File \"C:\\Users\\alozovsk\\Anaconda3\\envs\\modin\\lib\\site-packages\\pandas\\core\\internals\\managers.py\", line 1838, in _form_blocks\nE       numeric_blocks = _multi_blockify(\nE     File \"C:\\Users\\alozovsk\\Anaconda3\\envs\\modin\\lib\\site-packages\\pandas\\core\\internals\\managers.py\", line 1928, in _multi_blockify\nE       values, placement = _stack_arrays(\nE     File \"C:\\Users\\alozovsk\\Anaconda3\\envs\\modin\\lib\\site-packages\\pandas\\core\\internals\\managers.py\", line 1957, in _stack_arrays\nE       stacked = np.empty(shape, dtype=dtype)\nE   TypeError: Cannot interpret 'dtype('int32')' as a data type"
                },
                "teardown": {
                    "name": "teardown",
                    "duration": 0.0005172999999842887,
                    "outcome": "passed"
                },
                "outcome": "failed"
            },
            {
                "name": "modin/pandas/test/dataframe/test_iter.py::test___copy__[int_data]",
                "duration": 2.028866600000015,
                "run_index": 11,
                "setup": {
                    "name": "setup",
                    "duration": 0.0006477999999958683,
                    "outcome": "passed"
                },
                "call": {
                    "name": "call",
                    "duration": 2.0269995000000165,
                    "outcome": "failed",
                    "longrepr": "modin\\pandas\\test\\dataframe\\test_iter.py:146: in test___copy__\n    modin_df = pd.DataFrame(data)\nmodin\\experimental\\cloud\\meta_magic.py:155: in __new__\n    return cls.__real_cls__(*a, **kw)\nmodin\\experimental\\cloud\\rpyc_proxy.py:431: in __init__\n    __remote_end__ = remote_cls(*a, **kw)\nC:\\Users\\alozovsk\\Anaconda3\\envs\\modin\\lib\\site-packages\\rpyc\\core\\netref.py:253: in __call__\n    return syncreq(_self, consts.HANDLE_CALL, args, kwargs)\nC:\\Users\\alozovsk\\Anaconda3\\envs\\modin\\lib\\site-packages\\rpyc\\core\\netref.py:76: in syncreq\n    return conn.sync_request(handler, proxy, *args)\nmodin\\experimental\\cloud\\rpyc_proxy.py:165: in sync_request\n    return super().sync_request(handler, *args)\nC:\\Users\\alozovsk\\Anaconda3\\envs\\modin\\lib\\site-packages\\rpyc\\core\\protocol.py:481: in sync_request\n    return self.async_request(handler, *args, timeout=timeout).value\nC:\\Users\\alozovsk\\Anaconda3\\envs\\modin\\lib\\site-packages\\rpyc\\core\\async_.py:102: in value\n    raise self._obj\nE   _get_exception_class.<locals>.Derived: Cannot interpret 'dtype('int32')' as a data type\nE   \nE   ========= Remote Traceback (1) =========\nE   Traceback (most recent call last):\nE     File \"C:\\Users\\alozovsk\\Anaconda3\\envs\\modin\\lib\\site-packages\\rpyc\\core\\protocol.py\", line 327, in _dispatch_request\nE       res = self._HANDLERS[handler](self, *args)\nE     File \"C:\\Users\\alozovsk\\Anaconda3\\envs\\modin\\lib\\site-packages\\rpyc\\core\\protocol.py\", line 608, in _handle_call\nE       return obj(*args, **dict(kwargs))\nE     File \"C:\\prog\\modin\\modin\\pandas\\dataframe.py\", line 171, in __init__\nE       pandas_df = pandas.DataFrame(\nE     File \"C:\\Users\\alozovsk\\Anaconda3\\envs\\modin\\lib\\site-packages\\pandas\\core\\frame.py\", line 614, in __init__\nE       mgr = dict_to_mgr(data, index, columns, dtype=dtype, copy=copy, typ=manager)\nE     File \"C:\\Users\\alozovsk\\Anaconda3\\envs\\modin\\lib\\site-packages\\pandas\\core\\internals\\construction.py\", line 464, in dict_to_mgr\nE       return arrays_to_mgr(\nE     File \"C:\\Users\\alozovsk\\Anaconda3\\envs\\modin\\lib\\site-packages\\pandas\\core\\internals\\construction.py\", line 135, in arrays_to_mgr\nE       return create_block_manager_from_arrays(\nE     File \"C:\\Users\\alozovsk\\Anaconda3\\envs\\modin\\lib\\site-packages\\pandas\\core\\internals\\managers.py\", line 1773, in create_block_manager_from_arrays\nE       blocks = _form_blocks(arrays, names, axes, consolidate)\nE     File \"C:\\Users\\alozovsk\\Anaconda3\\envs\\modin\\lib\\site-packages\\pandas\\core\\internals\\managers.py\", line 1838, in _form_blocks\nE       numeric_blocks = _multi_blockify(\nE     File \"C:\\Users\\alozovsk\\Anaconda3\\envs\\modin\\lib\\site-packages\\pandas\\core\\internals\\managers.py\", line 1928, in _multi_blockify\nE       values, placement = _stack_arrays(\nE     File \"C:\\Users\\alozovsk\\Anaconda3\\envs\\modin\\lib\\site-packages\\pandas\\core\\internals\\managers.py\", line 1957, in _stack_arrays\nE       stacked = np.empty(shape, dtype=dtype)\nE   TypeError: Cannot interpret 'dtype('int32')' as a data type"
                },
                "teardown": {
                    "name": "teardown",
                    "duration": 0.0005715000000066084,
                    "outcome": "passed"
                },
                "outcome": "failed"
            },
            {
                "name": "modin/pandas/test/dataframe/test_iter.py::test___copy__[float_nan_data]",
                "duration": 64.51016560000002,
                "run_index": 12,
                "setup": {
                    "name": "setup",
                    "duration": 0.0006898000000035154,
                    "outcome": "passed"
                },
                "call": {
                    "name": "call",
                    "duration": 64.50790810000004,
                    "outcome": "passed"
                },
                "teardown": {
                    "name": "teardown",
                    "duration": 0.0008778999999776715,
                    "outcome": "passed"
                },
                "outcome": "passed"
            },
            {
                "name": "modin/pandas/test/dataframe/test_iter.py::test___deepcopy__[int_data]",
                "duration": 2.0635072000000036,
                "run_index": 13,
                "setup": {
                    "name": "setup",
                    "duration": 0.0006516999999917061,
                    "outcome": "passed"
                },
                "call": {
                    "name": "call",
                    "duration": 2.0616211999999905,
                    "outcome": "failed",
                    "longrepr": "modin\\pandas\\test\\dataframe\\test_iter.py:155: in test___deepcopy__\n    modin_df = pd.DataFrame(data)\nmodin\\experimental\\cloud\\meta_magic.py:155: in __new__\n    return cls.__real_cls__(*a, **kw)\nmodin\\experimental\\cloud\\rpyc_proxy.py:431: in __init__\n    __remote_end__ = remote_cls(*a, **kw)\nC:\\Users\\alozovsk\\Anaconda3\\envs\\modin\\lib\\site-packages\\rpyc\\core\\netref.py:253: in __call__\n    return syncreq(_self, consts.HANDLE_CALL, args, kwargs)\nC:\\Users\\alozovsk\\Anaconda3\\envs\\modin\\lib\\site-packages\\rpyc\\core\\netref.py:76: in syncreq\n    return conn.sync_request(handler, proxy, *args)\nmodin\\experimental\\cloud\\rpyc_proxy.py:165: in sync_request\n    return super().sync_request(handler, *args)\nC:\\Users\\alozovsk\\Anaconda3\\envs\\modin\\lib\\site-packages\\rpyc\\core\\protocol.py:481: in sync_request\n    return self.async_request(handler, *args, timeout=timeout).value\nC:\\Users\\alozovsk\\Anaconda3\\envs\\modin\\lib\\site-packages\\rpyc\\core\\async_.py:102: in value\n    raise self._obj\nE   _get_exception_class.<locals>.Derived: Cannot interpret 'dtype('int32')' as a data type\nE   \nE   ========= Remote Traceback (1) =========\nE   Traceback (most recent call last):\nE     File \"C:\\Users\\alozovsk\\Anaconda3\\envs\\modin\\lib\\site-packages\\rpyc\\core\\protocol.py\", line 327, in _dispatch_request\nE       res = self._HANDLERS[handler](self, *args)\nE     File \"C:\\Users\\alozovsk\\Anaconda3\\envs\\modin\\lib\\site-packages\\rpyc\\core\\protocol.py\", line 608, in _handle_call\nE       return obj(*args, **dict(kwargs))\nE     File \"C:\\prog\\modin\\modin\\pandas\\dataframe.py\", line 171, in __init__\nE       pandas_df = pandas.DataFrame(\nE     File \"C:\\Users\\alozovsk\\Anaconda3\\envs\\modin\\lib\\site-packages\\pandas\\core\\frame.py\", line 614, in __init__\nE       mgr = dict_to_mgr(data, index, columns, dtype=dtype, copy=copy, typ=manager)\nE     File \"C:\\Users\\alozovsk\\Anaconda3\\envs\\modin\\lib\\site-packages\\pandas\\core\\internals\\construction.py\", line 464, in dict_to_mgr\nE       return arrays_to_mgr(\nE     File \"C:\\Users\\alozovsk\\Anaconda3\\envs\\modin\\lib\\site-packages\\pandas\\core\\internals\\construction.py\", line 135, in arrays_to_mgr\nE       return create_block_manager_from_arrays(\nE     File \"C:\\Users\\alozovsk\\Anaconda3\\envs\\modin\\lib\\site-packages\\pandas\\core\\internals\\managers.py\", line 1773, in create_block_manager_from_arrays\nE       blocks = _form_blocks(arrays, names, axes, consolidate)\nE     File \"C:\\Users\\alozovsk\\Anaconda3\\envs\\modin\\lib\\site-packages\\pandas\\core\\internals\\managers.py\", line 1838, in _form_blocks\nE       numeric_blocks = _multi_blockify(\nE     File \"C:\\Users\\alozovsk\\Anaconda3\\envs\\modin\\lib\\site-packages\\pandas\\core\\internals\\managers.py\", line 1928, in _multi_blockify\nE       values, placement = _stack_arrays(\nE     File \"C:\\Users\\alozovsk\\Anaconda3\\envs\\modin\\lib\\site-packages\\pandas\\core\\internals\\managers.py\", line 1957, in _stack_arrays\nE       stacked = np.empty(shape, dtype=dtype)\nE   TypeError: Cannot interpret 'dtype('int32')' as a data type"
                },
                "teardown": {
                    "name": "teardown",
                    "duration": 0.0005826000000297427,
                    "outcome": "passed"
                },
                "outcome": "failed"
            },
            {
                "name": "modin/pandas/test/dataframe/test_iter.py::test___deepcopy__[float_nan_data]",
                "duration": 28.6461008,
                "run_index": 14,
                "setup": {
                    "name": "setup",
                    "duration": 0.002010100000006787,
                    "outcome": "passed"
                },
                "call": {
                    "name": "call",
                    "duration": 28.64113930000002,
                    "outcome": "passed"
                },
                "teardown": {
                    "name": "teardown",
                    "duration": 0.0009412999999653948,
                    "outcome": "passed"
                },
                "outcome": "passed"
            },
            {
                "name": "modin/pandas/test/dataframe/test_iter.py::test___repr__",
                "duration": 6.497588500000063,
                "run_index": 15,
                "setup": {
                    "name": "setup",
                    "duration": 0.0005836000000272179,
                    "outcome": "passed"
                },
                "call": {
                    "name": "call",
                    "duration": 6.495935299999985,
                    "outcome": "failed",
                    "longrepr": "modin\\pandas\\test\\dataframe\\test_iter.py:168: in test___repr__\n    modin_df = pd.DataFrame(frame_data)\nmodin\\experimental\\cloud\\meta_magic.py:155: in __new__\n    return cls.__real_cls__(*a, **kw)\nmodin\\experimental\\cloud\\rpyc_proxy.py:431: in __init__\n    __remote_end__ = remote_cls(*a, **kw)\nC:\\Users\\alozovsk\\Anaconda3\\envs\\modin\\lib\\site-packages\\rpyc\\core\\netref.py:253: in __call__\n    return syncreq(_self, consts.HANDLE_CALL, args, kwargs)\nC:\\Users\\alozovsk\\Anaconda3\\envs\\modin\\lib\\site-packages\\rpyc\\core\\netref.py:76: in syncreq\n    return conn.sync_request(handler, proxy, *args)\nmodin\\experimental\\cloud\\rpyc_proxy.py:165: in sync_request\n    return super().sync_request(handler, *args)\nC:\\Users\\alozovsk\\Anaconda3\\envs\\modin\\lib\\site-packages\\rpyc\\core\\protocol.py:481: in sync_request\n    return self.async_request(handler, *args, timeout=timeout).value\nC:\\Users\\alozovsk\\Anaconda3\\envs\\modin\\lib\\site-packages\\rpyc\\core\\async_.py:102: in value\n    raise self._obj\nE   _get_exception_class.<locals>.Derived: Cannot interpret 'dtype('int32')' as a data type\nE   \nE   ========= Remote Traceback (1) =========\nE   Traceback (most recent call last):\nE     File \"C:\\Users\\alozovsk\\Anaconda3\\envs\\modin\\lib\\site-packages\\rpyc\\core\\protocol.py\", line 327, in _dispatch_request\nE       res = self._HANDLERS[handler](self, *args)\nE     File \"C:\\Users\\alozovsk\\Anaconda3\\envs\\modin\\lib\\site-packages\\rpyc\\core\\protocol.py\", line 608, in _handle_call\nE       return obj(*args, **dict(kwargs))\nE     File \"C:\\prog\\modin\\modin\\pandas\\dataframe.py\", line 158, in __init__\nE       data = np.array(values, dtype=old_dtype)\nE   TypeError: Cannot interpret 'dtype('int32')' as a data type"
                },
                "teardown": {
                    "name": "teardown",
                    "duration": 0.00048600000002352317,
                    "outcome": "passed"
                },
                "outcome": "failed"
            },
            {
                "name": "modin/pandas/test/dataframe/test_iter.py::test_inplace_series_ops[int_data]",
                "duration": 3.9600205000000415,
                "run_index": 16,
                "setup": {
                    "name": "setup",
                    "duration": 0.0010642000000302687,
                    "outcome": "passed"
                },
                "call": {
                    "name": "call",
                    "duration": 3.9573495999999864,
                    "outcome": "failed",
                    "longrepr": "modin\\pandas\\test\\dataframe\\test_iter.py:235: in test_inplace_series_ops\n    modin_df = pd.DataFrame(data)\nmodin\\experimental\\cloud\\meta_magic.py:155: in __new__\n    return cls.__real_cls__(*a, **kw)\nmodin\\experimental\\cloud\\rpyc_proxy.py:431: in __init__\n    __remote_end__ = remote_cls(*a, **kw)\nC:\\Users\\alozovsk\\Anaconda3\\envs\\modin\\lib\\site-packages\\rpyc\\core\\netref.py:253: in __call__\n    return syncreq(_self, consts.HANDLE_CALL, args, kwargs)\nC:\\Users\\alozovsk\\Anaconda3\\envs\\modin\\lib\\site-packages\\rpyc\\core\\netref.py:76: in syncreq\n    return conn.sync_request(handler, proxy, *args)\nmodin\\experimental\\cloud\\rpyc_proxy.py:165: in sync_request\n    return super().sync_request(handler, *args)\nC:\\Users\\alozovsk\\Anaconda3\\envs\\modin\\lib\\site-packages\\rpyc\\core\\protocol.py:481: in sync_request\n    return self.async_request(handler, *args, timeout=timeout).value\nC:\\Users\\alozovsk\\Anaconda3\\envs\\modin\\lib\\site-packages\\rpyc\\core\\async_.py:102: in value\n    raise self._obj\nE   _get_exception_class.<locals>.Derived: Cannot interpret 'dtype('int32')' as a data type\nE   \nE   ========= Remote Traceback (1) =========\nE   Traceback (most recent call last):\nE     File \"C:\\Users\\alozovsk\\Anaconda3\\envs\\modin\\lib\\site-packages\\rpyc\\core\\protocol.py\", line 327, in _dispatch_request\nE       res = self._HANDLERS[handler](self, *args)\nE     File \"C:\\Users\\alozovsk\\Anaconda3\\envs\\modin\\lib\\site-packages\\rpyc\\core\\protocol.py\", line 608, in _handle_call\nE       return obj(*args, **dict(kwargs))\nE     File \"C:\\prog\\modin\\modin\\pandas\\dataframe.py\", line 171, in __init__\nE       pandas_df = pandas.DataFrame(\nE     File \"C:\\Users\\alozovsk\\Anaconda3\\envs\\modin\\lib\\site-packages\\pandas\\core\\frame.py\", line 614, in __init__\nE       mgr = dict_to_mgr(data, index, columns, dtype=dtype, copy=copy, typ=manager)\nE     File \"C:\\Users\\alozovsk\\Anaconda3\\envs\\modin\\lib\\site-packages\\pandas\\core\\internals\\construction.py\", line 464, in dict_to_mgr\nE       return arrays_to_mgr(\nE     File \"C:\\Users\\alozovsk\\Anaconda3\\envs\\modin\\lib\\site-packages\\pandas\\core\\internals\\construction.py\", line 135, in arrays_to_mgr\nE       return create_block_manager_from_arrays(\nE     File \"C:\\Users\\alozovsk\\Anaconda3\\envs\\modin\\lib\\site-packages\\pandas\\core\\internals\\managers.py\", line 1773, in create_block_manager_from_arrays\nE       blocks = _form_blocks(arrays, names, axes, consolidate)\nE     File \"C:\\Users\\alozovsk\\Anaconda3\\envs\\modin\\lib\\site-packages\\pandas\\core\\internals\\managers.py\", line 1838, in _form_blocks\nE       numeric_blocks = _multi_blockify(\nE     File \"C:\\Users\\alozovsk\\Anaconda3\\envs\\modin\\lib\\site-packages\\pandas\\core\\internals\\managers.py\", line 1928, in _multi_blockify\nE       values, placement = _stack_arrays(\nE     File \"C:\\Users\\alozovsk\\Anaconda3\\envs\\modin\\lib\\site-packages\\pandas\\core\\internals\\managers.py\", line 1957, in _stack_arrays\nE       stacked = np.empty(shape, dtype=dtype)\nE   TypeError: Cannot interpret 'dtype('int32')' as a data type"
                },
                "teardown": {
                    "name": "teardown",
                    "duration": 0.0005424999999945612,
                    "outcome": "passed"
                },
                "outcome": "failed"
            },
            {
                "name": "modin/pandas/test/dataframe/test_iter.py::test_inplace_series_ops[float_nan_data]",
                "duration": 55.05210880000004,
                "run_index": 17,
                "setup": {
                    "name": "setup",
                    "duration": 0.0009627000000023145,
                    "outcome": "passed"
                },
                "call": {
                    "name": "call",
                    "duration": 55.04956470000002,
                    "outcome": "passed"
                },
                "teardown": {
                    "name": "teardown",
                    "duration": 0.0006187000000181797,
                    "outcome": "passed"
                },
                "outcome": "passed"
            },
            {
                "name": "modin/pandas/test/dataframe/test_iter.py::test___setattr__",
                "duration": 0.033082699999965826,
                "run_index": 18,
                "setup": {
                    "name": "setup",
                    "duration": 0.0005256000000031236,
                    "outcome": "passed"
                },
                "call": {
                    "name": "call",
                    "duration": 0.031457499999987704,
                    "outcome": "passed"
                },
                "teardown": {
                    "name": "teardown",
                    "duration": 0.0005739999999718748,
                    "outcome": "passed"
                },
                "outcome": "passed"
            },
            {
                "name": "modin/pandas/test/dataframe/test_iter.py::test_isin[int_data]",
                "duration": 2.009745100000032,
                "run_index": 19,
                "setup": {
                    "name": "setup",
                    "duration": 0.0006243000000267784,
                    "outcome": "passed"
                },
                "call": {
                    "name": "call",
                    "duration": 2.0079710999999634,
                    "outcome": "failed",
                    "longrepr": "modin\\pandas\\test\\dataframe\\test_iter.py:262: in test_isin\n    modin_df = pd.DataFrame(data)\nmodin\\experimental\\cloud\\meta_magic.py:155: in __new__\n    return cls.__real_cls__(*a, **kw)\nmodin\\experimental\\cloud\\rpyc_proxy.py:431: in __init__\n    __remote_end__ = remote_cls(*a, **kw)\nC:\\Users\\alozovsk\\Anaconda3\\envs\\modin\\lib\\site-packages\\rpyc\\core\\netref.py:253: in __call__\n    return syncreq(_self, consts.HANDLE_CALL, args, kwargs)\nC:\\Users\\alozovsk\\Anaconda3\\envs\\modin\\lib\\site-packages\\rpyc\\core\\netref.py:76: in syncreq\n    return conn.sync_request(handler, proxy, *args)\nmodin\\experimental\\cloud\\rpyc_proxy.py:165: in sync_request\n    return super().sync_request(handler, *args)\nC:\\Users\\alozovsk\\Anaconda3\\envs\\modin\\lib\\site-packages\\rpyc\\core\\protocol.py:481: in sync_request\n    return self.async_request(handler, *args, timeout=timeout).value\nC:\\Users\\alozovsk\\Anaconda3\\envs\\modin\\lib\\site-packages\\rpyc\\core\\async_.py:102: in value\n    raise self._obj\nE   _get_exception_class.<locals>.Derived: Cannot interpret 'dtype('int32')' as a data type\nE   \nE   ========= Remote Traceback (1) =========\nE   Traceback (most recent call last):\nE     File \"C:\\Users\\alozovsk\\Anaconda3\\envs\\modin\\lib\\site-packages\\rpyc\\core\\protocol.py\", line 327, in _dispatch_request\nE       res = self._HANDLERS[handler](self, *args)\nE     File \"C:\\Users\\alozovsk\\Anaconda3\\envs\\modin\\lib\\site-packages\\rpyc\\core\\protocol.py\", line 608, in _handle_call\nE       return obj(*args, **dict(kwargs))\nE     File \"C:\\prog\\modin\\modin\\pandas\\dataframe.py\", line 171, in __init__\nE       pandas_df = pandas.DataFrame(\nE     File \"C:\\Users\\alozovsk\\Anaconda3\\envs\\modin\\lib\\site-packages\\pandas\\core\\frame.py\", line 614, in __init__\nE       mgr = dict_to_mgr(data, index, columns, dtype=dtype, copy=copy, typ=manager)\nE     File \"C:\\Users\\alozovsk\\Anaconda3\\envs\\modin\\lib\\site-packages\\pandas\\core\\internals\\construction.py\", line 464, in dict_to_mgr\nE       return arrays_to_mgr(\nE     File \"C:\\Users\\alozovsk\\Anaconda3\\envs\\modin\\lib\\site-packages\\pandas\\core\\internals\\construction.py\", line 135, in arrays_to_mgr\nE       return create_block_manager_from_arrays(\nE     File \"C:\\Users\\alozovsk\\Anaconda3\\envs\\modin\\lib\\site-packages\\pandas\\core\\internals\\managers.py\", line 1773, in create_block_manager_from_arrays\nE       blocks = _form_blocks(arrays, names, axes, consolidate)\nE     File \"C:\\Users\\alozovsk\\Anaconda3\\envs\\modin\\lib\\site-packages\\pandas\\core\\internals\\managers.py\", line 1838, in _form_blocks\nE       numeric_blocks = _multi_blockify(\nE     File \"C:\\Users\\alozovsk\\Anaconda3\\envs\\modin\\lib\\site-packages\\pandas\\core\\internals\\managers.py\", line 1928, in _multi_blockify\nE       values, placement = _stack_arrays(\nE     File \"C:\\Users\\alozovsk\\Anaconda3\\envs\\modin\\lib\\site-packages\\pandas\\core\\internals\\managers.py\", line 1957, in _stack_arrays\nE       stacked = np.empty(shape, dtype=dtype)\nE   TypeError: Cannot interpret 'dtype('int32')' as a data type"
                },
                "teardown": {
                    "name": "teardown",
                    "duration": 0.0005254000000149972,
                    "outcome": "passed"
                },
                "outcome": "failed"
            },
            {
                "name": "modin/pandas/test/dataframe/test_iter.py::test_isin[float_nan_data]",
                "duration": 94.42716880000006,
                "run_index": 20,
                "setup": {
                    "name": "setup",
                    "duration": 0.0006756000000223139,
                    "outcome": "passed"
                },
                "call": {
                    "name": "call",
                    "duration": 94.42520330000002,
                    "outcome": "passed"
                },
                "teardown": {
                    "name": "teardown",
                    "duration": 0.0006142999999951826,
                    "outcome": "passed"
                },
                "outcome": "passed"
            },
            {
                "name": "modin/pandas/test/dataframe/test_iter.py::test_constructor[int_data]",
                "duration": 1.985218199999963,
                "run_index": 21,
                "setup": {
                    "name": "setup",
                    "duration": 0.0006624999999758074,
                    "outcome": "passed"
                },
                "call": {
                    "name": "call",
                    "duration": 1.9832653999999934,
                    "outcome": "failed",
                    "longrepr": "modin\\pandas\\test\\dataframe\\test_iter.py:274: in test_constructor\n    modin_df = pd.DataFrame(data)\nmodin\\experimental\\cloud\\meta_magic.py:155: in __new__\n    return cls.__real_cls__(*a, **kw)\nmodin\\experimental\\cloud\\rpyc_proxy.py:431: in __init__\n    __remote_end__ = remote_cls(*a, **kw)\nC:\\Users\\alozovsk\\Anaconda3\\envs\\modin\\lib\\site-packages\\rpyc\\core\\netref.py:253: in __call__\n    return syncreq(_self, consts.HANDLE_CALL, args, kwargs)\nC:\\Users\\alozovsk\\Anaconda3\\envs\\modin\\lib\\site-packages\\rpyc\\core\\netref.py:76: in syncreq\n    return conn.sync_request(handler, proxy, *args)\nmodin\\experimental\\cloud\\rpyc_proxy.py:165: in sync_request\n    return super().sync_request(handler, *args)\nC:\\Users\\alozovsk\\Anaconda3\\envs\\modin\\lib\\site-packages\\rpyc\\core\\protocol.py:481: in sync_request\n    return self.async_request(handler, *args, timeout=timeout).value\nC:\\Users\\alozovsk\\Anaconda3\\envs\\modin\\lib\\site-packages\\rpyc\\core\\async_.py:102: in value\n    raise self._obj\nE   _get_exception_class.<locals>.Derived: Cannot interpret 'dtype('int32')' as a data type\nE   \nE   ========= Remote Traceback (1) =========\nE   Traceback (most recent call last):\nE     File \"C:\\Users\\alozovsk\\Anaconda3\\envs\\modin\\lib\\site-packages\\rpyc\\core\\protocol.py\", line 327, in _dispatch_request\nE       res = self._HANDLERS[handler](self, *args)\nE     File \"C:\\Users\\alozovsk\\Anaconda3\\envs\\modin\\lib\\site-packages\\rpyc\\core\\protocol.py\", line 608, in _handle_call\nE       return obj(*args, **dict(kwargs))\nE     File \"C:\\prog\\modin\\modin\\pandas\\dataframe.py\", line 171, in __init__\nE       pandas_df = pandas.DataFrame(\nE     File \"C:\\Users\\alozovsk\\Anaconda3\\envs\\modin\\lib\\site-packages\\pandas\\core\\frame.py\", line 614, in __init__\nE       mgr = dict_to_mgr(data, index, columns, dtype=dtype, copy=copy, typ=manager)\nE     File \"C:\\Users\\alozovsk\\Anaconda3\\envs\\modin\\lib\\site-packages\\pandas\\core\\internals\\construction.py\", line 464, in dict_to_mgr\nE       return arrays_to_mgr(\nE     File \"C:\\Users\\alozovsk\\Anaconda3\\envs\\modin\\lib\\site-packages\\pandas\\core\\internals\\construction.py\", line 135, in arrays_to_mgr\nE       return create_block_manager_from_arrays(\nE     File \"C:\\Users\\alozovsk\\Anaconda3\\envs\\modin\\lib\\site-packages\\pandas\\core\\internals\\managers.py\", line 1773, in create_block_manager_from_arrays\nE       blocks = _form_blocks(arrays, names, axes, consolidate)\nE     File \"C:\\Users\\alozovsk\\Anaconda3\\envs\\modin\\lib\\site-packages\\pandas\\core\\internals\\managers.py\", line 1838, in _form_blocks\nE       numeric_blocks = _multi_blockify(\nE     File \"C:\\Users\\alozovsk\\Anaconda3\\envs\\modin\\lib\\site-packages\\pandas\\core\\internals\\managers.py\", line 1928, in _multi_blockify\nE       values, placement = _stack_arrays(\nE     File \"C:\\Users\\alozovsk\\Anaconda3\\envs\\modin\\lib\\site-packages\\pandas\\core\\internals\\managers.py\", line 1957, in _stack_arrays\nE       stacked = np.empty(shape, dtype=dtype)\nE   TypeError: Cannot interpret 'dtype('int32')' as a data type"
                },
                "teardown": {
                    "name": "teardown",
                    "duration": 0.0006278000000179418,
                    "outcome": "passed"
                },
                "outcome": "failed"
            },
            {
                "name": "modin/pandas/test/dataframe/test_iter.py::test_constructor[float_nan_data]",
                "duration": 57.010242399999925,
                "run_index": 22,
                "setup": {
                    "name": "setup",
                    "duration": 0.0006768000000079155,
                    "outcome": "passed"
                },
                "call": {
                    "name": "call",
                    "duration": 57.00767589999998,
                    "outcome": "passed"
                },
                "teardown": {
                    "name": "teardown",
                    "duration": 0.0012128999999276857,
                    "outcome": "passed"
                },
                "outcome": "passed"
            },
            {
                "name": "modin/pandas/test/dataframe/test_iter.py::test_constructor_dtypes[data0]",
                "duration": 36.89070419999996,
                "run_index": 23,
                "setup": {
                    "name": "setup",
                    "duration": 0.0008023999999977605,
                    "outcome": "passed"
                },
                "call": {
                    "name": "call",
                    "duration": 36.888494599999945,
                    "outcome": "failed",
                    "longrepr": "modin\\pandas\\test\\dataframe\\test_iter.py:295: in test_constructor_dtypes\n    md_df, pd_df = create_test_dfs(data)\nmodin\\pandas\\test\\utils.py:823: in create_test_dfs\n    post_fn, [pd.DataFrame(*args, **kwargs), pandas.DataFrame(*args, **kwargs)]\nmodin\\experimental\\cloud\\meta_magic.py:155: in __new__\n    return cls.__real_cls__(*a, **kw)\nmodin\\experimental\\cloud\\rpyc_proxy.py:431: in __init__\n    __remote_end__ = remote_cls(*a, **kw)\nC:\\Users\\alozovsk\\Anaconda3\\envs\\modin\\lib\\site-packages\\rpyc\\core\\netref.py:253: in __call__\n    return syncreq(_self, consts.HANDLE_CALL, args, kwargs)\nC:\\Users\\alozovsk\\Anaconda3\\envs\\modin\\lib\\site-packages\\rpyc\\core\\netref.py:76: in syncreq\n    return conn.sync_request(handler, proxy, *args)\nmodin\\experimental\\cloud\\rpyc_proxy.py:165: in sync_request\n    return super().sync_request(handler, *args)\nC:\\Users\\alozovsk\\Anaconda3\\envs\\modin\\lib\\site-packages\\rpyc\\core\\protocol.py:481: in sync_request\n    return self.async_request(handler, *args, timeout=timeout).value\nC:\\Users\\alozovsk\\Anaconda3\\envs\\modin\\lib\\site-packages\\rpyc\\core\\async_.py:102: in value\n    raise self._obj\nE   _get_exception_class.<locals>.Derived: Cannot interpret 'dtype('float32')' as a data type\nE   \nE   ========= Remote Traceback (1) =========\nE   Traceback (most recent call last):\nE     File \"C:\\Users\\alozovsk\\Anaconda3\\envs\\modin\\lib\\site-packages\\rpyc\\core\\protocol.py\", line 327, in _dispatch_request\nE       res = self._HANDLERS[handler](self, *args)\nE     File \"C:\\Users\\alozovsk\\Anaconda3\\envs\\modin\\lib\\site-packages\\rpyc\\core\\protocol.py\", line 608, in _handle_call\nE       return obj(*args, **dict(kwargs))\nE     File \"C:\\prog\\modin\\modin\\pandas\\dataframe.py\", line 158, in __init__\nE       data = np.array(values, dtype=old_dtype)\nE   TypeError: Cannot interpret 'dtype('float32')' as a data type"
                },
                "teardown": {
                    "name": "teardown",
                    "duration": 0.0006048000000191678,
                    "outcome": "passed"
                },
                "outcome": "failed"
            },
            {
                "name": "modin/pandas/test/dataframe/test_iter.py::test_constructor_dtypes[data1]",
                "duration": 2.3522957000000133,
                "run_index": 24,
                "setup": {
                    "name": "setup",
                    "duration": 0.0009582999999793174,
                    "outcome": "passed"
                },
                "call": {
                    "name": "call",
                    "duration": 2.349753299999975,
                    "outcome": "failed",
                    "longrepr": "modin\\pandas\\test\\dataframe\\test_iter.py:296: in test_constructor_dtypes\n    df_equals(md_df, pd_df)\nmodin\\pandas\\test\\utils.py:543: in df_equals\n    assert_frame_equal(\nmodin\\conftest.py:93: in wrapper\n    return func(\npandas\\_libs\\testing.pyx:53: in pandas._libs.testing.assert_almost_equal\n    ???\npandas\\_libs\\testing.pyx:168: in pandas._libs.testing.assert_almost_equal\n    ???\nE   AssertionError: DataFrame.iloc[:, 0] (column name=\"0\") are different\nE   \nE   DataFrame.iloc[:, 0] (column name=\"0\") values are different (33.33333 %)\nE   [index]: [0, 1, 2]\nE   [left]:  [1.0, 4.0, nan]\nE   [right]: [1.0, 4.0, 7.0]"
                },
                "teardown": {
                    "name": "teardown",
                    "duration": 0.0006258000000798347,
                    "outcome": "passed"
                },
                "outcome": "failed"
            },
            {
                "name": "modin/pandas/test/dataframe/test_iter.py::test_constructor_dtypes[data2]",
                "duration": 0.046947299999942516,
                "run_index": 25,
                "setup": {
                    "name": "setup",
                    "duration": 0.0006677999999737949,
                    "outcome": "passed"
                },
                "call": {
                    "name": "call",
                    "duration": 0.044946500000037304,
                    "outcome": "passed"
                },
                "teardown": {
                    "name": "teardown",
                    "duration": 0.0006651999999576219,
                    "outcome": "passed"
                },
                "outcome": "passed"
            },
            {
                "name": "modin/pandas/test/dataframe/test_iter.py::test_constructor_columns_and_index",
                "duration": 0.09855160000006435,
                "run_index": 26,
                "setup": {
                    "name": "setup",
                    "duration": 0.000651100000027327,
                    "outcome": "passed"
                },
                "call": {
                    "name": "call",
                    "duration": 0.09462429999996402,
                    "outcome": "failed",
                    "longrepr": "modin\\pandas\\test\\dataframe\\test_iter.py:313: in test_constructor_columns_and_index\n    pd.DataFrame(modin_df, columns=[\"max_speed\", \"health\"]),\nmodin\\experimental\\cloud\\meta_magic.py:155: in __new__\n    return cls.__real_cls__(*a, **kw)\nmodin\\experimental\\cloud\\rpyc_proxy.py:431: in __init__\n    __remote_end__ = remote_cls(*a, **kw)\nC:\\Users\\alozovsk\\Anaconda3\\envs\\modin\\lib\\site-packages\\rpyc\\core\\netref.py:253: in __call__\n    return syncreq(_self, consts.HANDLE_CALL, args, kwargs)\nC:\\Users\\alozovsk\\Anaconda3\\envs\\modin\\lib\\site-packages\\rpyc\\core\\netref.py:76: in syncreq\n    return conn.sync_request(handler, proxy, *args)\nmodin\\experimental\\cloud\\rpyc_proxy.py:165: in sync_request\n    return super().sync_request(handler, *args)\nC:\\Users\\alozovsk\\Anaconda3\\envs\\modin\\lib\\site-packages\\rpyc\\core\\protocol.py:481: in sync_request\n    return self.async_request(handler, *args, timeout=timeout).value\nC:\\Users\\alozovsk\\Anaconda3\\envs\\modin\\lib\\site-packages\\rpyc\\core\\async_.py:102: in value\n    raise self._obj\nE   _get_exception_class.<locals>.Derived: 'list' object is not callable\nE   \nE   ========= Remote Traceback (2) =========\nE   Traceback (most recent call last):\nE     File \"C:\\Users\\alozovsk\\Anaconda3\\envs\\modin\\lib\\site-packages\\rpyc\\core\\protocol.py\", line 327, in _dispatch_request\nE       res = self._HANDLERS[handler](self, *args)\nE     File \"C:\\Users\\alozovsk\\Anaconda3\\envs\\modin\\lib\\site-packages\\rpyc\\core\\protocol.py\", line 608, in _handle_call\nE       return obj(*args, **dict(kwargs))\nE     File \"C:\\prog\\modin\\modin\\pandas\\dataframe.py\", line 140, in __init__\nE       self._query_compiler = data.loc[index, columns]._query_compiler\nE     File \"C:\\prog\\modin\\modin\\pandas\\indexing.py\", line 539, in __getitem__\nE       return self.df.__getitem__(col_loc)\nE     File \"C:\\prog\\modin\\modin\\pandas\\base.py\", line 2923, in __getitem__\nE       return self._getitem(key)\nE     File \"C:\\prog\\modin\\modin\\pandas\\dataframe.py\", line 2941, in _getitem\nE       key = apply_if_callable(key, self)\nE     File \"C:\\Users\\alozovsk\\Anaconda3\\envs\\modin\\lib\\site-packages\\pandas\\core\\common.py\", line 358, in apply_if_callable\nE       return maybe_callable(obj, **kwargs)\nE     File \"C:\\Users\\alozovsk\\Anaconda3\\envs\\modin\\lib\\site-packages\\rpyc\\core\\netref.py\", line 253, in __call__\nE       return syncreq(_self, consts.HANDLE_CALL, args, kwargs)\nE     File \"C:\\Users\\alozovsk\\Anaconda3\\envs\\modin\\lib\\site-packages\\rpyc\\core\\netref.py\", line 76, in syncreq\nE       return conn.sync_request(handler, proxy, *args)\nE     File \"C:\\Users\\alozovsk\\Anaconda3\\envs\\modin\\lib\\site-packages\\rpyc\\core\\protocol.py\", line 481, in sync_request\nE       return self.async_request(handler, *args, timeout=timeout).value\nE     File \"C:\\Users\\alozovsk\\Anaconda3\\envs\\modin\\lib\\site-packages\\rpyc\\core\\async_.py\", line 102, in value\nE       raise self._obj\nE   _get_exception_class.<locals>.Derived: 'list' object is not callable\nE   \nE   ========= Remote Traceback (1) =========\nE   Traceback (most recent call last):\nE     File \"C:\\Users\\alozovsk\\Anaconda3\\envs\\modin\\lib\\site-packages\\rpyc\\core\\protocol.py\", line 327, in _dispatch_request\nE       res = self._HANDLERS[handler](self, *args)\nE     File \"C:\\Users\\alozovsk\\Anaconda3\\envs\\modin\\lib\\site-packages\\rpyc\\core\\protocol.py\", line 608, in _handle_call\nE       return obj(*args, **dict(kwargs))\nE   TypeError: 'list' object is not callable"
                },
                "teardown": {
                    "name": "teardown",
                    "duration": 0.002625100000045677,
                    "outcome": "passed"
                },
                "outcome": "failed"
            }
        ],
        "summary": {
            "passed": 11,
            "failed": 16,
            "num_tests": 27,
            "duration": 600.06147813797
        },
        "created_at": "2021-08-28 10:01:48.334459"
    }
}