{
    "report": {
        "environment": {
            "Python": "3.8.11",
            "Platform": "Windows-10-10.0.19042-SP0"
        },
        "tests": [
            {
                "name": "modin/pandas/test/dataframe/test_iter.py::test_items_iteritems_iterrows[items]",
                "duration": 11.1665914,
                "run_index": 0,
                "setup": {
                    "name": "setup",
                    "duration": 5.5388178,
                    "outcome": "passed"
                },
                "call": {
                    "name": "call",
                    "duration": 0.08792739999999988,
                    "outcome": "failed",
                    "longrepr": "modin\\pandas\\test\\dataframe\\test_iter.py:43: in test_items_iteritems_iterrows\n    modin_df, pandas_df = pd.DataFrame(data), pandas.DataFrame(data)\nmodin\\experimental\\cloud\\meta_magic.py:155: in __new__\n    return cls.__real_cls__(*a, **kw)\nmodin\\experimental\\cloud\\rpyc_proxy.py:432: in __init__\n    a, kw = self._preprocess_init_args(*a, **kw)\nmodin\\experimental\\cloud\\rpyc_proxy.py:639: in _preprocess_init_args\n    (data,) = conn.deliver((data,), {})[0]\nmodin\\experimental\\cloud\\rpyc_proxy.py:81: in deliver\n    remote = iter(self._remote_batch_loads(tuple(pickled)))\nC:\\Users\\alozovsk\\Anaconda3\\envs\\modin\\lib\\site-packages\\rpyc\\core\\netref.py:254: in __call__\n    return syncreq(_self, consts.HANDLE_CALL, args, kwargs)\nC:\\Users\\alozovsk\\Anaconda3\\envs\\modin\\lib\\site-packages\\rpyc\\core\\netref.py:76: in syncreq\n    return conn.sync_request(handler, proxy, *args)\nmodin\\experimental\\cloud\\rpyc_proxy.py:165: in sync_request\n    return super().sync_request(handler, *args)\nC:\\Users\\alozovsk\\Anaconda3\\envs\\modin\\lib\\site-packages\\rpyc\\core\\protocol.py:500: in sync_request\n    return self.async_request(handler, *args, timeout=timeout).value\nC:\\Users\\alozovsk\\Anaconda3\\envs\\modin\\lib\\site-packages\\rpyc\\core\\async_.py:102: in value\n    raise self._obj\nE   _get_exception_class.<locals>.Derived: type object '_DTypeMeta' has no attribute '_abstract'\nE   \nE   ========= Remote Traceback (1) =========\nE   Traceback (most recent call last):\nE     File \"C:\\Users\\alozovsk\\Anaconda3\\envs\\modin\\lib\\site-packages\\rpyc\\core\\protocol.py\", line 338, in _dispatch_request\nE       res = self._HANDLERS[handler](self, *args)\nE     File \"C:\\Users\\alozovsk\\Anaconda3\\envs\\modin\\lib\\site-packages\\rpyc\\core\\protocol.py\", line 630, in _handle_call\nE       return obj(*args, **dict(kwargs))\nE     File \"C:\\prog\\modin\\modin\\experimental\\cloud\\rpyc_proxy.py\", line 34, in _batch_loads\nE       return tuple(pickle.loads(item) for item in items)\nE     File \"C:\\prog\\modin\\modin\\experimental\\cloud\\rpyc_proxy.py\", line 34, in <genexpr>\nE       return tuple(pickle.loads(item) for item in items)\nE   AttributeError: type object '_DTypeMeta' has no attribute '_abstract'"
                },
                "teardown": {
                    "name": "teardown",
                    "duration": 0.0010283999999991522,
                    "outcome": "passed"
                },
                "outcome": "failed"
            },
            {
                "name": "modin/pandas/test/dataframe/test_iter.py::test_items_iteritems_iterrows[iteritems]",
                "duration": 0.0912746000000002,
                "run_index": 1,
                "setup": {
                    "name": "setup",
                    "duration": 0.0012211999999998113,
                    "outcome": "passed"
                },
                "call": {
                    "name": "call",
                    "duration": 0.08812690000000067,
                    "outcome": "failed",
                    "longrepr": "modin\\pandas\\test\\dataframe\\test_iter.py:43: in test_items_iteritems_iterrows\n    modin_df, pandas_df = pd.DataFrame(data), pandas.DataFrame(data)\nmodin\\experimental\\cloud\\meta_magic.py:155: in __new__\n    return cls.__real_cls__(*a, **kw)\nmodin\\experimental\\cloud\\rpyc_proxy.py:432: in __init__\n    a, kw = self._preprocess_init_args(*a, **kw)\nmodin\\experimental\\cloud\\rpyc_proxy.py:639: in _preprocess_init_args\n    (data,) = conn.deliver((data,), {})[0]\nmodin\\experimental\\cloud\\rpyc_proxy.py:81: in deliver\n    remote = iter(self._remote_batch_loads(tuple(pickled)))\nC:\\Users\\alozovsk\\Anaconda3\\envs\\modin\\lib\\site-packages\\rpyc\\core\\netref.py:254: in __call__\n    return syncreq(_self, consts.HANDLE_CALL, args, kwargs)\nC:\\Users\\alozovsk\\Anaconda3\\envs\\modin\\lib\\site-packages\\rpyc\\core\\netref.py:76: in syncreq\n    return conn.sync_request(handler, proxy, *args)\nmodin\\experimental\\cloud\\rpyc_proxy.py:165: in sync_request\n    return super().sync_request(handler, *args)\nC:\\Users\\alozovsk\\Anaconda3\\envs\\modin\\lib\\site-packages\\rpyc\\core\\protocol.py:500: in sync_request\n    return self.async_request(handler, *args, timeout=timeout).value\nC:\\Users\\alozovsk\\Anaconda3\\envs\\modin\\lib\\site-packages\\rpyc\\core\\async_.py:102: in value\n    raise self._obj\nE   _get_exception_class.<locals>.Derived: type object '_DTypeMeta' has no attribute '_abstract'\nE   \nE   ========= Remote Traceback (1) =========\nE   Traceback (most recent call last):\nE     File \"C:\\Users\\alozovsk\\Anaconda3\\envs\\modin\\lib\\site-packages\\rpyc\\core\\protocol.py\", line 338, in _dispatch_request\nE       res = self._HANDLERS[handler](self, *args)\nE     File \"C:\\Users\\alozovsk\\Anaconda3\\envs\\modin\\lib\\site-packages\\rpyc\\core\\protocol.py\", line 630, in _handle_call\nE       return obj(*args, **dict(kwargs))\nE     File \"C:\\prog\\modin\\modin\\experimental\\cloud\\rpyc_proxy.py\", line 34, in _batch_loads\nE       return tuple(pickle.loads(item) for item in items)\nE     File \"C:\\prog\\modin\\modin\\experimental\\cloud\\rpyc_proxy.py\", line 34, in <genexpr>\nE       return tuple(pickle.loads(item) for item in items)\nE   AttributeError: type object '_DTypeMeta' has no attribute '_abstract'"
                },
                "teardown": {
                    "name": "teardown",
                    "duration": 0.0007052999999999088,
                    "outcome": "passed"
                },
                "outcome": "failed"
            },
            {
                "name": "modin/pandas/test/dataframe/test_iter.py::test_items_iteritems_iterrows[iterrows]",
                "duration": 0.09523649999999861,
                "run_index": 2,
                "setup": {
                    "name": "setup",
                    "duration": 0.0013503999999997518,
                    "outcome": "passed"
                },
                "call": {
                    "name": "call",
                    "duration": 0.09197419999999923,
                    "outcome": "failed",
                    "longrepr": "modin\\pandas\\test\\dataframe\\test_iter.py:43: in test_items_iteritems_iterrows\n    modin_df, pandas_df = pd.DataFrame(data), pandas.DataFrame(data)\nmodin\\experimental\\cloud\\meta_magic.py:155: in __new__\n    return cls.__real_cls__(*a, **kw)\nmodin\\experimental\\cloud\\rpyc_proxy.py:432: in __init__\n    a, kw = self._preprocess_init_args(*a, **kw)\nmodin\\experimental\\cloud\\rpyc_proxy.py:639: in _preprocess_init_args\n    (data,) = conn.deliver((data,), {})[0]\nmodin\\experimental\\cloud\\rpyc_proxy.py:81: in deliver\n    remote = iter(self._remote_batch_loads(tuple(pickled)))\nC:\\Users\\alozovsk\\Anaconda3\\envs\\modin\\lib\\site-packages\\rpyc\\core\\netref.py:254: in __call__\n    return syncreq(_self, consts.HANDLE_CALL, args, kwargs)\nC:\\Users\\alozovsk\\Anaconda3\\envs\\modin\\lib\\site-packages\\rpyc\\core\\netref.py:76: in syncreq\n    return conn.sync_request(handler, proxy, *args)\nmodin\\experimental\\cloud\\rpyc_proxy.py:165: in sync_request\n    return super().sync_request(handler, *args)\nC:\\Users\\alozovsk\\Anaconda3\\envs\\modin\\lib\\site-packages\\rpyc\\core\\protocol.py:500: in sync_request\n    return self.async_request(handler, *args, timeout=timeout).value\nC:\\Users\\alozovsk\\Anaconda3\\envs\\modin\\lib\\site-packages\\rpyc\\core\\async_.py:102: in value\n    raise self._obj\nE   _get_exception_class.<locals>.Derived: type object '_DTypeMeta' has no attribute '_abstract'\nE   \nE   ========= Remote Traceback (1) =========\nE   Traceback (most recent call last):\nE     File \"C:\\Users\\alozovsk\\Anaconda3\\envs\\modin\\lib\\site-packages\\rpyc\\core\\protocol.py\", line 338, in _dispatch_request\nE       res = self._HANDLERS[handler](self, *args)\nE     File \"C:\\Users\\alozovsk\\Anaconda3\\envs\\modin\\lib\\site-packages\\rpyc\\core\\protocol.py\", line 630, in _handle_call\nE       return obj(*args, **dict(kwargs))\nE     File \"C:\\prog\\modin\\modin\\experimental\\cloud\\rpyc_proxy.py\", line 34, in _batch_loads\nE       return tuple(pickle.loads(item) for item in items)\nE     File \"C:\\prog\\modin\\modin\\experimental\\cloud\\rpyc_proxy.py\", line 34, in <genexpr>\nE       return tuple(pickle.loads(item) for item in items)\nE   AttributeError: type object '_DTypeMeta' has no attribute '_abstract'"
                },
                "teardown": {
                    "name": "teardown",
                    "duration": 0.0005614999999998815,
                    "outcome": "passed"
                },
                "outcome": "failed"
            },
            {
                "name": "modin/pandas/test/dataframe/test_iter.py::test_itertuples_name[None]",
                "duration": 0.10002019999999945,
                "run_index": 3,
                "setup": {
                    "name": "setup",
                    "duration": 0.00113449999999915,
                    "outcome": "passed"
                },
                "call": {
                    "name": "call",
                    "duration": 0.09691320000000125,
                    "outcome": "failed",
                    "longrepr": "modin\\pandas\\test\\dataframe\\test_iter.py:57: in test_itertuples_name\n    modin_df, pandas_df = pd.DataFrame(data), pandas.DataFrame(data)\nmodin\\experimental\\cloud\\meta_magic.py:155: in __new__\n    return cls.__real_cls__(*a, **kw)\nmodin\\experimental\\cloud\\rpyc_proxy.py:432: in __init__\n    a, kw = self._preprocess_init_args(*a, **kw)\nmodin\\experimental\\cloud\\rpyc_proxy.py:639: in _preprocess_init_args\n    (data,) = conn.deliver((data,), {})[0]\nmodin\\experimental\\cloud\\rpyc_proxy.py:81: in deliver\n    remote = iter(self._remote_batch_loads(tuple(pickled)))\nC:\\Users\\alozovsk\\Anaconda3\\envs\\modin\\lib\\site-packages\\rpyc\\core\\netref.py:254: in __call__\n    return syncreq(_self, consts.HANDLE_CALL, args, kwargs)\nC:\\Users\\alozovsk\\Anaconda3\\envs\\modin\\lib\\site-packages\\rpyc\\core\\netref.py:76: in syncreq\n    return conn.sync_request(handler, proxy, *args)\nmodin\\experimental\\cloud\\rpyc_proxy.py:165: in sync_request\n    return super().sync_request(handler, *args)\nC:\\Users\\alozovsk\\Anaconda3\\envs\\modin\\lib\\site-packages\\rpyc\\core\\protocol.py:500: in sync_request\n    return self.async_request(handler, *args, timeout=timeout).value\nC:\\Users\\alozovsk\\Anaconda3\\envs\\modin\\lib\\site-packages\\rpyc\\core\\async_.py:102: in value\n    raise self._obj\nE   _get_exception_class.<locals>.Derived: type object '_DTypeMeta' has no attribute '_abstract'\nE   \nE   ========= Remote Traceback (1) =========\nE   Traceback (most recent call last):\nE     File \"C:\\Users\\alozovsk\\Anaconda3\\envs\\modin\\lib\\site-packages\\rpyc\\core\\protocol.py\", line 338, in _dispatch_request\nE       res = self._HANDLERS[handler](self, *args)\nE     File \"C:\\Users\\alozovsk\\Anaconda3\\envs\\modin\\lib\\site-packages\\rpyc\\core\\protocol.py\", line 630, in _handle_call\nE       return obj(*args, **dict(kwargs))\nE     File \"C:\\prog\\modin\\modin\\experimental\\cloud\\rpyc_proxy.py\", line 34, in _batch_loads\nE       return tuple(pickle.loads(item) for item in items)\nE     File \"C:\\prog\\modin\\modin\\experimental\\cloud\\rpyc_proxy.py\", line 34, in <genexpr>\nE       return tuple(pickle.loads(item) for item in items)\nE   AttributeError: type object '_DTypeMeta' has no attribute '_abstract'"
                },
                "teardown": {
                    "name": "teardown",
                    "duration": 0.0008379999999998944,
                    "outcome": "passed"
                },
                "outcome": "failed"
            },
            {
                "name": "modin/pandas/test/dataframe/test_iter.py::test_itertuples_name[NotPandas]",
                "duration": 0.12405440000000034,
                "run_index": 4,
                "setup": {
                    "name": "setup",
                    "duration": 0.00392180000000053,
                    "outcome": "passed"
                },
                "call": {
                    "name": "call",
                    "duration": 0.11567819999999962,
                    "outcome": "failed",
                    "longrepr": "modin\\pandas\\test\\dataframe\\test_iter.py:57: in test_itertuples_name\n    modin_df, pandas_df = pd.DataFrame(data), pandas.DataFrame(data)\nmodin\\experimental\\cloud\\meta_magic.py:155: in __new__\n    return cls.__real_cls__(*a, **kw)\nmodin\\experimental\\cloud\\rpyc_proxy.py:432: in __init__\n    a, kw = self._preprocess_init_args(*a, **kw)\nmodin\\experimental\\cloud\\rpyc_proxy.py:639: in _preprocess_init_args\n    (data,) = conn.deliver((data,), {})[0]\nmodin\\experimental\\cloud\\rpyc_proxy.py:81: in deliver\n    remote = iter(self._remote_batch_loads(tuple(pickled)))\nC:\\Users\\alozovsk\\Anaconda3\\envs\\modin\\lib\\site-packages\\rpyc\\core\\netref.py:254: in __call__\n    return syncreq(_self, consts.HANDLE_CALL, args, kwargs)\nC:\\Users\\alozovsk\\Anaconda3\\envs\\modin\\lib\\site-packages\\rpyc\\core\\netref.py:76: in syncreq\n    return conn.sync_request(handler, proxy, *args)\nmodin\\experimental\\cloud\\rpyc_proxy.py:165: in sync_request\n    return super().sync_request(handler, *args)\nC:\\Users\\alozovsk\\Anaconda3\\envs\\modin\\lib\\site-packages\\rpyc\\core\\protocol.py:500: in sync_request\n    return self.async_request(handler, *args, timeout=timeout).value\nC:\\Users\\alozovsk\\Anaconda3\\envs\\modin\\lib\\site-packages\\rpyc\\core\\async_.py:102: in value\n    raise self._obj\nE   _get_exception_class.<locals>.Derived: type object '_DTypeMeta' has no attribute '_abstract'\nE   \nE   ========= Remote Traceback (1) =========\nE   Traceback (most recent call last):\nE     File \"C:\\Users\\alozovsk\\Anaconda3\\envs\\modin\\lib\\site-packages\\rpyc\\core\\protocol.py\", line 338, in _dispatch_request\nE       res = self._HANDLERS[handler](self, *args)\nE     File \"C:\\Users\\alozovsk\\Anaconda3\\envs\\modin\\lib\\site-packages\\rpyc\\core\\protocol.py\", line 630, in _handle_call\nE       return obj(*args, **dict(kwargs))\nE     File \"C:\\prog\\modin\\modin\\experimental\\cloud\\rpyc_proxy.py\", line 34, in _batch_loads\nE       return tuple(pickle.loads(item) for item in items)\nE     File \"C:\\prog\\modin\\modin\\experimental\\cloud\\rpyc_proxy.py\", line 34, in <genexpr>\nE       return tuple(pickle.loads(item) for item in items)\nE   AttributeError: type object '_DTypeMeta' has no attribute '_abstract'"
                },
                "teardown": {
                    "name": "teardown",
                    "duration": 0.0005325999999996611,
                    "outcome": "passed"
                },
                "outcome": "failed"
            },
            {
                "name": "modin/pandas/test/dataframe/test_iter.py::test_itertuples_multiindex",
                "duration": 0.018241100000002675,
                "run_index": 5,
                "setup": {
                    "name": "setup",
                    "duration": 0.0005708000000002045,
                    "outcome": "passed"
                },
                "call": {
                    "name": "call",
                    "duration": 0.01648760000000138,
                    "outcome": "failed",
                    "longrepr": "modin\\pandas\\test\\dataframe\\test_iter.py:67: in test_itertuples_multiindex\n    modin_df, pandas_df = pd.DataFrame(data), pandas.DataFrame(data)\nmodin\\experimental\\cloud\\meta_magic.py:155: in __new__\n    return cls.__real_cls__(*a, **kw)\nmodin\\experimental\\cloud\\rpyc_proxy.py:432: in __init__\n    a, kw = self._preprocess_init_args(*a, **kw)\nmodin\\experimental\\cloud\\rpyc_proxy.py:639: in _preprocess_init_args\n    (data,) = conn.deliver((data,), {})[0]\nmodin\\experimental\\cloud\\rpyc_proxy.py:81: in deliver\n    remote = iter(self._remote_batch_loads(tuple(pickled)))\nC:\\Users\\alozovsk\\Anaconda3\\envs\\modin\\lib\\site-packages\\rpyc\\core\\netref.py:254: in __call__\n    return syncreq(_self, consts.HANDLE_CALL, args, kwargs)\nC:\\Users\\alozovsk\\Anaconda3\\envs\\modin\\lib\\site-packages\\rpyc\\core\\netref.py:76: in syncreq\n    return conn.sync_request(handler, proxy, *args)\nmodin\\experimental\\cloud\\rpyc_proxy.py:165: in sync_request\n    return super().sync_request(handler, *args)\nC:\\Users\\alozovsk\\Anaconda3\\envs\\modin\\lib\\site-packages\\rpyc\\core\\protocol.py:500: in sync_request\n    return self.async_request(handler, *args, timeout=timeout).value\nC:\\Users\\alozovsk\\Anaconda3\\envs\\modin\\lib\\site-packages\\rpyc\\core\\async_.py:102: in value\n    raise self._obj\nE   _get_exception_class.<locals>.Derived: type object '_DTypeMeta' has no attribute '_abstract'\nE   \nE   ========= Remote Traceback (1) =========\nE   Traceback (most recent call last):\nE     File \"C:\\Users\\alozovsk\\Anaconda3\\envs\\modin\\lib\\site-packages\\rpyc\\core\\protocol.py\", line 338, in _dispatch_request\nE       res = self._HANDLERS[handler](self, *args)\nE     File \"C:\\Users\\alozovsk\\Anaconda3\\envs\\modin\\lib\\site-packages\\rpyc\\core\\protocol.py\", line 630, in _handle_call\nE       return obj(*args, **dict(kwargs))\nE     File \"C:\\prog\\modin\\modin\\experimental\\cloud\\rpyc_proxy.py\", line 34, in _batch_loads\nE       return tuple(pickle.loads(item) for item in items)\nE     File \"C:\\prog\\modin\\modin\\experimental\\cloud\\rpyc_proxy.py\", line 34, in <genexpr>\nE       return tuple(pickle.loads(item) for item in items)\nE   AttributeError: type object '_DTypeMeta' has no attribute '_abstract'"
                },
                "teardown": {
                    "name": "teardown",
                    "duration": 0.0006119000000008867,
                    "outcome": "passed"
                },
                "outcome": "failed"
            },
            {
                "name": "modin/pandas/test/dataframe/test_iter.py::test___iter__",
                "duration": 0.01807379999999803,
                "run_index": 6,
                "setup": {
                    "name": "setup",
                    "duration": 0.0005229999999993851,
                    "outcome": "passed"
                },
                "call": {
                    "name": "call",
                    "duration": 0.016234700000000046,
                    "outcome": "failed",
                    "longrepr": "modin\\pandas\\test\\dataframe\\test_iter.py:81: in test___iter__\n    modin_df = pd.DataFrame(test_data_values[0])\nmodin\\experimental\\cloud\\meta_magic.py:155: in __new__\n    return cls.__real_cls__(*a, **kw)\nmodin\\experimental\\cloud\\rpyc_proxy.py:432: in __init__\n    a, kw = self._preprocess_init_args(*a, **kw)\nmodin\\experimental\\cloud\\rpyc_proxy.py:639: in _preprocess_init_args\n    (data,) = conn.deliver((data,), {})[0]\nmodin\\experimental\\cloud\\rpyc_proxy.py:81: in deliver\n    remote = iter(self._remote_batch_loads(tuple(pickled)))\nC:\\Users\\alozovsk\\Anaconda3\\envs\\modin\\lib\\site-packages\\rpyc\\core\\netref.py:254: in __call__\n    return syncreq(_self, consts.HANDLE_CALL, args, kwargs)\nC:\\Users\\alozovsk\\Anaconda3\\envs\\modin\\lib\\site-packages\\rpyc\\core\\netref.py:76: in syncreq\n    return conn.sync_request(handler, proxy, *args)\nmodin\\experimental\\cloud\\rpyc_proxy.py:165: in sync_request\n    return super().sync_request(handler, *args)\nC:\\Users\\alozovsk\\Anaconda3\\envs\\modin\\lib\\site-packages\\rpyc\\core\\protocol.py:500: in sync_request\n    return self.async_request(handler, *args, timeout=timeout).value\nC:\\Users\\alozovsk\\Anaconda3\\envs\\modin\\lib\\site-packages\\rpyc\\core\\async_.py:102: in value\n    raise self._obj\nE   _get_exception_class.<locals>.Derived: type object '_DTypeMeta' has no attribute '_abstract'\nE   \nE   ========= Remote Traceback (1) =========\nE   Traceback (most recent call last):\nE     File \"C:\\Users\\alozovsk\\Anaconda3\\envs\\modin\\lib\\site-packages\\rpyc\\core\\protocol.py\", line 338, in _dispatch_request\nE       res = self._HANDLERS[handler](self, *args)\nE     File \"C:\\Users\\alozovsk\\Anaconda3\\envs\\modin\\lib\\site-packages\\rpyc\\core\\protocol.py\", line 630, in _handle_call\nE       return obj(*args, **dict(kwargs))\nE     File \"C:\\prog\\modin\\modin\\experimental\\cloud\\rpyc_proxy.py\", line 34, in _batch_loads\nE       return tuple(pickle.loads(item) for item in items)\nE     File \"C:\\prog\\modin\\modin\\experimental\\cloud\\rpyc_proxy.py\", line 34, in <genexpr>\nE       return tuple(pickle.loads(item) for item in items)\nE   AttributeError: type object '_DTypeMeta' has no attribute '_abstract'"
                },
                "teardown": {
                    "name": "teardown",
                    "duration": 0.0007930999999992139,
                    "outcome": "passed"
                },
                "outcome": "failed"
            },
            {
                "name": "modin/pandas/test/dataframe/test_iter.py::test___contains__[int_data]",
                "duration": 0.021576799999998286,
                "run_index": 7,
                "setup": {
                    "name": "setup",
                    "duration": 0.0013487999999988176,
                    "outcome": "passed"
                },
                "call": {
                    "name": "call",
                    "duration": 0.01831939999999932,
                    "outcome": "failed",
                    "longrepr": "modin\\pandas\\test\\dataframe\\test_iter.py:96: in test___contains__\n    modin_df = pd.DataFrame(data)\nmodin\\experimental\\cloud\\meta_magic.py:155: in __new__\n    return cls.__real_cls__(*a, **kw)\nmodin\\experimental\\cloud\\rpyc_proxy.py:432: in __init__\n    a, kw = self._preprocess_init_args(*a, **kw)\nmodin\\experimental\\cloud\\rpyc_proxy.py:639: in _preprocess_init_args\n    (data,) = conn.deliver((data,), {})[0]\nmodin\\experimental\\cloud\\rpyc_proxy.py:81: in deliver\n    remote = iter(self._remote_batch_loads(tuple(pickled)))\nC:\\Users\\alozovsk\\Anaconda3\\envs\\modin\\lib\\site-packages\\rpyc\\core\\netref.py:254: in __call__\n    return syncreq(_self, consts.HANDLE_CALL, args, kwargs)\nC:\\Users\\alozovsk\\Anaconda3\\envs\\modin\\lib\\site-packages\\rpyc\\core\\netref.py:76: in syncreq\n    return conn.sync_request(handler, proxy, *args)\nmodin\\experimental\\cloud\\rpyc_proxy.py:165: in sync_request\n    return super().sync_request(handler, *args)\nC:\\Users\\alozovsk\\Anaconda3\\envs\\modin\\lib\\site-packages\\rpyc\\core\\protocol.py:500: in sync_request\n    return self.async_request(handler, *args, timeout=timeout).value\nC:\\Users\\alozovsk\\Anaconda3\\envs\\modin\\lib\\site-packages\\rpyc\\core\\async_.py:102: in value\n    raise self._obj\nE   _get_exception_class.<locals>.Derived: type object '_DTypeMeta' has no attribute '_abstract'\nE   \nE   ========= Remote Traceback (1) =========\nE   Traceback (most recent call last):\nE     File \"C:\\Users\\alozovsk\\Anaconda3\\envs\\modin\\lib\\site-packages\\rpyc\\core\\protocol.py\", line 338, in _dispatch_request\nE       res = self._HANDLERS[handler](self, *args)\nE     File \"C:\\Users\\alozovsk\\Anaconda3\\envs\\modin\\lib\\site-packages\\rpyc\\core\\protocol.py\", line 630, in _handle_call\nE       return obj(*args, **dict(kwargs))\nE     File \"C:\\prog\\modin\\modin\\experimental\\cloud\\rpyc_proxy.py\", line 34, in _batch_loads\nE       return tuple(pickle.loads(item) for item in items)\nE     File \"C:\\prog\\modin\\modin\\experimental\\cloud\\rpyc_proxy.py\", line 34, in <genexpr>\nE       return tuple(pickle.loads(item) for item in items)\nE   AttributeError: type object '_DTypeMeta' has no attribute '_abstract'"
                },
                "teardown": {
                    "name": "teardown",
                    "duration": 0.0005598000000013315,
                    "outcome": "passed"
                },
                "outcome": "failed"
            },
            {
                "name": "modin/pandas/test/dataframe/test_iter.py::test___contains__[float_nan_data]",
                "duration": 0.09932310000000477,
                "run_index": 8,
                "setup": {
                    "name": "setup",
                    "duration": 0.000637800000001576,
                    "outcome": "passed"
                },
                "call": {
                    "name": "call",
                    "duration": 0.09729970000000066,
                    "outcome": "failed",
                    "longrepr": "modin\\pandas\\test\\dataframe\\test_iter.py:96: in test___contains__\n    modin_df = pd.DataFrame(data)\nmodin\\experimental\\cloud\\meta_magic.py:155: in __new__\n    return cls.__real_cls__(*a, **kw)\nmodin\\experimental\\cloud\\rpyc_proxy.py:432: in __init__\n    a, kw = self._preprocess_init_args(*a, **kw)\nmodin\\experimental\\cloud\\rpyc_proxy.py:639: in _preprocess_init_args\n    (data,) = conn.deliver((data,), {})[0]\nmodin\\experimental\\cloud\\rpyc_proxy.py:81: in deliver\n    remote = iter(self._remote_batch_loads(tuple(pickled)))\nC:\\Users\\alozovsk\\Anaconda3\\envs\\modin\\lib\\site-packages\\rpyc\\core\\netref.py:254: in __call__\n    return syncreq(_self, consts.HANDLE_CALL, args, kwargs)\nC:\\Users\\alozovsk\\Anaconda3\\envs\\modin\\lib\\site-packages\\rpyc\\core\\netref.py:76: in syncreq\n    return conn.sync_request(handler, proxy, *args)\nmodin\\experimental\\cloud\\rpyc_proxy.py:165: in sync_request\n    return super().sync_request(handler, *args)\nC:\\Users\\alozovsk\\Anaconda3\\envs\\modin\\lib\\site-packages\\rpyc\\core\\protocol.py:500: in sync_request\n    return self.async_request(handler, *args, timeout=timeout).value\nC:\\Users\\alozovsk\\Anaconda3\\envs\\modin\\lib\\site-packages\\rpyc\\core\\async_.py:102: in value\n    raise self._obj\nE   _get_exception_class.<locals>.Derived: type object '_DTypeMeta' has no attribute '_abstract'\nE   \nE   ========= Remote Traceback (1) =========\nE   Traceback (most recent call last):\nE     File \"C:\\Users\\alozovsk\\Anaconda3\\envs\\modin\\lib\\site-packages\\rpyc\\core\\protocol.py\", line 338, in _dispatch_request\nE       res = self._HANDLERS[handler](self, *args)\nE     File \"C:\\Users\\alozovsk\\Anaconda3\\envs\\modin\\lib\\site-packages\\rpyc\\core\\protocol.py\", line 630, in _handle_call\nE       return obj(*args, **dict(kwargs))\nE     File \"C:\\prog\\modin\\modin\\experimental\\cloud\\rpyc_proxy.py\", line 34, in _batch_loads\nE       return tuple(pickle.loads(item) for item in items)\nE     File \"C:\\prog\\modin\\modin\\experimental\\cloud\\rpyc_proxy.py\", line 34, in <genexpr>\nE       return tuple(pickle.loads(item) for item in items)\nE   AttributeError: type object '_DTypeMeta' has no attribute '_abstract'"
                },
                "teardown": {
                    "name": "teardown",
                    "duration": 0.0007478000000009644,
                    "outcome": "passed"
                },
                "outcome": "failed"
            },
            {
                "name": "modin/pandas/test/dataframe/test_iter.py::test__options_display",
                "duration": 0.035204900000000094,
                "run_index": 9,
                "setup": {
                    "name": "setup",
                    "duration": 0.0005992999999993032,
                    "outcome": "passed"
                },
                "call": {
                    "name": "call",
                    "duration": 0.03346770000000099,
                    "outcome": "failed",
                    "longrepr": "modin\\pandas\\test\\dataframe\\test_iter.py:114: in test__options_display\n    modin_df = pd.DataFrame(frame_data)\nmodin\\experimental\\cloud\\meta_magic.py:155: in __new__\n    return cls.__real_cls__(*a, **kw)\nmodin\\experimental\\cloud\\rpyc_proxy.py:432: in __init__\n    a, kw = self._preprocess_init_args(*a, **kw)\nmodin\\experimental\\cloud\\rpyc_proxy.py:639: in _preprocess_init_args\n    (data,) = conn.deliver((data,), {})[0]\nmodin\\experimental\\cloud\\rpyc_proxy.py:81: in deliver\n    remote = iter(self._remote_batch_loads(tuple(pickled)))\nC:\\Users\\alozovsk\\Anaconda3\\envs\\modin\\lib\\site-packages\\rpyc\\core\\netref.py:254: in __call__\n    return syncreq(_self, consts.HANDLE_CALL, args, kwargs)\nC:\\Users\\alozovsk\\Anaconda3\\envs\\modin\\lib\\site-packages\\rpyc\\core\\netref.py:76: in syncreq\n    return conn.sync_request(handler, proxy, *args)\nmodin\\experimental\\cloud\\rpyc_proxy.py:165: in sync_request\n    return super().sync_request(handler, *args)\nC:\\Users\\alozovsk\\Anaconda3\\envs\\modin\\lib\\site-packages\\rpyc\\core\\protocol.py:500: in sync_request\n    return self.async_request(handler, *args, timeout=timeout).value\nC:\\Users\\alozovsk\\Anaconda3\\envs\\modin\\lib\\site-packages\\rpyc\\core\\async_.py:102: in value\n    raise self._obj\nE   _get_exception_class.<locals>.Derived: type object '_DTypeMeta' has no attribute '_abstract'\nE   \nE   ========= Remote Traceback (1) =========\nE   Traceback (most recent call last):\nE     File \"C:\\Users\\alozovsk\\Anaconda3\\envs\\modin\\lib\\site-packages\\rpyc\\core\\protocol.py\", line 338, in _dispatch_request\nE       res = self._HANDLERS[handler](self, *args)\nE     File \"C:\\Users\\alozovsk\\Anaconda3\\envs\\modin\\lib\\site-packages\\rpyc\\core\\protocol.py\", line 630, in _handle_call\nE       return obj(*args, **dict(kwargs))\nE     File \"C:\\prog\\modin\\modin\\experimental\\cloud\\rpyc_proxy.py\", line 34, in _batch_loads\nE       return tuple(pickle.loads(item) for item in items)\nE     File \"C:\\prog\\modin\\modin\\experimental\\cloud\\rpyc_proxy.py\", line 34, in <genexpr>\nE       return tuple(pickle.loads(item) for item in items)\nE   AttributeError: type object '_DTypeMeta' has no attribute '_abstract'"
                },
                "teardown": {
                    "name": "teardown",
                    "duration": 0.0005386000000004998,
                    "outcome": "passed"
                },
                "outcome": "failed"
            },
            {
                "name": "modin/pandas/test/dataframe/test_iter.py::test___finalize__",
                "duration": 0.02219190000000104,
                "run_index": 10,
                "setup": {
                    "name": "setup",
                    "duration": 0.0010305999999999926,
                    "outcome": "passed"
                },
                "call": {
                    "name": "call",
                    "duration": 0.019650300000000342,
                    "outcome": "failed",
                    "longrepr": "modin\\pandas\\test\\dataframe\\test_iter.py:141: in test___finalize__\n    pd.DataFrame(data).__finalize__(None)\nmodin\\experimental\\cloud\\meta_magic.py:155: in __new__\n    return cls.__real_cls__(*a, **kw)\nmodin\\experimental\\cloud\\rpyc_proxy.py:432: in __init__\n    a, kw = self._preprocess_init_args(*a, **kw)\nmodin\\experimental\\cloud\\rpyc_proxy.py:639: in _preprocess_init_args\n    (data,) = conn.deliver((data,), {})[0]\nmodin\\experimental\\cloud\\rpyc_proxy.py:81: in deliver\n    remote = iter(self._remote_batch_loads(tuple(pickled)))\nC:\\Users\\alozovsk\\Anaconda3\\envs\\modin\\lib\\site-packages\\rpyc\\core\\netref.py:254: in __call__\n    return syncreq(_self, consts.HANDLE_CALL, args, kwargs)\nC:\\Users\\alozovsk\\Anaconda3\\envs\\modin\\lib\\site-packages\\rpyc\\core\\netref.py:76: in syncreq\n    return conn.sync_request(handler, proxy, *args)\nmodin\\experimental\\cloud\\rpyc_proxy.py:165: in sync_request\n    return super().sync_request(handler, *args)\nC:\\Users\\alozovsk\\Anaconda3\\envs\\modin\\lib\\site-packages\\rpyc\\core\\protocol.py:500: in sync_request\n    return self.async_request(handler, *args, timeout=timeout).value\nC:\\Users\\alozovsk\\Anaconda3\\envs\\modin\\lib\\site-packages\\rpyc\\core\\async_.py:102: in value\n    raise self._obj\nE   _get_exception_class.<locals>.Derived: type object '_DTypeMeta' has no attribute '_abstract'\nE   \nE   ========= Remote Traceback (1) =========\nE   Traceback (most recent call last):\nE     File \"C:\\Users\\alozovsk\\Anaconda3\\envs\\modin\\lib\\site-packages\\rpyc\\core\\protocol.py\", line 338, in _dispatch_request\nE       res = self._HANDLERS[handler](self, *args)\nE     File \"C:\\Users\\alozovsk\\Anaconda3\\envs\\modin\\lib\\site-packages\\rpyc\\core\\protocol.py\", line 630, in _handle_call\nE       return obj(*args, **dict(kwargs))\nE     File \"C:\\prog\\modin\\modin\\experimental\\cloud\\rpyc_proxy.py\", line 34, in _batch_loads\nE       return tuple(pickle.loads(item) for item in items)\nE     File \"C:\\prog\\modin\\modin\\experimental\\cloud\\rpyc_proxy.py\", line 34, in <genexpr>\nE       return tuple(pickle.loads(item) for item in items)\nE   AttributeError: type object '_DTypeMeta' has no attribute '_abstract'"
                },
                "teardown": {
                    "name": "teardown",
                    "duration": 0.0004804000000007136,
                    "outcome": "passed"
                },
                "outcome": "failed"
            },
            {
                "name": "modin/pandas/test/dataframe/test_iter.py::test___copy__[int_data]",
                "duration": 0.010939999999999728,
                "run_index": 11,
                "setup": {
                    "name": "setup",
                    "duration": 0.0006465999999996086,
                    "outcome": "passed"
                },
                "call": {
                    "name": "call",
                    "duration": 0.00907630000000026,
                    "outcome": "failed",
                    "longrepr": "modin\\pandas\\test\\dataframe\\test_iter.py:146: in test___copy__\n    modin_df = pd.DataFrame(data)\nmodin\\experimental\\cloud\\meta_magic.py:155: in __new__\n    return cls.__real_cls__(*a, **kw)\nmodin\\experimental\\cloud\\rpyc_proxy.py:432: in __init__\n    a, kw = self._preprocess_init_args(*a, **kw)\nmodin\\experimental\\cloud\\rpyc_proxy.py:639: in _preprocess_init_args\n    (data,) = conn.deliver((data,), {})[0]\nmodin\\experimental\\cloud\\rpyc_proxy.py:81: in deliver\n    remote = iter(self._remote_batch_loads(tuple(pickled)))\nC:\\Users\\alozovsk\\Anaconda3\\envs\\modin\\lib\\site-packages\\rpyc\\core\\netref.py:254: in __call__\n    return syncreq(_self, consts.HANDLE_CALL, args, kwargs)\nC:\\Users\\alozovsk\\Anaconda3\\envs\\modin\\lib\\site-packages\\rpyc\\core\\netref.py:76: in syncreq\n    return conn.sync_request(handler, proxy, *args)\nmodin\\experimental\\cloud\\rpyc_proxy.py:165: in sync_request\n    return super().sync_request(handler, *args)\nC:\\Users\\alozovsk\\Anaconda3\\envs\\modin\\lib\\site-packages\\rpyc\\core\\protocol.py:500: in sync_request\n    return self.async_request(handler, *args, timeout=timeout).value\nC:\\Users\\alozovsk\\Anaconda3\\envs\\modin\\lib\\site-packages\\rpyc\\core\\async_.py:102: in value\n    raise self._obj\nE   _get_exception_class.<locals>.Derived: type object '_DTypeMeta' has no attribute '_abstract'\nE   \nE   ========= Remote Traceback (1) =========\nE   Traceback (most recent call last):\nE     File \"C:\\Users\\alozovsk\\Anaconda3\\envs\\modin\\lib\\site-packages\\rpyc\\core\\protocol.py\", line 338, in _dispatch_request\nE       res = self._HANDLERS[handler](self, *args)\nE     File \"C:\\Users\\alozovsk\\Anaconda3\\envs\\modin\\lib\\site-packages\\rpyc\\core\\protocol.py\", line 630, in _handle_call\nE       return obj(*args, **dict(kwargs))\nE     File \"C:\\prog\\modin\\modin\\experimental\\cloud\\rpyc_proxy.py\", line 34, in _batch_loads\nE       return tuple(pickle.loads(item) for item in items)\nE     File \"C:\\prog\\modin\\modin\\experimental\\cloud\\rpyc_proxy.py\", line 34, in <genexpr>\nE       return tuple(pickle.loads(item) for item in items)\nE   AttributeError: type object '_DTypeMeta' has no attribute '_abstract'"
                },
                "teardown": {
                    "name": "teardown",
                    "duration": 0.0005705000000002514,
                    "outcome": "passed"
                },
                "outcome": "failed"
            },
            {
                "name": "modin/pandas/test/dataframe/test_iter.py::test___copy__[float_nan_data]",
                "duration": 0.09325550000000149,
                "run_index": 12,
                "setup": {
                    "name": "setup",
                    "duration": 0.0009799000000008107,
                    "outcome": "passed"
                },
                "call": {
                    "name": "call",
                    "duration": 0.09075310000000059,
                    "outcome": "failed",
                    "longrepr": "modin\\pandas\\test\\dataframe\\test_iter.py:146: in test___copy__\n    modin_df = pd.DataFrame(data)\nmodin\\experimental\\cloud\\meta_magic.py:155: in __new__\n    return cls.__real_cls__(*a, **kw)\nmodin\\experimental\\cloud\\rpyc_proxy.py:432: in __init__\n    a, kw = self._preprocess_init_args(*a, **kw)\nmodin\\experimental\\cloud\\rpyc_proxy.py:639: in _preprocess_init_args\n    (data,) = conn.deliver((data,), {})[0]\nmodin\\experimental\\cloud\\rpyc_proxy.py:81: in deliver\n    remote = iter(self._remote_batch_loads(tuple(pickled)))\nC:\\Users\\alozovsk\\Anaconda3\\envs\\modin\\lib\\site-packages\\rpyc\\core\\netref.py:254: in __call__\n    return syncreq(_self, consts.HANDLE_CALL, args, kwargs)\nC:\\Users\\alozovsk\\Anaconda3\\envs\\modin\\lib\\site-packages\\rpyc\\core\\netref.py:76: in syncreq\n    return conn.sync_request(handler, proxy, *args)\nmodin\\experimental\\cloud\\rpyc_proxy.py:165: in sync_request\n    return super().sync_request(handler, *args)\nC:\\Users\\alozovsk\\Anaconda3\\envs\\modin\\lib\\site-packages\\rpyc\\core\\protocol.py:500: in sync_request\n    return self.async_request(handler, *args, timeout=timeout).value\nC:\\Users\\alozovsk\\Anaconda3\\envs\\modin\\lib\\site-packages\\rpyc\\core\\async_.py:102: in value\n    raise self._obj\nE   _get_exception_class.<locals>.Derived: type object '_DTypeMeta' has no attribute '_abstract'\nE   \nE   ========= Remote Traceback (1) =========\nE   Traceback (most recent call last):\nE     File \"C:\\Users\\alozovsk\\Anaconda3\\envs\\modin\\lib\\site-packages\\rpyc\\core\\protocol.py\", line 338, in _dispatch_request\nE       res = self._HANDLERS[handler](self, *args)\nE     File \"C:\\Users\\alozovsk\\Anaconda3\\envs\\modin\\lib\\site-packages\\rpyc\\core\\protocol.py\", line 630, in _handle_call\nE       return obj(*args, **dict(kwargs))\nE     File \"C:\\prog\\modin\\modin\\experimental\\cloud\\rpyc_proxy.py\", line 34, in _batch_loads\nE       return tuple(pickle.loads(item) for item in items)\nE     File \"C:\\prog\\modin\\modin\\experimental\\cloud\\rpyc_proxy.py\", line 34, in <genexpr>\nE       return tuple(pickle.loads(item) for item in items)\nE   AttributeError: type object '_DTypeMeta' has no attribute '_abstract'"
                },
                "teardown": {
                    "name": "teardown",
                    "duration": 0.0005425999999992825,
                    "outcome": "passed"
                },
                "outcome": "failed"
            },
            {
                "name": "modin/pandas/test/dataframe/test_iter.py::test___deepcopy__[int_data]",
                "duration": 0.019661900000000898,
                "run_index": 13,
                "setup": {
                    "name": "setup",
                    "duration": 0.0011019000000001,
                    "outcome": "passed"
                },
                "call": {
                    "name": "call",
                    "duration": 0.011678800000000322,
                    "outcome": "failed",
                    "longrepr": "modin\\pandas\\test\\dataframe\\test_iter.py:155: in test___deepcopy__\n    modin_df = pd.DataFrame(data)\nmodin\\experimental\\cloud\\meta_magic.py:155: in __new__\n    return cls.__real_cls__(*a, **kw)\nmodin\\experimental\\cloud\\rpyc_proxy.py:432: in __init__\n    a, kw = self._preprocess_init_args(*a, **kw)\nmodin\\experimental\\cloud\\rpyc_proxy.py:639: in _preprocess_init_args\n    (data,) = conn.deliver((data,), {})[0]\nmodin\\experimental\\cloud\\rpyc_proxy.py:81: in deliver\n    remote = iter(self._remote_batch_loads(tuple(pickled)))\nC:\\Users\\alozovsk\\Anaconda3\\envs\\modin\\lib\\site-packages\\rpyc\\core\\netref.py:254: in __call__\n    return syncreq(_self, consts.HANDLE_CALL, args, kwargs)\nC:\\Users\\alozovsk\\Anaconda3\\envs\\modin\\lib\\site-packages\\rpyc\\core\\netref.py:76: in syncreq\n    return conn.sync_request(handler, proxy, *args)\nmodin\\experimental\\cloud\\rpyc_proxy.py:165: in sync_request\n    return super().sync_request(handler, *args)\nC:\\Users\\alozovsk\\Anaconda3\\envs\\modin\\lib\\site-packages\\rpyc\\core\\protocol.py:500: in sync_request\n    return self.async_request(handler, *args, timeout=timeout).value\nC:\\Users\\alozovsk\\Anaconda3\\envs\\modin\\lib\\site-packages\\rpyc\\core\\async_.py:102: in value\n    raise self._obj\nE   _get_exception_class.<locals>.Derived: type object '_DTypeMeta' has no attribute '_abstract'\nE   \nE   ========= Remote Traceback (1) =========\nE   Traceback (most recent call last):\nE     File \"C:\\Users\\alozovsk\\Anaconda3\\envs\\modin\\lib\\site-packages\\rpyc\\core\\protocol.py\", line 338, in _dispatch_request\nE       res = self._HANDLERS[handler](self, *args)\nE     File \"C:\\Users\\alozovsk\\Anaconda3\\envs\\modin\\lib\\site-packages\\rpyc\\core\\protocol.py\", line 630, in _handle_call\nE       return obj(*args, **dict(kwargs))\nE     File \"C:\\prog\\modin\\modin\\experimental\\cloud\\rpyc_proxy.py\", line 34, in _batch_loads\nE       return tuple(pickle.loads(item) for item in items)\nE     File \"C:\\prog\\modin\\modin\\experimental\\cloud\\rpyc_proxy.py\", line 34, in <genexpr>\nE       return tuple(pickle.loads(item) for item in items)\nE   AttributeError: type object '_DTypeMeta' has no attribute '_abstract'"
                },
                "teardown": {
                    "name": "teardown",
                    "duration": 0.005779300000000376,
                    "outcome": "passed"
                },
                "outcome": "failed"
            },
            {
                "name": "modin/pandas/test/dataframe/test_iter.py::test___deepcopy__[float_nan_data]",
                "duration": 0.10417349999999814,
                "run_index": 14,
                "setup": {
                    "name": "setup",
                    "duration": 0.0020319999999998117,
                    "outcome": "passed"
                },
                "call": {
                    "name": "call",
                    "duration": 0.0993871999999989,
                    "outcome": "failed",
                    "longrepr": "modin\\pandas\\test\\dataframe\\test_iter.py:155: in test___deepcopy__\n    modin_df = pd.DataFrame(data)\nmodin\\experimental\\cloud\\meta_magic.py:155: in __new__\n    return cls.__real_cls__(*a, **kw)\nmodin\\experimental\\cloud\\rpyc_proxy.py:432: in __init__\n    a, kw = self._preprocess_init_args(*a, **kw)\nmodin\\experimental\\cloud\\rpyc_proxy.py:639: in _preprocess_init_args\n    (data,) = conn.deliver((data,), {})[0]\nmodin\\experimental\\cloud\\rpyc_proxy.py:81: in deliver\n    remote = iter(self._remote_batch_loads(tuple(pickled)))\nC:\\Users\\alozovsk\\Anaconda3\\envs\\modin\\lib\\site-packages\\rpyc\\core\\netref.py:254: in __call__\n    return syncreq(_self, consts.HANDLE_CALL, args, kwargs)\nC:\\Users\\alozovsk\\Anaconda3\\envs\\modin\\lib\\site-packages\\rpyc\\core\\netref.py:76: in syncreq\n    return conn.sync_request(handler, proxy, *args)\nmodin\\experimental\\cloud\\rpyc_proxy.py:165: in sync_request\n    return super().sync_request(handler, *args)\nC:\\Users\\alozovsk\\Anaconda3\\envs\\modin\\lib\\site-packages\\rpyc\\core\\protocol.py:500: in sync_request\n    return self.async_request(handler, *args, timeout=timeout).value\nC:\\Users\\alozovsk\\Anaconda3\\envs\\modin\\lib\\site-packages\\rpyc\\core\\async_.py:102: in value\n    raise self._obj\nE   _get_exception_class.<locals>.Derived: type object '_DTypeMeta' has no attribute '_abstract'\nE   \nE   ========= Remote Traceback (1) =========\nE   Traceback (most recent call last):\nE     File \"C:\\Users\\alozovsk\\Anaconda3\\envs\\modin\\lib\\site-packages\\rpyc\\core\\protocol.py\", line 338, in _dispatch_request\nE       res = self._HANDLERS[handler](self, *args)\nE     File \"C:\\Users\\alozovsk\\Anaconda3\\envs\\modin\\lib\\site-packages\\rpyc\\core\\protocol.py\", line 630, in _handle_call\nE       return obj(*args, **dict(kwargs))\nE     File \"C:\\prog\\modin\\modin\\experimental\\cloud\\rpyc_proxy.py\", line 34, in _batch_loads\nE       return tuple(pickle.loads(item) for item in items)\nE     File \"C:\\prog\\modin\\modin\\experimental\\cloud\\rpyc_proxy.py\", line 34, in <genexpr>\nE       return tuple(pickle.loads(item) for item in items)\nE   AttributeError: type object '_DTypeMeta' has no attribute '_abstract'"
                },
                "teardown": {
                    "name": "teardown",
                    "duration": 0.0007222999999996205,
                    "outcome": "passed"
                },
                "outcome": "failed"
            },
            {
                "name": "modin/pandas/test/dataframe/test_iter.py::test___repr__",
                "duration": 0.03704770000000224,
                "run_index": 15,
                "setup": {
                    "name": "setup",
                    "duration": 0.002237900000000792,
                    "outcome": "passed"
                },
                "call": {
                    "name": "call",
                    "duration": 0.032067200000000184,
                    "outcome": "failed",
                    "longrepr": "modin\\pandas\\test\\dataframe\\test_iter.py:168: in test___repr__\n    modin_df = pd.DataFrame(frame_data)\nmodin\\experimental\\cloud\\meta_magic.py:155: in __new__\n    return cls.__real_cls__(*a, **kw)\nmodin\\experimental\\cloud\\rpyc_proxy.py:432: in __init__\n    a, kw = self._preprocess_init_args(*a, **kw)\nmodin\\experimental\\cloud\\rpyc_proxy.py:639: in _preprocess_init_args\n    (data,) = conn.deliver((data,), {})[0]\nmodin\\experimental\\cloud\\rpyc_proxy.py:81: in deliver\n    remote = iter(self._remote_batch_loads(tuple(pickled)))\nC:\\Users\\alozovsk\\Anaconda3\\envs\\modin\\lib\\site-packages\\rpyc\\core\\netref.py:254: in __call__\n    return syncreq(_self, consts.HANDLE_CALL, args, kwargs)\nC:\\Users\\alozovsk\\Anaconda3\\envs\\modin\\lib\\site-packages\\rpyc\\core\\netref.py:76: in syncreq\n    return conn.sync_request(handler, proxy, *args)\nmodin\\experimental\\cloud\\rpyc_proxy.py:165: in sync_request\n    return super().sync_request(handler, *args)\nC:\\Users\\alozovsk\\Anaconda3\\envs\\modin\\lib\\site-packages\\rpyc\\core\\protocol.py:500: in sync_request\n    return self.async_request(handler, *args, timeout=timeout).value\nC:\\Users\\alozovsk\\Anaconda3\\envs\\modin\\lib\\site-packages\\rpyc\\core\\async_.py:102: in value\n    raise self._obj\nE   _get_exception_class.<locals>.Derived: type object '_DTypeMeta' has no attribute '_abstract'\nE   \nE   ========= Remote Traceback (1) =========\nE   Traceback (most recent call last):\nE     File \"C:\\Users\\alozovsk\\Anaconda3\\envs\\modin\\lib\\site-packages\\rpyc\\core\\protocol.py\", line 338, in _dispatch_request\nE       res = self._HANDLERS[handler](self, *args)\nE     File \"C:\\Users\\alozovsk\\Anaconda3\\envs\\modin\\lib\\site-packages\\rpyc\\core\\protocol.py\", line 630, in _handle_call\nE       return obj(*args, **dict(kwargs))\nE     File \"C:\\prog\\modin\\modin\\experimental\\cloud\\rpyc_proxy.py\", line 34, in _batch_loads\nE       return tuple(pickle.loads(item) for item in items)\nE     File \"C:\\prog\\modin\\modin\\experimental\\cloud\\rpyc_proxy.py\", line 34, in <genexpr>\nE       return tuple(pickle.loads(item) for item in items)\nE   AttributeError: type object '_DTypeMeta' has no attribute '_abstract'"
                },
                "teardown": {
                    "name": "teardown",
                    "duration": 0.0005047000000004687,
                    "outcome": "passed"
                },
                "outcome": "failed"
            },
            {
                "name": "modin/pandas/test/dataframe/test_iter.py::test_inplace_series_ops[int_data]",
                "duration": 0.03606200000000115,
                "run_index": 16,
                "setup": {
                    "name": "setup",
                    "duration": 0.0016314000000008377,
                    "outcome": "passed"
                },
                "call": {
                    "name": "call",
                    "duration": 0.030682899999998625,
                    "outcome": "failed",
                    "longrepr": "modin\\pandas\\test\\dataframe\\test_iter.py:235: in test_inplace_series_ops\n    modin_df = pd.DataFrame(data)\nmodin\\experimental\\cloud\\meta_magic.py:155: in __new__\n    return cls.__real_cls__(*a, **kw)\nmodin\\experimental\\cloud\\rpyc_proxy.py:432: in __init__\n    a, kw = self._preprocess_init_args(*a, **kw)\nmodin\\experimental\\cloud\\rpyc_proxy.py:639: in _preprocess_init_args\n    (data,) = conn.deliver((data,), {})[0]\nmodin\\experimental\\cloud\\rpyc_proxy.py:81: in deliver\n    remote = iter(self._remote_batch_loads(tuple(pickled)))\nC:\\Users\\alozovsk\\Anaconda3\\envs\\modin\\lib\\site-packages\\rpyc\\core\\netref.py:254: in __call__\n    return syncreq(_self, consts.HANDLE_CALL, args, kwargs)\nC:\\Users\\alozovsk\\Anaconda3\\envs\\modin\\lib\\site-packages\\rpyc\\core\\netref.py:76: in syncreq\n    return conn.sync_request(handler, proxy, *args)\nmodin\\experimental\\cloud\\rpyc_proxy.py:165: in sync_request\n    return super().sync_request(handler, *args)\nC:\\Users\\alozovsk\\Anaconda3\\envs\\modin\\lib\\site-packages\\rpyc\\core\\protocol.py:500: in sync_request\n    return self.async_request(handler, *args, timeout=timeout).value\nC:\\Users\\alozovsk\\Anaconda3\\envs\\modin\\lib\\site-packages\\rpyc\\core\\async_.py:102: in value\n    raise self._obj\nE   _get_exception_class.<locals>.Derived: type object '_DTypeMeta' has no attribute '_abstract'\nE   \nE   ========= Remote Traceback (1) =========\nE   Traceback (most recent call last):\nE     File \"C:\\Users\\alozovsk\\Anaconda3\\envs\\modin\\lib\\site-packages\\rpyc\\core\\protocol.py\", line 338, in _dispatch_request\nE       res = self._HANDLERS[handler](self, *args)\nE     File \"C:\\Users\\alozovsk\\Anaconda3\\envs\\modin\\lib\\site-packages\\rpyc\\core\\protocol.py\", line 630, in _handle_call\nE       return obj(*args, **dict(kwargs))\nE     File \"C:\\prog\\modin\\modin\\experimental\\cloud\\rpyc_proxy.py\", line 34, in _batch_loads\nE       return tuple(pickle.loads(item) for item in items)\nE     File \"C:\\prog\\modin\\modin\\experimental\\cloud\\rpyc_proxy.py\", line 34, in <genexpr>\nE       return tuple(pickle.loads(item) for item in items)\nE   AttributeError: type object '_DTypeMeta' has no attribute '_abstract'"
                },
                "teardown": {
                    "name": "teardown",
                    "duration": 0.002116300000000848,
                    "outcome": "passed"
                },
                "outcome": "failed"
            },
            {
                "name": "modin/pandas/test/dataframe/test_iter.py::test_inplace_series_ops[float_nan_data]",
                "duration": 0.10999220000000243,
                "run_index": 17,
                "setup": {
                    "name": "setup",
                    "duration": 0.0008893000000007589,
                    "outcome": "passed"
                },
                "call": {
                    "name": "call",
                    "duration": 0.10743470000000066,
                    "outcome": "failed",
                    "longrepr": "modin\\pandas\\test\\dataframe\\test_iter.py:235: in test_inplace_series_ops\n    modin_df = pd.DataFrame(data)\nmodin\\experimental\\cloud\\meta_magic.py:155: in __new__\n    return cls.__real_cls__(*a, **kw)\nmodin\\experimental\\cloud\\rpyc_proxy.py:432: in __init__\n    a, kw = self._preprocess_init_args(*a, **kw)\nmodin\\experimental\\cloud\\rpyc_proxy.py:639: in _preprocess_init_args\n    (data,) = conn.deliver((data,), {})[0]\nmodin\\experimental\\cloud\\rpyc_proxy.py:81: in deliver\n    remote = iter(self._remote_batch_loads(tuple(pickled)))\nC:\\Users\\alozovsk\\Anaconda3\\envs\\modin\\lib\\site-packages\\rpyc\\core\\netref.py:254: in __call__\n    return syncreq(_self, consts.HANDLE_CALL, args, kwargs)\nC:\\Users\\alozovsk\\Anaconda3\\envs\\modin\\lib\\site-packages\\rpyc\\core\\netref.py:76: in syncreq\n    return conn.sync_request(handler, proxy, *args)\nmodin\\experimental\\cloud\\rpyc_proxy.py:165: in sync_request\n    return super().sync_request(handler, *args)\nC:\\Users\\alozovsk\\Anaconda3\\envs\\modin\\lib\\site-packages\\rpyc\\core\\protocol.py:500: in sync_request\n    return self.async_request(handler, *args, timeout=timeout).value\nC:\\Users\\alozovsk\\Anaconda3\\envs\\modin\\lib\\site-packages\\rpyc\\core\\async_.py:102: in value\n    raise self._obj\nE   _get_exception_class.<locals>.Derived: type object '_DTypeMeta' has no attribute '_abstract'\nE   \nE   ========= Remote Traceback (1) =========\nE   Traceback (most recent call last):\nE     File \"C:\\Users\\alozovsk\\Anaconda3\\envs\\modin\\lib\\site-packages\\rpyc\\core\\protocol.py\", line 338, in _dispatch_request\nE       res = self._HANDLERS[handler](self, *args)\nE     File \"C:\\Users\\alozovsk\\Anaconda3\\envs\\modin\\lib\\site-packages\\rpyc\\core\\protocol.py\", line 630, in _handle_call\nE       return obj(*args, **dict(kwargs))\nE     File \"C:\\prog\\modin\\modin\\experimental\\cloud\\rpyc_proxy.py\", line 34, in _batch_loads\nE       return tuple(pickle.loads(item) for item in items)\nE     File \"C:\\prog\\modin\\modin\\experimental\\cloud\\rpyc_proxy.py\", line 34, in <genexpr>\nE       return tuple(pickle.loads(item) for item in items)\nE   AttributeError: type object '_DTypeMeta' has no attribute '_abstract'"
                },
                "teardown": {
                    "name": "teardown",
                    "duration": 0.0007789000000002488,
                    "outcome": "passed"
                },
                "outcome": "failed"
            },
            {
                "name": "modin/pandas/test/dataframe/test_iter.py::test___setattr__",
                "duration": 0.10444229999999699,
                "run_index": 18,
                "setup": {
                    "name": "setup",
                    "duration": 0.0016129999999989764,
                    "outcome": "passed"
                },
                "call": {
                    "name": "call",
                    "duration": 0.10062399999999982,
                    "outcome": "passed"
                },
                "teardown": {
                    "name": "teardown",
                    "duration": 0.0005922999999992129,
                    "outcome": "passed"
                },
                "outcome": "passed"
            },
            {
                "name": "modin/pandas/test/dataframe/test_iter.py::test_isin[int_data]",
                "duration": 0.13659770000000293,
                "run_index": 19,
                "setup": {
                    "name": "setup",
                    "duration": 0.0009156000000007936,
                    "outcome": "passed"
                },
                "call": {
                    "name": "call",
                    "duration": 0.13417570000000012,
                    "outcome": "failed",
                    "longrepr": "modin\\pandas\\test\\dataframe\\test_iter.py:262: in test_isin\n    modin_df = pd.DataFrame(data)\nmodin\\experimental\\cloud\\meta_magic.py:155: in __new__\n    return cls.__real_cls__(*a, **kw)\nmodin\\experimental\\cloud\\rpyc_proxy.py:432: in __init__\n    a, kw = self._preprocess_init_args(*a, **kw)\nmodin\\experimental\\cloud\\rpyc_proxy.py:639: in _preprocess_init_args\n    (data,) = conn.deliver((data,), {})[0]\nmodin\\experimental\\cloud\\rpyc_proxy.py:81: in deliver\n    remote = iter(self._remote_batch_loads(tuple(pickled)))\nC:\\Users\\alozovsk\\Anaconda3\\envs\\modin\\lib\\site-packages\\rpyc\\core\\netref.py:254: in __call__\n    return syncreq(_self, consts.HANDLE_CALL, args, kwargs)\nC:\\Users\\alozovsk\\Anaconda3\\envs\\modin\\lib\\site-packages\\rpyc\\core\\netref.py:76: in syncreq\n    return conn.sync_request(handler, proxy, *args)\nmodin\\experimental\\cloud\\rpyc_proxy.py:165: in sync_request\n    return super().sync_request(handler, *args)\nC:\\Users\\alozovsk\\Anaconda3\\envs\\modin\\lib\\site-packages\\rpyc\\core\\protocol.py:500: in sync_request\n    return self.async_request(handler, *args, timeout=timeout).value\nC:\\Users\\alozovsk\\Anaconda3\\envs\\modin\\lib\\site-packages\\rpyc\\core\\async_.py:102: in value\n    raise self._obj\nE   _get_exception_class.<locals>.Derived: type object 'ndarray' has no attribute '__iter__'\nE   \nE   ========= Remote Traceback (1) =========\nE   Traceback (most recent call last):\nE     File \"C:\\Users\\alozovsk\\Anaconda3\\envs\\modin\\lib\\site-packages\\rpyc\\core\\protocol.py\", line 338, in _dispatch_request\nE       res = self._HANDLERS[handler](self, *args)\nE     File \"C:\\Users\\alozovsk\\Anaconda3\\envs\\modin\\lib\\site-packages\\rpyc\\core\\protocol.py\", line 630, in _handle_call\nE       return obj(*args, **dict(kwargs))\nE     File \"C:\\prog\\modin\\modin\\experimental\\cloud\\rpyc_proxy.py\", line 34, in _batch_loads\nE       return tuple(pickle.loads(item) for item in items)\nE     File \"C:\\prog\\modin\\modin\\experimental\\cloud\\rpyc_proxy.py\", line 34, in <genexpr>\nE       return tuple(pickle.loads(item) for item in items)\nE   AttributeError: type object 'ndarray' has no attribute '__iter__'"
                },
                "teardown": {
                    "name": "teardown",
                    "duration": 0.0005908000000012237,
                    "outcome": "passed"
                },
                "outcome": "failed"
            },
            {
                "name": "modin/pandas/test/dataframe/test_iter.py::test_isin[float_nan_data]",
                "duration": 0.10936700000000066,
                "run_index": 20,
                "setup": {
                    "name": "setup",
                    "duration": 0.0008225999999993405,
                    "outcome": "passed"
                },
                "call": {
                    "name": "call",
                    "duration": 0.10716410000000032,
                    "outcome": "failed",
                    "longrepr": "modin\\pandas\\test\\dataframe\\test_iter.py:262: in test_isin\n    modin_df = pd.DataFrame(data)\nmodin\\experimental\\cloud\\meta_magic.py:155: in __new__\n    return cls.__real_cls__(*a, **kw)\nmodin\\experimental\\cloud\\rpyc_proxy.py:432: in __init__\n    a, kw = self._preprocess_init_args(*a, **kw)\nmodin\\experimental\\cloud\\rpyc_proxy.py:639: in _preprocess_init_args\n    (data,) = conn.deliver((data,), {})[0]\nmodin\\experimental\\cloud\\rpyc_proxy.py:81: in deliver\n    remote = iter(self._remote_batch_loads(tuple(pickled)))\nC:\\Users\\alozovsk\\Anaconda3\\envs\\modin\\lib\\site-packages\\rpyc\\core\\netref.py:254: in __call__\n    return syncreq(_self, consts.HANDLE_CALL, args, kwargs)\nC:\\Users\\alozovsk\\Anaconda3\\envs\\modin\\lib\\site-packages\\rpyc\\core\\netref.py:76: in syncreq\n    return conn.sync_request(handler, proxy, *args)\nmodin\\experimental\\cloud\\rpyc_proxy.py:165: in sync_request\n    return super().sync_request(handler, *args)\nC:\\Users\\alozovsk\\Anaconda3\\envs\\modin\\lib\\site-packages\\rpyc\\core\\protocol.py:500: in sync_request\n    return self.async_request(handler, *args, timeout=timeout).value\nC:\\Users\\alozovsk\\Anaconda3\\envs\\modin\\lib\\site-packages\\rpyc\\core\\async_.py:102: in value\n    raise self._obj\nE   _get_exception_class.<locals>.Derived: type object '_DTypeMeta' has no attribute '_abstract'\nE   \nE   ========= Remote Traceback (1) =========\nE   Traceback (most recent call last):\nE     File \"C:\\Users\\alozovsk\\Anaconda3\\envs\\modin\\lib\\site-packages\\rpyc\\core\\protocol.py\", line 338, in _dispatch_request\nE       res = self._HANDLERS[handler](self, *args)\nE     File \"C:\\Users\\alozovsk\\Anaconda3\\envs\\modin\\lib\\site-packages\\rpyc\\core\\protocol.py\", line 630, in _handle_call\nE       return obj(*args, **dict(kwargs))\nE     File \"C:\\prog\\modin\\modin\\experimental\\cloud\\rpyc_proxy.py\", line 34, in _batch_loads\nE       return tuple(pickle.loads(item) for item in items)\nE     File \"C:\\prog\\modin\\modin\\experimental\\cloud\\rpyc_proxy.py\", line 34, in <genexpr>\nE       return tuple(pickle.loads(item) for item in items)\nE   AttributeError: type object '_DTypeMeta' has no attribute '_abstract'"
                },
                "teardown": {
                    "name": "teardown",
                    "duration": 0.0005577000000016596,
                    "outcome": "passed"
                },
                "outcome": "failed"
            },
            {
                "name": "modin/pandas/test/dataframe/test_iter.py::test_constructor[int_data]",
                "duration": 0.13161899999999704,
                "run_index": 21,
                "setup": {
                    "name": "setup",
                    "duration": 0.0009374999999991473,
                    "outcome": "passed"
                },
                "call": {
                    "name": "call",
                    "duration": 0.12888329999999826,
                    "outcome": "failed",
                    "longrepr": "modin\\pandas\\test\\dataframe\\test_iter.py:274: in test_constructor\n    modin_df = pd.DataFrame(data)\nmodin\\experimental\\cloud\\meta_magic.py:155: in __new__\n    return cls.__real_cls__(*a, **kw)\nmodin\\experimental\\cloud\\rpyc_proxy.py:432: in __init__\n    a, kw = self._preprocess_init_args(*a, **kw)\nmodin\\experimental\\cloud\\rpyc_proxy.py:639: in _preprocess_init_args\n    (data,) = conn.deliver((data,), {})[0]\nmodin\\experimental\\cloud\\rpyc_proxy.py:81: in deliver\n    remote = iter(self._remote_batch_loads(tuple(pickled)))\nC:\\Users\\alozovsk\\Anaconda3\\envs\\modin\\lib\\site-packages\\rpyc\\core\\netref.py:254: in __call__\n    return syncreq(_self, consts.HANDLE_CALL, args, kwargs)\nC:\\Users\\alozovsk\\Anaconda3\\envs\\modin\\lib\\site-packages\\rpyc\\core\\netref.py:76: in syncreq\n    return conn.sync_request(handler, proxy, *args)\nmodin\\experimental\\cloud\\rpyc_proxy.py:165: in sync_request\n    return super().sync_request(handler, *args)\nC:\\Users\\alozovsk\\Anaconda3\\envs\\modin\\lib\\site-packages\\rpyc\\core\\protocol.py:500: in sync_request\n    return self.async_request(handler, *args, timeout=timeout).value\nC:\\Users\\alozovsk\\Anaconda3\\envs\\modin\\lib\\site-packages\\rpyc\\core\\async_.py:102: in value\n    raise self._obj\nE   _get_exception_class.<locals>.Derived: type object 'ndarray' has no attribute '__iter__'\nE   \nE   ========= Remote Traceback (1) =========\nE   Traceback (most recent call last):\nE     File \"C:\\Users\\alozovsk\\Anaconda3\\envs\\modin\\lib\\site-packages\\rpyc\\core\\protocol.py\", line 338, in _dispatch_request\nE       res = self._HANDLERS[handler](self, *args)\nE     File \"C:\\Users\\alozovsk\\Anaconda3\\envs\\modin\\lib\\site-packages\\rpyc\\core\\protocol.py\", line 630, in _handle_call\nE       return obj(*args, **dict(kwargs))\nE     File \"C:\\prog\\modin\\modin\\experimental\\cloud\\rpyc_proxy.py\", line 34, in _batch_loads\nE       return tuple(pickle.loads(item) for item in items)\nE     File \"C:\\prog\\modin\\modin\\experimental\\cloud\\rpyc_proxy.py\", line 34, in <genexpr>\nE       return tuple(pickle.loads(item) for item in items)\nE   AttributeError: type object 'ndarray' has no attribute '__iter__'"
                },
                "teardown": {
                    "name": "teardown",
                    "duration": 0.0008607000000004916,
                    "outcome": "passed"
                },
                "outcome": "failed"
            },
            {
                "name": "modin/pandas/test/dataframe/test_iter.py::test_constructor[float_nan_data]",
                "duration": 0.13750420000000219,
                "run_index": 22,
                "setup": {
                    "name": "setup",
                    "duration": 0.00391480000000044,
                    "outcome": "passed"
                },
                "call": {
                    "name": "call",
                    "duration": 0.12467679999999959,
                    "outcome": "failed",
                    "longrepr": "modin\\pandas\\test\\dataframe\\test_iter.py:274: in test_constructor\n    modin_df = pd.DataFrame(data)\nmodin\\experimental\\cloud\\meta_magic.py:155: in __new__\n    return cls.__real_cls__(*a, **kw)\nmodin\\experimental\\cloud\\rpyc_proxy.py:432: in __init__\n    a, kw = self._preprocess_init_args(*a, **kw)\nmodin\\experimental\\cloud\\rpyc_proxy.py:639: in _preprocess_init_args\n    (data,) = conn.deliver((data,), {})[0]\nmodin\\experimental\\cloud\\rpyc_proxy.py:81: in deliver\n    remote = iter(self._remote_batch_loads(tuple(pickled)))\nC:\\Users\\alozovsk\\Anaconda3\\envs\\modin\\lib\\site-packages\\rpyc\\core\\netref.py:254: in __call__\n    return syncreq(_self, consts.HANDLE_CALL, args, kwargs)\nC:\\Users\\alozovsk\\Anaconda3\\envs\\modin\\lib\\site-packages\\rpyc\\core\\netref.py:76: in syncreq\n    return conn.sync_request(handler, proxy, *args)\nmodin\\experimental\\cloud\\rpyc_proxy.py:165: in sync_request\n    return super().sync_request(handler, *args)\nC:\\Users\\alozovsk\\Anaconda3\\envs\\modin\\lib\\site-packages\\rpyc\\core\\protocol.py:500: in sync_request\n    return self.async_request(handler, *args, timeout=timeout).value\nC:\\Users\\alozovsk\\Anaconda3\\envs\\modin\\lib\\site-packages\\rpyc\\core\\async_.py:102: in value\n    raise self._obj\nE   _get_exception_class.<locals>.Derived: type object '_DTypeMeta' has no attribute '_abstract'\nE   \nE   ========= Remote Traceback (1) =========\nE   Traceback (most recent call last):\nE     File \"C:\\Users\\alozovsk\\Anaconda3\\envs\\modin\\lib\\site-packages\\rpyc\\core\\protocol.py\", line 338, in _dispatch_request\nE       res = self._HANDLERS[handler](self, *args)\nE     File \"C:\\Users\\alozovsk\\Anaconda3\\envs\\modin\\lib\\site-packages\\rpyc\\core\\protocol.py\", line 630, in _handle_call\nE       return obj(*args, **dict(kwargs))\nE     File \"C:\\prog\\modin\\modin\\experimental\\cloud\\rpyc_proxy.py\", line 34, in _batch_loads\nE       return tuple(pickle.loads(item) for item in items)\nE     File \"C:\\prog\\modin\\modin\\experimental\\cloud\\rpyc_proxy.py\", line 34, in <genexpr>\nE       return tuple(pickle.loads(item) for item in items)\nE   AttributeError: type object '_DTypeMeta' has no attribute '_abstract'"
                },
                "teardown": {
                    "name": "teardown",
                    "duration": 0.0049978000000017175,
                    "outcome": "passed"
                },
                "outcome": "failed"
            },
            {
                "name": "modin/pandas/test/dataframe/test_iter.py::test_constructor_dtypes[data0]",
                "duration": 0.025133799999995432,
                "run_index": 23,
                "setup": {
                    "name": "setup",
                    "duration": 0.0011484999999993306,
                    "outcome": "passed"
                },
                "call": {
                    "name": "call",
                    "duration": 0.02231729999999743,
                    "outcome": "failed",
                    "longrepr": "modin\\pandas\\test\\dataframe\\test_iter.py:295: in test_constructor_dtypes\n    md_df, pd_df = create_test_dfs(data)\nmodin\\pandas\\test\\utils.py:824: in create_test_dfs\n    post_fn, [pd.DataFrame(*args, **kwargs), pandas.DataFrame(*args, **kwargs)]\nmodin\\experimental\\cloud\\meta_magic.py:155: in __new__\n    return cls.__real_cls__(*a, **kw)\nmodin\\experimental\\cloud\\rpyc_proxy.py:432: in __init__\n    a, kw = self._preprocess_init_args(*a, **kw)\nmodin\\experimental\\cloud\\rpyc_proxy.py:639: in _preprocess_init_args\n    (data,) = conn.deliver((data,), {})[0]\nmodin\\experimental\\cloud\\rpyc_proxy.py:81: in deliver\n    remote = iter(self._remote_batch_loads(tuple(pickled)))\nC:\\Users\\alozovsk\\Anaconda3\\envs\\modin\\lib\\site-packages\\rpyc\\core\\netref.py:254: in __call__\n    return syncreq(_self, consts.HANDLE_CALL, args, kwargs)\nC:\\Users\\alozovsk\\Anaconda3\\envs\\modin\\lib\\site-packages\\rpyc\\core\\netref.py:76: in syncreq\n    return conn.sync_request(handler, proxy, *args)\nmodin\\experimental\\cloud\\rpyc_proxy.py:165: in sync_request\n    return super().sync_request(handler, *args)\nC:\\Users\\alozovsk\\Anaconda3\\envs\\modin\\lib\\site-packages\\rpyc\\core\\protocol.py:500: in sync_request\n    return self.async_request(handler, *args, timeout=timeout).value\nC:\\Users\\alozovsk\\Anaconda3\\envs\\modin\\lib\\site-packages\\rpyc\\core\\async_.py:102: in value\n    raise self._obj\nE   _get_exception_class.<locals>.Derived: type object 'ndarray' has no attribute '__iter__'\nE   \nE   ========= Remote Traceback (1) =========\nE   Traceback (most recent call last):\nE     File \"C:\\Users\\alozovsk\\Anaconda3\\envs\\modin\\lib\\site-packages\\rpyc\\core\\protocol.py\", line 338, in _dispatch_request\nE       res = self._HANDLERS[handler](self, *args)\nE     File \"C:\\Users\\alozovsk\\Anaconda3\\envs\\modin\\lib\\site-packages\\rpyc\\core\\protocol.py\", line 630, in _handle_call\nE       return obj(*args, **dict(kwargs))\nE     File \"C:\\prog\\modin\\modin\\experimental\\cloud\\rpyc_proxy.py\", line 34, in _batch_loads\nE       return tuple(pickle.loads(item) for item in items)\nE     File \"C:\\prog\\modin\\modin\\experimental\\cloud\\rpyc_proxy.py\", line 34, in <genexpr>\nE       return tuple(pickle.loads(item) for item in items)\nE   AttributeError: type object 'ndarray' has no attribute '__iter__'"
                },
                "teardown": {
                    "name": "teardown",
                    "duration": 0.0005194999999993399,
                    "outcome": "passed"
                },
                "outcome": "failed"
            },
            {
                "name": "modin/pandas/test/dataframe/test_iter.py::test_constructor_dtypes[data1]",
                "duration": 0.04503379999999524,
                "run_index": 24,
                "setup": {
                    "name": "setup",
                    "duration": 0.001326699999999903,
                    "outcome": "passed"
                },
                "call": {
                    "name": "call",
                    "duration": 0.04177259999999805,
                    "outcome": "failed",
                    "longrepr": "modin\\pandas\\test\\dataframe\\test_iter.py:295: in test_constructor_dtypes\n    md_df, pd_df = create_test_dfs(data)\nmodin\\pandas\\test\\utils.py:824: in create_test_dfs\n    post_fn, [pd.DataFrame(*args, **kwargs), pandas.DataFrame(*args, **kwargs)]\nmodin\\experimental\\cloud\\meta_magic.py:155: in __new__\n    return cls.__real_cls__(*a, **kw)\nmodin\\experimental\\cloud\\rpyc_proxy.py:432: in __init__\n    a, kw = self._preprocess_init_args(*a, **kw)\nmodin\\experimental\\cloud\\rpyc_proxy.py:639: in _preprocess_init_args\n    (data,) = conn.deliver((data,), {})[0]\nmodin\\experimental\\cloud\\rpyc_proxy.py:81: in deliver\n    remote = iter(self._remote_batch_loads(tuple(pickled)))\nC:\\Users\\alozovsk\\Anaconda3\\envs\\modin\\lib\\site-packages\\rpyc\\core\\netref.py:254: in __call__\n    return syncreq(_self, consts.HANDLE_CALL, args, kwargs)\nC:\\Users\\alozovsk\\Anaconda3\\envs\\modin\\lib\\site-packages\\rpyc\\core\\netref.py:76: in syncreq\n    return conn.sync_request(handler, proxy, *args)\nmodin\\experimental\\cloud\\rpyc_proxy.py:165: in sync_request\n    return super().sync_request(handler, *args)\nC:\\Users\\alozovsk\\Anaconda3\\envs\\modin\\lib\\site-packages\\rpyc\\core\\protocol.py:500: in sync_request\n    return self.async_request(handler, *args, timeout=timeout).value\nC:\\Users\\alozovsk\\Anaconda3\\envs\\modin\\lib\\site-packages\\rpyc\\core\\async_.py:102: in value\n    raise self._obj\nE   _get_exception_class.<locals>.Derived: type object 'ndarray' has no attribute '__iter__'\nE   \nE   ========= Remote Traceback (1) =========\nE   Traceback (most recent call last):\nE     File \"C:\\Users\\alozovsk\\Anaconda3\\envs\\modin\\lib\\site-packages\\rpyc\\core\\protocol.py\", line 338, in _dispatch_request\nE       res = self._HANDLERS[handler](self, *args)\nE     File \"C:\\Users\\alozovsk\\Anaconda3\\envs\\modin\\lib\\site-packages\\rpyc\\core\\protocol.py\", line 630, in _handle_call\nE       return obj(*args, **dict(kwargs))\nE     File \"C:\\prog\\modin\\modin\\experimental\\cloud\\rpyc_proxy.py\", line 34, in _batch_loads\nE       return tuple(pickle.loads(item) for item in items)\nE     File \"C:\\prog\\modin\\modin\\experimental\\cloud\\rpyc_proxy.py\", line 34, in <genexpr>\nE       return tuple(pickle.loads(item) for item in items)\nE   AttributeError: type object 'ndarray' has no attribute '__iter__'"
                },
                "teardown": {
                    "name": "teardown",
                    "duration": 0.0006077999999973827,
                    "outcome": "passed"
                },
                "outcome": "failed"
            },
            {
                "name": "modin/pandas/test/dataframe/test_iter.py::test_constructor_dtypes[data2]",
                "duration": 0.025454900000003278,
                "run_index": 25,
                "setup": {
                    "name": "setup",
                    "duration": 0.0009903000000015538,
                    "outcome": "passed"
                },
                "call": {
                    "name": "call",
                    "duration": 0.022968699999999842,
                    "outcome": "failed",
                    "longrepr": "modin\\pandas\\test\\dataframe\\test_iter.py:295: in test_constructor_dtypes\n    md_df, pd_df = create_test_dfs(data)\nmodin\\pandas\\test\\utils.py:824: in create_test_dfs\n    post_fn, [pd.DataFrame(*args, **kwargs), pandas.DataFrame(*args, **kwargs)]\nmodin\\experimental\\cloud\\meta_magic.py:155: in __new__\n    return cls.__real_cls__(*a, **kw)\nmodin\\experimental\\cloud\\rpyc_proxy.py:432: in __init__\n    a, kw = self._preprocess_init_args(*a, **kw)\nmodin\\experimental\\cloud\\rpyc_proxy.py:639: in _preprocess_init_args\n    (data,) = conn.deliver((data,), {})[0]\nmodin\\experimental\\cloud\\rpyc_proxy.py:81: in deliver\n    remote = iter(self._remote_batch_loads(tuple(pickled)))\nC:\\Users\\alozovsk\\Anaconda3\\envs\\modin\\lib\\site-packages\\rpyc\\core\\netref.py:254: in __call__\n    return syncreq(_self, consts.HANDLE_CALL, args, kwargs)\nC:\\Users\\alozovsk\\Anaconda3\\envs\\modin\\lib\\site-packages\\rpyc\\core\\netref.py:76: in syncreq\n    return conn.sync_request(handler, proxy, *args)\nmodin\\experimental\\cloud\\rpyc_proxy.py:165: in sync_request\n    return super().sync_request(handler, *args)\nC:\\Users\\alozovsk\\Anaconda3\\envs\\modin\\lib\\site-packages\\rpyc\\core\\protocol.py:500: in sync_request\n    return self.async_request(handler, *args, timeout=timeout).value\nC:\\Users\\alozovsk\\Anaconda3\\envs\\modin\\lib\\site-packages\\rpyc\\core\\async_.py:102: in value\n    raise self._obj\nE   _get_exception_class.<locals>.Derived: type object 'ndarray' has no attribute '__iter__'\nE   \nE   ========= Remote Traceback (1) =========\nE   Traceback (most recent call last):\nE     File \"C:\\Users\\alozovsk\\Anaconda3\\envs\\modin\\lib\\site-packages\\rpyc\\core\\protocol.py\", line 338, in _dispatch_request\nE       res = self._HANDLERS[handler](self, *args)\nE     File \"C:\\Users\\alozovsk\\Anaconda3\\envs\\modin\\lib\\site-packages\\rpyc\\core\\protocol.py\", line 630, in _handle_call\nE       return obj(*args, **dict(kwargs))\nE     File \"C:\\prog\\modin\\modin\\experimental\\cloud\\rpyc_proxy.py\", line 34, in _batch_loads\nE       return tuple(pickle.loads(item) for item in items)\nE     File \"C:\\prog\\modin\\modin\\experimental\\cloud\\rpyc_proxy.py\", line 34, in <genexpr>\nE       return tuple(pickle.loads(item) for item in items)\nE   AttributeError: type object 'ndarray' has no attribute '__iter__'"
                },
                "teardown": {
                    "name": "teardown",
                    "duration": 0.000505600000000328,
                    "outcome": "passed"
                },
                "outcome": "failed"
            },
            {
                "name": "modin/pandas/test/dataframe/test_iter.py::test_constructor_columns_and_index",
                "duration": 0.08438990000000501,
                "run_index": 26,
                "setup": {
                    "name": "setup",
                    "duration": 0.0004924000000023909,
                    "outcome": "passed"
                },
                "call": {
                    "name": "call",
                    "duration": 0.07993659999999991,
                    "outcome": "failed",
                    "longrepr": "modin\\pandas\\test\\dataframe\\test_iter.py:313: in test_constructor_columns_and_index\n    pd.DataFrame(modin_df, columns=[\"max_speed\", \"health\"]),\nmodin\\experimental\\cloud\\meta_magic.py:155: in __new__\n    return cls.__real_cls__(*a, **kw)\nmodin\\experimental\\cloud\\rpyc_proxy.py:434: in __init__\n    __remote_end__ = remote_cls(*a, **kw)\nC:\\Users\\alozovsk\\Anaconda3\\envs\\modin\\lib\\site-packages\\rpyc\\core\\netref.py:254: in __call__\n    return syncreq(_self, consts.HANDLE_CALL, args, kwargs)\nC:\\Users\\alozovsk\\Anaconda3\\envs\\modin\\lib\\site-packages\\rpyc\\core\\netref.py:76: in syncreq\n    return conn.sync_request(handler, proxy, *args)\nmodin\\experimental\\cloud\\rpyc_proxy.py:165: in sync_request\n    return super().sync_request(handler, *args)\nC:\\Users\\alozovsk\\Anaconda3\\envs\\modin\\lib\\site-packages\\rpyc\\core\\protocol.py:500: in sync_request\n    return self.async_request(handler, *args, timeout=timeout).value\nC:\\Users\\alozovsk\\Anaconda3\\envs\\modin\\lib\\site-packages\\rpyc\\core\\async_.py:102: in value\n    raise self._obj\nE   _get_exception_class.<locals>.Derived: 'list' object is not callable\nE   \nE   ========= Remote Traceback (2) =========\nE   Traceback (most recent call last):\nE     File \"C:\\Users\\alozovsk\\Anaconda3\\envs\\modin\\lib\\site-packages\\rpyc\\core\\protocol.py\", line 338, in _dispatch_request\nE       res = self._HANDLERS[handler](self, *args)\nE     File \"C:\\Users\\alozovsk\\Anaconda3\\envs\\modin\\lib\\site-packages\\rpyc\\core\\protocol.py\", line 630, in _handle_call\nE       return obj(*args, **dict(kwargs))\nE     File \"C:\\prog\\modin\\modin\\pandas\\dataframe.py\", line 141, in __init__\nE       self._query_compiler = data.loc[index, columns]._query_compiler\nE     File \"C:\\prog\\modin\\modin\\pandas\\indexing.py\", line 539, in __getitem__\nE       row_loc, col_loc, ndim = self._parse_row_and_column_locators(key)\nE     File \"C:\\prog\\modin\\modin\\pandas\\indexing.py\", line 505, in _parse_row_and_column_locators\nE       col_loc = col_loc(self.df) if callable(col_loc) else col_loc\nE     File \"C:\\Users\\alozovsk\\Anaconda3\\envs\\modin\\lib\\site-packages\\rpyc\\core\\netref.py\", line 254, in __call__\nE       return syncreq(_self, consts.HANDLE_CALL, args, kwargs)\nE     File \"C:\\Users\\alozovsk\\Anaconda3\\envs\\modin\\lib\\site-packages\\rpyc\\core\\netref.py\", line 76, in syncreq\nE       return conn.sync_request(handler, proxy, *args)\nE     File \"C:\\Users\\alozovsk\\Anaconda3\\envs\\modin\\lib\\site-packages\\rpyc\\core\\protocol.py\", line 500, in sync_request\nE       return self.async_request(handler, *args, timeout=timeout).value\nE     File \"C:\\Users\\alozovsk\\Anaconda3\\envs\\modin\\lib\\site-packages\\rpyc\\core\\async_.py\", line 102, in value\nE       raise self._obj\nE   _get_exception_class.<locals>.Derived: 'list' object is not callable\nE   \nE   ========= Remote Traceback (1) =========\nE   Traceback (most recent call last):\nE     File \"C:\\Users\\alozovsk\\Anaconda3\\envs\\modin\\lib\\site-packages\\rpyc\\core\\protocol.py\", line 338, in _dispatch_request\nE       res = self._HANDLERS[handler](self, *args)\nE     File \"C:\\Users\\alozovsk\\Anaconda3\\envs\\modin\\lib\\site-packages\\rpyc\\core\\protocol.py\", line 630, in _handle_call\nE       return obj(*args, **dict(kwargs))\nE   TypeError: 'list' object is not callable"
                },
                "teardown": {
                    "name": "teardown",
                    "duration": 0.0034685000000003186,
                    "outcome": "passed"
                },
                "outcome": "failed"
            }
        ],
        "summary": {
            "failed": 26,
            "passed": 1,
            "num_tests": 27,
            "duration": 16.668325185775757
        },
        "created_at": "2021-11-27 20:32:36.367304"
    }
}