{
    "report": {
        "environment": {
            "Python": "3.8.11",
            "Platform": "Windows-10-10.0.19042-SP0"
        },
        "tests": [
            {
                "name": "modin/pandas/test/dataframe/test_iter.py::test_items_iteritems_iterrows[items]",
                "duration": 10.8231428,
                "run_index": 0,
                "setup": {
                    "name": "setup",
                    "duration": 5.3672743,
                    "outcome": "passed"
                },
                "call": {
                    "name": "call",
                    "duration": 0.08780199999999994,
                    "outcome": "failed",
                    "longrepr": "modin\\pandas\\test\\dataframe\\test_iter.py:43: in test_items_iteritems_iterrows\n    modin_df, pandas_df = pd.DataFrame(data), pandas.DataFrame(data)\nmodin\\experimental\\cloud\\meta_magic.py:155: in __new__\n    return cls.__real_cls__(*a, **kw)\nmodin\\experimental\\cloud\\rpyc_proxy.py:436: in __init__\n    a, kw = preprocess(*a, **kw)\nmodin\\experimental\\cloud\\rpyc_proxy.py:643: in _preprocess_init_args\n    (data,) = conn.deliver((data,), {})[0]\nmodin\\experimental\\cloud\\rpyc_proxy.py:81: in deliver\n    remote = iter(self._remote_batch_loads(tuple(pickled)))\nC:\\Users\\alozovsk\\Anaconda3\\envs\\modin\\lib\\site-packages\\rpyc\\core\\netref.py:254: in __call__\n    return syncreq(_self, consts.HANDLE_CALL, args, kwargs)\nC:\\Users\\alozovsk\\Anaconda3\\envs\\modin\\lib\\site-packages\\rpyc\\core\\netref.py:76: in syncreq\n    return conn.sync_request(handler, proxy, *args)\nmodin\\experimental\\cloud\\rpyc_proxy.py:165: in sync_request\n    return super().sync_request(handler, *args)\nC:\\Users\\alozovsk\\Anaconda3\\envs\\modin\\lib\\site-packages\\rpyc\\core\\protocol.py:500: in sync_request\n    return self.async_request(handler, *args, timeout=timeout).value\nC:\\Users\\alozovsk\\Anaconda3\\envs\\modin\\lib\\site-packages\\rpyc\\core\\async_.py:102: in value\n    raise self._obj\nE   _get_exception_class.<locals>.Derived: type object '_DTypeMeta' has no attribute '_abstract'\nE   \nE   ========= Remote Traceback (1) =========\nE   Traceback (most recent call last):\nE     File \"C:\\Users\\alozovsk\\Anaconda3\\envs\\modin\\lib\\site-packages\\rpyc\\core\\protocol.py\", line 338, in _dispatch_request\nE       res = self._HANDLERS[handler](self, *args)\nE     File \"C:\\Users\\alozovsk\\Anaconda3\\envs\\modin\\lib\\site-packages\\rpyc\\core\\protocol.py\", line 630, in _handle_call\nE       return obj(*args, **dict(kwargs))\nE     File \"C:\\prog\\modin\\modin\\experimental\\cloud\\rpyc_proxy.py\", line 34, in _batch_loads\nE       return tuple(pickle.loads(item) for item in items)\nE     File \"C:\\prog\\modin\\modin\\experimental\\cloud\\rpyc_proxy.py\", line 34, in <genexpr>\nE       return tuple(pickle.loads(item) for item in items)\nE   AttributeError: type object '_DTypeMeta' has no attribute '_abstract'"
                },
                "teardown": {
                    "name": "teardown",
                    "duration": 0.0007921999999993545,
                    "outcome": "passed"
                },
                "outcome": "failed"
            },
            {
                "name": "modin/pandas/test/dataframe/test_iter.py::test_items_iteritems_iterrows[iteritems]",
                "duration": 0.0692239999999984,
                "run_index": 1,
                "setup": {
                    "name": "setup",
                    "duration": 0.000574699999999595,
                    "outcome": "passed"
                },
                "call": {
                    "name": "call",
                    "duration": 0.06753430000000016,
                    "outcome": "failed",
                    "longrepr": "modin\\pandas\\test\\dataframe\\test_iter.py:43: in test_items_iteritems_iterrows\n    modin_df, pandas_df = pd.DataFrame(data), pandas.DataFrame(data)\nmodin\\experimental\\cloud\\meta_magic.py:155: in __new__\n    return cls.__real_cls__(*a, **kw)\nmodin\\experimental\\cloud\\rpyc_proxy.py:436: in __init__\n    a, kw = preprocess(*a, **kw)\nmodin\\experimental\\cloud\\rpyc_proxy.py:643: in _preprocess_init_args\n    (data,) = conn.deliver((data,), {})[0]\nmodin\\experimental\\cloud\\rpyc_proxy.py:81: in deliver\n    remote = iter(self._remote_batch_loads(tuple(pickled)))\nC:\\Users\\alozovsk\\Anaconda3\\envs\\modin\\lib\\site-packages\\rpyc\\core\\netref.py:254: in __call__\n    return syncreq(_self, consts.HANDLE_CALL, args, kwargs)\nC:\\Users\\alozovsk\\Anaconda3\\envs\\modin\\lib\\site-packages\\rpyc\\core\\netref.py:76: in syncreq\n    return conn.sync_request(handler, proxy, *args)\nmodin\\experimental\\cloud\\rpyc_proxy.py:165: in sync_request\n    return super().sync_request(handler, *args)\nC:\\Users\\alozovsk\\Anaconda3\\envs\\modin\\lib\\site-packages\\rpyc\\core\\protocol.py:500: in sync_request\n    return self.async_request(handler, *args, timeout=timeout).value\nC:\\Users\\alozovsk\\Anaconda3\\envs\\modin\\lib\\site-packages\\rpyc\\core\\async_.py:102: in value\n    raise self._obj\nE   _get_exception_class.<locals>.Derived: type object '_DTypeMeta' has no attribute '_abstract'\nE   \nE   ========= Remote Traceback (1) =========\nE   Traceback (most recent call last):\nE     File \"C:\\Users\\alozovsk\\Anaconda3\\envs\\modin\\lib\\site-packages\\rpyc\\core\\protocol.py\", line 338, in _dispatch_request\nE       res = self._HANDLERS[handler](self, *args)\nE     File \"C:\\Users\\alozovsk\\Anaconda3\\envs\\modin\\lib\\site-packages\\rpyc\\core\\protocol.py\", line 630, in _handle_call\nE       return obj(*args, **dict(kwargs))\nE     File \"C:\\prog\\modin\\modin\\experimental\\cloud\\rpyc_proxy.py\", line 34, in _batch_loads\nE       return tuple(pickle.loads(item) for item in items)\nE     File \"C:\\prog\\modin\\modin\\experimental\\cloud\\rpyc_proxy.py\", line 34, in <genexpr>\nE       return tuple(pickle.loads(item) for item in items)\nE   AttributeError: type object '_DTypeMeta' has no attribute '_abstract'"
                },
                "teardown": {
                    "name": "teardown",
                    "duration": 0.0005402999999990499,
                    "outcome": "passed"
                },
                "outcome": "failed"
            },
            {
                "name": "modin/pandas/test/dataframe/test_iter.py::test_items_iteritems_iterrows[iterrows]",
                "duration": 0.06932919999999854,
                "run_index": 2,
                "setup": {
                    "name": "setup",
                    "duration": 0.0006083999999990652,
                    "outcome": "passed"
                },
                "call": {
                    "name": "call",
                    "duration": 0.06740300000000055,
                    "outcome": "failed",
                    "longrepr": "modin\\pandas\\test\\dataframe\\test_iter.py:43: in test_items_iteritems_iterrows\n    modin_df, pandas_df = pd.DataFrame(data), pandas.DataFrame(data)\nmodin\\experimental\\cloud\\meta_magic.py:155: in __new__\n    return cls.__real_cls__(*a, **kw)\nmodin\\experimental\\cloud\\rpyc_proxy.py:436: in __init__\n    a, kw = preprocess(*a, **kw)\nmodin\\experimental\\cloud\\rpyc_proxy.py:643: in _preprocess_init_args\n    (data,) = conn.deliver((data,), {})[0]\nmodin\\experimental\\cloud\\rpyc_proxy.py:81: in deliver\n    remote = iter(self._remote_batch_loads(tuple(pickled)))\nC:\\Users\\alozovsk\\Anaconda3\\envs\\modin\\lib\\site-packages\\rpyc\\core\\netref.py:254: in __call__\n    return syncreq(_self, consts.HANDLE_CALL, args, kwargs)\nC:\\Users\\alozovsk\\Anaconda3\\envs\\modin\\lib\\site-packages\\rpyc\\core\\netref.py:76: in syncreq\n    return conn.sync_request(handler, proxy, *args)\nmodin\\experimental\\cloud\\rpyc_proxy.py:165: in sync_request\n    return super().sync_request(handler, *args)\nC:\\Users\\alozovsk\\Anaconda3\\envs\\modin\\lib\\site-packages\\rpyc\\core\\protocol.py:500: in sync_request\n    return self.async_request(handler, *args, timeout=timeout).value\nC:\\Users\\alozovsk\\Anaconda3\\envs\\modin\\lib\\site-packages\\rpyc\\core\\async_.py:102: in value\n    raise self._obj\nE   _get_exception_class.<locals>.Derived: type object '_DTypeMeta' has no attribute '_abstract'\nE   \nE   ========= Remote Traceback (1) =========\nE   Traceback (most recent call last):\nE     File \"C:\\Users\\alozovsk\\Anaconda3\\envs\\modin\\lib\\site-packages\\rpyc\\core\\protocol.py\", line 338, in _dispatch_request\nE       res = self._HANDLERS[handler](self, *args)\nE     File \"C:\\Users\\alozovsk\\Anaconda3\\envs\\modin\\lib\\site-packages\\rpyc\\core\\protocol.py\", line 630, in _handle_call\nE       return obj(*args, **dict(kwargs))\nE     File \"C:\\prog\\modin\\modin\\experimental\\cloud\\rpyc_proxy.py\", line 34, in _batch_loads\nE       return tuple(pickle.loads(item) for item in items)\nE     File \"C:\\prog\\modin\\modin\\experimental\\cloud\\rpyc_proxy.py\", line 34, in <genexpr>\nE       return tuple(pickle.loads(item) for item in items)\nE   AttributeError: type object '_DTypeMeta' has no attribute '_abstract'"
                },
                "teardown": {
                    "name": "teardown",
                    "duration": 0.0007093999999998601,
                    "outcome": "passed"
                },
                "outcome": "failed"
            },
            {
                "name": "modin/pandas/test/dataframe/test_iter.py::test_itertuples_name[None]",
                "duration": 0.07166480000000064,
                "run_index": 3,
                "setup": {
                    "name": "setup",
                    "duration": 0.001278400000000346,
                    "outcome": "passed"
                },
                "call": {
                    "name": "call",
                    "duration": 0.06847480000000061,
                    "outcome": "failed",
                    "longrepr": "modin\\pandas\\test\\dataframe\\test_iter.py:57: in test_itertuples_name\n    modin_df, pandas_df = pd.DataFrame(data), pandas.DataFrame(data)\nmodin\\experimental\\cloud\\meta_magic.py:155: in __new__\n    return cls.__real_cls__(*a, **kw)\nmodin\\experimental\\cloud\\rpyc_proxy.py:436: in __init__\n    a, kw = preprocess(*a, **kw)\nmodin\\experimental\\cloud\\rpyc_proxy.py:643: in _preprocess_init_args\n    (data,) = conn.deliver((data,), {})[0]\nmodin\\experimental\\cloud\\rpyc_proxy.py:81: in deliver\n    remote = iter(self._remote_batch_loads(tuple(pickled)))\nC:\\Users\\alozovsk\\Anaconda3\\envs\\modin\\lib\\site-packages\\rpyc\\core\\netref.py:254: in __call__\n    return syncreq(_self, consts.HANDLE_CALL, args, kwargs)\nC:\\Users\\alozovsk\\Anaconda3\\envs\\modin\\lib\\site-packages\\rpyc\\core\\netref.py:76: in syncreq\n    return conn.sync_request(handler, proxy, *args)\nmodin\\experimental\\cloud\\rpyc_proxy.py:165: in sync_request\n    return super().sync_request(handler, *args)\nC:\\Users\\alozovsk\\Anaconda3\\envs\\modin\\lib\\site-packages\\rpyc\\core\\protocol.py:500: in sync_request\n    return self.async_request(handler, *args, timeout=timeout).value\nC:\\Users\\alozovsk\\Anaconda3\\envs\\modin\\lib\\site-packages\\rpyc\\core\\async_.py:102: in value\n    raise self._obj\nE   _get_exception_class.<locals>.Derived: type object '_DTypeMeta' has no attribute '_abstract'\nE   \nE   ========= Remote Traceback (1) =========\nE   Traceback (most recent call last):\nE     File \"C:\\Users\\alozovsk\\Anaconda3\\envs\\modin\\lib\\site-packages\\rpyc\\core\\protocol.py\", line 338, in _dispatch_request\nE       res = self._HANDLERS[handler](self, *args)\nE     File \"C:\\Users\\alozovsk\\Anaconda3\\envs\\modin\\lib\\site-packages\\rpyc\\core\\protocol.py\", line 630, in _handle_call\nE       return obj(*args, **dict(kwargs))\nE     File \"C:\\prog\\modin\\modin\\experimental\\cloud\\rpyc_proxy.py\", line 34, in _batch_loads\nE       return tuple(pickle.loads(item) for item in items)\nE     File \"C:\\prog\\modin\\modin\\experimental\\cloud\\rpyc_proxy.py\", line 34, in <genexpr>\nE       return tuple(pickle.loads(item) for item in items)\nE   AttributeError: type object '_DTypeMeta' has no attribute '_abstract'"
                },
                "teardown": {
                    "name": "teardown",
                    "duration": 0.0006331999999993343,
                    "outcome": "passed"
                },
                "outcome": "failed"
            },
            {
                "name": "modin/pandas/test/dataframe/test_iter.py::test_itertuples_name[NotPandas]",
                "duration": 0.08037209999999995,
                "run_index": 4,
                "setup": {
                    "name": "setup",
                    "duration": 0.0009242000000000417,
                    "outcome": "passed"
                },
                "call": {
                    "name": "call",
                    "duration": 0.07801109999999944,
                    "outcome": "failed",
                    "longrepr": "modin\\pandas\\test\\dataframe\\test_iter.py:57: in test_itertuples_name\n    modin_df, pandas_df = pd.DataFrame(data), pandas.DataFrame(data)\nmodin\\experimental\\cloud\\meta_magic.py:155: in __new__\n    return cls.__real_cls__(*a, **kw)\nmodin\\experimental\\cloud\\rpyc_proxy.py:436: in __init__\n    a, kw = preprocess(*a, **kw)\nmodin\\experimental\\cloud\\rpyc_proxy.py:643: in _preprocess_init_args\n    (data,) = conn.deliver((data,), {})[0]\nmodin\\experimental\\cloud\\rpyc_proxy.py:81: in deliver\n    remote = iter(self._remote_batch_loads(tuple(pickled)))\nC:\\Users\\alozovsk\\Anaconda3\\envs\\modin\\lib\\site-packages\\rpyc\\core\\netref.py:254: in __call__\n    return syncreq(_self, consts.HANDLE_CALL, args, kwargs)\nC:\\Users\\alozovsk\\Anaconda3\\envs\\modin\\lib\\site-packages\\rpyc\\core\\netref.py:76: in syncreq\n    return conn.sync_request(handler, proxy, *args)\nmodin\\experimental\\cloud\\rpyc_proxy.py:165: in sync_request\n    return super().sync_request(handler, *args)\nC:\\Users\\alozovsk\\Anaconda3\\envs\\modin\\lib\\site-packages\\rpyc\\core\\protocol.py:500: in sync_request\n    return self.async_request(handler, *args, timeout=timeout).value\nC:\\Users\\alozovsk\\Anaconda3\\envs\\modin\\lib\\site-packages\\rpyc\\core\\async_.py:102: in value\n    raise self._obj\nE   _get_exception_class.<locals>.Derived: type object '_DTypeMeta' has no attribute '_abstract'\nE   \nE   ========= Remote Traceback (1) =========\nE   Traceback (most recent call last):\nE     File \"C:\\Users\\alozovsk\\Anaconda3\\envs\\modin\\lib\\site-packages\\rpyc\\core\\protocol.py\", line 338, in _dispatch_request\nE       res = self._HANDLERS[handler](self, *args)\nE     File \"C:\\Users\\alozovsk\\Anaconda3\\envs\\modin\\lib\\site-packages\\rpyc\\core\\protocol.py\", line 630, in _handle_call\nE       return obj(*args, **dict(kwargs))\nE     File \"C:\\prog\\modin\\modin\\experimental\\cloud\\rpyc_proxy.py\", line 34, in _batch_loads\nE       return tuple(pickle.loads(item) for item in items)\nE     File \"C:\\prog\\modin\\modin\\experimental\\cloud\\rpyc_proxy.py\", line 34, in <genexpr>\nE       return tuple(pickle.loads(item) for item in items)\nE   AttributeError: type object '_DTypeMeta' has no attribute '_abstract'"
                },
                "teardown": {
                    "name": "teardown",
                    "duration": 0.0005126000000004183,
                    "outcome": "passed"
                },
                "outcome": "failed"
            },
            {
                "name": "modin/pandas/test/dataframe/test_iter.py::test_itertuples_multiindex",
                "duration": 0.01255810000000146,
                "run_index": 5,
                "setup": {
                    "name": "setup",
                    "duration": 0.0005649000000005344,
                    "outcome": "passed"
                },
                "call": {
                    "name": "call",
                    "duration": 0.01081089999999918,
                    "outcome": "failed",
                    "longrepr": "modin\\pandas\\test\\dataframe\\test_iter.py:67: in test_itertuples_multiindex\n    modin_df, pandas_df = pd.DataFrame(data), pandas.DataFrame(data)\nmodin\\experimental\\cloud\\meta_magic.py:155: in __new__\n    return cls.__real_cls__(*a, **kw)\nmodin\\experimental\\cloud\\rpyc_proxy.py:436: in __init__\n    a, kw = preprocess(*a, **kw)\nmodin\\experimental\\cloud\\rpyc_proxy.py:643: in _preprocess_init_args\n    (data,) = conn.deliver((data,), {})[0]\nmodin\\experimental\\cloud\\rpyc_proxy.py:81: in deliver\n    remote = iter(self._remote_batch_loads(tuple(pickled)))\nC:\\Users\\alozovsk\\Anaconda3\\envs\\modin\\lib\\site-packages\\rpyc\\core\\netref.py:254: in __call__\n    return syncreq(_self, consts.HANDLE_CALL, args, kwargs)\nC:\\Users\\alozovsk\\Anaconda3\\envs\\modin\\lib\\site-packages\\rpyc\\core\\netref.py:76: in syncreq\n    return conn.sync_request(handler, proxy, *args)\nmodin\\experimental\\cloud\\rpyc_proxy.py:165: in sync_request\n    return super().sync_request(handler, *args)\nC:\\Users\\alozovsk\\Anaconda3\\envs\\modin\\lib\\site-packages\\rpyc\\core\\protocol.py:500: in sync_request\n    return self.async_request(handler, *args, timeout=timeout).value\nC:\\Users\\alozovsk\\Anaconda3\\envs\\modin\\lib\\site-packages\\rpyc\\core\\async_.py:102: in value\n    raise self._obj\nE   _get_exception_class.<locals>.Derived: type object '_DTypeMeta' has no attribute '_abstract'\nE   \nE   ========= Remote Traceback (1) =========\nE   Traceback (most recent call last):\nE     File \"C:\\Users\\alozovsk\\Anaconda3\\envs\\modin\\lib\\site-packages\\rpyc\\core\\protocol.py\", line 338, in _dispatch_request\nE       res = self._HANDLERS[handler](self, *args)\nE     File \"C:\\Users\\alozovsk\\Anaconda3\\envs\\modin\\lib\\site-packages\\rpyc\\core\\protocol.py\", line 630, in _handle_call\nE       return obj(*args, **dict(kwargs))\nE     File \"C:\\prog\\modin\\modin\\experimental\\cloud\\rpyc_proxy.py\", line 34, in _batch_loads\nE       return tuple(pickle.loads(item) for item in items)\nE     File \"C:\\prog\\modin\\modin\\experimental\\cloud\\rpyc_proxy.py\", line 34, in <genexpr>\nE       return tuple(pickle.loads(item) for item in items)\nE   AttributeError: type object '_DTypeMeta' has no attribute '_abstract'"
                },
                "teardown": {
                    "name": "teardown",
                    "duration": 0.0006174000000012114,
                    "outcome": "passed"
                },
                "outcome": "failed"
            },
            {
                "name": "modin/pandas/test/dataframe/test_iter.py::test___iter__",
                "duration": 0.013333899999999232,
                "run_index": 6,
                "setup": {
                    "name": "setup",
                    "duration": 0.0006588000000000704,
                    "outcome": "passed"
                },
                "call": {
                    "name": "call",
                    "duration": 0.011570399999998315,
                    "outcome": "failed",
                    "longrepr": "modin\\pandas\\test\\dataframe\\test_iter.py:81: in test___iter__\n    modin_df = pd.DataFrame(test_data_values[0])\nmodin\\experimental\\cloud\\meta_magic.py:155: in __new__\n    return cls.__real_cls__(*a, **kw)\nmodin\\experimental\\cloud\\rpyc_proxy.py:436: in __init__\n    a, kw = preprocess(*a, **kw)\nmodin\\experimental\\cloud\\rpyc_proxy.py:643: in _preprocess_init_args\n    (data,) = conn.deliver((data,), {})[0]\nmodin\\experimental\\cloud\\rpyc_proxy.py:81: in deliver\n    remote = iter(self._remote_batch_loads(tuple(pickled)))\nC:\\Users\\alozovsk\\Anaconda3\\envs\\modin\\lib\\site-packages\\rpyc\\core\\netref.py:254: in __call__\n    return syncreq(_self, consts.HANDLE_CALL, args, kwargs)\nC:\\Users\\alozovsk\\Anaconda3\\envs\\modin\\lib\\site-packages\\rpyc\\core\\netref.py:76: in syncreq\n    return conn.sync_request(handler, proxy, *args)\nmodin\\experimental\\cloud\\rpyc_proxy.py:165: in sync_request\n    return super().sync_request(handler, *args)\nC:\\Users\\alozovsk\\Anaconda3\\envs\\modin\\lib\\site-packages\\rpyc\\core\\protocol.py:500: in sync_request\n    return self.async_request(handler, *args, timeout=timeout).value\nC:\\Users\\alozovsk\\Anaconda3\\envs\\modin\\lib\\site-packages\\rpyc\\core\\async_.py:102: in value\n    raise self._obj\nE   _get_exception_class.<locals>.Derived: type object '_DTypeMeta' has no attribute '_abstract'\nE   \nE   ========= Remote Traceback (1) =========\nE   Traceback (most recent call last):\nE     File \"C:\\Users\\alozovsk\\Anaconda3\\envs\\modin\\lib\\site-packages\\rpyc\\core\\protocol.py\", line 338, in _dispatch_request\nE       res = self._HANDLERS[handler](self, *args)\nE     File \"C:\\Users\\alozovsk\\Anaconda3\\envs\\modin\\lib\\site-packages\\rpyc\\core\\protocol.py\", line 630, in _handle_call\nE       return obj(*args, **dict(kwargs))\nE     File \"C:\\prog\\modin\\modin\\experimental\\cloud\\rpyc_proxy.py\", line 34, in _batch_loads\nE       return tuple(pickle.loads(item) for item in items)\nE     File \"C:\\prog\\modin\\modin\\experimental\\cloud\\rpyc_proxy.py\", line 34, in <genexpr>\nE       return tuple(pickle.loads(item) for item in items)\nE   AttributeError: type object '_DTypeMeta' has no attribute '_abstract'"
                },
                "teardown": {
                    "name": "teardown",
                    "duration": 0.00044590000000077623,
                    "outcome": "passed"
                },
                "outcome": "failed"
            },
            {
                "name": "modin/pandas/test/dataframe/test_iter.py::test___contains__[int_data]",
                "duration": 0.009778799999997645,
                "run_index": 7,
                "setup": {
                    "name": "setup",
                    "duration": 0.0005879999999987007,
                    "outcome": "passed"
                },
                "call": {
                    "name": "call",
                    "duration": 0.008119499999999391,
                    "outcome": "failed",
                    "longrepr": "modin\\pandas\\test\\dataframe\\test_iter.py:96: in test___contains__\n    modin_df = pd.DataFrame(data)\nmodin\\experimental\\cloud\\meta_magic.py:155: in __new__\n    return cls.__real_cls__(*a, **kw)\nmodin\\experimental\\cloud\\rpyc_proxy.py:436: in __init__\n    a, kw = preprocess(*a, **kw)\nmodin\\experimental\\cloud\\rpyc_proxy.py:643: in _preprocess_init_args\n    (data,) = conn.deliver((data,), {})[0]\nmodin\\experimental\\cloud\\rpyc_proxy.py:81: in deliver\n    remote = iter(self._remote_batch_loads(tuple(pickled)))\nC:\\Users\\alozovsk\\Anaconda3\\envs\\modin\\lib\\site-packages\\rpyc\\core\\netref.py:254: in __call__\n    return syncreq(_self, consts.HANDLE_CALL, args, kwargs)\nC:\\Users\\alozovsk\\Anaconda3\\envs\\modin\\lib\\site-packages\\rpyc\\core\\netref.py:76: in syncreq\n    return conn.sync_request(handler, proxy, *args)\nmodin\\experimental\\cloud\\rpyc_proxy.py:165: in sync_request\n    return super().sync_request(handler, *args)\nC:\\Users\\alozovsk\\Anaconda3\\envs\\modin\\lib\\site-packages\\rpyc\\core\\protocol.py:500: in sync_request\n    return self.async_request(handler, *args, timeout=timeout).value\nC:\\Users\\alozovsk\\Anaconda3\\envs\\modin\\lib\\site-packages\\rpyc\\core\\async_.py:102: in value\n    raise self._obj\nE   _get_exception_class.<locals>.Derived: type object '_DTypeMeta' has no attribute '_abstract'\nE   \nE   ========= Remote Traceback (1) =========\nE   Traceback (most recent call last):\nE     File \"C:\\Users\\alozovsk\\Anaconda3\\envs\\modin\\lib\\site-packages\\rpyc\\core\\protocol.py\", line 338, in _dispatch_request\nE       res = self._HANDLERS[handler](self, *args)\nE     File \"C:\\Users\\alozovsk\\Anaconda3\\envs\\modin\\lib\\site-packages\\rpyc\\core\\protocol.py\", line 630, in _handle_call\nE       return obj(*args, **dict(kwargs))\nE     File \"C:\\prog\\modin\\modin\\experimental\\cloud\\rpyc_proxy.py\", line 34, in _batch_loads\nE       return tuple(pickle.loads(item) for item in items)\nE     File \"C:\\prog\\modin\\modin\\experimental\\cloud\\rpyc_proxy.py\", line 34, in <genexpr>\nE       return tuple(pickle.loads(item) for item in items)\nE   AttributeError: type object '_DTypeMeta' has no attribute '_abstract'"
                },
                "teardown": {
                    "name": "teardown",
                    "duration": 0.0004833000000008525,
                    "outcome": "passed"
                },
                "outcome": "failed"
            },
            {
                "name": "modin/pandas/test/dataframe/test_iter.py::test___contains__[float_nan_data]",
                "duration": 0.06937660000000179,
                "run_index": 8,
                "setup": {
                    "name": "setup",
                    "duration": 0.0006160000000008381,
                    "outcome": "passed"
                },
                "call": {
                    "name": "call",
                    "duration": 0.06763579999999969,
                    "outcome": "failed",
                    "longrepr": "modin\\pandas\\test\\dataframe\\test_iter.py:96: in test___contains__\n    modin_df = pd.DataFrame(data)\nmodin\\experimental\\cloud\\meta_magic.py:155: in __new__\n    return cls.__real_cls__(*a, **kw)\nmodin\\experimental\\cloud\\rpyc_proxy.py:436: in __init__\n    a, kw = preprocess(*a, **kw)\nmodin\\experimental\\cloud\\rpyc_proxy.py:643: in _preprocess_init_args\n    (data,) = conn.deliver((data,), {})[0]\nmodin\\experimental\\cloud\\rpyc_proxy.py:81: in deliver\n    remote = iter(self._remote_batch_loads(tuple(pickled)))\nC:\\Users\\alozovsk\\Anaconda3\\envs\\modin\\lib\\site-packages\\rpyc\\core\\netref.py:254: in __call__\n    return syncreq(_self, consts.HANDLE_CALL, args, kwargs)\nC:\\Users\\alozovsk\\Anaconda3\\envs\\modin\\lib\\site-packages\\rpyc\\core\\netref.py:76: in syncreq\n    return conn.sync_request(handler, proxy, *args)\nmodin\\experimental\\cloud\\rpyc_proxy.py:165: in sync_request\n    return super().sync_request(handler, *args)\nC:\\Users\\alozovsk\\Anaconda3\\envs\\modin\\lib\\site-packages\\rpyc\\core\\protocol.py:500: in sync_request\n    return self.async_request(handler, *args, timeout=timeout).value\nC:\\Users\\alozovsk\\Anaconda3\\envs\\modin\\lib\\site-packages\\rpyc\\core\\async_.py:102: in value\n    raise self._obj\nE   _get_exception_class.<locals>.Derived: type object '_DTypeMeta' has no attribute '_abstract'\nE   \nE   ========= Remote Traceback (1) =========\nE   Traceback (most recent call last):\nE     File \"C:\\Users\\alozovsk\\Anaconda3\\envs\\modin\\lib\\site-packages\\rpyc\\core\\protocol.py\", line 338, in _dispatch_request\nE       res = self._HANDLERS[handler](self, *args)\nE     File \"C:\\Users\\alozovsk\\Anaconda3\\envs\\modin\\lib\\site-packages\\rpyc\\core\\protocol.py\", line 630, in _handle_call\nE       return obj(*args, **dict(kwargs))\nE     File \"C:\\prog\\modin\\modin\\experimental\\cloud\\rpyc_proxy.py\", line 34, in _batch_loads\nE       return tuple(pickle.loads(item) for item in items)\nE     File \"C:\\prog\\modin\\modin\\experimental\\cloud\\rpyc_proxy.py\", line 34, in <genexpr>\nE       return tuple(pickle.loads(item) for item in items)\nE   AttributeError: type object '_DTypeMeta' has no attribute '_abstract'"
                },
                "teardown": {
                    "name": "teardown",
                    "duration": 0.00050880000000042,
                    "outcome": "passed"
                },
                "outcome": "failed"
            },
            {
                "name": "modin/pandas/test/dataframe/test_iter.py::test__options_display",
                "duration": 0.019970700000000008,
                "run_index": 9,
                "setup": {
                    "name": "setup",
                    "duration": 0.0004881999999994946,
                    "outcome": "passed"
                },
                "call": {
                    "name": "call",
                    "duration": 0.017879000000000644,
                    "outcome": "failed",
                    "longrepr": "modin\\pandas\\test\\dataframe\\test_iter.py:114: in test__options_display\n    modin_df = pd.DataFrame(frame_data)\nmodin\\experimental\\cloud\\meta_magic.py:155: in __new__\n    return cls.__real_cls__(*a, **kw)\nmodin\\experimental\\cloud\\rpyc_proxy.py:436: in __init__\n    a, kw = preprocess(*a, **kw)\nmodin\\experimental\\cloud\\rpyc_proxy.py:643: in _preprocess_init_args\n    (data,) = conn.deliver((data,), {})[0]\nmodin\\experimental\\cloud\\rpyc_proxy.py:81: in deliver\n    remote = iter(self._remote_batch_loads(tuple(pickled)))\nC:\\Users\\alozovsk\\Anaconda3\\envs\\modin\\lib\\site-packages\\rpyc\\core\\netref.py:254: in __call__\n    return syncreq(_self, consts.HANDLE_CALL, args, kwargs)\nC:\\Users\\alozovsk\\Anaconda3\\envs\\modin\\lib\\site-packages\\rpyc\\core\\netref.py:76: in syncreq\n    return conn.sync_request(handler, proxy, *args)\nmodin\\experimental\\cloud\\rpyc_proxy.py:165: in sync_request\n    return super().sync_request(handler, *args)\nC:\\Users\\alozovsk\\Anaconda3\\envs\\modin\\lib\\site-packages\\rpyc\\core\\protocol.py:500: in sync_request\n    return self.async_request(handler, *args, timeout=timeout).value\nC:\\Users\\alozovsk\\Anaconda3\\envs\\modin\\lib\\site-packages\\rpyc\\core\\async_.py:102: in value\n    raise self._obj\nE   _get_exception_class.<locals>.Derived: type object '_DTypeMeta' has no attribute '_abstract'\nE   \nE   ========= Remote Traceback (1) =========\nE   Traceback (most recent call last):\nE     File \"C:\\Users\\alozovsk\\Anaconda3\\envs\\modin\\lib\\site-packages\\rpyc\\core\\protocol.py\", line 338, in _dispatch_request\nE       res = self._HANDLERS[handler](self, *args)\nE     File \"C:\\Users\\alozovsk\\Anaconda3\\envs\\modin\\lib\\site-packages\\rpyc\\core\\protocol.py\", line 630, in _handle_call\nE       return obj(*args, **dict(kwargs))\nE     File \"C:\\prog\\modin\\modin\\experimental\\cloud\\rpyc_proxy.py\", line 34, in _batch_loads\nE       return tuple(pickle.loads(item) for item in items)\nE     File \"C:\\prog\\modin\\modin\\experimental\\cloud\\rpyc_proxy.py\", line 34, in <genexpr>\nE       return tuple(pickle.loads(item) for item in items)\nE   AttributeError: type object '_DTypeMeta' has no attribute '_abstract'"
                },
                "teardown": {
                    "name": "teardown",
                    "duration": 0.0011153000000003743,
                    "outcome": "passed"
                },
                "outcome": "failed"
            },
            {
                "name": "modin/pandas/test/dataframe/test_iter.py::test___finalize__",
                "duration": 0.011021299999999457,
                "run_index": 10,
                "setup": {
                    "name": "setup",
                    "duration": 0.0005116999999987826,
                    "outcome": "passed"
                },
                "call": {
                    "name": "call",
                    "duration": 0.009566600000001202,
                    "outcome": "failed",
                    "longrepr": "modin\\pandas\\test\\dataframe\\test_iter.py:141: in test___finalize__\n    pd.DataFrame(data).__finalize__(None)\nmodin\\experimental\\cloud\\meta_magic.py:155: in __new__\n    return cls.__real_cls__(*a, **kw)\nmodin\\experimental\\cloud\\rpyc_proxy.py:436: in __init__\n    a, kw = preprocess(*a, **kw)\nmodin\\experimental\\cloud\\rpyc_proxy.py:643: in _preprocess_init_args\n    (data,) = conn.deliver((data,), {})[0]\nmodin\\experimental\\cloud\\rpyc_proxy.py:81: in deliver\n    remote = iter(self._remote_batch_loads(tuple(pickled)))\nC:\\Users\\alozovsk\\Anaconda3\\envs\\modin\\lib\\site-packages\\rpyc\\core\\netref.py:254: in __call__\n    return syncreq(_self, consts.HANDLE_CALL, args, kwargs)\nC:\\Users\\alozovsk\\Anaconda3\\envs\\modin\\lib\\site-packages\\rpyc\\core\\netref.py:76: in syncreq\n    return conn.sync_request(handler, proxy, *args)\nmodin\\experimental\\cloud\\rpyc_proxy.py:165: in sync_request\n    return super().sync_request(handler, *args)\nC:\\Users\\alozovsk\\Anaconda3\\envs\\modin\\lib\\site-packages\\rpyc\\core\\protocol.py:500: in sync_request\n    return self.async_request(handler, *args, timeout=timeout).value\nC:\\Users\\alozovsk\\Anaconda3\\envs\\modin\\lib\\site-packages\\rpyc\\core\\async_.py:102: in value\n    raise self._obj\nE   _get_exception_class.<locals>.Derived: type object '_DTypeMeta' has no attribute '_abstract'\nE   \nE   ========= Remote Traceback (1) =========\nE   Traceback (most recent call last):\nE     File \"C:\\Users\\alozovsk\\Anaconda3\\envs\\modin\\lib\\site-packages\\rpyc\\core\\protocol.py\", line 338, in _dispatch_request\nE       res = self._HANDLERS[handler](self, *args)\nE     File \"C:\\Users\\alozovsk\\Anaconda3\\envs\\modin\\lib\\site-packages\\rpyc\\core\\protocol.py\", line 630, in _handle_call\nE       return obj(*args, **dict(kwargs))\nE     File \"C:\\prog\\modin\\modin\\experimental\\cloud\\rpyc_proxy.py\", line 34, in _batch_loads\nE       return tuple(pickle.loads(item) for item in items)\nE     File \"C:\\prog\\modin\\modin\\experimental\\cloud\\rpyc_proxy.py\", line 34, in <genexpr>\nE       return tuple(pickle.loads(item) for item in items)\nE   AttributeError: type object '_DTypeMeta' has no attribute '_abstract'"
                },
                "teardown": {
                    "name": "teardown",
                    "duration": 0.00043130000000068947,
                    "outcome": "passed"
                },
                "outcome": "failed"
            },
            {
                "name": "modin/pandas/test/dataframe/test_iter.py::test___copy__[int_data]",
                "duration": 0.017280500000003585,
                "run_index": 11,
                "setup": {
                    "name": "setup",
                    "duration": 0.0031839000000015716,
                    "outcome": "passed"
                },
                "call": {
                    "name": "call",
                    "duration": 0.010376700000000127,
                    "outcome": "failed",
                    "longrepr": "modin\\pandas\\test\\dataframe\\test_iter.py:146: in test___copy__\n    modin_df = pd.DataFrame(data)\nmodin\\experimental\\cloud\\meta_magic.py:155: in __new__\n    return cls.__real_cls__(*a, **kw)\nmodin\\experimental\\cloud\\rpyc_proxy.py:436: in __init__\n    a, kw = preprocess(*a, **kw)\nmodin\\experimental\\cloud\\rpyc_proxy.py:643: in _preprocess_init_args\n    (data,) = conn.deliver((data,), {})[0]\nmodin\\experimental\\cloud\\rpyc_proxy.py:81: in deliver\n    remote = iter(self._remote_batch_loads(tuple(pickled)))\nC:\\Users\\alozovsk\\Anaconda3\\envs\\modin\\lib\\site-packages\\rpyc\\core\\netref.py:254: in __call__\n    return syncreq(_self, consts.HANDLE_CALL, args, kwargs)\nC:\\Users\\alozovsk\\Anaconda3\\envs\\modin\\lib\\site-packages\\rpyc\\core\\netref.py:76: in syncreq\n    return conn.sync_request(handler, proxy, *args)\nmodin\\experimental\\cloud\\rpyc_proxy.py:165: in sync_request\n    return super().sync_request(handler, *args)\nC:\\Users\\alozovsk\\Anaconda3\\envs\\modin\\lib\\site-packages\\rpyc\\core\\protocol.py:500: in sync_request\n    return self.async_request(handler, *args, timeout=timeout).value\nC:\\Users\\alozovsk\\Anaconda3\\envs\\modin\\lib\\site-packages\\rpyc\\core\\async_.py:102: in value\n    raise self._obj\nE   _get_exception_class.<locals>.Derived: type object '_DTypeMeta' has no attribute '_abstract'\nE   \nE   ========= Remote Traceback (1) =========\nE   Traceback (most recent call last):\nE     File \"C:\\Users\\alozovsk\\Anaconda3\\envs\\modin\\lib\\site-packages\\rpyc\\core\\protocol.py\", line 338, in _dispatch_request\nE       res = self._HANDLERS[handler](self, *args)\nE     File \"C:\\Users\\alozovsk\\Anaconda3\\envs\\modin\\lib\\site-packages\\rpyc\\core\\protocol.py\", line 630, in _handle_call\nE       return obj(*args, **dict(kwargs))\nE     File \"C:\\prog\\modin\\modin\\experimental\\cloud\\rpyc_proxy.py\", line 34, in _batch_loads\nE       return tuple(pickle.loads(item) for item in items)\nE     File \"C:\\prog\\modin\\modin\\experimental\\cloud\\rpyc_proxy.py\", line 34, in <genexpr>\nE       return tuple(pickle.loads(item) for item in items)\nE   AttributeError: type object '_DTypeMeta' has no attribute '_abstract'"
                },
                "teardown": {
                    "name": "teardown",
                    "duration": 0.000536000000000314,
                    "outcome": "passed"
                },
                "outcome": "failed"
            },
            {
                "name": "modin/pandas/test/dataframe/test_iter.py::test___copy__[float_nan_data]",
                "duration": 0.0690791000000015,
                "run_index": 12,
                "setup": {
                    "name": "setup",
                    "duration": 0.0006895000000000095,
                    "outcome": "passed"
                },
                "call": {
                    "name": "call",
                    "duration": 0.06720770000000087,
                    "outcome": "failed",
                    "longrepr": "modin\\pandas\\test\\dataframe\\test_iter.py:146: in test___copy__\n    modin_df = pd.DataFrame(data)\nmodin\\experimental\\cloud\\meta_magic.py:155: in __new__\n    return cls.__real_cls__(*a, **kw)\nmodin\\experimental\\cloud\\rpyc_proxy.py:436: in __init__\n    a, kw = preprocess(*a, **kw)\nmodin\\experimental\\cloud\\rpyc_proxy.py:643: in _preprocess_init_args\n    (data,) = conn.deliver((data,), {})[0]\nmodin\\experimental\\cloud\\rpyc_proxy.py:81: in deliver\n    remote = iter(self._remote_batch_loads(tuple(pickled)))\nC:\\Users\\alozovsk\\Anaconda3\\envs\\modin\\lib\\site-packages\\rpyc\\core\\netref.py:254: in __call__\n    return syncreq(_self, consts.HANDLE_CALL, args, kwargs)\nC:\\Users\\alozovsk\\Anaconda3\\envs\\modin\\lib\\site-packages\\rpyc\\core\\netref.py:76: in syncreq\n    return conn.sync_request(handler, proxy, *args)\nmodin\\experimental\\cloud\\rpyc_proxy.py:165: in sync_request\n    return super().sync_request(handler, *args)\nC:\\Users\\alozovsk\\Anaconda3\\envs\\modin\\lib\\site-packages\\rpyc\\core\\protocol.py:500: in sync_request\n    return self.async_request(handler, *args, timeout=timeout).value\nC:\\Users\\alozovsk\\Anaconda3\\envs\\modin\\lib\\site-packages\\rpyc\\core\\async_.py:102: in value\n    raise self._obj\nE   _get_exception_class.<locals>.Derived: type object '_DTypeMeta' has no attribute '_abstract'\nE   \nE   ========= Remote Traceback (1) =========\nE   Traceback (most recent call last):\nE     File \"C:\\Users\\alozovsk\\Anaconda3\\envs\\modin\\lib\\site-packages\\rpyc\\core\\protocol.py\", line 338, in _dispatch_request\nE       res = self._HANDLERS[handler](self, *args)\nE     File \"C:\\Users\\alozovsk\\Anaconda3\\envs\\modin\\lib\\site-packages\\rpyc\\core\\protocol.py\", line 630, in _handle_call\nE       return obj(*args, **dict(kwargs))\nE     File \"C:\\prog\\modin\\modin\\experimental\\cloud\\rpyc_proxy.py\", line 34, in _batch_loads\nE       return tuple(pickle.loads(item) for item in items)\nE     File \"C:\\prog\\modin\\modin\\experimental\\cloud\\rpyc_proxy.py\", line 34, in <genexpr>\nE       return tuple(pickle.loads(item) for item in items)\nE   AttributeError: type object '_DTypeMeta' has no attribute '_abstract'"
                },
                "teardown": {
                    "name": "teardown",
                    "duration": 0.0004924000000006146,
                    "outcome": "passed"
                },
                "outcome": "failed"
            },
            {
                "name": "modin/pandas/test/dataframe/test_iter.py::test___deepcopy__[int_data]",
                "duration": 0.010903199999997781,
                "run_index": 13,
                "setup": {
                    "name": "setup",
                    "duration": 0.0006140999999999508,
                    "outcome": "passed"
                },
                "call": {
                    "name": "call",
                    "duration": 0.009197899999998427,
                    "outcome": "failed",
                    "longrepr": "modin\\pandas\\test\\dataframe\\test_iter.py:155: in test___deepcopy__\n    modin_df = pd.DataFrame(data)\nmodin\\experimental\\cloud\\meta_magic.py:155: in __new__\n    return cls.__real_cls__(*a, **kw)\nmodin\\experimental\\cloud\\rpyc_proxy.py:436: in __init__\n    a, kw = preprocess(*a, **kw)\nmodin\\experimental\\cloud\\rpyc_proxy.py:643: in _preprocess_init_args\n    (data,) = conn.deliver((data,), {})[0]\nmodin\\experimental\\cloud\\rpyc_proxy.py:81: in deliver\n    remote = iter(self._remote_batch_loads(tuple(pickled)))\nC:\\Users\\alozovsk\\Anaconda3\\envs\\modin\\lib\\site-packages\\rpyc\\core\\netref.py:254: in __call__\n    return syncreq(_self, consts.HANDLE_CALL, args, kwargs)\nC:\\Users\\alozovsk\\Anaconda3\\envs\\modin\\lib\\site-packages\\rpyc\\core\\netref.py:76: in syncreq\n    return conn.sync_request(handler, proxy, *args)\nmodin\\experimental\\cloud\\rpyc_proxy.py:165: in sync_request\n    return super().sync_request(handler, *args)\nC:\\Users\\alozovsk\\Anaconda3\\envs\\modin\\lib\\site-packages\\rpyc\\core\\protocol.py:500: in sync_request\n    return self.async_request(handler, *args, timeout=timeout).value\nC:\\Users\\alozovsk\\Anaconda3\\envs\\modin\\lib\\site-packages\\rpyc\\core\\async_.py:102: in value\n    raise self._obj\nE   _get_exception_class.<locals>.Derived: type object '_DTypeMeta' has no attribute '_abstract'\nE   \nE   ========= Remote Traceback (1) =========\nE   Traceback (most recent call last):\nE     File \"C:\\Users\\alozovsk\\Anaconda3\\envs\\modin\\lib\\site-packages\\rpyc\\core\\protocol.py\", line 338, in _dispatch_request\nE       res = self._HANDLERS[handler](self, *args)\nE     File \"C:\\Users\\alozovsk\\Anaconda3\\envs\\modin\\lib\\site-packages\\rpyc\\core\\protocol.py\", line 630, in _handle_call\nE       return obj(*args, **dict(kwargs))\nE     File \"C:\\prog\\modin\\modin\\experimental\\cloud\\rpyc_proxy.py\", line 34, in _batch_loads\nE       return tuple(pickle.loads(item) for item in items)\nE     File \"C:\\prog\\modin\\modin\\experimental\\cloud\\rpyc_proxy.py\", line 34, in <genexpr>\nE       return tuple(pickle.loads(item) for item in items)\nE   AttributeError: type object '_DTypeMeta' has no attribute '_abstract'"
                },
                "teardown": {
                    "name": "teardown",
                    "duration": 0.00047709999999945296,
                    "outcome": "passed"
                },
                "outcome": "failed"
            },
            {
                "name": "modin/pandas/test/dataframe/test_iter.py::test___deepcopy__[float_nan_data]",
                "duration": 0.07382450000000063,
                "run_index": 14,
                "setup": {
                    "name": "setup",
                    "duration": 0.0006263000000004126,
                    "outcome": "passed"
                },
                "call": {
                    "name": "call",
                    "duration": 0.07210049999999946,
                    "outcome": "failed",
                    "longrepr": "modin\\pandas\\test\\dataframe\\test_iter.py:155: in test___deepcopy__\n    modin_df = pd.DataFrame(data)\nmodin\\experimental\\cloud\\meta_magic.py:155: in __new__\n    return cls.__real_cls__(*a, **kw)\nmodin\\experimental\\cloud\\rpyc_proxy.py:436: in __init__\n    a, kw = preprocess(*a, **kw)\nmodin\\experimental\\cloud\\rpyc_proxy.py:643: in _preprocess_init_args\n    (data,) = conn.deliver((data,), {})[0]\nmodin\\experimental\\cloud\\rpyc_proxy.py:81: in deliver\n    remote = iter(self._remote_batch_loads(tuple(pickled)))\nC:\\Users\\alozovsk\\Anaconda3\\envs\\modin\\lib\\site-packages\\rpyc\\core\\netref.py:254: in __call__\n    return syncreq(_self, consts.HANDLE_CALL, args, kwargs)\nC:\\Users\\alozovsk\\Anaconda3\\envs\\modin\\lib\\site-packages\\rpyc\\core\\netref.py:76: in syncreq\n    return conn.sync_request(handler, proxy, *args)\nmodin\\experimental\\cloud\\rpyc_proxy.py:165: in sync_request\n    return super().sync_request(handler, *args)\nC:\\Users\\alozovsk\\Anaconda3\\envs\\modin\\lib\\site-packages\\rpyc\\core\\protocol.py:500: in sync_request\n    return self.async_request(handler, *args, timeout=timeout).value\nC:\\Users\\alozovsk\\Anaconda3\\envs\\modin\\lib\\site-packages\\rpyc\\core\\async_.py:102: in value\n    raise self._obj\nE   _get_exception_class.<locals>.Derived: type object '_DTypeMeta' has no attribute '_abstract'\nE   \nE   ========= Remote Traceback (1) =========\nE   Traceback (most recent call last):\nE     File \"C:\\Users\\alozovsk\\Anaconda3\\envs\\modin\\lib\\site-packages\\rpyc\\core\\protocol.py\", line 338, in _dispatch_request\nE       res = self._HANDLERS[handler](self, *args)\nE     File \"C:\\Users\\alozovsk\\Anaconda3\\envs\\modin\\lib\\site-packages\\rpyc\\core\\protocol.py\", line 630, in _handle_call\nE       return obj(*args, **dict(kwargs))\nE     File \"C:\\prog\\modin\\modin\\experimental\\cloud\\rpyc_proxy.py\", line 34, in _batch_loads\nE       return tuple(pickle.loads(item) for item in items)\nE     File \"C:\\prog\\modin\\modin\\experimental\\cloud\\rpyc_proxy.py\", line 34, in <genexpr>\nE       return tuple(pickle.loads(item) for item in items)\nE   AttributeError: type object '_DTypeMeta' has no attribute '_abstract'"
                },
                "teardown": {
                    "name": "teardown",
                    "duration": 0.00047140000000034377,
                    "outcome": "passed"
                },
                "outcome": "failed"
            },
            {
                "name": "modin/pandas/test/dataframe/test_iter.py::test___repr__",
                "duration": 0.019308900000000406,
                "run_index": 15,
                "setup": {
                    "name": "setup",
                    "duration": 0.0005325000000002689,
                    "outcome": "passed"
                },
                "call": {
                    "name": "call",
                    "duration": 0.017716000000000065,
                    "outcome": "failed",
                    "longrepr": "modin\\pandas\\test\\dataframe\\test_iter.py:168: in test___repr__\n    modin_df = pd.DataFrame(frame_data)\nmodin\\experimental\\cloud\\meta_magic.py:155: in __new__\n    return cls.__real_cls__(*a, **kw)\nmodin\\experimental\\cloud\\rpyc_proxy.py:436: in __init__\n    a, kw = preprocess(*a, **kw)\nmodin\\experimental\\cloud\\rpyc_proxy.py:643: in _preprocess_init_args\n    (data,) = conn.deliver((data,), {})[0]\nmodin\\experimental\\cloud\\rpyc_proxy.py:81: in deliver\n    remote = iter(self._remote_batch_loads(tuple(pickled)))\nC:\\Users\\alozovsk\\Anaconda3\\envs\\modin\\lib\\site-packages\\rpyc\\core\\netref.py:254: in __call__\n    return syncreq(_self, consts.HANDLE_CALL, args, kwargs)\nC:\\Users\\alozovsk\\Anaconda3\\envs\\modin\\lib\\site-packages\\rpyc\\core\\netref.py:76: in syncreq\n    return conn.sync_request(handler, proxy, *args)\nmodin\\experimental\\cloud\\rpyc_proxy.py:165: in sync_request\n    return super().sync_request(handler, *args)\nC:\\Users\\alozovsk\\Anaconda3\\envs\\modin\\lib\\site-packages\\rpyc\\core\\protocol.py:500: in sync_request\n    return self.async_request(handler, *args, timeout=timeout).value\nC:\\Users\\alozovsk\\Anaconda3\\envs\\modin\\lib\\site-packages\\rpyc\\core\\async_.py:102: in value\n    raise self._obj\nE   _get_exception_class.<locals>.Derived: type object '_DTypeMeta' has no attribute '_abstract'\nE   \nE   ========= Remote Traceback (1) =========\nE   Traceback (most recent call last):\nE     File \"C:\\Users\\alozovsk\\Anaconda3\\envs\\modin\\lib\\site-packages\\rpyc\\core\\protocol.py\", line 338, in _dispatch_request\nE       res = self._HANDLERS[handler](self, *args)\nE     File \"C:\\Users\\alozovsk\\Anaconda3\\envs\\modin\\lib\\site-packages\\rpyc\\core\\protocol.py\", line 630, in _handle_call\nE       return obj(*args, **dict(kwargs))\nE     File \"C:\\prog\\modin\\modin\\experimental\\cloud\\rpyc_proxy.py\", line 34, in _batch_loads\nE       return tuple(pickle.loads(item) for item in items)\nE     File \"C:\\prog\\modin\\modin\\experimental\\cloud\\rpyc_proxy.py\", line 34, in <genexpr>\nE       return tuple(pickle.loads(item) for item in items)\nE   AttributeError: type object '_DTypeMeta' has no attribute '_abstract'"
                },
                "teardown": {
                    "name": "teardown",
                    "duration": 0.0005278999999998035,
                    "outcome": "passed"
                },
                "outcome": "failed"
            },
            {
                "name": "modin/pandas/test/dataframe/test_iter.py::test_inplace_series_ops[int_data]",
                "duration": 0.012344599999995154,
                "run_index": 16,
                "setup": {
                    "name": "setup",
                    "duration": 0.000628099999998355,
                    "outcome": "passed"
                },
                "call": {
                    "name": "call",
                    "duration": 0.010626999999999498,
                    "outcome": "failed",
                    "longrepr": "modin\\pandas\\test\\dataframe\\test_iter.py:235: in test_inplace_series_ops\n    modin_df = pd.DataFrame(data)\nmodin\\experimental\\cloud\\meta_magic.py:155: in __new__\n    return cls.__real_cls__(*a, **kw)\nmodin\\experimental\\cloud\\rpyc_proxy.py:436: in __init__\n    a, kw = preprocess(*a, **kw)\nmodin\\experimental\\cloud\\rpyc_proxy.py:643: in _preprocess_init_args\n    (data,) = conn.deliver((data,), {})[0]\nmodin\\experimental\\cloud\\rpyc_proxy.py:81: in deliver\n    remote = iter(self._remote_batch_loads(tuple(pickled)))\nC:\\Users\\alozovsk\\Anaconda3\\envs\\modin\\lib\\site-packages\\rpyc\\core\\netref.py:254: in __call__\n    return syncreq(_self, consts.HANDLE_CALL, args, kwargs)\nC:\\Users\\alozovsk\\Anaconda3\\envs\\modin\\lib\\site-packages\\rpyc\\core\\netref.py:76: in syncreq\n    return conn.sync_request(handler, proxy, *args)\nmodin\\experimental\\cloud\\rpyc_proxy.py:165: in sync_request\n    return super().sync_request(handler, *args)\nC:\\Users\\alozovsk\\Anaconda3\\envs\\modin\\lib\\site-packages\\rpyc\\core\\protocol.py:500: in sync_request\n    return self.async_request(handler, *args, timeout=timeout).value\nC:\\Users\\alozovsk\\Anaconda3\\envs\\modin\\lib\\site-packages\\rpyc\\core\\async_.py:102: in value\n    raise self._obj\nE   _get_exception_class.<locals>.Derived: type object '_DTypeMeta' has no attribute '_abstract'\nE   \nE   ========= Remote Traceback (1) =========\nE   Traceback (most recent call last):\nE     File \"C:\\Users\\alozovsk\\Anaconda3\\envs\\modin\\lib\\site-packages\\rpyc\\core\\protocol.py\", line 338, in _dispatch_request\nE       res = self._HANDLERS[handler](self, *args)\nE     File \"C:\\Users\\alozovsk\\Anaconda3\\envs\\modin\\lib\\site-packages\\rpyc\\core\\protocol.py\", line 630, in _handle_call\nE       return obj(*args, **dict(kwargs))\nE     File \"C:\\prog\\modin\\modin\\experimental\\cloud\\rpyc_proxy.py\", line 34, in _batch_loads\nE       return tuple(pickle.loads(item) for item in items)\nE     File \"C:\\prog\\modin\\modin\\experimental\\cloud\\rpyc_proxy.py\", line 34, in <genexpr>\nE       return tuple(pickle.loads(item) for item in items)\nE   AttributeError: type object '_DTypeMeta' has no attribute '_abstract'"
                },
                "teardown": {
                    "name": "teardown",
                    "duration": 0.000461399999998946,
                    "outcome": "passed"
                },
                "outcome": "failed"
            },
            {
                "name": "modin/pandas/test/dataframe/test_iter.py::test_inplace_series_ops[float_nan_data]",
                "duration": 0.0810689,
                "run_index": 17,
                "setup": {
                    "name": "setup",
                    "duration": 0.0006252999999993847,
                    "outcome": "passed"
                },
                "call": {
                    "name": "call",
                    "duration": 0.07911920000000094,
                    "outcome": "failed",
                    "longrepr": "modin\\pandas\\test\\dataframe\\test_iter.py:235: in test_inplace_series_ops\n    modin_df = pd.DataFrame(data)\nmodin\\experimental\\cloud\\meta_magic.py:155: in __new__\n    return cls.__real_cls__(*a, **kw)\nmodin\\experimental\\cloud\\rpyc_proxy.py:436: in __init__\n    a, kw = preprocess(*a, **kw)\nmodin\\experimental\\cloud\\rpyc_proxy.py:643: in _preprocess_init_args\n    (data,) = conn.deliver((data,), {})[0]\nmodin\\experimental\\cloud\\rpyc_proxy.py:81: in deliver\n    remote = iter(self._remote_batch_loads(tuple(pickled)))\nC:\\Users\\alozovsk\\Anaconda3\\envs\\modin\\lib\\site-packages\\rpyc\\core\\netref.py:254: in __call__\n    return syncreq(_self, consts.HANDLE_CALL, args, kwargs)\nC:\\Users\\alozovsk\\Anaconda3\\envs\\modin\\lib\\site-packages\\rpyc\\core\\netref.py:76: in syncreq\n    return conn.sync_request(handler, proxy, *args)\nmodin\\experimental\\cloud\\rpyc_proxy.py:165: in sync_request\n    return super().sync_request(handler, *args)\nC:\\Users\\alozovsk\\Anaconda3\\envs\\modin\\lib\\site-packages\\rpyc\\core\\protocol.py:500: in sync_request\n    return self.async_request(handler, *args, timeout=timeout).value\nC:\\Users\\alozovsk\\Anaconda3\\envs\\modin\\lib\\site-packages\\rpyc\\core\\async_.py:102: in value\n    raise self._obj\nE   _get_exception_class.<locals>.Derived: type object '_DTypeMeta' has no attribute '_abstract'\nE   \nE   ========= Remote Traceback (1) =========\nE   Traceback (most recent call last):\nE     File \"C:\\Users\\alozovsk\\Anaconda3\\envs\\modin\\lib\\site-packages\\rpyc\\core\\protocol.py\", line 338, in _dispatch_request\nE       res = self._HANDLERS[handler](self, *args)\nE     File \"C:\\Users\\alozovsk\\Anaconda3\\envs\\modin\\lib\\site-packages\\rpyc\\core\\protocol.py\", line 630, in _handle_call\nE       return obj(*args, **dict(kwargs))\nE     File \"C:\\prog\\modin\\modin\\experimental\\cloud\\rpyc_proxy.py\", line 34, in _batch_loads\nE       return tuple(pickle.loads(item) for item in items)\nE     File \"C:\\prog\\modin\\modin\\experimental\\cloud\\rpyc_proxy.py\", line 34, in <genexpr>\nE       return tuple(pickle.loads(item) for item in items)\nE   AttributeError: type object '_DTypeMeta' has no attribute '_abstract'"
                },
                "teardown": {
                    "name": "teardown",
                    "duration": 0.0006991000000002856,
                    "outcome": "passed"
                },
                "outcome": "failed"
            },
            {
                "name": "modin/pandas/test/dataframe/test_iter.py::test___setattr__",
                "duration": 0.12091070000000137,
                "run_index": 18,
                "setup": {
                    "name": "setup",
                    "duration": 0.0005777000000009025,
                    "outcome": "passed"
                },
                "call": {
                    "name": "call",
                    "duration": 0.11935330000000022,
                    "outcome": "passed"
                },
                "teardown": {
                    "name": "teardown",
                    "duration": 0.0004019999999993473,
                    "outcome": "passed"
                },
                "outcome": "passed"
            },
            {
                "name": "modin/pandas/test/dataframe/test_iter.py::test_isin[int_data]",
                "duration": 0.11587330000000406,
                "run_index": 19,
                "setup": {
                    "name": "setup",
                    "duration": 0.0005995000000016404,
                    "outcome": "passed"
                },
                "call": {
                    "name": "call",
                    "duration": 0.11421280000000067,
                    "outcome": "failed",
                    "longrepr": "modin\\pandas\\test\\dataframe\\test_iter.py:262: in test_isin\n    modin_df = pd.DataFrame(data)\nmodin\\experimental\\cloud\\meta_magic.py:155: in __new__\n    return cls.__real_cls__(*a, **kw)\nmodin\\experimental\\cloud\\rpyc_proxy.py:436: in __init__\n    a, kw = preprocess(*a, **kw)\nmodin\\experimental\\cloud\\rpyc_proxy.py:643: in _preprocess_init_args\n    (data,) = conn.deliver((data,), {})[0]\nmodin\\experimental\\cloud\\rpyc_proxy.py:81: in deliver\n    remote = iter(self._remote_batch_loads(tuple(pickled)))\nC:\\Users\\alozovsk\\Anaconda3\\envs\\modin\\lib\\site-packages\\rpyc\\core\\netref.py:254: in __call__\n    return syncreq(_self, consts.HANDLE_CALL, args, kwargs)\nC:\\Users\\alozovsk\\Anaconda3\\envs\\modin\\lib\\site-packages\\rpyc\\core\\netref.py:76: in syncreq\n    return conn.sync_request(handler, proxy, *args)\nmodin\\experimental\\cloud\\rpyc_proxy.py:165: in sync_request\n    return super().sync_request(handler, *args)\nC:\\Users\\alozovsk\\Anaconda3\\envs\\modin\\lib\\site-packages\\rpyc\\core\\protocol.py:500: in sync_request\n    return self.async_request(handler, *args, timeout=timeout).value\nC:\\Users\\alozovsk\\Anaconda3\\envs\\modin\\lib\\site-packages\\rpyc\\core\\async_.py:102: in value\n    raise self._obj\nE   _get_exception_class.<locals>.Derived: type object 'ndarray' has no attribute '__iter__'\nE   \nE   ========= Remote Traceback (1) =========\nE   Traceback (most recent call last):\nE     File \"C:\\Users\\alozovsk\\Anaconda3\\envs\\modin\\lib\\site-packages\\rpyc\\core\\protocol.py\", line 338, in _dispatch_request\nE       res = self._HANDLERS[handler](self, *args)\nE     File \"C:\\Users\\alozovsk\\Anaconda3\\envs\\modin\\lib\\site-packages\\rpyc\\core\\protocol.py\", line 630, in _handle_call\nE       return obj(*args, **dict(kwargs))\nE     File \"C:\\prog\\modin\\modin\\experimental\\cloud\\rpyc_proxy.py\", line 34, in _batch_loads\nE       return tuple(pickle.loads(item) for item in items)\nE     File \"C:\\prog\\modin\\modin\\experimental\\cloud\\rpyc_proxy.py\", line 34, in <genexpr>\nE       return tuple(pickle.loads(item) for item in items)\nE   AttributeError: type object 'ndarray' has no attribute '__iter__'"
                },
                "teardown": {
                    "name": "teardown",
                    "duration": 0.0004615000000001146,
                    "outcome": "passed"
                },
                "outcome": "failed"
            },
            {
                "name": "modin/pandas/test/dataframe/test_iter.py::test_isin[float_nan_data]",
                "duration": 0.07542220000000022,
                "run_index": 20,
                "setup": {
                    "name": "setup",
                    "duration": 0.0006059000000000481,
                    "outcome": "passed"
                },
                "call": {
                    "name": "call",
                    "duration": 0.07368190000000041,
                    "outcome": "failed",
                    "longrepr": "modin\\pandas\\test\\dataframe\\test_iter.py:262: in test_isin\n    modin_df = pd.DataFrame(data)\nmodin\\experimental\\cloud\\meta_magic.py:155: in __new__\n    return cls.__real_cls__(*a, **kw)\nmodin\\experimental\\cloud\\rpyc_proxy.py:436: in __init__\n    a, kw = preprocess(*a, **kw)\nmodin\\experimental\\cloud\\rpyc_proxy.py:643: in _preprocess_init_args\n    (data,) = conn.deliver((data,), {})[0]\nmodin\\experimental\\cloud\\rpyc_proxy.py:81: in deliver\n    remote = iter(self._remote_batch_loads(tuple(pickled)))\nC:\\Users\\alozovsk\\Anaconda3\\envs\\modin\\lib\\site-packages\\rpyc\\core\\netref.py:254: in __call__\n    return syncreq(_self, consts.HANDLE_CALL, args, kwargs)\nC:\\Users\\alozovsk\\Anaconda3\\envs\\modin\\lib\\site-packages\\rpyc\\core\\netref.py:76: in syncreq\n    return conn.sync_request(handler, proxy, *args)\nmodin\\experimental\\cloud\\rpyc_proxy.py:165: in sync_request\n    return super().sync_request(handler, *args)\nC:\\Users\\alozovsk\\Anaconda3\\envs\\modin\\lib\\site-packages\\rpyc\\core\\protocol.py:500: in sync_request\n    return self.async_request(handler, *args, timeout=timeout).value\nC:\\Users\\alozovsk\\Anaconda3\\envs\\modin\\lib\\site-packages\\rpyc\\core\\async_.py:102: in value\n    raise self._obj\nE   _get_exception_class.<locals>.Derived: type object '_DTypeMeta' has no attribute '_abstract'\nE   \nE   ========= Remote Traceback (1) =========\nE   Traceback (most recent call last):\nE     File \"C:\\Users\\alozovsk\\Anaconda3\\envs\\modin\\lib\\site-packages\\rpyc\\core\\protocol.py\", line 338, in _dispatch_request\nE       res = self._HANDLERS[handler](self, *args)\nE     File \"C:\\Users\\alozovsk\\Anaconda3\\envs\\modin\\lib\\site-packages\\rpyc\\core\\protocol.py\", line 630, in _handle_call\nE       return obj(*args, **dict(kwargs))\nE     File \"C:\\prog\\modin\\modin\\experimental\\cloud\\rpyc_proxy.py\", line 34, in _batch_loads\nE       return tuple(pickle.loads(item) for item in items)\nE     File \"C:\\prog\\modin\\modin\\experimental\\cloud\\rpyc_proxy.py\", line 34, in <genexpr>\nE       return tuple(pickle.loads(item) for item in items)\nE   AttributeError: type object '_DTypeMeta' has no attribute '_abstract'"
                },
                "teardown": {
                    "name": "teardown",
                    "duration": 0.0005284999999997098,
                    "outcome": "passed"
                },
                "outcome": "failed"
            },
            {
                "name": "modin/pandas/test/dataframe/test_iter.py::test_constructor[int_data]",
                "duration": 0.12102340000000211,
                "run_index": 21,
                "setup": {
                    "name": "setup",
                    "duration": 0.0007504000000011501,
                    "outcome": "passed"
                },
                "call": {
                    "name": "call",
                    "duration": 0.11903539999999957,
                    "outcome": "failed",
                    "longrepr": "modin\\pandas\\test\\dataframe\\test_iter.py:274: in test_constructor\n    modin_df = pd.DataFrame(data)\nmodin\\experimental\\cloud\\meta_magic.py:155: in __new__\n    return cls.__real_cls__(*a, **kw)\nmodin\\experimental\\cloud\\rpyc_proxy.py:436: in __init__\n    a, kw = preprocess(*a, **kw)\nmodin\\experimental\\cloud\\rpyc_proxy.py:643: in _preprocess_init_args\n    (data,) = conn.deliver((data,), {})[0]\nmodin\\experimental\\cloud\\rpyc_proxy.py:81: in deliver\n    remote = iter(self._remote_batch_loads(tuple(pickled)))\nC:\\Users\\alozovsk\\Anaconda3\\envs\\modin\\lib\\site-packages\\rpyc\\core\\netref.py:254: in __call__\n    return syncreq(_self, consts.HANDLE_CALL, args, kwargs)\nC:\\Users\\alozovsk\\Anaconda3\\envs\\modin\\lib\\site-packages\\rpyc\\core\\netref.py:76: in syncreq\n    return conn.sync_request(handler, proxy, *args)\nmodin\\experimental\\cloud\\rpyc_proxy.py:165: in sync_request\n    return super().sync_request(handler, *args)\nC:\\Users\\alozovsk\\Anaconda3\\envs\\modin\\lib\\site-packages\\rpyc\\core\\protocol.py:500: in sync_request\n    return self.async_request(handler, *args, timeout=timeout).value\nC:\\Users\\alozovsk\\Anaconda3\\envs\\modin\\lib\\site-packages\\rpyc\\core\\async_.py:102: in value\n    raise self._obj\nE   _get_exception_class.<locals>.Derived: type object 'ndarray' has no attribute '__iter__'\nE   \nE   ========= Remote Traceback (1) =========\nE   Traceback (most recent call last):\nE     File \"C:\\Users\\alozovsk\\Anaconda3\\envs\\modin\\lib\\site-packages\\rpyc\\core\\protocol.py\", line 338, in _dispatch_request\nE       res = self._HANDLERS[handler](self, *args)\nE     File \"C:\\Users\\alozovsk\\Anaconda3\\envs\\modin\\lib\\site-packages\\rpyc\\core\\protocol.py\", line 630, in _handle_call\nE       return obj(*args, **dict(kwargs))\nE     File \"C:\\prog\\modin\\modin\\experimental\\cloud\\rpyc_proxy.py\", line 34, in _batch_loads\nE       return tuple(pickle.loads(item) for item in items)\nE     File \"C:\\prog\\modin\\modin\\experimental\\cloud\\rpyc_proxy.py\", line 34, in <genexpr>\nE       return tuple(pickle.loads(item) for item in items)\nE   AttributeError: type object 'ndarray' has no attribute '__iter__'"
                },
                "teardown": {
                    "name": "teardown",
                    "duration": 0.000487200000000243,
                    "outcome": "passed"
                },
                "outcome": "failed"
            },
            {
                "name": "modin/pandas/test/dataframe/test_iter.py::test_constructor[float_nan_data]",
                "duration": 0.0779221000000021,
                "run_index": 22,
                "setup": {
                    "name": "setup",
                    "duration": 0.000585300000000899,
                    "outcome": "passed"
                },
                "call": {
                    "name": "call",
                    "duration": 0.0762716000000001,
                    "outcome": "failed",
                    "longrepr": "modin\\pandas\\test\\dataframe\\test_iter.py:274: in test_constructor\n    modin_df = pd.DataFrame(data)\nmodin\\experimental\\cloud\\meta_magic.py:155: in __new__\n    return cls.__real_cls__(*a, **kw)\nmodin\\experimental\\cloud\\rpyc_proxy.py:436: in __init__\n    a, kw = preprocess(*a, **kw)\nmodin\\experimental\\cloud\\rpyc_proxy.py:643: in _preprocess_init_args\n    (data,) = conn.deliver((data,), {})[0]\nmodin\\experimental\\cloud\\rpyc_proxy.py:81: in deliver\n    remote = iter(self._remote_batch_loads(tuple(pickled)))\nC:\\Users\\alozovsk\\Anaconda3\\envs\\modin\\lib\\site-packages\\rpyc\\core\\netref.py:254: in __call__\n    return syncreq(_self, consts.HANDLE_CALL, args, kwargs)\nC:\\Users\\alozovsk\\Anaconda3\\envs\\modin\\lib\\site-packages\\rpyc\\core\\netref.py:76: in syncreq\n    return conn.sync_request(handler, proxy, *args)\nmodin\\experimental\\cloud\\rpyc_proxy.py:165: in sync_request\n    return super().sync_request(handler, *args)\nC:\\Users\\alozovsk\\Anaconda3\\envs\\modin\\lib\\site-packages\\rpyc\\core\\protocol.py:500: in sync_request\n    return self.async_request(handler, *args, timeout=timeout).value\nC:\\Users\\alozovsk\\Anaconda3\\envs\\modin\\lib\\site-packages\\rpyc\\core\\async_.py:102: in value\n    raise self._obj\nE   _get_exception_class.<locals>.Derived: type object '_DTypeMeta' has no attribute '_abstract'\nE   \nE   ========= Remote Traceback (1) =========\nE   Traceback (most recent call last):\nE     File \"C:\\Users\\alozovsk\\Anaconda3\\envs\\modin\\lib\\site-packages\\rpyc\\core\\protocol.py\", line 338, in _dispatch_request\nE       res = self._HANDLERS[handler](self, *args)\nE     File \"C:\\Users\\alozovsk\\Anaconda3\\envs\\modin\\lib\\site-packages\\rpyc\\core\\protocol.py\", line 630, in _handle_call\nE       return obj(*args, **dict(kwargs))\nE     File \"C:\\prog\\modin\\modin\\experimental\\cloud\\rpyc_proxy.py\", line 34, in _batch_loads\nE       return tuple(pickle.loads(item) for item in items)\nE     File \"C:\\prog\\modin\\modin\\experimental\\cloud\\rpyc_proxy.py\", line 34, in <genexpr>\nE       return tuple(pickle.loads(item) for item in items)\nE   AttributeError: type object '_DTypeMeta' has no attribute '_abstract'"
                },
                "teardown": {
                    "name": "teardown",
                    "duration": 0.0004799000000001996,
                    "outcome": "passed"
                },
                "outcome": "failed"
            },
            {
                "name": "modin/pandas/test/dataframe/test_iter.py::test_constructor_dtypes[data0]",
                "duration": 0.01418009999999903,
                "run_index": 23,
                "setup": {
                    "name": "setup",
                    "duration": 0.0005755000000000621,
                    "outcome": "passed"
                },
                "call": {
                    "name": "call",
                    "duration": 0.01254400000000011,
                    "outcome": "failed",
                    "longrepr": "modin\\pandas\\test\\dataframe\\test_iter.py:295: in test_constructor_dtypes\n    md_df, pd_df = create_test_dfs(data)\nmodin\\pandas\\test\\utils.py:841: in create_test_dfs\n    post_fn, [pd.DataFrame(*args, **kwargs), pandas.DataFrame(*args, **kwargs)]\nmodin\\experimental\\cloud\\meta_magic.py:155: in __new__\n    return cls.__real_cls__(*a, **kw)\nmodin\\experimental\\cloud\\rpyc_proxy.py:436: in __init__\n    a, kw = preprocess(*a, **kw)\nmodin\\experimental\\cloud\\rpyc_proxy.py:643: in _preprocess_init_args\n    (data,) = conn.deliver((data,), {})[0]\nmodin\\experimental\\cloud\\rpyc_proxy.py:81: in deliver\n    remote = iter(self._remote_batch_loads(tuple(pickled)))\nC:\\Users\\alozovsk\\Anaconda3\\envs\\modin\\lib\\site-packages\\rpyc\\core\\netref.py:254: in __call__\n    return syncreq(_self, consts.HANDLE_CALL, args, kwargs)\nC:\\Users\\alozovsk\\Anaconda3\\envs\\modin\\lib\\site-packages\\rpyc\\core\\netref.py:76: in syncreq\n    return conn.sync_request(handler, proxy, *args)\nmodin\\experimental\\cloud\\rpyc_proxy.py:165: in sync_request\n    return super().sync_request(handler, *args)\nC:\\Users\\alozovsk\\Anaconda3\\envs\\modin\\lib\\site-packages\\rpyc\\core\\protocol.py:500: in sync_request\n    return self.async_request(handler, *args, timeout=timeout).value\nC:\\Users\\alozovsk\\Anaconda3\\envs\\modin\\lib\\site-packages\\rpyc\\core\\async_.py:102: in value\n    raise self._obj\nE   _get_exception_class.<locals>.Derived: type object 'ndarray' has no attribute '__iter__'\nE   \nE   ========= Remote Traceback (1) =========\nE   Traceback (most recent call last):\nE     File \"C:\\Users\\alozovsk\\Anaconda3\\envs\\modin\\lib\\site-packages\\rpyc\\core\\protocol.py\", line 338, in _dispatch_request\nE       res = self._HANDLERS[handler](self, *args)\nE     File \"C:\\Users\\alozovsk\\Anaconda3\\envs\\modin\\lib\\site-packages\\rpyc\\core\\protocol.py\", line 630, in _handle_call\nE       return obj(*args, **dict(kwargs))\nE     File \"C:\\prog\\modin\\modin\\experimental\\cloud\\rpyc_proxy.py\", line 34, in _batch_loads\nE       return tuple(pickle.loads(item) for item in items)\nE     File \"C:\\prog\\modin\\modin\\experimental\\cloud\\rpyc_proxy.py\", line 34, in <genexpr>\nE       return tuple(pickle.loads(item) for item in items)\nE   AttributeError: type object 'ndarray' has no attribute '__iter__'"
                },
                "teardown": {
                    "name": "teardown",
                    "duration": 0.00048509999999879483,
                    "outcome": "passed"
                },
                "outcome": "failed"
            },
            {
                "name": "modin/pandas/test/dataframe/test_iter.py::test_constructor_dtypes[data1]",
                "duration": 0.027145200000001424,
                "run_index": 24,
                "setup": {
                    "name": "setup",
                    "duration": 0.0005942000000001002,
                    "outcome": "passed"
                },
                "call": {
                    "name": "call",
                    "duration": 0.025495900000001015,
                    "outcome": "failed",
                    "longrepr": "modin\\pandas\\test\\dataframe\\test_iter.py:295: in test_constructor_dtypes\n    md_df, pd_df = create_test_dfs(data)\nmodin\\pandas\\test\\utils.py:841: in create_test_dfs\n    post_fn, [pd.DataFrame(*args, **kwargs), pandas.DataFrame(*args, **kwargs)]\nmodin\\experimental\\cloud\\meta_magic.py:155: in __new__\n    return cls.__real_cls__(*a, **kw)\nmodin\\experimental\\cloud\\rpyc_proxy.py:436: in __init__\n    a, kw = preprocess(*a, **kw)\nmodin\\experimental\\cloud\\rpyc_proxy.py:643: in _preprocess_init_args\n    (data,) = conn.deliver((data,), {})[0]\nmodin\\experimental\\cloud\\rpyc_proxy.py:81: in deliver\n    remote = iter(self._remote_batch_loads(tuple(pickled)))\nC:\\Users\\alozovsk\\Anaconda3\\envs\\modin\\lib\\site-packages\\rpyc\\core\\netref.py:254: in __call__\n    return syncreq(_self, consts.HANDLE_CALL, args, kwargs)\nC:\\Users\\alozovsk\\Anaconda3\\envs\\modin\\lib\\site-packages\\rpyc\\core\\netref.py:76: in syncreq\n    return conn.sync_request(handler, proxy, *args)\nmodin\\experimental\\cloud\\rpyc_proxy.py:165: in sync_request\n    return super().sync_request(handler, *args)\nC:\\Users\\alozovsk\\Anaconda3\\envs\\modin\\lib\\site-packages\\rpyc\\core\\protocol.py:500: in sync_request\n    return self.async_request(handler, *args, timeout=timeout).value\nC:\\Users\\alozovsk\\Anaconda3\\envs\\modin\\lib\\site-packages\\rpyc\\core\\async_.py:102: in value\n    raise self._obj\nE   _get_exception_class.<locals>.Derived: type object 'ndarray' has no attribute '__iter__'\nE   \nE   ========= Remote Traceback (1) =========\nE   Traceback (most recent call last):\nE     File \"C:\\Users\\alozovsk\\Anaconda3\\envs\\modin\\lib\\site-packages\\rpyc\\core\\protocol.py\", line 338, in _dispatch_request\nE       res = self._HANDLERS[handler](self, *args)\nE     File \"C:\\Users\\alozovsk\\Anaconda3\\envs\\modin\\lib\\site-packages\\rpyc\\core\\protocol.py\", line 630, in _handle_call\nE       return obj(*args, **dict(kwargs))\nE     File \"C:\\prog\\modin\\modin\\experimental\\cloud\\rpyc_proxy.py\", line 34, in _batch_loads\nE       return tuple(pickle.loads(item) for item in items)\nE     File \"C:\\prog\\modin\\modin\\experimental\\cloud\\rpyc_proxy.py\", line 34, in <genexpr>\nE       return tuple(pickle.loads(item) for item in items)\nE   AttributeError: type object 'ndarray' has no attribute '__iter__'"
                },
                "teardown": {
                    "name": "teardown",
                    "duration": 0.00046090000000020837,
                    "outcome": "passed"
                },
                "outcome": "failed"
            },
            {
                "name": "modin/pandas/test/dataframe/test_iter.py::test_constructor_dtypes[data2]",
                "duration": 0.01428929999999795,
                "run_index": 25,
                "setup": {
                    "name": "setup",
                    "duration": 0.0008989999999986509,
                    "outcome": "passed"
                },
                "call": {
                    "name": "call",
                    "duration": 0.011990400000000179,
                    "outcome": "failed",
                    "longrepr": "modin\\pandas\\test\\dataframe\\test_iter.py:295: in test_constructor_dtypes\n    md_df, pd_df = create_test_dfs(data)\nmodin\\pandas\\test\\utils.py:841: in create_test_dfs\n    post_fn, [pd.DataFrame(*args, **kwargs), pandas.DataFrame(*args, **kwargs)]\nmodin\\experimental\\cloud\\meta_magic.py:155: in __new__\n    return cls.__real_cls__(*a, **kw)\nmodin\\experimental\\cloud\\rpyc_proxy.py:436: in __init__\n    a, kw = preprocess(*a, **kw)\nmodin\\experimental\\cloud\\rpyc_proxy.py:643: in _preprocess_init_args\n    (data,) = conn.deliver((data,), {})[0]\nmodin\\experimental\\cloud\\rpyc_proxy.py:81: in deliver\n    remote = iter(self._remote_batch_loads(tuple(pickled)))\nC:\\Users\\alozovsk\\Anaconda3\\envs\\modin\\lib\\site-packages\\rpyc\\core\\netref.py:254: in __call__\n    return syncreq(_self, consts.HANDLE_CALL, args, kwargs)\nC:\\Users\\alozovsk\\Anaconda3\\envs\\modin\\lib\\site-packages\\rpyc\\core\\netref.py:76: in syncreq\n    return conn.sync_request(handler, proxy, *args)\nmodin\\experimental\\cloud\\rpyc_proxy.py:165: in sync_request\n    return super().sync_request(handler, *args)\nC:\\Users\\alozovsk\\Anaconda3\\envs\\modin\\lib\\site-packages\\rpyc\\core\\protocol.py:500: in sync_request\n    return self.async_request(handler, *args, timeout=timeout).value\nC:\\Users\\alozovsk\\Anaconda3\\envs\\modin\\lib\\site-packages\\rpyc\\core\\async_.py:102: in value\n    raise self._obj\nE   _get_exception_class.<locals>.Derived: type object 'ndarray' has no attribute '__iter__'\nE   \nE   ========= Remote Traceback (1) =========\nE   Traceback (most recent call last):\nE     File \"C:\\Users\\alozovsk\\Anaconda3\\envs\\modin\\lib\\site-packages\\rpyc\\core\\protocol.py\", line 338, in _dispatch_request\nE       res = self._HANDLERS[handler](self, *args)\nE     File \"C:\\Users\\alozovsk\\Anaconda3\\envs\\modin\\lib\\site-packages\\rpyc\\core\\protocol.py\", line 630, in _handle_call\nE       return obj(*args, **dict(kwargs))\nE     File \"C:\\prog\\modin\\modin\\experimental\\cloud\\rpyc_proxy.py\", line 34, in _batch_loads\nE       return tuple(pickle.loads(item) for item in items)\nE     File \"C:\\prog\\modin\\modin\\experimental\\cloud\\rpyc_proxy.py\", line 34, in <genexpr>\nE       return tuple(pickle.loads(item) for item in items)\nE   AttributeError: type object 'ndarray' has no attribute '__iter__'"
                },
                "teardown": {
                    "name": "teardown",
                    "duration": 0.0005009000000004704,
                    "outcome": "passed"
                },
                "outcome": "failed"
            },
            {
                "name": "modin/pandas/test/dataframe/test_iter.py::test_constructor_columns_and_index",
                "duration": 0.07015990000000016,
                "run_index": 26,
                "setup": {
                    "name": "setup",
                    "duration": 0.0005141999999995761,
                    "outcome": "passed"
                },
                "call": {
                    "name": "call",
                    "duration": 0.06586080000000116,
                    "outcome": "failed",
                    "longrepr": "modin\\pandas\\test\\dataframe\\test_iter.py:313: in test_constructor_columns_and_index\n    pd.DataFrame(modin_df, columns=[\"max_speed\", \"health\"]),\nmodin\\experimental\\cloud\\meta_magic.py:155: in __new__\n    return cls.__real_cls__(*a, **kw)\nmodin\\experimental\\cloud\\rpyc_proxy.py:438: in __init__\n    __remote_end__ = remote_cls(*a, **kw)\nC:\\Users\\alozovsk\\Anaconda3\\envs\\modin\\lib\\site-packages\\rpyc\\core\\netref.py:254: in __call__\n    return syncreq(_self, consts.HANDLE_CALL, args, kwargs)\nC:\\Users\\alozovsk\\Anaconda3\\envs\\modin\\lib\\site-packages\\rpyc\\core\\netref.py:76: in syncreq\n    return conn.sync_request(handler, proxy, *args)\nmodin\\experimental\\cloud\\rpyc_proxy.py:165: in sync_request\n    return super().sync_request(handler, *args)\nC:\\Users\\alozovsk\\Anaconda3\\envs\\modin\\lib\\site-packages\\rpyc\\core\\protocol.py:500: in sync_request\n    return self.async_request(handler, *args, timeout=timeout).value\nC:\\Users\\alozovsk\\Anaconda3\\envs\\modin\\lib\\site-packages\\rpyc\\core\\async_.py:102: in value\n    raise self._obj\nE   _get_exception_class.<locals>.Derived: 'list' object is not callable\nE   \nE   ========= Remote Traceback (2) =========\nE   Traceback (most recent call last):\nE     File \"C:\\Users\\alozovsk\\Anaconda3\\envs\\modin\\lib\\site-packages\\rpyc\\core\\protocol.py\", line 338, in _dispatch_request\nE       res = self._HANDLERS[handler](self, *args)\nE     File \"C:\\Users\\alozovsk\\Anaconda3\\envs\\modin\\lib\\site-packages\\rpyc\\core\\protocol.py\", line 630, in _handle_call\nE       return obj(*args, **dict(kwargs))\nE     File \"C:\\prog\\modin\\modin\\pandas\\dataframe.py\", line 141, in __init__\nE       self._query_compiler = data.loc[index, columns]._query_compiler\nE     File \"C:\\prog\\modin\\modin\\pandas\\indexing.py\", line 654, in __getitem__\nE       row_loc, col_loc, ndim = self._parse_row_and_column_locators(key)\nE     File \"C:\\prog\\modin\\modin\\pandas\\indexing.py\", line 583, in _parse_row_and_column_locators\nE       col_loc = col_loc(self.df) if callable(col_loc) else col_loc\nE     File \"C:\\Users\\alozovsk\\Anaconda3\\envs\\modin\\lib\\site-packages\\rpyc\\core\\netref.py\", line 254, in __call__\nE       return syncreq(_self, consts.HANDLE_CALL, args, kwargs)\nE     File \"C:\\Users\\alozovsk\\Anaconda3\\envs\\modin\\lib\\site-packages\\rpyc\\core\\netref.py\", line 76, in syncreq\nE       return conn.sync_request(handler, proxy, *args)\nE     File \"C:\\Users\\alozovsk\\Anaconda3\\envs\\modin\\lib\\site-packages\\rpyc\\core\\protocol.py\", line 500, in sync_request\nE       return self.async_request(handler, *args, timeout=timeout).value\nE     File \"C:\\Users\\alozovsk\\Anaconda3\\envs\\modin\\lib\\site-packages\\rpyc\\core\\async_.py\", line 102, in value\nE       raise self._obj\nE   _get_exception_class.<locals>.Derived: 'list' object is not callable\nE   \nE   ========= Remote Traceback (1) =========\nE   Traceback (most recent call last):\nE     File \"C:\\Users\\alozovsk\\Anaconda3\\envs\\modin\\lib\\site-packages\\rpyc\\core\\protocol.py\", line 338, in _dispatch_request\nE       res = self._HANDLERS[handler](self, *args)\nE     File \"C:\\Users\\alozovsk\\Anaconda3\\envs\\modin\\lib\\site-packages\\rpyc\\core\\protocol.py\", line 630, in _handle_call\nE       return obj(*args, **dict(kwargs))\nE   TypeError: 'list' object is not callable"
                },
                "teardown": {
                    "name": "teardown",
                    "duration": 0.0032706999999998487,
                    "outcome": "passed"
                },
                "outcome": "failed"
            }
        ],
        "summary": {
            "failed": 26,
            "passed": 1,
            "num_tests": 27,
            "duration": 14.248164415359497
        },
        "created_at": "2022-01-12 19:03:33.420393"
    }
}