{
    "report": {
        "environment": {
            "Python": "3.8.11",
            "Platform": "Windows-10-10.0.19042-SP0"
        },
        "tests": [
            {
                "name": "modin/pandas/test/dataframe/test_pickle.py::test_dataframe_pickle[True]",
                "duration": 10.749041599999998,
                "run_index": 0,
                "setup": {
                    "name": "setup",
                    "duration": 5.3738603,
                    "outcome": "error",
                    "longrepr": "modin\\pandas\\test\\dataframe\\test_pickle.py:26: in modin_df\n    return pd.DataFrame({\"col1\": np.arange(1000), \"col2\": np.arange(2000, 3000)})\nmodin\\experimental\\cloud\\meta_magic.py:155: in __new__\n    return cls.__real_cls__(*a, **kw)\nmodin\\experimental\\cloud\\rpyc_proxy.py:431: in __init__\n    __remote_end__ = remote_cls(*a, **kw)\nC:\\Users\\alozovsk\\Anaconda3\\envs\\modin\\lib\\site-packages\\rpyc\\core\\netref.py:253: in __call__\n    return syncreq(_self, consts.HANDLE_CALL, args, kwargs)\nC:\\Users\\alozovsk\\Anaconda3\\envs\\modin\\lib\\site-packages\\rpyc\\core\\netref.py:76: in syncreq\n    return conn.sync_request(handler, proxy, *args)\nmodin\\experimental\\cloud\\rpyc_proxy.py:165: in sync_request\n    return super().sync_request(handler, *args)\nC:\\Users\\alozovsk\\Anaconda3\\envs\\modin\\lib\\site-packages\\rpyc\\core\\protocol.py:484: in sync_request\n    return self.async_request(handler, *args, timeout=timeout).value\nC:\\Users\\alozovsk\\Anaconda3\\envs\\modin\\lib\\site-packages\\rpyc\\core\\async_.py:102: in value\n    raise self._obj\nE   _get_exception_class.<locals>.Derived: Cannot interpret 'dtype('int32')' as a data type\nE   \nE   ========= Remote Traceback (1) =========\nE   Traceback (most recent call last):\nE     File \"C:\\Users\\alozovsk\\Anaconda3\\envs\\modin\\lib\\site-packages\\rpyc\\core\\protocol.py\", line 326, in _dispatch_request\nE       res = self._HANDLERS[handler](self, *args)\nE     File \"C:\\Users\\alozovsk\\Anaconda3\\envs\\modin\\lib\\site-packages\\rpyc\\core\\protocol.py\", line 614, in _handle_call\nE       return obj(*args, **dict(kwargs))\nE     File \"C:\\prog\\modin\\modin\\pandas\\dataframe.py\", line 172, in __init__\nE       pandas_df = pandas.DataFrame(\nE     File \"C:\\Users\\alozovsk\\Anaconda3\\envs\\modin\\lib\\site-packages\\pandas\\core\\frame.py\", line 614, in __init__\nE       mgr = dict_to_mgr(data, index, columns, dtype=dtype, copy=copy, typ=manager)\nE     File \"C:\\Users\\alozovsk\\Anaconda3\\envs\\modin\\lib\\site-packages\\pandas\\core\\internals\\construction.py\", line 464, in dict_to_mgr\nE       return arrays_to_mgr(\nE     File \"C:\\Users\\alozovsk\\Anaconda3\\envs\\modin\\lib\\site-packages\\pandas\\core\\internals\\construction.py\", line 135, in arrays_to_mgr\nE       return create_block_manager_from_arrays(\nE     File \"C:\\Users\\alozovsk\\Anaconda3\\envs\\modin\\lib\\site-packages\\pandas\\core\\internals\\managers.py\", line 1773, in create_block_manager_from_arrays\nE       blocks = _form_blocks(arrays, names, axes, consolidate)\nE     File \"C:\\Users\\alozovsk\\Anaconda3\\envs\\modin\\lib\\site-packages\\pandas\\core\\internals\\managers.py\", line 1838, in _form_blocks\nE       numeric_blocks = _multi_blockify(\nE     File \"C:\\Users\\alozovsk\\Anaconda3\\envs\\modin\\lib\\site-packages\\pandas\\core\\internals\\managers.py\", line 1928, in _multi_blockify\nE       values, placement = _stack_arrays(\nE     File \"C:\\Users\\alozovsk\\Anaconda3\\envs\\modin\\lib\\site-packages\\pandas\\core\\internals\\managers.py\", line 1957, in _stack_arrays\nE       stacked = np.empty(shape, dtype=dtype)\nE   TypeError: Cannot interpret 'dtype('int32')' as a data type",
                    "stderr": "INFO:SLAVE/18813:server started on [127.0.0.1]:18813\r\nINFO:SLAVE/18813:accepted ('127.0.0.1', 65496) with fd 580\r\nINFO:SLAVE/18813:welcome ('127.0.0.1', 65496)\r\nUserWarning: Distributing <netref class 'rpyc.core.netref.type'> object. This may take some time.\r\nDEBUG:SLAVE/18813:Exception caught\r\nTraceback (most recent call last):\r\n  File \"C:\\Users\\alozovsk\\Anaconda3\\envs\\modin\\lib\\site-packages\\rpyc\\core\\protocol.py\", line 326, in _dispatch_request\r\n    res = self._HANDLERS[handler](self, *args)\r\n  File \"C:\\Users\\alozovsk\\Anaconda3\\envs\\modin\\lib\\site-packages\\rpyc\\core\\protocol.py\", line 630, in _handle_getattr\r\n    return self._access_attr(obj, name, (), \"_rpyc_getattr\", \"allow_getattr\", getattr)\r\n  File \"C:\\Users\\alozovsk\\Anaconda3\\envs\\modin\\lib\\site-packages\\rpyc\\core\\protocol.py\", line 552, in _access_attr\r\n    return accessor(obj, name, *args)\r\nAttributeError: type object 'object' has no attribute 'dtype'\r\nDEBUG:SLAVE/18813:Exception caught\r\nTraceback (most recent call last):\r\n  File \"C:\\Users\\alozovsk\\Anaconda3\\envs\\modin\\lib\\site-packages\\rpyc\\core\\protocol.py\", line 326, in _dispatch_request\r\n    res = self._HANDLERS[handler](self, *args)\r\n  File \"C:\\Users\\alozovsk\\Anaconda3\\envs\\modin\\lib\\site-packages\\rpyc\\core\\protocol.py\", line 630, in _handle_getattr\r\n    return self._access_attr(obj, name, (), \"_rpyc_getattr\", \"allow_getattr\", getattr)\r\n  File \"C:\\Users\\alozovsk\\Anaconda3\\envs\\modin\\lib\\site-packages\\rpyc\\core\\protocol.py\", line 552, in _access_attr\r\n    return accessor(obj, name, *args)\r\nAttributeError: type object 'object' has no attribute 'dtype'\r\nDEBUG:SLAVE/18813:Exception caught\r\nTraceback (most recent call last):\r\n  File \"C:\\Users\\alozovsk\\Anaconda3\\envs\\modin\\lib\\site-packages\\rpyc\\core\\protocol.py\", line 326, in _dispatch_request\r\n    res = self._HANDLERS[handler](self, *args)\r\n  File \"C:\\Users\\alozovsk\\Anaconda3\\envs\\modin\\lib\\site-packages\\rpyc\\core\\protocol.py\", line 630, in _handle_getattr\r\n    return self._access_attr(obj, name, (), \"_rpyc_getattr\", \"allow_getattr\", getattr)\r\n  File \"C:\\Users\\alozovsk\\Anaconda3\\envs\\modin\\lib\\site-packages\\rpyc\\core\\protocol.py\", line 552, in _access_attr\r\n    return accessor(obj, name, *args)\r\nAttributeError: type object 'object' has no attribute 'dtype'\r\nDEBUG:SLAVE/18813:Exception caught\r\nTraceback (most recent call last):\r\n  File \"C:\\Users\\alozovsk\\Anaconda3\\envs\\modin\\lib\\site-packages\\rpyc\\core\\protocol.py\", line 326, in _dispatch_request\r\n    res = self._HANDLERS[handler](self, *args)\r\n  File \"C:\\Users\\alozovsk\\Anaconda3\\envs\\modin\\lib\\site-packages\\rpyc\\core\\protocol.py\", line 630, in _handle_getattr\r\n    return self._access_attr(obj, name, (), \"_rpyc_getattr\", \"allow_getattr\", getattr)\r\n  File \"C:\\Users\\alozovsk\\Anaconda3\\envs\\modin\\lib\\site-packages\\rpyc\\core\\protocol.py\", line 552, in _access_attr\r\n    return accessor(obj, name, *args)\r\nAttributeError: type object 'object' has no attribute 'dtype'\r\nDEBUG:SLAVE/18813:Exception caught\r\nTraceback (most recent call last):\r\n  File \"C:\\Users\\alozovsk\\Anaconda3\\envs\\modin\\lib\\site-packages\\rpyc\\core\\protocol.py\", line 326, in _dispatch_request\r\n    res = self._HANDLERS[handler](self, *args)\r\n  File \"C:\\Users\\alozovsk\\Anaconda3\\envs\\modin\\lib\\site-packages\\rpyc\\core\\protocol.py\", line 614, in _handle_call\r\n    return obj(*args, **dict(kwargs))\r\n  File \"C:\\prog\\modin\\modin\\pandas\\dataframe.py\", line 172, in __init__\r\n    pandas_df = pandas.DataFrame(\r\n  File \"C:\\Users\\alozovsk\\Anaconda3\\envs\\modin\\lib\\site-packages\\pandas\\core\\frame.py\", line 614, in __init__\r\n    mgr = dict_to_mgr(data, index, columns, dtype=dtype, copy=copy, typ=manager)\r\n  File \"C:\\Users\\alozovsk\\Anaconda3\\envs\\modin\\lib\\site-packages\\pandas\\core\\internals\\construction.py\", line 464, in dict_to_mgr\r\n    return arrays_to_mgr(\r\n  File \"C:\\Users\\alozovsk\\Anaconda3\\envs\\modin\\lib\\site-packages\\pandas\\core\\internals\\construction.py\", line 135, in arrays_to_mgr\r\n    return create_block_manager_from_arrays(\r\n  File \"C:\\Users\\alozovsk\\Anaconda3\\envs\\modin\\lib\\site-packages\\pandas\\core\\internals\\managers.py\", line 1773, in create_block_manager_from_arrays\r\n    blocks = _form_blocks(arrays, names, axes, consolidate)\r\n  File \"C:\\Users\\alozovsk\\Anaconda3\\envs\\modin\\lib\\site-packages\\pandas\\core\\internals\\managers.py\", line 1838, in _form_blocks\r\n    numeric_blocks = _multi_blockify(\r\n  File \"C:\\Users\\alozovsk\\Anaconda3\\envs\\modin\\lib\\site-packages\\pandas\\core\\internals\\managers.py\", line 1928, in _multi_blockify\r\n    values, placement = _stack_arrays(\r\n  File \"C:\\Users\\alozovsk\\Anaconda3\\envs\\modin\\lib\\site-packages\\pandas\\core\\internals\\managers.py\", line 1957, in _stack_arrays\r\n    stacked = np.empty(shape, dtype=dtype)\r\nTypeError: Cannot interpret 'dtype('int32')' as a data type\r\n"
                },
                "teardown": {
                    "name": "teardown",
                    "duration": 0.0013209999999990174,
                    "outcome": "passed"
                },
                "outcome": "error"
            },
            {
                "name": "modin/pandas/test/dataframe/test_pickle.py::test_dataframe_pickle[False]",
                "duration": 0.21550690000000117,
                "run_index": 1,
                "setup": {
                    "name": "setup",
                    "duration": 0.10742300000000071,
                    "outcome": "error",
                    "longrepr": "modin\\pandas\\test\\dataframe\\test_pickle.py:26: in modin_df\n    return pd.DataFrame({\"col1\": np.arange(1000), \"col2\": np.arange(2000, 3000)})\nmodin\\experimental\\cloud\\meta_magic.py:155: in __new__\n    return cls.__real_cls__(*a, **kw)\nmodin\\experimental\\cloud\\rpyc_proxy.py:431: in __init__\n    __remote_end__ = remote_cls(*a, **kw)\nC:\\Users\\alozovsk\\Anaconda3\\envs\\modin\\lib\\site-packages\\rpyc\\core\\netref.py:253: in __call__\n    return syncreq(_self, consts.HANDLE_CALL, args, kwargs)\nC:\\Users\\alozovsk\\Anaconda3\\envs\\modin\\lib\\site-packages\\rpyc\\core\\netref.py:76: in syncreq\n    return conn.sync_request(handler, proxy, *args)\nmodin\\experimental\\cloud\\rpyc_proxy.py:165: in sync_request\n    return super().sync_request(handler, *args)\nC:\\Users\\alozovsk\\Anaconda3\\envs\\modin\\lib\\site-packages\\rpyc\\core\\protocol.py:484: in sync_request\n    return self.async_request(handler, *args, timeout=timeout).value\nC:\\Users\\alozovsk\\Anaconda3\\envs\\modin\\lib\\site-packages\\rpyc\\core\\async_.py:102: in value\n    raise self._obj\nE   _get_exception_class.<locals>.Derived: Cannot interpret 'dtype('int32')' as a data type\nE   \nE   ========= Remote Traceback (1) =========\nE   Traceback (most recent call last):\nE     File \"C:\\Users\\alozovsk\\Anaconda3\\envs\\modin\\lib\\site-packages\\rpyc\\core\\protocol.py\", line 326, in _dispatch_request\nE       res = self._HANDLERS[handler](self, *args)\nE     File \"C:\\Users\\alozovsk\\Anaconda3\\envs\\modin\\lib\\site-packages\\rpyc\\core\\protocol.py\", line 614, in _handle_call\nE       return obj(*args, **dict(kwargs))\nE     File \"C:\\prog\\modin\\modin\\pandas\\dataframe.py\", line 172, in __init__\nE       pandas_df = pandas.DataFrame(\nE     File \"C:\\Users\\alozovsk\\Anaconda3\\envs\\modin\\lib\\site-packages\\pandas\\core\\frame.py\", line 614, in __init__\nE       mgr = dict_to_mgr(data, index, columns, dtype=dtype, copy=copy, typ=manager)\nE     File \"C:\\Users\\alozovsk\\Anaconda3\\envs\\modin\\lib\\site-packages\\pandas\\core\\internals\\construction.py\", line 464, in dict_to_mgr\nE       return arrays_to_mgr(\nE     File \"C:\\Users\\alozovsk\\Anaconda3\\envs\\modin\\lib\\site-packages\\pandas\\core\\internals\\construction.py\", line 135, in arrays_to_mgr\nE       return create_block_manager_from_arrays(\nE     File \"C:\\Users\\alozovsk\\Anaconda3\\envs\\modin\\lib\\site-packages\\pandas\\core\\internals\\managers.py\", line 1773, in create_block_manager_from_arrays\nE       blocks = _form_blocks(arrays, names, axes, consolidate)\nE     File \"C:\\Users\\alozovsk\\Anaconda3\\envs\\modin\\lib\\site-packages\\pandas\\core\\internals\\managers.py\", line 1838, in _form_blocks\nE       numeric_blocks = _multi_blockify(\nE     File \"C:\\Users\\alozovsk\\Anaconda3\\envs\\modin\\lib\\site-packages\\pandas\\core\\internals\\managers.py\", line 1928, in _multi_blockify\nE       values, placement = _stack_arrays(\nE     File \"C:\\Users\\alozovsk\\Anaconda3\\envs\\modin\\lib\\site-packages\\pandas\\core\\internals\\managers.py\", line 1957, in _stack_arrays\nE       stacked = np.empty(shape, dtype=dtype)\nE   TypeError: Cannot interpret 'dtype('int32')' as a data type",
                    "stderr": "DEBUG:SLAVE/18813:Exception caught\r\nTraceback (most recent call last):\r\n  File \"C:\\Users\\alozovsk\\Anaconda3\\envs\\modin\\lib\\site-packages\\rpyc\\core\\protocol.py\", line 326, in _dispatch_request\r\n    res = self._HANDLERS[handler](self, *args)\r\n  File \"C:\\Users\\alozovsk\\Anaconda3\\envs\\modin\\lib\\site-packages\\rpyc\\core\\protocol.py\", line 630, in _handle_getattr\r\n    return self._access_attr(obj, name, (), \"_rpyc_getattr\", \"allow_getattr\", getattr)\r\n  File \"C:\\Users\\alozovsk\\Anaconda3\\envs\\modin\\lib\\site-packages\\rpyc\\core\\protocol.py\", line 552, in _access_attr\r\n    return accessor(obj, name, *args)\r\nAttributeError: type object 'object' has no attribute 'dtype'\r\nDEBUG:SLAVE/18813:Exception caught\r\nTraceback (most recent call last):\r\n  File \"C:\\Users\\alozovsk\\Anaconda3\\envs\\modin\\lib\\site-packages\\rpyc\\core\\protocol.py\", line 326, in _dispatch_request\r\n    res = self._HANDLERS[handler](self, *args)\r\n  File \"C:\\Users\\alozovsk\\Anaconda3\\envs\\modin\\lib\\site-packages\\rpyc\\core\\protocol.py\", line 630, in _handle_getattr\r\n    return self._access_attr(obj, name, (), \"_rpyc_getattr\", \"allow_getattr\", getattr)\r\n  File \"C:\\Users\\alozovsk\\Anaconda3\\envs\\modin\\lib\\site-packages\\rpyc\\core\\protocol.py\", line 552, in _access_attr\r\n    return accessor(obj, name, *args)\r\nAttributeError: type object 'object' has no attribute 'dtype'\r\nDEBUG:SLAVE/18813:Exception caught\r\nTraceback (most recent call last):\r\n  File \"C:\\Users\\alozovsk\\Anaconda3\\envs\\modin\\lib\\site-packages\\rpyc\\core\\protocol.py\", line 326, in _dispatch_request\r\n    res = self._HANDLERS[handler](self, *args)\r\n  File \"C:\\Users\\alozovsk\\Anaconda3\\envs\\modin\\lib\\site-packages\\rpyc\\core\\protocol.py\", line 630, in _handle_getattr\r\n    return self._access_attr(obj, name, (), \"_rpyc_getattr\", \"allow_getattr\", getattr)\r\n  File \"C:\\Users\\alozovsk\\Anaconda3\\envs\\modin\\lib\\site-packages\\rpyc\\core\\protocol.py\", line 552, in _access_attr\r\n    return accessor(obj, name, *args)\r\nAttributeError: type object 'object' has no attribute 'dtype'\r\nDEBUG:SLAVE/18813:Exception caught\r\nTraceback (most recent call last):\r\n  File \"C:\\Users\\alozovsk\\Anaconda3\\envs\\modin\\lib\\site-packages\\rpyc\\core\\protocol.py\", line 326, in _dispatch_request\r\n    res = self._HANDLERS[handler](self, *args)\r\n  File \"C:\\Users\\alozovsk\\Anaconda3\\envs\\modin\\lib\\site-packages\\rpyc\\core\\protocol.py\", line 630, in _handle_getattr\r\n    return self._access_attr(obj, name, (), \"_rpyc_getattr\", \"allow_getattr\", getattr)\r\n  File \"C:\\Users\\alozovsk\\Anaconda3\\envs\\modin\\lib\\site-packages\\rpyc\\core\\protocol.py\", line 552, in _access_attr\r\n    return accessor(obj, name, *args)\r\nAttributeError: type object 'object' has no attribute 'dtype'\r\nDEBUG:SLAVE/18813:Exception caught\r\nTraceback (most recent call last):\r\n  File \"C:\\Users\\alozovsk\\Anaconda3\\envs\\modin\\lib\\site-packages\\rpyc\\core\\protocol.py\", line 326, in _dispatch_request\r\n    res = self._HANDLERS[handler](self, *args)\r\n  File \"C:\\Users\\alozovsk\\Anaconda3\\envs\\modin\\lib\\site-packages\\rpyc\\core\\protocol.py\", line 614, in _handle_call\r\n    return obj(*args, **dict(kwargs))\r\n  File \"C:\\prog\\modin\\modin\\pandas\\dataframe.py\", line 172, in __init__\r\n    pandas_df = pandas.DataFrame(\r\n  File \"C:\\Users\\alozovsk\\Anaconda3\\envs\\modin\\lib\\site-packages\\pandas\\core\\frame.py\", line 614, in __init__\r\n    mgr = dict_to_mgr(data, index, columns, dtype=dtype, copy=copy, typ=manager)\r\n  File \"C:\\Users\\alozovsk\\Anaconda3\\envs\\modin\\lib\\site-packages\\pandas\\core\\internals\\construction.py\", line 464, in dict_to_mgr\r\n    return arrays_to_mgr(\r\n  File \"C:\\Users\\alozovsk\\Anaconda3\\envs\\modin\\lib\\site-packages\\pandas\\core\\internals\\construction.py\", line 135, in arrays_to_mgr\r\n    return create_block_manager_from_arrays(\r\n  File \"C:\\Users\\alozovsk\\Anaconda3\\envs\\modin\\lib\\site-packages\\pandas\\core\\internals\\managers.py\", line 1773, in create_block_manager_from_arrays\r\n    blocks = _form_blocks(arrays, names, axes, consolidate)\r\n  File \"C:\\Users\\alozovsk\\Anaconda3\\envs\\modin\\lib\\site-packages\\pandas\\core\\internals\\managers.py\", line 1838, in _form_blocks\r\n    numeric_blocks = _multi_blockify(\r\n  File \"C:\\Users\\alozovsk\\Anaconda3\\envs\\modin\\lib\\site-packages\\pandas\\core\\internals\\managers.py\", line 1928, in _multi_blockify\r\n    values, placement = _stack_arrays(\r\n  File \"C:\\Users\\alozovsk\\Anaconda3\\envs\\modin\\lib\\site-packages\\pandas\\core\\internals\\managers.py\", line 1957, in _stack_arrays\r\n    stacked = np.empty(shape, dtype=dtype)\r\nTypeError: Cannot interpret 'dtype('int32')' as a data type\r\n"
                },
                "teardown": {
                    "name": "teardown",
                    "duration": 0.0006608999999997422,
                    "outcome": "passed"
                },
                "outcome": "error"
            },
            {
                "name": "modin/pandas/test/dataframe/test_pickle.py::test_column_pickle[True]",
                "duration": 0.1976047000000012,
                "run_index": 2,
                "setup": {
                    "name": "setup",
                    "duration": 0.09855390000000064,
                    "outcome": "error",
                    "longrepr": "modin\\pandas\\test\\dataframe\\test_pickle.py:26: in modin_df\n    return pd.DataFrame({\"col1\": np.arange(1000), \"col2\": np.arange(2000, 3000)})\nmodin\\experimental\\cloud\\meta_magic.py:155: in __new__\n    return cls.__real_cls__(*a, **kw)\nmodin\\experimental\\cloud\\rpyc_proxy.py:431: in __init__\n    __remote_end__ = remote_cls(*a, **kw)\nC:\\Users\\alozovsk\\Anaconda3\\envs\\modin\\lib\\site-packages\\rpyc\\core\\netref.py:253: in __call__\n    return syncreq(_self, consts.HANDLE_CALL, args, kwargs)\nC:\\Users\\alozovsk\\Anaconda3\\envs\\modin\\lib\\site-packages\\rpyc\\core\\netref.py:76: in syncreq\n    return conn.sync_request(handler, proxy, *args)\nmodin\\experimental\\cloud\\rpyc_proxy.py:165: in sync_request\n    return super().sync_request(handler, *args)\nC:\\Users\\alozovsk\\Anaconda3\\envs\\modin\\lib\\site-packages\\rpyc\\core\\protocol.py:484: in sync_request\n    return self.async_request(handler, *args, timeout=timeout).value\nC:\\Users\\alozovsk\\Anaconda3\\envs\\modin\\lib\\site-packages\\rpyc\\core\\async_.py:102: in value\n    raise self._obj\nE   _get_exception_class.<locals>.Derived: Cannot interpret 'dtype('int32')' as a data type\nE   \nE   ========= Remote Traceback (1) =========\nE   Traceback (most recent call last):\nE     File \"C:\\Users\\alozovsk\\Anaconda3\\envs\\modin\\lib\\site-packages\\rpyc\\core\\protocol.py\", line 326, in _dispatch_request\nE       res = self._HANDLERS[handler](self, *args)\nE     File \"C:\\Users\\alozovsk\\Anaconda3\\envs\\modin\\lib\\site-packages\\rpyc\\core\\protocol.py\", line 614, in _handle_call\nE       return obj(*args, **dict(kwargs))\nE     File \"C:\\prog\\modin\\modin\\pandas\\dataframe.py\", line 172, in __init__\nE       pandas_df = pandas.DataFrame(\nE     File \"C:\\Users\\alozovsk\\Anaconda3\\envs\\modin\\lib\\site-packages\\pandas\\core\\frame.py\", line 614, in __init__\nE       mgr = dict_to_mgr(data, index, columns, dtype=dtype, copy=copy, typ=manager)\nE     File \"C:\\Users\\alozovsk\\Anaconda3\\envs\\modin\\lib\\site-packages\\pandas\\core\\internals\\construction.py\", line 464, in dict_to_mgr\nE       return arrays_to_mgr(\nE     File \"C:\\Users\\alozovsk\\Anaconda3\\envs\\modin\\lib\\site-packages\\pandas\\core\\internals\\construction.py\", line 135, in arrays_to_mgr\nE       return create_block_manager_from_arrays(\nE     File \"C:\\Users\\alozovsk\\Anaconda3\\envs\\modin\\lib\\site-packages\\pandas\\core\\internals\\managers.py\", line 1773, in create_block_manager_from_arrays\nE       blocks = _form_blocks(arrays, names, axes, consolidate)\nE     File \"C:\\Users\\alozovsk\\Anaconda3\\envs\\modin\\lib\\site-packages\\pandas\\core\\internals\\managers.py\", line 1838, in _form_blocks\nE       numeric_blocks = _multi_blockify(\nE     File \"C:\\Users\\alozovsk\\Anaconda3\\envs\\modin\\lib\\site-packages\\pandas\\core\\internals\\managers.py\", line 1928, in _multi_blockify\nE       values, placement = _stack_arrays(\nE     File \"C:\\Users\\alozovsk\\Anaconda3\\envs\\modin\\lib\\site-packages\\pandas\\core\\internals\\managers.py\", line 1957, in _stack_arrays\nE       stacked = np.empty(shape, dtype=dtype)\nE   TypeError: Cannot interpret 'dtype('int32')' as a data type",
                    "stderr": "DEBUG:SLAVE/18813:Exception caught\r\nTraceback (most recent call last):\r\n  File \"C:\\Users\\alozovsk\\Anaconda3\\envs\\modin\\lib\\site-packages\\rpyc\\core\\protocol.py\", line 326, in _dispatch_request\r\n    res = self._HANDLERS[handler](self, *args)\r\n  File \"C:\\Users\\alozovsk\\Anaconda3\\envs\\modin\\lib\\site-packages\\rpyc\\core\\protocol.py\", line 630, in _handle_getattr\r\n    return self._access_attr(obj, name, (), \"_rpyc_getattr\", \"allow_getattr\", getattr)\r\n  File \"C:\\Users\\alozovsk\\Anaconda3\\envs\\modin\\lib\\site-packages\\rpyc\\core\\protocol.py\", line 552, in _access_attr\r\n    return accessor(obj, name, *args)\r\nAttributeError: type object 'object' has no attribute 'dtype'\r\nDEBUG:SLAVE/18813:Exception caught\r\nTraceback (most recent call last):\r\n  File \"C:\\Users\\alozovsk\\Anaconda3\\envs\\modin\\lib\\site-packages\\rpyc\\core\\protocol.py\", line 326, in _dispatch_request\r\n    res = self._HANDLERS[handler](self, *args)\r\n  File \"C:\\Users\\alozovsk\\Anaconda3\\envs\\modin\\lib\\site-packages\\rpyc\\core\\protocol.py\", line 630, in _handle_getattr\r\n    return self._access_attr(obj, name, (), \"_rpyc_getattr\", \"allow_getattr\", getattr)\r\n  File \"C:\\Users\\alozovsk\\Anaconda3\\envs\\modin\\lib\\site-packages\\rpyc\\core\\protocol.py\", line 552, in _access_attr\r\n    return accessor(obj, name, *args)\r\nAttributeError: type object 'object' has no attribute 'dtype'\r\nDEBUG:SLAVE/18813:Exception caught\r\nTraceback (most recent call last):\r\n  File \"C:\\Users\\alozovsk\\Anaconda3\\envs\\modin\\lib\\site-packages\\rpyc\\core\\protocol.py\", line 326, in _dispatch_request\r\n    res = self._HANDLERS[handler](self, *args)\r\n  File \"C:\\Users\\alozovsk\\Anaconda3\\envs\\modin\\lib\\site-packages\\rpyc\\core\\protocol.py\", line 630, in _handle_getattr\r\n    return self._access_attr(obj, name, (), \"_rpyc_getattr\", \"allow_getattr\", getattr)\r\n  File \"C:\\Users\\alozovsk\\Anaconda3\\envs\\modin\\lib\\site-packages\\rpyc\\core\\protocol.py\", line 552, in _access_attr\r\n    return accessor(obj, name, *args)\r\nAttributeError: type object 'object' has no attribute 'dtype'\r\nDEBUG:SLAVE/18813:Exception caught\r\nTraceback (most recent call last):\r\n  File \"C:\\Users\\alozovsk\\Anaconda3\\envs\\modin\\lib\\site-packages\\rpyc\\core\\protocol.py\", line 326, in _dispatch_request\r\n    res = self._HANDLERS[handler](self, *args)\r\n  File \"C:\\Users\\alozovsk\\Anaconda3\\envs\\modin\\lib\\site-packages\\rpyc\\core\\protocol.py\", line 630, in _handle_getattr\r\n    return self._access_attr(obj, name, (), \"_rpyc_getattr\", \"allow_getattr\", getattr)\r\n  File \"C:\\Users\\alozovsk\\Anaconda3\\envs\\modin\\lib\\site-packages\\rpyc\\core\\protocol.py\", line 552, in _access_attr\r\n    return accessor(obj, name, *args)\r\nAttributeError: type object 'object' has no attribute 'dtype'\r\nDEBUG:SLAVE/18813:Exception caught\r\nTraceback (most recent call last):\r\n  File \"C:\\Users\\alozovsk\\Anaconda3\\envs\\modin\\lib\\site-packages\\rpyc\\core\\protocol.py\", line 326, in _dispatch_request\r\n    res = self._HANDLERS[handler](self, *args)\r\n  File \"C:\\Users\\alozovsk\\Anaconda3\\envs\\modin\\lib\\site-packages\\rpyc\\core\\protocol.py\", line 614, in _handle_call\r\n    return obj(*args, **dict(kwargs))\r\n  File \"C:\\prog\\modin\\modin\\pandas\\dataframe.py\", line 172, in __init__\r\n    pandas_df = pandas.DataFrame(\r\n  File \"C:\\Users\\alozovsk\\Anaconda3\\envs\\modin\\lib\\site-packages\\pandas\\core\\frame.py\", line 614, in __init__\r\n    mgr = dict_to_mgr(data, index, columns, dtype=dtype, copy=copy, typ=manager)\r\n  File \"C:\\Users\\alozovsk\\Anaconda3\\envs\\modin\\lib\\site-packages\\pandas\\core\\internals\\construction.py\", line 464, in dict_to_mgr\r\n    return arrays_to_mgr(\r\n  File \"C:\\Users\\alozovsk\\Anaconda3\\envs\\modin\\lib\\site-packages\\pandas\\core\\internals\\construction.py\", line 135, in arrays_to_mgr\r\n    return create_block_manager_from_arrays(\r\n  File \"C:\\Users\\alozovsk\\Anaconda3\\envs\\modin\\lib\\site-packages\\pandas\\core\\internals\\managers.py\", line 1773, in create_block_manager_from_arrays\r\n    blocks = _form_blocks(arrays, names, axes, consolidate)\r\n  File \"C:\\Users\\alozovsk\\Anaconda3\\envs\\modin\\lib\\site-packages\\pandas\\core\\internals\\managers.py\", line 1838, in _form_blocks\r\n    numeric_blocks = _multi_blockify(\r\n  File \"C:\\Users\\alozovsk\\Anaconda3\\envs\\modin\\lib\\site-packages\\pandas\\core\\internals\\managers.py\", line 1928, in _multi_blockify\r\n    values, placement = _stack_arrays(\r\n  File \"C:\\Users\\alozovsk\\Anaconda3\\envs\\modin\\lib\\site-packages\\pandas\\core\\internals\\managers.py\", line 1957, in _stack_arrays\r\n    stacked = np.empty(shape, dtype=dtype)\r\nTypeError: Cannot interpret 'dtype('int32')' as a data type\r\n"
                },
                "teardown": {
                    "name": "teardown",
                    "duration": 0.0004968999999999113,
                    "outcome": "passed"
                },
                "outcome": "error"
            },
            {
                "name": "modin/pandas/test/dataframe/test_pickle.py::test_column_pickle[False]",
                "duration": 0.2061547000000008,
                "run_index": 3,
                "setup": {
                    "name": "setup",
                    "duration": 0.10255219999999987,
                    "outcome": "error",
                    "longrepr": "modin\\pandas\\test\\dataframe\\test_pickle.py:26: in modin_df\n    return pd.DataFrame({\"col1\": np.arange(1000), \"col2\": np.arange(2000, 3000)})\nmodin\\experimental\\cloud\\meta_magic.py:155: in __new__\n    return cls.__real_cls__(*a, **kw)\nmodin\\experimental\\cloud\\rpyc_proxy.py:431: in __init__\n    __remote_end__ = remote_cls(*a, **kw)\nC:\\Users\\alozovsk\\Anaconda3\\envs\\modin\\lib\\site-packages\\rpyc\\core\\netref.py:253: in __call__\n    return syncreq(_self, consts.HANDLE_CALL, args, kwargs)\nC:\\Users\\alozovsk\\Anaconda3\\envs\\modin\\lib\\site-packages\\rpyc\\core\\netref.py:76: in syncreq\n    return conn.sync_request(handler, proxy, *args)\nmodin\\experimental\\cloud\\rpyc_proxy.py:165: in sync_request\n    return super().sync_request(handler, *args)\nC:\\Users\\alozovsk\\Anaconda3\\envs\\modin\\lib\\site-packages\\rpyc\\core\\protocol.py:484: in sync_request\n    return self.async_request(handler, *args, timeout=timeout).value\nC:\\Users\\alozovsk\\Anaconda3\\envs\\modin\\lib\\site-packages\\rpyc\\core\\async_.py:102: in value\n    raise self._obj\nE   _get_exception_class.<locals>.Derived: Cannot interpret 'dtype('int32')' as a data type\nE   \nE   ========= Remote Traceback (1) =========\nE   Traceback (most recent call last):\nE     File \"C:\\Users\\alozovsk\\Anaconda3\\envs\\modin\\lib\\site-packages\\rpyc\\core\\protocol.py\", line 326, in _dispatch_request\nE       res = self._HANDLERS[handler](self, *args)\nE     File \"C:\\Users\\alozovsk\\Anaconda3\\envs\\modin\\lib\\site-packages\\rpyc\\core\\protocol.py\", line 614, in _handle_call\nE       return obj(*args, **dict(kwargs))\nE     File \"C:\\prog\\modin\\modin\\pandas\\dataframe.py\", line 172, in __init__\nE       pandas_df = pandas.DataFrame(\nE     File \"C:\\Users\\alozovsk\\Anaconda3\\envs\\modin\\lib\\site-packages\\pandas\\core\\frame.py\", line 614, in __init__\nE       mgr = dict_to_mgr(data, index, columns, dtype=dtype, copy=copy, typ=manager)\nE     File \"C:\\Users\\alozovsk\\Anaconda3\\envs\\modin\\lib\\site-packages\\pandas\\core\\internals\\construction.py\", line 464, in dict_to_mgr\nE       return arrays_to_mgr(\nE     File \"C:\\Users\\alozovsk\\Anaconda3\\envs\\modin\\lib\\site-packages\\pandas\\core\\internals\\construction.py\", line 135, in arrays_to_mgr\nE       return create_block_manager_from_arrays(\nE     File \"C:\\Users\\alozovsk\\Anaconda3\\envs\\modin\\lib\\site-packages\\pandas\\core\\internals\\managers.py\", line 1773, in create_block_manager_from_arrays\nE       blocks = _form_blocks(arrays, names, axes, consolidate)\nE     File \"C:\\Users\\alozovsk\\Anaconda3\\envs\\modin\\lib\\site-packages\\pandas\\core\\internals\\managers.py\", line 1838, in _form_blocks\nE       numeric_blocks = _multi_blockify(\nE     File \"C:\\Users\\alozovsk\\Anaconda3\\envs\\modin\\lib\\site-packages\\pandas\\core\\internals\\managers.py\", line 1928, in _multi_blockify\nE       values, placement = _stack_arrays(\nE     File \"C:\\Users\\alozovsk\\Anaconda3\\envs\\modin\\lib\\site-packages\\pandas\\core\\internals\\managers.py\", line 1957, in _stack_arrays\nE       stacked = np.empty(shape, dtype=dtype)\nE   TypeError: Cannot interpret 'dtype('int32')' as a data type",
                    "stderr": "DEBUG:SLAVE/18813:Exception caught\r\nTraceback (most recent call last):\r\n  File \"C:\\Users\\alozovsk\\Anaconda3\\envs\\modin\\lib\\site-packages\\rpyc\\core\\protocol.py\", line 326, in _dispatch_request\r\n    res = self._HANDLERS[handler](self, *args)\r\n  File \"C:\\Users\\alozovsk\\Anaconda3\\envs\\modin\\lib\\site-packages\\rpyc\\core\\protocol.py\", line 630, in _handle_getattr\r\n    return self._access_attr(obj, name, (), \"_rpyc_getattr\", \"allow_getattr\", getattr)\r\n  File \"C:\\Users\\alozovsk\\Anaconda3\\envs\\modin\\lib\\site-packages\\rpyc\\core\\protocol.py\", line 552, in _access_attr\r\n    return accessor(obj, name, *args)\r\nAttributeError: type object 'object' has no attribute 'dtype'\r\nDEBUG:SLAVE/18813:Exception caught\r\nTraceback (most recent call last):\r\n  File \"C:\\Users\\alozovsk\\Anaconda3\\envs\\modin\\lib\\site-packages\\rpyc\\core\\protocol.py\", line 326, in _dispatch_request\r\n    res = self._HANDLERS[handler](self, *args)\r\n  File \"C:\\Users\\alozovsk\\Anaconda3\\envs\\modin\\lib\\site-packages\\rpyc\\core\\protocol.py\", line 630, in _handle_getattr\r\n    return self._access_attr(obj, name, (), \"_rpyc_getattr\", \"allow_getattr\", getattr)\r\n  File \"C:\\Users\\alozovsk\\Anaconda3\\envs\\modin\\lib\\site-packages\\rpyc\\core\\protocol.py\", line 552, in _access_attr\r\n    return accessor(obj, name, *args)\r\nAttributeError: type object 'object' has no attribute 'dtype'\r\nDEBUG:SLAVE/18813:Exception caught\r\nTraceback (most recent call last):\r\n  File \"C:\\Users\\alozovsk\\Anaconda3\\envs\\modin\\lib\\site-packages\\rpyc\\core\\protocol.py\", line 326, in _dispatch_request\r\n    res = self._HANDLERS[handler](self, *args)\r\n  File \"C:\\Users\\alozovsk\\Anaconda3\\envs\\modin\\lib\\site-packages\\rpyc\\core\\protocol.py\", line 630, in _handle_getattr\r\n    return self._access_attr(obj, name, (), \"_rpyc_getattr\", \"allow_getattr\", getattr)\r\n  File \"C:\\Users\\alozovsk\\Anaconda3\\envs\\modin\\lib\\site-packages\\rpyc\\core\\protocol.py\", line 552, in _access_attr\r\n    return accessor(obj, name, *args)\r\nAttributeError: type object 'object' has no attribute 'dtype'\r\nDEBUG:SLAVE/18813:Exception caught\r\nTraceback (most recent call last):\r\n  File \"C:\\Users\\alozovsk\\Anaconda3\\envs\\modin\\lib\\site-packages\\rpyc\\core\\protocol.py\", line 326, in _dispatch_request\r\n    res = self._HANDLERS[handler](self, *args)\r\n  File \"C:\\Users\\alozovsk\\Anaconda3\\envs\\modin\\lib\\site-packages\\rpyc\\core\\protocol.py\", line 630, in _handle_getattr\r\n    return self._access_attr(obj, name, (), \"_rpyc_getattr\", \"allow_getattr\", getattr)\r\n  File \"C:\\Users\\alozovsk\\Anaconda3\\envs\\modin\\lib\\site-packages\\rpyc\\core\\protocol.py\", line 552, in _access_attr\r\n    return accessor(obj, name, *args)\r\nAttributeError: type object 'object' has no attribute 'dtype'\r\nDEBUG:SLAVE/18813:Exception caught\r\nTraceback (most recent call last):\r\n  File \"C:\\Users\\alozovsk\\Anaconda3\\envs\\modin\\lib\\site-packages\\rpyc\\core\\protocol.py\", line 326, in _dispatch_request\r\n    res = self._HANDLERS[handler](self, *args)\r\n  File \"C:\\Users\\alozovsk\\Anaconda3\\envs\\modin\\lib\\site-packages\\rpyc\\core\\protocol.py\", line 614, in _handle_call\r\n    return obj(*args, **dict(kwargs))\r\n  File \"C:\\prog\\modin\\modin\\pandas\\dataframe.py\", line 172, in __init__\r\n    pandas_df = pandas.DataFrame(\r\n  File \"C:\\Users\\alozovsk\\Anaconda3\\envs\\modin\\lib\\site-packages\\pandas\\core\\frame.py\", line 614, in __init__\r\n    mgr = dict_to_mgr(data, index, columns, dtype=dtype, copy=copy, typ=manager)\r\n  File \"C:\\Users\\alozovsk\\Anaconda3\\envs\\modin\\lib\\site-packages\\pandas\\core\\internals\\construction.py\", line 464, in dict_to_mgr\r\n    return arrays_to_mgr(\r\n  File \"C:\\Users\\alozovsk\\Anaconda3\\envs\\modin\\lib\\site-packages\\pandas\\core\\internals\\construction.py\", line 135, in arrays_to_mgr\r\n    return create_block_manager_from_arrays(\r\n  File \"C:\\Users\\alozovsk\\Anaconda3\\envs\\modin\\lib\\site-packages\\pandas\\core\\internals\\managers.py\", line 1773, in create_block_manager_from_arrays\r\n    blocks = _form_blocks(arrays, names, axes, consolidate)\r\n  File \"C:\\Users\\alozovsk\\Anaconda3\\envs\\modin\\lib\\site-packages\\pandas\\core\\internals\\managers.py\", line 1838, in _form_blocks\r\n    numeric_blocks = _multi_blockify(\r\n  File \"C:\\Users\\alozovsk\\Anaconda3\\envs\\modin\\lib\\site-packages\\pandas\\core\\internals\\managers.py\", line 1928, in _multi_blockify\r\n    values, placement = _stack_arrays(\r\n  File \"C:\\Users\\alozovsk\\Anaconda3\\envs\\modin\\lib\\site-packages\\pandas\\core\\internals\\managers.py\", line 1957, in _stack_arrays\r\n    stacked = np.empty(shape, dtype=dtype)\r\nTypeError: Cannot interpret 'dtype('int32')' as a data type\r\n"
                },
                "teardown": {
                    "name": "teardown",
                    "duration": 0.0010503000000010587,
                    "outcome": "passed"
                },
                "outcome": "error"
            }
        ],
        "summary": {
            "error": 4,
            "num_tests": 4,
            "duration": 10.114486694335938
        },
        "created_at": "2021-10-01 12:08:07.938995"
    }
}