{
    "report": {
        "environment": {
            "Python": "3.8.11",
            "Platform": "Windows-10-10.0.19042-SP0"
        },
        "tests": [
            {
                "name": "modin/pandas/test/dataframe/test_pickle.py::test_dataframe_pickle[True]",
                "duration": 11.2319207,
                "run_index": 0,
                "setup": {
                    "name": "setup",
                    "duration": 5.6155322,
                    "outcome": "error",
                    "longrepr": "modin\\pandas\\test\\dataframe\\test_pickle.py:26: in modin_df\n    return pd.DataFrame({\"col1\": np.arange(1000), \"col2\": np.arange(2000, 3000)})\nmodin\\experimental\\cloud\\meta_magic.py:155: in __new__\n    return cls.__real_cls__(*a, **kw)\nmodin\\experimental\\cloud\\rpyc_proxy.py:431: in __init__\n    __remote_end__ = remote_cls(*a, **kw)\nC:\\Users\\alozovsk\\Anaconda3\\envs\\modin\\lib\\site-packages\\rpyc\\core\\netref.py:254: in __call__\n    return syncreq(_self, consts.HANDLE_CALL, args, kwargs)\nC:\\Users\\alozovsk\\Anaconda3\\envs\\modin\\lib\\site-packages\\rpyc\\core\\netref.py:76: in syncreq\n    return conn.sync_request(handler, proxy, *args)\nmodin\\experimental\\cloud\\rpyc_proxy.py:165: in sync_request\n    return super().sync_request(handler, *args)\nC:\\Users\\alozovsk\\Anaconda3\\envs\\modin\\lib\\site-packages\\rpyc\\core\\protocol.py:484: in sync_request\n    return self.async_request(handler, *args, timeout=timeout).value\nC:\\Users\\alozovsk\\Anaconda3\\envs\\modin\\lib\\site-packages\\rpyc\\core\\async_.py:102: in value\n    raise self._obj\nE   _get_exception_class.<locals>.Derived: Cannot interpret 'dtype('int32')' as a data type\nE   \nE   ========= Remote Traceback (1) =========\nE   Traceback (most recent call last):\nE     File \"C:\\Users\\alozovsk\\Anaconda3\\envs\\modin\\lib\\site-packages\\rpyc\\core\\protocol.py\", line 326, in _dispatch_request\nE       res = self._HANDLERS[handler](self, *args)\nE     File \"C:\\Users\\alozovsk\\Anaconda3\\envs\\modin\\lib\\site-packages\\rpyc\\core\\protocol.py\", line 614, in _handle_call\nE       return obj(*args, **dict(kwargs))\nE     File \"C:\\prog\\modin\\modin\\pandas\\dataframe.py\", line 172, in __init__\nE       pandas_df = pandas.DataFrame(\nE     File \"C:\\Users\\alozovsk\\Anaconda3\\envs\\modin\\lib\\site-packages\\pandas\\core\\frame.py\", line 614, in __init__\nE       mgr = dict_to_mgr(data, index, columns, dtype=dtype, copy=copy, typ=manager)\nE     File \"C:\\Users\\alozovsk\\Anaconda3\\envs\\modin\\lib\\site-packages\\pandas\\core\\internals\\construction.py\", line 464, in dict_to_mgr\nE       return arrays_to_mgr(\nE     File \"C:\\Users\\alozovsk\\Anaconda3\\envs\\modin\\lib\\site-packages\\pandas\\core\\internals\\construction.py\", line 135, in arrays_to_mgr\nE       return create_block_manager_from_arrays(\nE     File \"C:\\Users\\alozovsk\\Anaconda3\\envs\\modin\\lib\\site-packages\\pandas\\core\\internals\\managers.py\", line 1773, in create_block_manager_from_arrays\nE       blocks = _form_blocks(arrays, names, axes, consolidate)\nE     File \"C:\\Users\\alozovsk\\Anaconda3\\envs\\modin\\lib\\site-packages\\pandas\\core\\internals\\managers.py\", line 1838, in _form_blocks\nE       numeric_blocks = _multi_blockify(\nE     File \"C:\\Users\\alozovsk\\Anaconda3\\envs\\modin\\lib\\site-packages\\pandas\\core\\internals\\managers.py\", line 1928, in _multi_blockify\nE       values, placement = _stack_arrays(\nE     File \"C:\\Users\\alozovsk\\Anaconda3\\envs\\modin\\lib\\site-packages\\pandas\\core\\internals\\managers.py\", line 1957, in _stack_arrays\nE       stacked = np.empty(shape, dtype=dtype)\nE   TypeError: Cannot interpret 'dtype('int32')' as a data type"
                },
                "teardown": {
                    "name": "teardown",
                    "duration": 0.0008563000000005871,
                    "outcome": "passed"
                },
                "outcome": "error"
            },
            {
                "name": "modin/pandas/test/dataframe/test_pickle.py::test_dataframe_pickle[False]",
                "duration": 0.21322679999999927,
                "run_index": 1,
                "setup": {
                    "name": "setup",
                    "duration": 0.10632969999999986,
                    "outcome": "error",
                    "longrepr": "modin\\pandas\\test\\dataframe\\test_pickle.py:26: in modin_df\n    return pd.DataFrame({\"col1\": np.arange(1000), \"col2\": np.arange(2000, 3000)})\nmodin\\experimental\\cloud\\meta_magic.py:155: in __new__\n    return cls.__real_cls__(*a, **kw)\nmodin\\experimental\\cloud\\rpyc_proxy.py:431: in __init__\n    __remote_end__ = remote_cls(*a, **kw)\nC:\\Users\\alozovsk\\Anaconda3\\envs\\modin\\lib\\site-packages\\rpyc\\core\\netref.py:254: in __call__\n    return syncreq(_self, consts.HANDLE_CALL, args, kwargs)\nC:\\Users\\alozovsk\\Anaconda3\\envs\\modin\\lib\\site-packages\\rpyc\\core\\netref.py:76: in syncreq\n    return conn.sync_request(handler, proxy, *args)\nmodin\\experimental\\cloud\\rpyc_proxy.py:165: in sync_request\n    return super().sync_request(handler, *args)\nC:\\Users\\alozovsk\\Anaconda3\\envs\\modin\\lib\\site-packages\\rpyc\\core\\protocol.py:484: in sync_request\n    return self.async_request(handler, *args, timeout=timeout).value\nC:\\Users\\alozovsk\\Anaconda3\\envs\\modin\\lib\\site-packages\\rpyc\\core\\async_.py:102: in value\n    raise self._obj\nE   _get_exception_class.<locals>.Derived: Cannot interpret 'dtype('int32')' as a data type\nE   \nE   ========= Remote Traceback (1) =========\nE   Traceback (most recent call last):\nE     File \"C:\\Users\\alozovsk\\Anaconda3\\envs\\modin\\lib\\site-packages\\rpyc\\core\\protocol.py\", line 326, in _dispatch_request\nE       res = self._HANDLERS[handler](self, *args)\nE     File \"C:\\Users\\alozovsk\\Anaconda3\\envs\\modin\\lib\\site-packages\\rpyc\\core\\protocol.py\", line 614, in _handle_call\nE       return obj(*args, **dict(kwargs))\nE     File \"C:\\prog\\modin\\modin\\pandas\\dataframe.py\", line 172, in __init__\nE       pandas_df = pandas.DataFrame(\nE     File \"C:\\Users\\alozovsk\\Anaconda3\\envs\\modin\\lib\\site-packages\\pandas\\core\\frame.py\", line 614, in __init__\nE       mgr = dict_to_mgr(data, index, columns, dtype=dtype, copy=copy, typ=manager)\nE     File \"C:\\Users\\alozovsk\\Anaconda3\\envs\\modin\\lib\\site-packages\\pandas\\core\\internals\\construction.py\", line 464, in dict_to_mgr\nE       return arrays_to_mgr(\nE     File \"C:\\Users\\alozovsk\\Anaconda3\\envs\\modin\\lib\\site-packages\\pandas\\core\\internals\\construction.py\", line 135, in arrays_to_mgr\nE       return create_block_manager_from_arrays(\nE     File \"C:\\Users\\alozovsk\\Anaconda3\\envs\\modin\\lib\\site-packages\\pandas\\core\\internals\\managers.py\", line 1773, in create_block_manager_from_arrays\nE       blocks = _form_blocks(arrays, names, axes, consolidate)\nE     File \"C:\\Users\\alozovsk\\Anaconda3\\envs\\modin\\lib\\site-packages\\pandas\\core\\internals\\managers.py\", line 1838, in _form_blocks\nE       numeric_blocks = _multi_blockify(\nE     File \"C:\\Users\\alozovsk\\Anaconda3\\envs\\modin\\lib\\site-packages\\pandas\\core\\internals\\managers.py\", line 1928, in _multi_blockify\nE       values, placement = _stack_arrays(\nE     File \"C:\\Users\\alozovsk\\Anaconda3\\envs\\modin\\lib\\site-packages\\pandas\\core\\internals\\managers.py\", line 1957, in _stack_arrays\nE       stacked = np.empty(shape, dtype=dtype)\nE   TypeError: Cannot interpret 'dtype('int32')' as a data type"
                },
                "teardown": {
                    "name": "teardown",
                    "duration": 0.0005673999999995516,
                    "outcome": "passed"
                },
                "outcome": "error"
            },
            {
                "name": "modin/pandas/test/dataframe/test_pickle.py::test_column_pickle[True]",
                "duration": 0.1735466999999975,
                "run_index": 2,
                "setup": {
                    "name": "setup",
                    "duration": 0.08645069999999855,
                    "outcome": "error",
                    "longrepr": "modin\\pandas\\test\\dataframe\\test_pickle.py:26: in modin_df\n    return pd.DataFrame({\"col1\": np.arange(1000), \"col2\": np.arange(2000, 3000)})\nmodin\\experimental\\cloud\\meta_magic.py:155: in __new__\n    return cls.__real_cls__(*a, **kw)\nmodin\\experimental\\cloud\\rpyc_proxy.py:431: in __init__\n    __remote_end__ = remote_cls(*a, **kw)\nC:\\Users\\alozovsk\\Anaconda3\\envs\\modin\\lib\\site-packages\\rpyc\\core\\netref.py:254: in __call__\n    return syncreq(_self, consts.HANDLE_CALL, args, kwargs)\nC:\\Users\\alozovsk\\Anaconda3\\envs\\modin\\lib\\site-packages\\rpyc\\core\\netref.py:76: in syncreq\n    return conn.sync_request(handler, proxy, *args)\nmodin\\experimental\\cloud\\rpyc_proxy.py:165: in sync_request\n    return super().sync_request(handler, *args)\nC:\\Users\\alozovsk\\Anaconda3\\envs\\modin\\lib\\site-packages\\rpyc\\core\\protocol.py:484: in sync_request\n    return self.async_request(handler, *args, timeout=timeout).value\nC:\\Users\\alozovsk\\Anaconda3\\envs\\modin\\lib\\site-packages\\rpyc\\core\\async_.py:102: in value\n    raise self._obj\nE   _get_exception_class.<locals>.Derived: Cannot interpret 'dtype('int32')' as a data type\nE   \nE   ========= Remote Traceback (1) =========\nE   Traceback (most recent call last):\nE     File \"C:\\Users\\alozovsk\\Anaconda3\\envs\\modin\\lib\\site-packages\\rpyc\\core\\protocol.py\", line 326, in _dispatch_request\nE       res = self._HANDLERS[handler](self, *args)\nE     File \"C:\\Users\\alozovsk\\Anaconda3\\envs\\modin\\lib\\site-packages\\rpyc\\core\\protocol.py\", line 614, in _handle_call\nE       return obj(*args, **dict(kwargs))\nE     File \"C:\\prog\\modin\\modin\\pandas\\dataframe.py\", line 172, in __init__\nE       pandas_df = pandas.DataFrame(\nE     File \"C:\\Users\\alozovsk\\Anaconda3\\envs\\modin\\lib\\site-packages\\pandas\\core\\frame.py\", line 614, in __init__\nE       mgr = dict_to_mgr(data, index, columns, dtype=dtype, copy=copy, typ=manager)\nE     File \"C:\\Users\\alozovsk\\Anaconda3\\envs\\modin\\lib\\site-packages\\pandas\\core\\internals\\construction.py\", line 464, in dict_to_mgr\nE       return arrays_to_mgr(\nE     File \"C:\\Users\\alozovsk\\Anaconda3\\envs\\modin\\lib\\site-packages\\pandas\\core\\internals\\construction.py\", line 135, in arrays_to_mgr\nE       return create_block_manager_from_arrays(\nE     File \"C:\\Users\\alozovsk\\Anaconda3\\envs\\modin\\lib\\site-packages\\pandas\\core\\internals\\managers.py\", line 1773, in create_block_manager_from_arrays\nE       blocks = _form_blocks(arrays, names, axes, consolidate)\nE     File \"C:\\Users\\alozovsk\\Anaconda3\\envs\\modin\\lib\\site-packages\\pandas\\core\\internals\\managers.py\", line 1838, in _form_blocks\nE       numeric_blocks = _multi_blockify(\nE     File \"C:\\Users\\alozovsk\\Anaconda3\\envs\\modin\\lib\\site-packages\\pandas\\core\\internals\\managers.py\", line 1928, in _multi_blockify\nE       values, placement = _stack_arrays(\nE     File \"C:\\Users\\alozovsk\\Anaconda3\\envs\\modin\\lib\\site-packages\\pandas\\core\\internals\\managers.py\", line 1957, in _stack_arrays\nE       stacked = np.empty(shape, dtype=dtype)\nE   TypeError: Cannot interpret 'dtype('int32')' as a data type"
                },
                "teardown": {
                    "name": "teardown",
                    "duration": 0.0006453000000004039,
                    "outcome": "passed"
                },
                "outcome": "error"
            },
            {
                "name": "modin/pandas/test/dataframe/test_pickle.py::test_column_pickle[False]",
                "duration": 0.19275870000000062,
                "run_index": 3,
                "setup": {
                    "name": "setup",
                    "duration": 0.0958351000000004,
                    "outcome": "error",
                    "longrepr": "modin\\pandas\\test\\dataframe\\test_pickle.py:26: in modin_df\n    return pd.DataFrame({\"col1\": np.arange(1000), \"col2\": np.arange(2000, 3000)})\nmodin\\experimental\\cloud\\meta_magic.py:155: in __new__\n    return cls.__real_cls__(*a, **kw)\nmodin\\experimental\\cloud\\rpyc_proxy.py:431: in __init__\n    __remote_end__ = remote_cls(*a, **kw)\nC:\\Users\\alozovsk\\Anaconda3\\envs\\modin\\lib\\site-packages\\rpyc\\core\\netref.py:254: in __call__\n    return syncreq(_self, consts.HANDLE_CALL, args, kwargs)\nC:\\Users\\alozovsk\\Anaconda3\\envs\\modin\\lib\\site-packages\\rpyc\\core\\netref.py:76: in syncreq\n    return conn.sync_request(handler, proxy, *args)\nmodin\\experimental\\cloud\\rpyc_proxy.py:165: in sync_request\n    return super().sync_request(handler, *args)\nC:\\Users\\alozovsk\\Anaconda3\\envs\\modin\\lib\\site-packages\\rpyc\\core\\protocol.py:484: in sync_request\n    return self.async_request(handler, *args, timeout=timeout).value\nC:\\Users\\alozovsk\\Anaconda3\\envs\\modin\\lib\\site-packages\\rpyc\\core\\async_.py:102: in value\n    raise self._obj\nE   _get_exception_class.<locals>.Derived: Cannot interpret 'dtype('int32')' as a data type\nE   \nE   ========= Remote Traceback (1) =========\nE   Traceback (most recent call last):\nE     File \"C:\\Users\\alozovsk\\Anaconda3\\envs\\modin\\lib\\site-packages\\rpyc\\core\\protocol.py\", line 326, in _dispatch_request\nE       res = self._HANDLERS[handler](self, *args)\nE     File \"C:\\Users\\alozovsk\\Anaconda3\\envs\\modin\\lib\\site-packages\\rpyc\\core\\protocol.py\", line 614, in _handle_call\nE       return obj(*args, **dict(kwargs))\nE     File \"C:\\prog\\modin\\modin\\pandas\\dataframe.py\", line 172, in __init__\nE       pandas_df = pandas.DataFrame(\nE     File \"C:\\Users\\alozovsk\\Anaconda3\\envs\\modin\\lib\\site-packages\\pandas\\core\\frame.py\", line 614, in __init__\nE       mgr = dict_to_mgr(data, index, columns, dtype=dtype, copy=copy, typ=manager)\nE     File \"C:\\Users\\alozovsk\\Anaconda3\\envs\\modin\\lib\\site-packages\\pandas\\core\\internals\\construction.py\", line 464, in dict_to_mgr\nE       return arrays_to_mgr(\nE     File \"C:\\Users\\alozovsk\\Anaconda3\\envs\\modin\\lib\\site-packages\\pandas\\core\\internals\\construction.py\", line 135, in arrays_to_mgr\nE       return create_block_manager_from_arrays(\nE     File \"C:\\Users\\alozovsk\\Anaconda3\\envs\\modin\\lib\\site-packages\\pandas\\core\\internals\\managers.py\", line 1773, in create_block_manager_from_arrays\nE       blocks = _form_blocks(arrays, names, axes, consolidate)\nE     File \"C:\\Users\\alozovsk\\Anaconda3\\envs\\modin\\lib\\site-packages\\pandas\\core\\internals\\managers.py\", line 1838, in _form_blocks\nE       numeric_blocks = _multi_blockify(\nE     File \"C:\\Users\\alozovsk\\Anaconda3\\envs\\modin\\lib\\site-packages\\pandas\\core\\internals\\managers.py\", line 1928, in _multi_blockify\nE       values, placement = _stack_arrays(\nE     File \"C:\\Users\\alozovsk\\Anaconda3\\envs\\modin\\lib\\site-packages\\pandas\\core\\internals\\managers.py\", line 1957, in _stack_arrays\nE       stacked = np.empty(shape, dtype=dtype)\nE   TypeError: Cannot interpret 'dtype('int32')' as a data type"
                },
                "teardown": {
                    "name": "teardown",
                    "duration": 0.0010884999999998257,
                    "outcome": "passed"
                },
                "outcome": "error"
            }
        ],
        "summary": {
            "error": 4,
            "num_tests": 4,
            "duration": 9.776016235351562
        },
        "created_at": "2021-10-31 15:25:19.709831"
    }
}