{
    "report": {
        "environment": {
            "Python": "3.8.10",
            "Platform": "Windows-10-10.0.19042-SP0"
        },
        "tests": [
            {
                "name": "modin/pandas/test/test_reshape.py::test_get_dummies",
                "duration": 9.587339699999998,
                "run_index": 0,
                "setup": {
                    "name": "setup",
                    "duration": 4.6825062,
                    "outcome": "passed"
                },
                "call": {
                    "name": "call",
                    "duration": 0.22156819999999922,
                    "outcome": "failed",
                    "longrepr": "C:\\Users\\alozovsk\\Anaconda3\\envs\\modin\\lib\\site-packages\\pandas\\core\\arrays\\categorical.py:340: in __init__\n    codes, categories = factorize(values, sort=True)\nC:\\Users\\alozovsk\\Anaconda3\\envs\\modin\\lib\\site-packages\\pandas\\core\\algorithms.py:715: in factorize\n    values, dtype = _ensure_data(values)\nC:\\Users\\alozovsk\\Anaconda3\\envs\\modin\\lib\\site-packages\\pandas\\core\\algorithms.py:142: in _ensure_data\n    if needs_i8_conversion(values.dtype) or needs_i8_conversion(dtype):\nC:\\Users\\alozovsk\\Anaconda3\\envs\\modin\\lib\\site-packages\\pandas\\core\\dtypes\\common.py:1228: in needs_i8_conversion\n    is_datetime_or_timedelta_dtype(arr_or_dtype)\nC:\\Users\\alozovsk\\Anaconda3\\envs\\modin\\lib\\site-packages\\pandas\\core\\dtypes\\common.py:1067: in is_datetime_or_timedelta_dtype\n    return _is_dtype_type(arr_or_dtype, classes(np.datetime64, np.timedelta64))\nC:\\Users\\alozovsk\\Anaconda3\\envs\\modin\\lib\\site-packages\\pandas\\core\\dtypes\\common.py:1640: in _is_dtype_type\n    elif is_list_like(arr_or_dtype):\npandas\\_libs\\lib.pyx:1033: in pandas._libs.lib.is_list_like\n    ???\npandas\\_libs\\lib.pyx:1038: in pandas._libs.lib.c_is_list_like\n    ???\nC:\\Users\\alozovsk\\Anaconda3\\envs\\modin\\lib\\abc.py:98: in __instancecheck__\n    return _abc_instancecheck(cls, instance)\nC:\\Users\\alozovsk\\Anaconda3\\envs\\modin\\lib\\abc.py:102: in __subclasscheck__\n    return _abc_subclasscheck(cls, subclass)\nE   TypeError: issubclass() arg 1 must be a class\n\nDuring handling of the above exception, another exception occurred:\nmodin\\pandas\\test\\test_reshape.py:25: in test_get_dummies\n    pd.get_dummies(s)\nmodin\\pandas\\general.py:560: in get_dummies\n    pandas.get_dummies(\nC:\\Users\\alozovsk\\Anaconda3\\envs\\modin\\lib\\site-packages\\pandas\\core\\reshape\\reshape.py:905: in get_dummies\n    result = _get_dummies_1d(\nC:\\Users\\alozovsk\\Anaconda3\\envs\\modin\\lib\\site-packages\\pandas\\core\\reshape\\reshape.py:929: in _get_dummies_1d\n    codes, levels = factorize_from_iterable(Series(data))\nC:\\Users\\alozovsk\\Anaconda3\\envs\\modin\\lib\\site-packages\\pandas\\core\\arrays\\categorical.py:2609: in factorize_from_iterable\n    cat = Categorical(values, ordered=False)\nC:\\Users\\alozovsk\\Anaconda3\\envs\\modin\\lib\\site-packages\\pandas\\core\\arrays\\categorical.py:342: in __init__\n    codes, categories = factorize(values, sort=False)\nC:\\Users\\alozovsk\\Anaconda3\\envs\\modin\\lib\\site-packages\\pandas\\core\\algorithms.py:715: in factorize\n    values, dtype = _ensure_data(values)\nC:\\Users\\alozovsk\\Anaconda3\\envs\\modin\\lib\\site-packages\\pandas\\core\\algorithms.py:142: in _ensure_data\n    if needs_i8_conversion(values.dtype) or needs_i8_conversion(dtype):\nC:\\Users\\alozovsk\\Anaconda3\\envs\\modin\\lib\\site-packages\\pandas\\core\\dtypes\\common.py:1228: in needs_i8_conversion\n    is_datetime_or_timedelta_dtype(arr_or_dtype)\nC:\\Users\\alozovsk\\Anaconda3\\envs\\modin\\lib\\site-packages\\pandas\\core\\dtypes\\common.py:1067: in is_datetime_or_timedelta_dtype\n    return _is_dtype_type(arr_or_dtype, classes(np.datetime64, np.timedelta64))\nC:\\Users\\alozovsk\\Anaconda3\\envs\\modin\\lib\\site-packages\\pandas\\core\\dtypes\\common.py:1640: in _is_dtype_type\n    elif is_list_like(arr_or_dtype):\npandas\\_libs\\lib.pyx:1033: in pandas._libs.lib.is_list_like\n    ???\npandas\\_libs\\lib.pyx:1038: in pandas._libs.lib.c_is_list_like\n    ???\nC:\\Users\\alozovsk\\Anaconda3\\envs\\modin\\lib\\abc.py:98: in __instancecheck__\n    return _abc_instancecheck(cls, instance)\nC:\\Users\\alozovsk\\Anaconda3\\envs\\modin\\lib\\abc.py:102: in __subclasscheck__\n    return _abc_subclasscheck(cls, subclass)\nE   TypeError: issubclass() arg 1 must be a class"
                },
                "teardown": {
                    "name": "teardown",
                    "duration": 0.0007590999999997905,
                    "outcome": "passed"
                },
                "outcome": "failed"
            },
            {
                "name": "modin/pandas/test/test_reshape.py::test_melt",
                "duration": 3.4772798000000025,
                "run_index": 1,
                "setup": {
                    "name": "setup",
                    "duration": 0.00046740000000067283,
                    "outcome": "passed"
                },
                "call": {
                    "name": "call",
                    "duration": 3.4757539,
                    "outcome": "failed",
                    "longrepr": "modin\\pandas\\test\\test_reshape.py:71: in test_melt\n    pd.melt(pd.DataFrame(data))\nE   Failed: DID NOT WARN. No warnings of type (<class 'UserWarning'>,) was emitted. The list of emitted warnings is: []."
                },
                "teardown": {
                    "name": "teardown",
                    "duration": 0.0005911000000011768,
                    "outcome": "passed"
                },
                "outcome": "failed"
            },
            {
                "name": "modin/pandas/test/test_reshape.py::test_crosstab",
                "duration": 0.09016529999999712,
                "run_index": 2,
                "setup": {
                    "name": "setup",
                    "duration": 0.0004966999999993504,
                    "outcome": "passed"
                },
                "call": {
                    "name": "call",
                    "duration": 0.08854229999999852,
                    "outcome": "failed",
                    "longrepr": "modin\\pandas\\test\\test_reshape.py:101: in test_crosstab\n    df = pd.crosstab(a, [b, c], rownames=[\"a\"], colnames=[\"b\", \"c\"])\nmodin\\pandas\\general.py:629: in crosstab\n    return DataFrame(pandas_crosstab)\nmodin\\experimental\\cloud\\meta_magic.py:155: in __new__\n    return cls.__real_cls__(*a, **kw)\nmodin\\experimental\\cloud\\rpyc_proxy.py:430: in __init__\n    __remote_end__ = remote_cls(*a, **kw)\nC:\\Users\\alozovsk\\Anaconda3\\envs\\modin\\lib\\site-packages\\rpyc\\core\\netref.py:253: in __call__\n    return syncreq(_self, consts.HANDLE_CALL, args, kwargs)\nC:\\Users\\alozovsk\\Anaconda3\\envs\\modin\\lib\\site-packages\\rpyc\\core\\netref.py:76: in syncreq\n    return conn.sync_request(handler, proxy, *args)\nmodin\\experimental\\cloud\\rpyc_proxy.py:160: in sync_request\n    return super().sync_request(handler, *args)\nC:\\Users\\alozovsk\\Anaconda3\\envs\\modin\\lib\\site-packages\\rpyc\\core\\protocol.py:469: in sync_request\n    return self.async_request(handler, *args, timeout=timeout).value\nC:\\Users\\alozovsk\\Anaconda3\\envs\\modin\\lib\\site-packages\\rpyc\\core\\async_.py:102: in value\n    raise self._obj\nE   _get_exception_class.<locals>.Derived: Expected list, got type\nE   \nE   ========= Remote Traceback (1) =========\nE   Traceback (most recent call last):\nE     File \"C:\\Users\\alozovsk\\Anaconda3\\envs\\modin\\lib\\site-packages\\rpyc\\core\\protocol.py\", line 320, in _dispatch_request\nE       res = self._HANDLERS[handler](self, *args)\nE     File \"C:\\Users\\alozovsk\\Anaconda3\\envs\\modin\\lib\\site-packages\\rpyc\\core\\protocol.py\", line 593, in _handle_call\nE       return obj(*args, **dict(kwargs))\nE     File \"C:\\prog\\modin\\modin\\pandas\\dataframe.py\", line 174, in __init__\nE       self._query_compiler = from_pandas(pandas_df)._query_compiler\nE     File \"C:\\prog\\modin\\modin\\pandas\\utils.py\", line 67, in from_pandas\nE       return DataFrame(query_compiler=FactoryDispatcher.from_pandas(df))\nE     File \"C:\\prog\\modin\\modin\\data_management\\factories\\dispatcher.py\", line 152, in from_pandas\nE       return cls.__factory._from_pandas(df)\nE     File \"C:\\prog\\modin\\modin\\data_management\\factories\\factories.py\", line 166, in _from_pandas\nE       return cls.io_cls.from_pandas(df)\nE     File \"C:\\prog\\modin\\modin\\engines\\base\\io\\io.py\", line 80, in from_pandas\nE       return cls.query_compiler_cls.from_pandas(df, cls.frame_cls)\nE     File \"C:\\prog\\modin\\modin\\backends\\pandas\\query_compiler.py\", line 259, in from_pandas\nE       return cls(data_cls.from_pandas(df))\nE     File \"C:\\prog\\modin\\modin\\engines\\base\\frame\\data.py\", line 2151, in from_pandas\nE       new_index = df.index\nE     File \"pandas\\_libs\\properties.pyx\", line 62, in pandas._libs.properties.AxisProperty.__get__\nE   TypeError: Expected list, got type"
                },
                "teardown": {
                    "name": "teardown",
                    "duration": 0.0006295999999998969,
                    "outcome": "passed"
                },
                "outcome": "failed"
            },
            {
                "name": "modin/pandas/test/test_reshape.py::test_lreshape",
                "duration": 0.28156360000000014,
                "run_index": 3,
                "setup": {
                    "name": "setup",
                    "duration": 0.0005509000000003539,
                    "outcome": "passed"
                },
                "call": {
                    "name": "call",
                    "duration": 0.28002859999999963,
                    "outcome": "failed",
                    "longrepr": "modin\\pandas\\test\\test_reshape.py:128: in test_lreshape\n    df = pd.lreshape(data, {\"year\": [\"year1\", \"year2\"], \"hr\": [\"hr1\", \"hr2\"]})\nmodin\\pandas\\general.py:638: in lreshape\n    pandas.lreshape(to_pandas(data), groups, dropna=dropna, label=label)\nC:\\Users\\alozovsk\\Anaconda3\\envs\\modin\\lib\\site-packages\\pandas\\util\\_decorators.py:199: in wrapper\n    return func(*args, **kwargs)\nC:\\Users\\alozovsk\\Anaconda3\\envs\\modin\\lib\\site-packages\\pandas\\core\\reshape\\melt.py:220: in lreshape\n    mdata[target] = concat_compat(to_concat)\nC:\\Users\\alozovsk\\Anaconda3\\envs\\modin\\lib\\site-packages\\pandas\\core\\dtypes\\concat.py:171: in concat_compat\n    return np.concatenate(to_concat, axis=axis)\n<__array_function__ internals>:5: in concatenate\n    ???\nC:\\Users\\alozovsk\\Anaconda3\\envs\\modin\\lib\\site-packages\\rpyc\\core\\netref.py:275: in method\n    return syncreq(_self, consts.HANDLE_CALLATTR, name, args, kwargs)\nC:\\Users\\alozovsk\\Anaconda3\\envs\\modin\\lib\\site-packages\\rpyc\\core\\netref.py:76: in syncreq\n    return conn.sync_request(handler, proxy, *args)\nmodin\\experimental\\cloud\\rpyc_proxy.py:160: in sync_request\n    return super().sync_request(handler, *args)\nC:\\Users\\alozovsk\\Anaconda3\\envs\\modin\\lib\\site-packages\\rpyc\\core\\protocol.py:469: in sync_request\n    return self.async_request(handler, *args, timeout=timeout).value\nmodin\\experimental\\cloud\\rpyc_proxy.py:178: in async_request\n    return super().async_request(handler, *args, **kw)\nC:\\Users\\alozovsk\\Anaconda3\\envs\\modin\\lib\\site-packages\\rpyc\\core\\protocol.py:493: in async_request\n    self._async_request(handler, args, res)\nC:\\Users\\alozovsk\\Anaconda3\\envs\\modin\\lib\\site-packages\\rpyc\\core\\protocol.py:475: in _async_request\n    self._send(consts.MSG_REQUEST, seq, (handler, self._box(args)))\nC:\\Users\\alozovsk\\Anaconda3\\envs\\modin\\lib\\site-packages\\rpyc\\core\\protocol.py:233: in _send\n    data = brine.dump((msg, seq, args))\nC:\\Users\\alozovsk\\Anaconda3\\envs\\modin\\lib\\site-packages\\rpyc\\core\\brine.py:373: in dump\n    _dump(obj, stream)\nC:\\Users\\alozovsk\\Anaconda3\\envs\\modin\\lib\\site-packages\\rpyc\\core\\brine.py:192: in _dump\n    _dump_registry.get(type(obj), _undumpable)(obj, stream)\nC:\\Users\\alozovsk\\Anaconda3\\envs\\modin\\lib\\site-packages\\rpyc\\core\\brine.py:184: in _dump_tuple\n    _dump(item, stream)\nC:\\Users\\alozovsk\\Anaconda3\\envs\\modin\\lib\\site-packages\\rpyc\\core\\brine.py:192: in _dump\n    _dump_registry.get(type(obj), _undumpable)(obj, stream)\nC:\\Users\\alozovsk\\Anaconda3\\envs\\modin\\lib\\site-packages\\rpyc\\core\\brine.py:184: in _dump_tuple\n    _dump(item, stream)\nC:\\Users\\alozovsk\\Anaconda3\\envs\\modin\\lib\\site-packages\\rpyc\\core\\brine.py:192: in _dump\n    _dump_registry.get(type(obj), _undumpable)(obj, stream)\nC:\\Users\\alozovsk\\Anaconda3\\envs\\modin\\lib\\site-packages\\rpyc\\core\\brine.py:184: in _dump_tuple\n    _dump(item, stream)\nC:\\Users\\alozovsk\\Anaconda3\\envs\\modin\\lib\\site-packages\\rpyc\\core\\brine.py:192: in _dump\n    _dump_registry.get(type(obj), _undumpable)(obj, stream)\nC:\\Users\\alozovsk\\Anaconda3\\envs\\modin\\lib\\site-packages\\rpyc\\core\\brine.py:184: in _dump_tuple\n    _dump(item, stream)\nC:\\Users\\alozovsk\\Anaconda3\\envs\\modin\\lib\\site-packages\\rpyc\\core\\brine.py:192: in _dump\n    _dump_registry.get(type(obj), _undumpable)(obj, stream)\nC:\\Users\\alozovsk\\Anaconda3\\envs\\modin\\lib\\site-packages\\rpyc\\core\\brine.py:184: in _dump_tuple\n    _dump(item, stream)\nC:\\Users\\alozovsk\\Anaconda3\\envs\\modin\\lib\\site-packages\\rpyc\\core\\brine.py:192: in _dump\n    _dump_registry.get(type(obj), _undumpable)(obj, stream)\nC:\\Users\\alozovsk\\Anaconda3\\envs\\modin\\lib\\site-packages\\rpyc\\core\\brine.py:184: in _dump_tuple\n    _dump(item, stream)\nC:\\Users\\alozovsk\\Anaconda3\\envs\\modin\\lib\\site-packages\\rpyc\\core\\brine.py:192: in _dump\n    _dump_registry.get(type(obj), _undumpable)(obj, stream)\nC:\\Users\\alozovsk\\Anaconda3\\envs\\modin\\lib\\site-packages\\rpyc\\core\\brine.py:184: in _dump_tuple\n    _dump(item, stream)\nC:\\Users\\alozovsk\\Anaconda3\\envs\\modin\\lib\\site-packages\\rpyc\\core\\brine.py:192: in _dump\n    _dump_registry.get(type(obj), _undumpable)(obj, stream)\nC:\\Users\\alozovsk\\Anaconda3\\envs\\modin\\lib\\site-packages\\rpyc\\core\\brine.py:184: in _dump_tuple\n    _dump(item, stream)\nC:\\Users\\alozovsk\\Anaconda3\\envs\\modin\\lib\\site-packages\\rpyc\\core\\brine.py:192: in _dump\n    _dump_registry.get(type(obj), _undumpable)(obj, stream)\nC:\\Users\\alozovsk\\Anaconda3\\envs\\modin\\lib\\site-packages\\rpyc\\core\\brine.py:184: in _dump_tuple\n    _dump(item, stream)\nC:\\Users\\alozovsk\\Anaconda3\\envs\\modin\\lib\\site-packages\\rpyc\\core\\brine.py:192: in _dump\n    _dump_registry.get(type(obj), _undumpable)(obj, stream)\nC:\\Users\\alozovsk\\Anaconda3\\envs\\modin\\lib\\site-packages\\rpyc\\core\\brine.py:188: in _undumpable\n    raise TypeError(\"cannot dump %r\" % (obj,))\nE   TypeError: cannot dump <member '____id_pack__' of 'BaseNetref' objects>"
                },
                "teardown": {
                    "name": "teardown",
                    "duration": 0.0004331999999998004,
                    "outcome": "passed"
                },
                "outcome": "failed"
            },
            {
                "name": "modin/pandas/test/test_reshape.py::test_wide_to_long",
                "duration": 0.22943410000000064,
                "run_index": 4,
                "setup": {
                    "name": "setup",
                    "duration": 0.0004697000000000173,
                    "outcome": "passed"
                },
                "call": {
                    "name": "call",
                    "duration": 0.22737750000000112,
                    "outcome": "failed",
                    "longrepr": "modin\\pandas\\test\\test_reshape.py:147: in test_wide_to_long\n    df = pd.wide_to_long(data, [\"hr\", \"year\"], \"team\", \"index\")\nmodin\\pandas\\general.py:652: in wide_to_long\n    pandas.wide_to_long(to_pandas(df), stubnames, i, j, sep=sep, suffix=suffix)\nC:\\Users\\alozovsk\\Anaconda3\\envs\\modin\\lib\\site-packages\\pandas\\core\\reshape\\melt.py:506: in wide_to_long\n    if df[i].duplicated().any():\nC:\\Users\\alozovsk\\Anaconda3\\envs\\modin\\lib\\site-packages\\rpyc\\core\\netref.py:275: in method\n    return syncreq(_self, consts.HANDLE_CALLATTR, name, args, kwargs)\nC:\\Users\\alozovsk\\Anaconda3\\envs\\modin\\lib\\site-packages\\rpyc\\core\\netref.py:76: in syncreq\n    return conn.sync_request(handler, proxy, *args)\nmodin\\experimental\\cloud\\rpyc_proxy.py:160: in sync_request\n    return super().sync_request(handler, *args)\nC:\\Users\\alozovsk\\Anaconda3\\envs\\modin\\lib\\site-packages\\rpyc\\core\\protocol.py:469: in sync_request\n    return self.async_request(handler, *args, timeout=timeout).value\nC:\\Users\\alozovsk\\Anaconda3\\envs\\modin\\lib\\site-packages\\rpyc\\core\\async_.py:102: in value\n    raise self._obj\nE   _get_exception_class.<locals>.Derived: 'list' object is not callable\nE   \nE   ========= Remote Traceback (2) =========\nE   Traceback (most recent call last):\nE     File \"C:\\Users\\alozovsk\\Anaconda3\\envs\\modin\\lib\\site-packages\\rpyc\\core\\protocol.py\", line 320, in _dispatch_request\nE       res = self._HANDLERS[handler](self, *args)\nE     File \"C:\\Users\\alozovsk\\Anaconda3\\envs\\modin\\lib\\site-packages\\rpyc\\core\\protocol.py\", line 619, in _handle_callattr\nE       return self._handle_call(obj, args, kwargs)\nE     File \"C:\\Users\\alozovsk\\Anaconda3\\envs\\modin\\lib\\site-packages\\rpyc\\core\\protocol.py\", line 593, in _handle_call\nE       return obj(*args, **dict(kwargs))\nE     File \"C:\\Users\\alozovsk\\Anaconda3\\envs\\modin\\lib\\site-packages\\pandas\\core\\frame.py\", line 2989, in __getitem__\nE       key = com.apply_if_callable(key, self)\nE     File \"C:\\Users\\alozovsk\\Anaconda3\\envs\\modin\\lib\\site-packages\\pandas\\core\\common.py\", line 329, in apply_if_callable\nE       return maybe_callable(obj, **kwargs)\nE     File \"C:\\Users\\alozovsk\\Anaconda3\\envs\\modin\\lib\\site-packages\\rpyc\\core\\netref.py\", line 253, in __call__\nE       return syncreq(_self, consts.HANDLE_CALL, args, kwargs)\nE     File \"C:\\Users\\alozovsk\\Anaconda3\\envs\\modin\\lib\\site-packages\\rpyc\\core\\netref.py\", line 76, in syncreq\nE       return conn.sync_request(handler, proxy, *args)\nE     File \"C:\\Users\\alozovsk\\Anaconda3\\envs\\modin\\lib\\site-packages\\rpyc\\core\\protocol.py\", line 469, in sync_request\nE       return self.async_request(handler, *args, timeout=timeout).value\nE     File \"C:\\Users\\alozovsk\\Anaconda3\\envs\\modin\\lib\\site-packages\\rpyc\\core\\async_.py\", line 102, in value\nE       raise self._obj\nE   _get_exception_class.<locals>.Derived: 'list' object is not callable\nE   \nE   ========= Remote Traceback (1) =========\nE   Traceback (most recent call last):\nE     File \"C:\\Users\\alozovsk\\Anaconda3\\envs\\modin\\lib\\site-packages\\rpyc\\core\\protocol.py\", line 320, in _dispatch_request\nE       res = self._HANDLERS[handler](self, *args)\nE     File \"C:\\Users\\alozovsk\\Anaconda3\\envs\\modin\\lib\\site-packages\\rpyc\\core\\protocol.py\", line 593, in _handle_call\nE       return obj(*args, **dict(kwargs))\nE   TypeError: 'list' object is not callable"
                },
                "teardown": {
                    "name": "teardown",
                    "duration": 0.0011171999999994853,
                    "outcome": "passed"
                },
                "outcome": "failed"
            }
        ],
        "summary": {
            "failed": 5,
            "num_tests": 5,
            "duration": 13.5467050075531
        },
        "created_at": "2021-07-28 22:53:29.593031"
    }
}