{
    "report": {
        "environment": {
            "Python": "3.8.10",
            "Platform": "Windows-10-10.0.19042-SP0"
        },
        "tests": [
            {
                "name": "modin/pandas/test/dataframe/test_iter.py::test_items_iteritems_iterrows[items]",
                "duration": 11.123418100000002,
                "run_index": 0,
                "setup": {
                    "name": "setup",
                    "duration": 4.843246700000001,
                    "outcome": "passed"
                },
                "call": {
                    "name": "call",
                    "duration": 1.4361558000000016,
                    "outcome": "failed",
                    "longrepr": "modin\\pandas\\test\\dataframe\\test_iter.py:43: in test_items_iteritems_iterrows\n    modin_df, pandas_df = pd.DataFrame(data), pandas.DataFrame(data)\nmodin\\experimental\\cloud\\meta_magic.py:155: in __new__\n    return cls.__real_cls__(*a, **kw)\nmodin\\experimental\\cloud\\rpyc_proxy.py:430: in __init__\n    __remote_end__ = remote_cls(*a, **kw)\nC:\\Users\\alozovsk\\Anaconda3\\envs\\modin\\lib\\site-packages\\rpyc\\core\\netref.py:253: in __call__\n    return syncreq(_self, consts.HANDLE_CALL, args, kwargs)\nC:\\Users\\alozovsk\\Anaconda3\\envs\\modin\\lib\\site-packages\\rpyc\\core\\netref.py:76: in syncreq\n    return conn.sync_request(handler, proxy, *args)\nmodin\\experimental\\cloud\\rpyc_proxy.py:160: in sync_request\n    return super().sync_request(handler, *args)\nC:\\Users\\alozovsk\\Anaconda3\\envs\\modin\\lib\\site-packages\\rpyc\\core\\protocol.py:469: in sync_request\n    return self.async_request(handler, *args, timeout=timeout).value\nC:\\Users\\alozovsk\\Anaconda3\\envs\\modin\\lib\\site-packages\\rpyc\\core\\async_.py:102: in value\n    raise self._obj\nE   _get_exception_class.<locals>.Derived: __array__() takes 1 positional argument but 2 were given\nE   \nE   ========= Remote Traceback (1) =========\nE   Traceback (most recent call last):\nE     File \"C:\\Users\\alozovsk\\Anaconda3\\envs\\modin\\lib\\site-packages\\rpyc\\core\\protocol.py\", line 320, in _dispatch_request\nE       res = self._HANDLERS[handler](self, *args)\nE     File \"C:\\Users\\alozovsk\\Anaconda3\\envs\\modin\\lib\\site-packages\\rpyc\\core\\protocol.py\", line 593, in _handle_call\nE       return obj(*args, **dict(kwargs))\nE     File \"C:\\prog\\modin\\modin\\pandas\\dataframe.py\", line 171, in __init__\nE       pandas_df = pandas.DataFrame(\nE     File \"C:\\Users\\alozovsk\\Anaconda3\\envs\\modin\\lib\\site-packages\\pandas\\core\\frame.py\", line 529, in __init__\nE       mgr = init_dict(data, index, columns, dtype=dtype)\nE     File \"C:\\Users\\alozovsk\\Anaconda3\\envs\\modin\\lib\\site-packages\\pandas\\core\\internals\\construction.py\", line 287, in init_dict\nE       return arrays_to_mgr(arrays, data_names, index, columns, dtype=dtype)\nE     File \"C:\\Users\\alozovsk\\Anaconda3\\envs\\modin\\lib\\site-packages\\pandas\\core\\internals\\construction.py\", line 85, in arrays_to_mgr\nE       arrays = _homogenize(arrays, index, dtype)\nE     File \"C:\\Users\\alozovsk\\Anaconda3\\envs\\modin\\lib\\site-packages\\pandas\\core\\internals\\construction.py\", line 355, in _homogenize\nE       val = sanitize_array(\nE     File \"C:\\Users\\alozovsk\\Anaconda3\\envs\\modin\\lib\\site-packages\\pandas\\core\\construction.py\", line 482, in sanitize_array\nE       subarr = maybe_convert_platform(data)\nE     File \"C:\\Users\\alozovsk\\Anaconda3\\envs\\modin\\lib\\site-packages\\pandas\\core\\dtypes\\cast.py\", line 112, in maybe_convert_platform\nE       values = construct_1d_object_array_from_listlike(values)\nE     File \"C:\\Users\\alozovsk\\Anaconda3\\envs\\modin\\lib\\site-packages\\pandas\\core\\dtypes\\cast.py\", line 1639, in construct_1d_object_array_from_listlike\nE       result[:] = values\nE   TypeError: __array__() takes 1 positional argument but 2 were given"
                },
                "teardown": {
                    "name": "teardown",
                    "duration": 0.0007688999999988511,
                    "outcome": "passed"
                },
                "outcome": "failed"
            },
            {
                "name": "modin/pandas/test/dataframe/test_iter.py::test_items_iteritems_iterrows[iteritems]",
                "duration": 0.6763662999999998,
                "run_index": 1,
                "setup": {
                    "name": "setup",
                    "duration": 0.0013667999999995573,
                    "outcome": "passed"
                },
                "call": {
                    "name": "call",
                    "duration": 0.6731384000000009,
                    "outcome": "failed",
                    "longrepr": "modin\\pandas\\test\\dataframe\\test_iter.py:43: in test_items_iteritems_iterrows\n    modin_df, pandas_df = pd.DataFrame(data), pandas.DataFrame(data)\nmodin\\experimental\\cloud\\meta_magic.py:155: in __new__\n    return cls.__real_cls__(*a, **kw)\nmodin\\experimental\\cloud\\rpyc_proxy.py:430: in __init__\n    __remote_end__ = remote_cls(*a, **kw)\nC:\\Users\\alozovsk\\Anaconda3\\envs\\modin\\lib\\site-packages\\rpyc\\core\\netref.py:253: in __call__\n    return syncreq(_self, consts.HANDLE_CALL, args, kwargs)\nC:\\Users\\alozovsk\\Anaconda3\\envs\\modin\\lib\\site-packages\\rpyc\\core\\netref.py:76: in syncreq\n    return conn.sync_request(handler, proxy, *args)\nmodin\\experimental\\cloud\\rpyc_proxy.py:160: in sync_request\n    return super().sync_request(handler, *args)\nC:\\Users\\alozovsk\\Anaconda3\\envs\\modin\\lib\\site-packages\\rpyc\\core\\protocol.py:469: in sync_request\n    return self.async_request(handler, *args, timeout=timeout).value\nC:\\Users\\alozovsk\\Anaconda3\\envs\\modin\\lib\\site-packages\\rpyc\\core\\async_.py:102: in value\n    raise self._obj\nE   _get_exception_class.<locals>.Derived: __array__() takes 1 positional argument but 2 were given\nE   \nE   ========= Remote Traceback (1) =========\nE   Traceback (most recent call last):\nE     File \"C:\\Users\\alozovsk\\Anaconda3\\envs\\modin\\lib\\site-packages\\rpyc\\core\\protocol.py\", line 320, in _dispatch_request\nE       res = self._HANDLERS[handler](self, *args)\nE     File \"C:\\Users\\alozovsk\\Anaconda3\\envs\\modin\\lib\\site-packages\\rpyc\\core\\protocol.py\", line 593, in _handle_call\nE       return obj(*args, **dict(kwargs))\nE     File \"C:\\prog\\modin\\modin\\pandas\\dataframe.py\", line 171, in __init__\nE       pandas_df = pandas.DataFrame(\nE     File \"C:\\Users\\alozovsk\\Anaconda3\\envs\\modin\\lib\\site-packages\\pandas\\core\\frame.py\", line 529, in __init__\nE       mgr = init_dict(data, index, columns, dtype=dtype)\nE     File \"C:\\Users\\alozovsk\\Anaconda3\\envs\\modin\\lib\\site-packages\\pandas\\core\\internals\\construction.py\", line 287, in init_dict\nE       return arrays_to_mgr(arrays, data_names, index, columns, dtype=dtype)\nE     File \"C:\\Users\\alozovsk\\Anaconda3\\envs\\modin\\lib\\site-packages\\pandas\\core\\internals\\construction.py\", line 85, in arrays_to_mgr\nE       arrays = _homogenize(arrays, index, dtype)\nE     File \"C:\\Users\\alozovsk\\Anaconda3\\envs\\modin\\lib\\site-packages\\pandas\\core\\internals\\construction.py\", line 355, in _homogenize\nE       val = sanitize_array(\nE     File \"C:\\Users\\alozovsk\\Anaconda3\\envs\\modin\\lib\\site-packages\\pandas\\core\\construction.py\", line 482, in sanitize_array\nE       subarr = maybe_convert_platform(data)\nE     File \"C:\\Users\\alozovsk\\Anaconda3\\envs\\modin\\lib\\site-packages\\pandas\\core\\dtypes\\cast.py\", line 112, in maybe_convert_platform\nE       values = construct_1d_object_array_from_listlike(values)\nE     File \"C:\\Users\\alozovsk\\Anaconda3\\envs\\modin\\lib\\site-packages\\pandas\\core\\dtypes\\cast.py\", line 1639, in construct_1d_object_array_from_listlike\nE       result[:] = values\nE   TypeError: __array__() takes 1 positional argument but 2 were given"
                },
                "teardown": {
                    "name": "teardown",
                    "duration": 0.0004942999999997255,
                    "outcome": "passed"
                },
                "outcome": "failed"
            },
            {
                "name": "modin/pandas/test/dataframe/test_iter.py::test_items_iteritems_iterrows[iterrows]",
                "duration": 0.6923149000000013,
                "run_index": 2,
                "setup": {
                    "name": "setup",
                    "duration": 0.0009367000000004566,
                    "outcome": "passed"
                },
                "call": {
                    "name": "call",
                    "duration": 0.6897711999999991,
                    "outcome": "failed",
                    "longrepr": "modin\\pandas\\test\\dataframe\\test_iter.py:43: in test_items_iteritems_iterrows\n    modin_df, pandas_df = pd.DataFrame(data), pandas.DataFrame(data)\nmodin\\experimental\\cloud\\meta_magic.py:155: in __new__\n    return cls.__real_cls__(*a, **kw)\nmodin\\experimental\\cloud\\rpyc_proxy.py:430: in __init__\n    __remote_end__ = remote_cls(*a, **kw)\nC:\\Users\\alozovsk\\Anaconda3\\envs\\modin\\lib\\site-packages\\rpyc\\core\\netref.py:253: in __call__\n    return syncreq(_self, consts.HANDLE_CALL, args, kwargs)\nC:\\Users\\alozovsk\\Anaconda3\\envs\\modin\\lib\\site-packages\\rpyc\\core\\netref.py:76: in syncreq\n    return conn.sync_request(handler, proxy, *args)\nmodin\\experimental\\cloud\\rpyc_proxy.py:160: in sync_request\n    return super().sync_request(handler, *args)\nC:\\Users\\alozovsk\\Anaconda3\\envs\\modin\\lib\\site-packages\\rpyc\\core\\protocol.py:469: in sync_request\n    return self.async_request(handler, *args, timeout=timeout).value\nC:\\Users\\alozovsk\\Anaconda3\\envs\\modin\\lib\\site-packages\\rpyc\\core\\async_.py:102: in value\n    raise self._obj\nE   _get_exception_class.<locals>.Derived: __array__() takes 1 positional argument but 2 were given\nE   \nE   ========= Remote Traceback (1) =========\nE   Traceback (most recent call last):\nE     File \"C:\\Users\\alozovsk\\Anaconda3\\envs\\modin\\lib\\site-packages\\rpyc\\core\\protocol.py\", line 320, in _dispatch_request\nE       res = self._HANDLERS[handler](self, *args)\nE     File \"C:\\Users\\alozovsk\\Anaconda3\\envs\\modin\\lib\\site-packages\\rpyc\\core\\protocol.py\", line 593, in _handle_call\nE       return obj(*args, **dict(kwargs))\nE     File \"C:\\prog\\modin\\modin\\pandas\\dataframe.py\", line 171, in __init__\nE       pandas_df = pandas.DataFrame(\nE     File \"C:\\Users\\alozovsk\\Anaconda3\\envs\\modin\\lib\\site-packages\\pandas\\core\\frame.py\", line 529, in __init__\nE       mgr = init_dict(data, index, columns, dtype=dtype)\nE     File \"C:\\Users\\alozovsk\\Anaconda3\\envs\\modin\\lib\\site-packages\\pandas\\core\\internals\\construction.py\", line 287, in init_dict\nE       return arrays_to_mgr(arrays, data_names, index, columns, dtype=dtype)\nE     File \"C:\\Users\\alozovsk\\Anaconda3\\envs\\modin\\lib\\site-packages\\pandas\\core\\internals\\construction.py\", line 85, in arrays_to_mgr\nE       arrays = _homogenize(arrays, index, dtype)\nE     File \"C:\\Users\\alozovsk\\Anaconda3\\envs\\modin\\lib\\site-packages\\pandas\\core\\internals\\construction.py\", line 355, in _homogenize\nE       val = sanitize_array(\nE     File \"C:\\Users\\alozovsk\\Anaconda3\\envs\\modin\\lib\\site-packages\\pandas\\core\\construction.py\", line 482, in sanitize_array\nE       subarr = maybe_convert_platform(data)\nE     File \"C:\\Users\\alozovsk\\Anaconda3\\envs\\modin\\lib\\site-packages\\pandas\\core\\dtypes\\cast.py\", line 112, in maybe_convert_platform\nE       values = construct_1d_object_array_from_listlike(values)\nE     File \"C:\\Users\\alozovsk\\Anaconda3\\envs\\modin\\lib\\site-packages\\pandas\\core\\dtypes\\cast.py\", line 1639, in construct_1d_object_array_from_listlike\nE       result[:] = values\nE   TypeError: __array__() takes 1 positional argument but 2 were given"
                },
                "teardown": {
                    "name": "teardown",
                    "duration": 0.0006703000000012338,
                    "outcome": "passed"
                },
                "outcome": "failed"
            },
            {
                "name": "modin/pandas/test/dataframe/test_iter.py::test_itertuples_name[None]",
                "duration": 0.6651202000000023,
                "run_index": 3,
                "setup": {
                    "name": "setup",
                    "duration": 0.0008018000000014069,
                    "outcome": "passed"
                },
                "call": {
                    "name": "call",
                    "duration": 0.6630237000000001,
                    "outcome": "failed",
                    "longrepr": "modin\\pandas\\test\\dataframe\\test_iter.py:57: in test_itertuples_name\n    modin_df, pandas_df = pd.DataFrame(data), pandas.DataFrame(data)\nmodin\\experimental\\cloud\\meta_magic.py:155: in __new__\n    return cls.__real_cls__(*a, **kw)\nmodin\\experimental\\cloud\\rpyc_proxy.py:430: in __init__\n    __remote_end__ = remote_cls(*a, **kw)\nC:\\Users\\alozovsk\\Anaconda3\\envs\\modin\\lib\\site-packages\\rpyc\\core\\netref.py:253: in __call__\n    return syncreq(_self, consts.HANDLE_CALL, args, kwargs)\nC:\\Users\\alozovsk\\Anaconda3\\envs\\modin\\lib\\site-packages\\rpyc\\core\\netref.py:76: in syncreq\n    return conn.sync_request(handler, proxy, *args)\nmodin\\experimental\\cloud\\rpyc_proxy.py:160: in sync_request\n    return super().sync_request(handler, *args)\nC:\\Users\\alozovsk\\Anaconda3\\envs\\modin\\lib\\site-packages\\rpyc\\core\\protocol.py:469: in sync_request\n    return self.async_request(handler, *args, timeout=timeout).value\nC:\\Users\\alozovsk\\Anaconda3\\envs\\modin\\lib\\site-packages\\rpyc\\core\\async_.py:102: in value\n    raise self._obj\nE   _get_exception_class.<locals>.Derived: __array__() takes 1 positional argument but 2 were given\nE   \nE   ========= Remote Traceback (1) =========\nE   Traceback (most recent call last):\nE     File \"C:\\Users\\alozovsk\\Anaconda3\\envs\\modin\\lib\\site-packages\\rpyc\\core\\protocol.py\", line 320, in _dispatch_request\nE       res = self._HANDLERS[handler](self, *args)\nE     File \"C:\\Users\\alozovsk\\Anaconda3\\envs\\modin\\lib\\site-packages\\rpyc\\core\\protocol.py\", line 593, in _handle_call\nE       return obj(*args, **dict(kwargs))\nE     File \"C:\\prog\\modin\\modin\\pandas\\dataframe.py\", line 171, in __init__\nE       pandas_df = pandas.DataFrame(\nE     File \"C:\\Users\\alozovsk\\Anaconda3\\envs\\modin\\lib\\site-packages\\pandas\\core\\frame.py\", line 529, in __init__\nE       mgr = init_dict(data, index, columns, dtype=dtype)\nE     File \"C:\\Users\\alozovsk\\Anaconda3\\envs\\modin\\lib\\site-packages\\pandas\\core\\internals\\construction.py\", line 287, in init_dict\nE       return arrays_to_mgr(arrays, data_names, index, columns, dtype=dtype)\nE     File \"C:\\Users\\alozovsk\\Anaconda3\\envs\\modin\\lib\\site-packages\\pandas\\core\\internals\\construction.py\", line 85, in arrays_to_mgr\nE       arrays = _homogenize(arrays, index, dtype)\nE     File \"C:\\Users\\alozovsk\\Anaconda3\\envs\\modin\\lib\\site-packages\\pandas\\core\\internals\\construction.py\", line 355, in _homogenize\nE       val = sanitize_array(\nE     File \"C:\\Users\\alozovsk\\Anaconda3\\envs\\modin\\lib\\site-packages\\pandas\\core\\construction.py\", line 482, in sanitize_array\nE       subarr = maybe_convert_platform(data)\nE     File \"C:\\Users\\alozovsk\\Anaconda3\\envs\\modin\\lib\\site-packages\\pandas\\core\\dtypes\\cast.py\", line 112, in maybe_convert_platform\nE       values = construct_1d_object_array_from_listlike(values)\nE     File \"C:\\Users\\alozovsk\\Anaconda3\\envs\\modin\\lib\\site-packages\\pandas\\core\\dtypes\\cast.py\", line 1639, in construct_1d_object_array_from_listlike\nE       result[:] = values\nE   TypeError: __array__() takes 1 positional argument but 2 were given"
                },
                "teardown": {
                    "name": "teardown",
                    "duration": 0.0004928999999993522,
                    "outcome": "passed"
                },
                "outcome": "failed"
            },
            {
                "name": "modin/pandas/test/dataframe/test_iter.py::test_itertuples_name[NotPandas]",
                "duration": 0.6717258000000026,
                "run_index": 4,
                "setup": {
                    "name": "setup",
                    "duration": 0.0008668000000007225,
                    "outcome": "passed"
                },
                "call": {
                    "name": "call",
                    "duration": 0.6694632000000009,
                    "outcome": "failed",
                    "longrepr": "modin\\pandas\\test\\dataframe\\test_iter.py:57: in test_itertuples_name\n    modin_df, pandas_df = pd.DataFrame(data), pandas.DataFrame(data)\nmodin\\experimental\\cloud\\meta_magic.py:155: in __new__\n    return cls.__real_cls__(*a, **kw)\nmodin\\experimental\\cloud\\rpyc_proxy.py:430: in __init__\n    __remote_end__ = remote_cls(*a, **kw)\nC:\\Users\\alozovsk\\Anaconda3\\envs\\modin\\lib\\site-packages\\rpyc\\core\\netref.py:253: in __call__\n    return syncreq(_self, consts.HANDLE_CALL, args, kwargs)\nC:\\Users\\alozovsk\\Anaconda3\\envs\\modin\\lib\\site-packages\\rpyc\\core\\netref.py:76: in syncreq\n    return conn.sync_request(handler, proxy, *args)\nmodin\\experimental\\cloud\\rpyc_proxy.py:160: in sync_request\n    return super().sync_request(handler, *args)\nC:\\Users\\alozovsk\\Anaconda3\\envs\\modin\\lib\\site-packages\\rpyc\\core\\protocol.py:469: in sync_request\n    return self.async_request(handler, *args, timeout=timeout).value\nC:\\Users\\alozovsk\\Anaconda3\\envs\\modin\\lib\\site-packages\\rpyc\\core\\async_.py:102: in value\n    raise self._obj\nE   _get_exception_class.<locals>.Derived: __array__() takes 1 positional argument but 2 were given\nE   \nE   ========= Remote Traceback (1) =========\nE   Traceback (most recent call last):\nE     File \"C:\\Users\\alozovsk\\Anaconda3\\envs\\modin\\lib\\site-packages\\rpyc\\core\\protocol.py\", line 320, in _dispatch_request\nE       res = self._HANDLERS[handler](self, *args)\nE     File \"C:\\Users\\alozovsk\\Anaconda3\\envs\\modin\\lib\\site-packages\\rpyc\\core\\protocol.py\", line 593, in _handle_call\nE       return obj(*args, **dict(kwargs))\nE     File \"C:\\prog\\modin\\modin\\pandas\\dataframe.py\", line 171, in __init__\nE       pandas_df = pandas.DataFrame(\nE     File \"C:\\Users\\alozovsk\\Anaconda3\\envs\\modin\\lib\\site-packages\\pandas\\core\\frame.py\", line 529, in __init__\nE       mgr = init_dict(data, index, columns, dtype=dtype)\nE     File \"C:\\Users\\alozovsk\\Anaconda3\\envs\\modin\\lib\\site-packages\\pandas\\core\\internals\\construction.py\", line 287, in init_dict\nE       return arrays_to_mgr(arrays, data_names, index, columns, dtype=dtype)\nE     File \"C:\\Users\\alozovsk\\Anaconda3\\envs\\modin\\lib\\site-packages\\pandas\\core\\internals\\construction.py\", line 85, in arrays_to_mgr\nE       arrays = _homogenize(arrays, index, dtype)\nE     File \"C:\\Users\\alozovsk\\Anaconda3\\envs\\modin\\lib\\site-packages\\pandas\\core\\internals\\construction.py\", line 355, in _homogenize\nE       val = sanitize_array(\nE     File \"C:\\Users\\alozovsk\\Anaconda3\\envs\\modin\\lib\\site-packages\\pandas\\core\\construction.py\", line 482, in sanitize_array\nE       subarr = maybe_convert_platform(data)\nE     File \"C:\\Users\\alozovsk\\Anaconda3\\envs\\modin\\lib\\site-packages\\pandas\\core\\dtypes\\cast.py\", line 112, in maybe_convert_platform\nE       values = construct_1d_object_array_from_listlike(values)\nE     File \"C:\\Users\\alozovsk\\Anaconda3\\envs\\modin\\lib\\site-packages\\pandas\\core\\dtypes\\cast.py\", line 1639, in construct_1d_object_array_from_listlike\nE       result[:] = values\nE   TypeError: __array__() takes 1 positional argument but 2 were given"
                },
                "teardown": {
                    "name": "teardown",
                    "duration": 0.0005290000000002237,
                    "outcome": "passed"
                },
                "outcome": "failed"
            },
            {
                "name": "modin/pandas/test/dataframe/test_iter.py::test_itertuples_multiindex",
                "duration": 3.476468399999998,
                "run_index": 5,
                "setup": {
                    "name": "setup",
                    "duration": 0.0009259999999997603,
                    "outcome": "passed"
                },
                "call": {
                    "name": "call",
                    "duration": 3.4737668,
                    "outcome": "failed",
                    "longrepr": "modin\\pandas\\test\\dataframe\\test_iter.py:72: in test_itertuples_multiindex\n    modin_df.columns = new_idx\nmodin\\experimental\\cloud\\rpyc_proxy.py:499: in __setattr__\n    setattr(self.__remote_end__, name, value)\nC:\\Users\\alozovsk\\Anaconda3\\envs\\modin\\lib\\site-packages\\rpyc\\core\\netref.py:178: in __setattr__\n    syncreq(self, consts.HANDLE_SETATTR, name, value)\nC:\\Users\\alozovsk\\Anaconda3\\envs\\modin\\lib\\site-packages\\rpyc\\core\\netref.py:76: in syncreq\n    return conn.sync_request(handler, proxy, *args)\nmodin\\experimental\\cloud\\rpyc_proxy.py:160: in sync_request\n    return super().sync_request(handler, *args)\nC:\\Users\\alozovsk\\Anaconda3\\envs\\modin\\lib\\site-packages\\rpyc\\core\\protocol.py:469: in sync_request\n    return self.async_request(handler, *args, timeout=timeout).value\nC:\\Users\\alozovsk\\Anaconda3\\envs\\modin\\lib\\site-packages\\rpyc\\core\\async_.py:102: in value\n    raise self._obj\nE   _get_exception_class.<locals>.Derived: 'slice' object has no attribute '__array__'\nE   \nE   ========= Remote Traceback (3) =========\nE   Traceback (most recent call last):\nE     File \"C:\\Users\\alozovsk\\Anaconda3\\envs\\modin\\lib\\site-packages\\rpyc\\core\\protocol.py\", line 320, in _dispatch_request\nE       res = self._HANDLERS[handler](self, *args)\nE     File \"C:\\Users\\alozovsk\\Anaconda3\\envs\\modin\\lib\\site-packages\\rpyc\\core\\protocol.py\", line 615, in _handle_setattr\nE       return self._access_attr(obj, name, (value,), \"_rpyc_setattr\", \"allow_setattr\", setattr)\nE     File \"C:\\Users\\alozovsk\\Anaconda3\\envs\\modin\\lib\\site-packages\\rpyc\\core\\protocol.py\", line 537, in _access_attr\nE       return accessor(obj, name, *args)\nE     File \"C:\\prog\\modin\\modin\\pandas\\dataframe.py\", line 2418, in __setattr__\nE       object.__setattr__(self, key, value)\nE     File \"C:\\prog\\modin\\modin\\pandas\\dataframe.py\", line 262, in _set_columns\nE       self._query_compiler.columns = new_columns\nE     File \"C:\\prog\\modin\\modin\\backends\\pandas\\query_compiler.py\", line 96, in set_axis\nE       self._modin_frame.columns = cols\nE     File \"C:\\prog\\modin\\modin\\engines\\base\\frame\\data.py\", line 270, in _set_columns\nE       self.synchronize_labels(axis=1)\nE     File \"C:\\prog\\modin\\modin\\engines\\base\\frame\\data.py\", line 399, in synchronize_labels\nE       [\nE     File \"C:\\prog\\modin\\modin\\engines\\base\\frame\\data.py\", line 400, in <listcomp>\nE       [\nE     File \"C:\\prog\\modin\\modin\\engines\\base\\frame\\data.py\", line 403, in <listcomp>\nE       cols=self.columns[\nE     File \"C:\\Users\\alozovsk\\Anaconda3\\envs\\modin\\lib\\site-packages\\rpyc\\core\\netref.py\", line 275, in method\nE       return syncreq(_self, consts.HANDLE_CALLATTR, name, args, kwargs)\nE     File \"C:\\Users\\alozovsk\\Anaconda3\\envs\\modin\\lib\\site-packages\\rpyc\\core\\netref.py\", line 76, in syncreq\nE       return conn.sync_request(handler, proxy, *args)\nE     File \"C:\\Users\\alozovsk\\Anaconda3\\envs\\modin\\lib\\site-packages\\rpyc\\core\\protocol.py\", line 469, in sync_request\nE       return self.async_request(handler, *args, timeout=timeout).value\nE     File \"C:\\Users\\alozovsk\\Anaconda3\\envs\\modin\\lib\\site-packages\\rpyc\\core\\async_.py\", line 102, in value\nE       raise self._obj\nE   _get_exception_class.<locals>.Derived: 'slice' object has no attribute '__array__'\nE   \nE   ========= Remote Traceback (2) =========\nE   Traceback (most recent call last):\nE     File \"C:\\Users\\alozovsk\\Anaconda3\\envs\\modin\\lib\\site-packages\\rpyc\\core\\protocol.py\", line 320, in _dispatch_request\nE       res = self._HANDLERS[handler](self, *args)\nE     File \"C:\\Users\\alozovsk\\Anaconda3\\envs\\modin\\lib\\site-packages\\rpyc\\core\\protocol.py\", line 619, in _handle_callattr\nE       return self._handle_call(obj, args, kwargs)\nE     File \"C:\\Users\\alozovsk\\Anaconda3\\envs\\modin\\lib\\site-packages\\rpyc\\core\\protocol.py\", line 593, in _handle_call\nE       return obj(*args, **dict(kwargs))\nE     File \"C:\\Users\\alozovsk\\Anaconda3\\envs\\modin\\lib\\site-packages\\pandas\\core\\indexes\\multi.py\", line 2045, in __getitem__\nE       new_codes = [level_codes[key] for level_codes in self.codes]\nE     File \"C:\\Users\\alozovsk\\Anaconda3\\envs\\modin\\lib\\site-packages\\pandas\\core\\indexes\\multi.py\", line 2045, in <listcomp>\nE       new_codes = [level_codes[key] for level_codes in self.codes]\nE     File \"C:\\prog\\modin\\modin\\experimental\\cloud\\rpyc_proxy.py\", line 213, in __array__\nE       return pickle.loads(self._remote_pickled_array(this))\nE     File \"C:\\Users\\alozovsk\\Anaconda3\\envs\\modin\\lib\\site-packages\\rpyc\\core\\netref.py\", line 253, in __call__\nE       return syncreq(_self, consts.HANDLE_CALL, args, kwargs)\nE     File \"C:\\Users\\alozovsk\\Anaconda3\\envs\\modin\\lib\\site-packages\\rpyc\\core\\netref.py\", line 76, in syncreq\nE       return conn.sync_request(handler, proxy, *args)\nE     File \"C:\\prog\\modin\\modin\\experimental\\cloud\\rpyc_proxy.py\", line 160, in sync_request\nE       return super().sync_request(handler, *args)\nE     File \"C:\\Users\\alozovsk\\Anaconda3\\envs\\modin\\lib\\site-packages\\rpyc\\core\\protocol.py\", line 469, in sync_request\nE       return self.async_request(handler, *args, timeout=timeout).value\nE     File \"C:\\Users\\alozovsk\\Anaconda3\\envs\\modin\\lib\\site-packages\\rpyc\\core\\async_.py\", line 102, in value\nE       raise self._obj\nE   _get_exception_class.<locals>.Derived: 'slice' object has no attribute '__array__'\nE   \nE   ========= Remote Traceback (1) =========\nE   Traceback (most recent call last):\nE     File \"C:\\Users\\alozovsk\\Anaconda3\\envs\\modin\\lib\\site-packages\\rpyc\\core\\protocol.py\", line 320, in _dispatch_request\nE       res = self._HANDLERS[handler](self, *args)\nE     File \"C:\\Users\\alozovsk\\Anaconda3\\envs\\modin\\lib\\site-packages\\rpyc\\core\\protocol.py\", line 593, in _handle_call\nE       return obj(*args, **dict(kwargs))\nE     File \"C:\\prog\\modin\\modin\\experimental\\cloud\\rpyc_proxy.py\", line 38, in _pickled_array\nE       return pickle.dumps(obj.__array__())\nE   AttributeError: 'slice' object has no attribute '__array__'"
                },
                "teardown": {
                    "name": "teardown",
                    "duration": 0.0008495999999986736,
                    "outcome": "passed"
                },
                "outcome": "failed"
            },
            {
                "name": "modin/pandas/test/dataframe/test_iter.py::test___iter__",
                "duration": 3.082989900000001,
                "run_index": 6,
                "setup": {
                    "name": "setup",
                    "duration": 0.0009233000000001823,
                    "outcome": "passed"
                },
                "call": {
                    "name": "call",
                    "duration": 3.080627200000002,
                    "outcome": "passed"
                },
                "teardown": {
                    "name": "teardown",
                    "duration": 0.000516099999998687,
                    "outcome": "passed"
                },
                "outcome": "passed"
            },
            {
                "name": "modin/pandas/test/dataframe/test_iter.py::test___contains__[int_data]",
                "duration": 3.238464900000004,
                "run_index": 7,
                "setup": {
                    "name": "setup",
                    "duration": 0.0006601000000010515,
                    "outcome": "passed"
                },
                "call": {
                    "name": "call",
                    "duration": 3.2365089000000005,
                    "outcome": "passed"
                },
                "teardown": {
                    "name": "teardown",
                    "duration": 0.0006358000000012964,
                    "outcome": "passed"
                },
                "outcome": "passed"
            },
            {
                "name": "modin/pandas/test/dataframe/test_iter.py::test___contains__[float_nan_data]",
                "duration": 1.3209165000000063,
                "run_index": 8,
                "setup": {
                    "name": "setup",
                    "duration": 0.0005930000000020641,
                    "outcome": "passed"
                },
                "call": {
                    "name": "call",
                    "duration": 1.3192175000000006,
                    "outcome": "failed",
                    "longrepr": "modin\\pandas\\test\\dataframe\\test_iter.py:96: in test___contains__\n    modin_df = pd.DataFrame(data)\nmodin\\experimental\\cloud\\meta_magic.py:155: in __new__\n    return cls.__real_cls__(*a, **kw)\nmodin\\experimental\\cloud\\rpyc_proxy.py:430: in __init__\n    __remote_end__ = remote_cls(*a, **kw)\nC:\\Users\\alozovsk\\Anaconda3\\envs\\modin\\lib\\site-packages\\rpyc\\core\\netref.py:253: in __call__\n    return syncreq(_self, consts.HANDLE_CALL, args, kwargs)\nC:\\Users\\alozovsk\\Anaconda3\\envs\\modin\\lib\\site-packages\\rpyc\\core\\netref.py:76: in syncreq\n    return conn.sync_request(handler, proxy, *args)\nmodin\\experimental\\cloud\\rpyc_proxy.py:160: in sync_request\n    return super().sync_request(handler, *args)\nC:\\Users\\alozovsk\\Anaconda3\\envs\\modin\\lib\\site-packages\\rpyc\\core\\protocol.py:469: in sync_request\n    return self.async_request(handler, *args, timeout=timeout).value\nC:\\Users\\alozovsk\\Anaconda3\\envs\\modin\\lib\\site-packages\\rpyc\\core\\async_.py:102: in value\n    raise self._obj\nE   _get_exception_class.<locals>.Derived: __array__() takes 1 positional argument but 2 were given\nE   \nE   ========= Remote Traceback (1) =========\nE   Traceback (most recent call last):\nE     File \"C:\\Users\\alozovsk\\Anaconda3\\envs\\modin\\lib\\site-packages\\rpyc\\core\\protocol.py\", line 320, in _dispatch_request\nE       res = self._HANDLERS[handler](self, *args)\nE     File \"C:\\Users\\alozovsk\\Anaconda3\\envs\\modin\\lib\\site-packages\\rpyc\\core\\protocol.py\", line 593, in _handle_call\nE       return obj(*args, **dict(kwargs))\nE     File \"C:\\prog\\modin\\modin\\pandas\\dataframe.py\", line 171, in __init__\nE       pandas_df = pandas.DataFrame(\nE     File \"C:\\Users\\alozovsk\\Anaconda3\\envs\\modin\\lib\\site-packages\\pandas\\core\\frame.py\", line 529, in __init__\nE       mgr = init_dict(data, index, columns, dtype=dtype)\nE     File \"C:\\Users\\alozovsk\\Anaconda3\\envs\\modin\\lib\\site-packages\\pandas\\core\\internals\\construction.py\", line 287, in init_dict\nE       return arrays_to_mgr(arrays, data_names, index, columns, dtype=dtype)\nE     File \"C:\\Users\\alozovsk\\Anaconda3\\envs\\modin\\lib\\site-packages\\pandas\\core\\internals\\construction.py\", line 85, in arrays_to_mgr\nE       arrays = _homogenize(arrays, index, dtype)\nE     File \"C:\\Users\\alozovsk\\Anaconda3\\envs\\modin\\lib\\site-packages\\pandas\\core\\internals\\construction.py\", line 355, in _homogenize\nE       val = sanitize_array(\nE     File \"C:\\Users\\alozovsk\\Anaconda3\\envs\\modin\\lib\\site-packages\\pandas\\core\\construction.py\", line 482, in sanitize_array\nE       subarr = maybe_convert_platform(data)\nE     File \"C:\\Users\\alozovsk\\Anaconda3\\envs\\modin\\lib\\site-packages\\pandas\\core\\dtypes\\cast.py\", line 112, in maybe_convert_platform\nE       values = construct_1d_object_array_from_listlike(values)\nE     File \"C:\\Users\\alozovsk\\Anaconda3\\envs\\modin\\lib\\site-packages\\pandas\\core\\dtypes\\cast.py\", line 1639, in construct_1d_object_array_from_listlike\nE       result[:] = values\nE   TypeError: __array__() takes 1 positional argument but 2 were given"
                },
                "teardown": {
                    "name": "teardown",
                    "duration": 0.00051300000000154,
                    "outcome": "passed"
                },
                "outcome": "failed"
            },
            {
                "name": "modin/pandas/test/dataframe/test_iter.py::test__options_display",
                "duration": 5.5196525999999935,
                "run_index": 9,
                "setup": {
                    "name": "setup",
                    "duration": 0.0008047999999973854,
                    "outcome": "passed"
                },
                "call": {
                    "name": "call",
                    "duration": 5.5172302,
                    "outcome": "failed",
                    "longrepr": "modin\\pandas\\test\\dataframe\\test_iter.py:114: in test__options_display\n    modin_df = pd.DataFrame(frame_data)\nmodin\\experimental\\cloud\\meta_magic.py:155: in __new__\n    return cls.__real_cls__(*a, **kw)\nmodin\\experimental\\cloud\\rpyc_proxy.py:430: in __init__\n    __remote_end__ = remote_cls(*a, **kw)\nC:\\Users\\alozovsk\\Anaconda3\\envs\\modin\\lib\\site-packages\\rpyc\\core\\netref.py:253: in __call__\n    return syncreq(_self, consts.HANDLE_CALL, args, kwargs)\nC:\\Users\\alozovsk\\Anaconda3\\envs\\modin\\lib\\site-packages\\rpyc\\core\\netref.py:76: in syncreq\n    return conn.sync_request(handler, proxy, *args)\nmodin\\experimental\\cloud\\rpyc_proxy.py:160: in sync_request\n    return super().sync_request(handler, *args)\nC:\\Users\\alozovsk\\Anaconda3\\envs\\modin\\lib\\site-packages\\rpyc\\core\\protocol.py:469: in sync_request\n    return self.async_request(handler, *args, timeout=timeout).value\nC:\\Users\\alozovsk\\Anaconda3\\envs\\modin\\lib\\site-packages\\rpyc\\core\\async_.py:102: in value\n    raise self._obj\nE   _get_exception_class.<locals>.Derived: Cannot interpret 'dtype('int32')' as a data type\nE   \nE   ========= Remote Traceback (1) =========\nE   Traceback (most recent call last):\nE     File \"C:\\Users\\alozovsk\\Anaconda3\\envs\\modin\\lib\\site-packages\\rpyc\\core\\protocol.py\", line 320, in _dispatch_request\nE       res = self._HANDLERS[handler](self, *args)\nE     File \"C:\\Users\\alozovsk\\Anaconda3\\envs\\modin\\lib\\site-packages\\rpyc\\core\\protocol.py\", line 593, in _handle_call\nE       return obj(*args, **dict(kwargs))\nE     File \"C:\\prog\\modin\\modin\\pandas\\dataframe.py\", line 158, in __init__\nE       data = np.array(values, dtype=old_dtype)\nE   TypeError: Cannot interpret 'dtype('int32')' as a data type"
                },
                "teardown": {
                    "name": "teardown",
                    "duration": 0.0008127999999985036,
                    "outcome": "passed"
                },
                "outcome": "failed"
            },
            {
                "name": "modin/pandas/test/dataframe/test_iter.py::test___finalize__",
                "duration": 3.5498851999999985,
                "run_index": 10,
                "setup": {
                    "name": "setup",
                    "duration": 0.0007379000000007352,
                    "outcome": "passed"
                },
                "call": {
                    "name": "call",
                    "duration": 3.5477731000000006,
                    "outcome": "failed",
                    "longrepr": "modin\\pandas\\test\\dataframe\\test_iter.py:141: in test___finalize__\n    pd.DataFrame(data).__finalize__(None)\nE   Failed: DID NOT WARN. No warnings of type (<class 'UserWarning'>,) was emitted. The list of emitted warnings is: []."
                },
                "teardown": {
                    "name": "teardown",
                    "duration": 0.0006362999999964813,
                    "outcome": "passed"
                },
                "outcome": "failed"
            },
            {
                "name": "modin/pandas/test/dataframe/test_iter.py::test___copy__[int_data]",
                "duration": 3.2841439000000108,
                "run_index": 11,
                "setup": {
                    "name": "setup",
                    "duration": 0.0008309000000039646,
                    "outcome": "passed"
                },
                "call": {
                    "name": "call",
                    "duration": 3.2819195000000008,
                    "outcome": "passed"
                },
                "teardown": {
                    "name": "teardown",
                    "duration": 0.0005626000000020781,
                    "outcome": "passed"
                },
                "outcome": "passed"
            },
            {
                "name": "modin/pandas/test/dataframe/test_iter.py::test___copy__[float_nan_data]",
                "duration": 1.3077532999999946,
                "run_index": 12,
                "setup": {
                    "name": "setup",
                    "duration": 0.0007464999999982069,
                    "outcome": "passed"
                },
                "call": {
                    "name": "call",
                    "duration": 1.305713400000002,
                    "outcome": "failed",
                    "longrepr": "modin\\pandas\\test\\dataframe\\test_iter.py:146: in test___copy__\n    modin_df = pd.DataFrame(data)\nmodin\\experimental\\cloud\\meta_magic.py:155: in __new__\n    return cls.__real_cls__(*a, **kw)\nmodin\\experimental\\cloud\\rpyc_proxy.py:430: in __init__\n    __remote_end__ = remote_cls(*a, **kw)\nC:\\Users\\alozovsk\\Anaconda3\\envs\\modin\\lib\\site-packages\\rpyc\\core\\netref.py:253: in __call__\n    return syncreq(_self, consts.HANDLE_CALL, args, kwargs)\nC:\\Users\\alozovsk\\Anaconda3\\envs\\modin\\lib\\site-packages\\rpyc\\core\\netref.py:76: in syncreq\n    return conn.sync_request(handler, proxy, *args)\nmodin\\experimental\\cloud\\rpyc_proxy.py:160: in sync_request\n    return super().sync_request(handler, *args)\nC:\\Users\\alozovsk\\Anaconda3\\envs\\modin\\lib\\site-packages\\rpyc\\core\\protocol.py:469: in sync_request\n    return self.async_request(handler, *args, timeout=timeout).value\nC:\\Users\\alozovsk\\Anaconda3\\envs\\modin\\lib\\site-packages\\rpyc\\core\\async_.py:102: in value\n    raise self._obj\nE   _get_exception_class.<locals>.Derived: __array__() takes 1 positional argument but 2 were given\nE   \nE   ========= Remote Traceback (1) =========\nE   Traceback (most recent call last):\nE     File \"C:\\Users\\alozovsk\\Anaconda3\\envs\\modin\\lib\\site-packages\\rpyc\\core\\protocol.py\", line 320, in _dispatch_request\nE       res = self._HANDLERS[handler](self, *args)\nE     File \"C:\\Users\\alozovsk\\Anaconda3\\envs\\modin\\lib\\site-packages\\rpyc\\core\\protocol.py\", line 593, in _handle_call\nE       return obj(*args, **dict(kwargs))\nE     File \"C:\\prog\\modin\\modin\\pandas\\dataframe.py\", line 171, in __init__\nE       pandas_df = pandas.DataFrame(\nE     File \"C:\\Users\\alozovsk\\Anaconda3\\envs\\modin\\lib\\site-packages\\pandas\\core\\frame.py\", line 529, in __init__\nE       mgr = init_dict(data, index, columns, dtype=dtype)\nE     File \"C:\\Users\\alozovsk\\Anaconda3\\envs\\modin\\lib\\site-packages\\pandas\\core\\internals\\construction.py\", line 287, in init_dict\nE       return arrays_to_mgr(arrays, data_names, index, columns, dtype=dtype)\nE     File \"C:\\Users\\alozovsk\\Anaconda3\\envs\\modin\\lib\\site-packages\\pandas\\core\\internals\\construction.py\", line 85, in arrays_to_mgr\nE       arrays = _homogenize(arrays, index, dtype)\nE     File \"C:\\Users\\alozovsk\\Anaconda3\\envs\\modin\\lib\\site-packages\\pandas\\core\\internals\\construction.py\", line 355, in _homogenize\nE       val = sanitize_array(\nE     File \"C:\\Users\\alozovsk\\Anaconda3\\envs\\modin\\lib\\site-packages\\pandas\\core\\construction.py\", line 482, in sanitize_array\nE       subarr = maybe_convert_platform(data)\nE     File \"C:\\Users\\alozovsk\\Anaconda3\\envs\\modin\\lib\\site-packages\\pandas\\core\\dtypes\\cast.py\", line 112, in maybe_convert_platform\nE       values = construct_1d_object_array_from_listlike(values)\nE     File \"C:\\Users\\alozovsk\\Anaconda3\\envs\\modin\\lib\\site-packages\\pandas\\core\\dtypes\\cast.py\", line 1639, in construct_1d_object_array_from_listlike\nE       result[:] = values\nE   TypeError: __array__() takes 1 positional argument but 2 were given"
                },
                "teardown": {
                    "name": "teardown",
                    "duration": 0.0005468999999962421,
                    "outcome": "passed"
                },
                "outcome": "failed"
            },
            {
                "name": "modin/pandas/test/dataframe/test_iter.py::test___deepcopy__[int_data]",
                "duration": 3.490889999999993,
                "run_index": 13,
                "setup": {
                    "name": "setup",
                    "duration": 0.0009204999999994357,
                    "outcome": "passed"
                },
                "call": {
                    "name": "call",
                    "duration": 3.488392300000001,
                    "outcome": "passed"
                },
                "teardown": {
                    "name": "teardown",
                    "duration": 0.0006566999999932932,
                    "outcome": "passed"
                },
                "outcome": "passed"
            },
            {
                "name": "modin/pandas/test/dataframe/test_iter.py::test___deepcopy__[float_nan_data]",
                "duration": 1.7191094000000007,
                "run_index": 14,
                "setup": {
                    "name": "setup",
                    "duration": 0.0008456999999992831,
                    "outcome": "passed"
                },
                "call": {
                    "name": "call",
                    "duration": 1.7169121000000018,
                    "outcome": "failed",
                    "longrepr": "modin\\pandas\\test\\dataframe\\test_iter.py:155: in test___deepcopy__\n    modin_df = pd.DataFrame(data)\nmodin\\experimental\\cloud\\meta_magic.py:155: in __new__\n    return cls.__real_cls__(*a, **kw)\nmodin\\experimental\\cloud\\rpyc_proxy.py:430: in __init__\n    __remote_end__ = remote_cls(*a, **kw)\nC:\\Users\\alozovsk\\Anaconda3\\envs\\modin\\lib\\site-packages\\rpyc\\core\\netref.py:253: in __call__\n    return syncreq(_self, consts.HANDLE_CALL, args, kwargs)\nC:\\Users\\alozovsk\\Anaconda3\\envs\\modin\\lib\\site-packages\\rpyc\\core\\netref.py:76: in syncreq\n    return conn.sync_request(handler, proxy, *args)\nmodin\\experimental\\cloud\\rpyc_proxy.py:160: in sync_request\n    return super().sync_request(handler, *args)\nC:\\Users\\alozovsk\\Anaconda3\\envs\\modin\\lib\\site-packages\\rpyc\\core\\protocol.py:469: in sync_request\n    return self.async_request(handler, *args, timeout=timeout).value\nC:\\Users\\alozovsk\\Anaconda3\\envs\\modin\\lib\\site-packages\\rpyc\\core\\async_.py:102: in value\n    raise self._obj\nE   _get_exception_class.<locals>.Derived: __array__() takes 1 positional argument but 2 were given\nE   \nE   ========= Remote Traceback (1) =========\nE   Traceback (most recent call last):\nE     File \"C:\\Users\\alozovsk\\Anaconda3\\envs\\modin\\lib\\site-packages\\rpyc\\core\\protocol.py\", line 320, in _dispatch_request\nE       res = self._HANDLERS[handler](self, *args)\nE     File \"C:\\Users\\alozovsk\\Anaconda3\\envs\\modin\\lib\\site-packages\\rpyc\\core\\protocol.py\", line 593, in _handle_call\nE       return obj(*args, **dict(kwargs))\nE     File \"C:\\prog\\modin\\modin\\pandas\\dataframe.py\", line 171, in __init__\nE       pandas_df = pandas.DataFrame(\nE     File \"C:\\Users\\alozovsk\\Anaconda3\\envs\\modin\\lib\\site-packages\\pandas\\core\\frame.py\", line 529, in __init__\nE       mgr = init_dict(data, index, columns, dtype=dtype)\nE     File \"C:\\Users\\alozovsk\\Anaconda3\\envs\\modin\\lib\\site-packages\\pandas\\core\\internals\\construction.py\", line 287, in init_dict\nE       return arrays_to_mgr(arrays, data_names, index, columns, dtype=dtype)\nE     File \"C:\\Users\\alozovsk\\Anaconda3\\envs\\modin\\lib\\site-packages\\pandas\\core\\internals\\construction.py\", line 85, in arrays_to_mgr\nE       arrays = _homogenize(arrays, index, dtype)\nE     File \"C:\\Users\\alozovsk\\Anaconda3\\envs\\modin\\lib\\site-packages\\pandas\\core\\internals\\construction.py\", line 355, in _homogenize\nE       val = sanitize_array(\nE     File \"C:\\Users\\alozovsk\\Anaconda3\\envs\\modin\\lib\\site-packages\\pandas\\core\\construction.py\", line 482, in sanitize_array\nE       subarr = maybe_convert_platform(data)\nE     File \"C:\\Users\\alozovsk\\Anaconda3\\envs\\modin\\lib\\site-packages\\pandas\\core\\dtypes\\cast.py\", line 112, in maybe_convert_platform\nE       values = construct_1d_object_array_from_listlike(values)\nE     File \"C:\\Users\\alozovsk\\Anaconda3\\envs\\modin\\lib\\site-packages\\pandas\\core\\dtypes\\cast.py\", line 1639, in construct_1d_object_array_from_listlike\nE       result[:] = values\nE   TypeError: __array__() takes 1 positional argument but 2 were given"
                },
                "teardown": {
                    "name": "teardown",
                    "duration": 0.0005059000000002811,
                    "outcome": "passed"
                },
                "outcome": "failed"
            },
            {
                "name": "modin/pandas/test/dataframe/test_iter.py::test___repr__",
                "duration": 5.56018379999999,
                "run_index": 15,
                "setup": {
                    "name": "setup",
                    "duration": 0.0009027999999986491,
                    "outcome": "passed"
                },
                "call": {
                    "name": "call",
                    "duration": 5.557774099999996,
                    "outcome": "failed",
                    "longrepr": "modin\\pandas\\test\\dataframe\\test_iter.py:168: in test___repr__\n    modin_df = pd.DataFrame(frame_data)\nmodin\\experimental\\cloud\\meta_magic.py:155: in __new__\n    return cls.__real_cls__(*a, **kw)\nmodin\\experimental\\cloud\\rpyc_proxy.py:430: in __init__\n    __remote_end__ = remote_cls(*a, **kw)\nC:\\Users\\alozovsk\\Anaconda3\\envs\\modin\\lib\\site-packages\\rpyc\\core\\netref.py:253: in __call__\n    return syncreq(_self, consts.HANDLE_CALL, args, kwargs)\nC:\\Users\\alozovsk\\Anaconda3\\envs\\modin\\lib\\site-packages\\rpyc\\core\\netref.py:76: in syncreq\n    return conn.sync_request(handler, proxy, *args)\nmodin\\experimental\\cloud\\rpyc_proxy.py:160: in sync_request\n    return super().sync_request(handler, *args)\nC:\\Users\\alozovsk\\Anaconda3\\envs\\modin\\lib\\site-packages\\rpyc\\core\\protocol.py:469: in sync_request\n    return self.async_request(handler, *args, timeout=timeout).value\nC:\\Users\\alozovsk\\Anaconda3\\envs\\modin\\lib\\site-packages\\rpyc\\core\\async_.py:102: in value\n    raise self._obj\nE   _get_exception_class.<locals>.Derived: Cannot interpret 'dtype('int32')' as a data type\nE   \nE   ========= Remote Traceback (1) =========\nE   Traceback (most recent call last):\nE     File \"C:\\Users\\alozovsk\\Anaconda3\\envs\\modin\\lib\\site-packages\\rpyc\\core\\protocol.py\", line 320, in _dispatch_request\nE       res = self._HANDLERS[handler](self, *args)\nE     File \"C:\\Users\\alozovsk\\Anaconda3\\envs\\modin\\lib\\site-packages\\rpyc\\core\\protocol.py\", line 593, in _handle_call\nE       return obj(*args, **dict(kwargs))\nE     File \"C:\\prog\\modin\\modin\\pandas\\dataframe.py\", line 158, in __init__\nE       data = np.array(values, dtype=old_dtype)\nE   TypeError: Cannot interpret 'dtype('int32')' as a data type"
                },
                "teardown": {
                    "name": "teardown",
                    "duration": 0.0006040999999967767,
                    "outcome": "passed"
                },
                "outcome": "failed"
            },
            {
                "name": "modin/pandas/test/dataframe/test_iter.py::test_inplace_series_ops[int_data]",
                "duration": 3.671584100000004,
                "run_index": 16,
                "setup": {
                    "name": "setup",
                    "duration": 0.0008938000000000557,
                    "outcome": "passed"
                },
                "call": {
                    "name": "call",
                    "duration": 3.669251199999998,
                    "outcome": "passed"
                },
                "teardown": {
                    "name": "teardown",
                    "duration": 0.000545300000005966,
                    "outcome": "passed"
                },
                "outcome": "passed"
            },
            {
                "name": "modin/pandas/test/dataframe/test_iter.py::test_inplace_series_ops[float_nan_data]",
                "duration": 0.6018663999999916,
                "run_index": 17,
                "setup": {
                    "name": "setup",
                    "duration": 0.0006692999999984295,
                    "outcome": "passed"
                },
                "call": {
                    "name": "call",
                    "duration": 0.6000464999999977,
                    "outcome": "failed",
                    "longrepr": "modin\\pandas\\test\\dataframe\\test_iter.py:235: in test_inplace_series_ops\n    modin_df = pd.DataFrame(data)\nmodin\\experimental\\cloud\\meta_magic.py:155: in __new__\n    return cls.__real_cls__(*a, **kw)\nmodin\\experimental\\cloud\\rpyc_proxy.py:430: in __init__\n    __remote_end__ = remote_cls(*a, **kw)\nC:\\Users\\alozovsk\\Anaconda3\\envs\\modin\\lib\\site-packages\\rpyc\\core\\netref.py:253: in __call__\n    return syncreq(_self, consts.HANDLE_CALL, args, kwargs)\nC:\\Users\\alozovsk\\Anaconda3\\envs\\modin\\lib\\site-packages\\rpyc\\core\\netref.py:76: in syncreq\n    return conn.sync_request(handler, proxy, *args)\nmodin\\experimental\\cloud\\rpyc_proxy.py:160: in sync_request\n    return super().sync_request(handler, *args)\nC:\\Users\\alozovsk\\Anaconda3\\envs\\modin\\lib\\site-packages\\rpyc\\core\\protocol.py:469: in sync_request\n    return self.async_request(handler, *args, timeout=timeout).value\nC:\\Users\\alozovsk\\Anaconda3\\envs\\modin\\lib\\site-packages\\rpyc\\core\\async_.py:102: in value\n    raise self._obj\nE   _get_exception_class.<locals>.Derived: __array__() takes 1 positional argument but 2 were given\nE   \nE   ========= Remote Traceback (1) =========\nE   Traceback (most recent call last):\nE     File \"C:\\Users\\alozovsk\\Anaconda3\\envs\\modin\\lib\\site-packages\\rpyc\\core\\protocol.py\", line 320, in _dispatch_request\nE       res = self._HANDLERS[handler](self, *args)\nE     File \"C:\\Users\\alozovsk\\Anaconda3\\envs\\modin\\lib\\site-packages\\rpyc\\core\\protocol.py\", line 593, in _handle_call\nE       return obj(*args, **dict(kwargs))\nE     File \"C:\\prog\\modin\\modin\\pandas\\dataframe.py\", line 171, in __init__\nE       pandas_df = pandas.DataFrame(\nE     File \"C:\\Users\\alozovsk\\Anaconda3\\envs\\modin\\lib\\site-packages\\pandas\\core\\frame.py\", line 529, in __init__\nE       mgr = init_dict(data, index, columns, dtype=dtype)\nE     File \"C:\\Users\\alozovsk\\Anaconda3\\envs\\modin\\lib\\site-packages\\pandas\\core\\internals\\construction.py\", line 287, in init_dict\nE       return arrays_to_mgr(arrays, data_names, index, columns, dtype=dtype)\nE     File \"C:\\Users\\alozovsk\\Anaconda3\\envs\\modin\\lib\\site-packages\\pandas\\core\\internals\\construction.py\", line 85, in arrays_to_mgr\nE       arrays = _homogenize(arrays, index, dtype)\nE     File \"C:\\Users\\alozovsk\\Anaconda3\\envs\\modin\\lib\\site-packages\\pandas\\core\\internals\\construction.py\", line 355, in _homogenize\nE       val = sanitize_array(\nE     File \"C:\\Users\\alozovsk\\Anaconda3\\envs\\modin\\lib\\site-packages\\pandas\\core\\construction.py\", line 482, in sanitize_array\nE       subarr = maybe_convert_platform(data)\nE     File \"C:\\Users\\alozovsk\\Anaconda3\\envs\\modin\\lib\\site-packages\\pandas\\core\\dtypes\\cast.py\", line 112, in maybe_convert_platform\nE       values = construct_1d_object_array_from_listlike(values)\nE     File \"C:\\Users\\alozovsk\\Anaconda3\\envs\\modin\\lib\\site-packages\\pandas\\core\\dtypes\\cast.py\", line 1639, in construct_1d_object_array_from_listlike\nE       result[:] = values\nE   TypeError: __array__() takes 1 positional argument but 2 were given"
                },
                "teardown": {
                    "name": "teardown",
                    "duration": 0.0004812999999970202,
                    "outcome": "passed"
                },
                "outcome": "failed"
            },
            {
                "name": "modin/pandas/test/dataframe/test_iter.py::test___setattr__",
                "duration": 0.062062600000011514,
                "run_index": 18,
                "setup": {
                    "name": "setup",
                    "duration": 0.0008398000000013894,
                    "outcome": "passed"
                },
                "call": {
                    "name": "call",
                    "duration": 0.05971630000000516,
                    "outcome": "passed"
                },
                "teardown": {
                    "name": "teardown",
                    "duration": 0.0006667000000035728,
                    "outcome": "passed"
                },
                "outcome": "passed"
            },
            {
                "name": "modin/pandas/test/dataframe/test_iter.py::test_isin[int_data]",
                "duration": 3.5865691000000055,
                "run_index": 19,
                "setup": {
                    "name": "setup",
                    "duration": 0.000610600000001682,
                    "outcome": "passed"
                },
                "call": {
                    "name": "call",
                    "duration": 3.5847671000000005,
                    "outcome": "passed"
                },
                "teardown": {
                    "name": "teardown",
                    "duration": 0.0005808000000016023,
                    "outcome": "passed"
                },
                "outcome": "passed"
            },
            {
                "name": "modin/pandas/test/dataframe/test_iter.py::test_isin[float_nan_data]",
                "duration": 0.6035250000000119,
                "run_index": 20,
                "setup": {
                    "name": "setup",
                    "duration": 0.0006589000000047918,
                    "outcome": "passed"
                },
                "call": {
                    "name": "call",
                    "duration": 0.6016885000000016,
                    "outcome": "failed",
                    "longrepr": "modin\\pandas\\test\\dataframe\\test_iter.py:262: in test_isin\n    modin_df = pd.DataFrame(data)\nmodin\\experimental\\cloud\\meta_magic.py:155: in __new__\n    return cls.__real_cls__(*a, **kw)\nmodin\\experimental\\cloud\\rpyc_proxy.py:430: in __init__\n    __remote_end__ = remote_cls(*a, **kw)\nC:\\Users\\alozovsk\\Anaconda3\\envs\\modin\\lib\\site-packages\\rpyc\\core\\netref.py:253: in __call__\n    return syncreq(_self, consts.HANDLE_CALL, args, kwargs)\nC:\\Users\\alozovsk\\Anaconda3\\envs\\modin\\lib\\site-packages\\rpyc\\core\\netref.py:76: in syncreq\n    return conn.sync_request(handler, proxy, *args)\nmodin\\experimental\\cloud\\rpyc_proxy.py:160: in sync_request\n    return super().sync_request(handler, *args)\nC:\\Users\\alozovsk\\Anaconda3\\envs\\modin\\lib\\site-packages\\rpyc\\core\\protocol.py:469: in sync_request\n    return self.async_request(handler, *args, timeout=timeout).value\nC:\\Users\\alozovsk\\Anaconda3\\envs\\modin\\lib\\site-packages\\rpyc\\core\\async_.py:102: in value\n    raise self._obj\nE   _get_exception_class.<locals>.Derived: __array__() takes 1 positional argument but 2 were given\nE   \nE   ========= Remote Traceback (1) =========\nE   Traceback (most recent call last):\nE     File \"C:\\Users\\alozovsk\\Anaconda3\\envs\\modin\\lib\\site-packages\\rpyc\\core\\protocol.py\", line 320, in _dispatch_request\nE       res = self._HANDLERS[handler](self, *args)\nE     File \"C:\\Users\\alozovsk\\Anaconda3\\envs\\modin\\lib\\site-packages\\rpyc\\core\\protocol.py\", line 593, in _handle_call\nE       return obj(*args, **dict(kwargs))\nE     File \"C:\\prog\\modin\\modin\\pandas\\dataframe.py\", line 171, in __init__\nE       pandas_df = pandas.DataFrame(\nE     File \"C:\\Users\\alozovsk\\Anaconda3\\envs\\modin\\lib\\site-packages\\pandas\\core\\frame.py\", line 529, in __init__\nE       mgr = init_dict(data, index, columns, dtype=dtype)\nE     File \"C:\\Users\\alozovsk\\Anaconda3\\envs\\modin\\lib\\site-packages\\pandas\\core\\internals\\construction.py\", line 287, in init_dict\nE       return arrays_to_mgr(arrays, data_names, index, columns, dtype=dtype)\nE     File \"C:\\Users\\alozovsk\\Anaconda3\\envs\\modin\\lib\\site-packages\\pandas\\core\\internals\\construction.py\", line 85, in arrays_to_mgr\nE       arrays = _homogenize(arrays, index, dtype)\nE     File \"C:\\Users\\alozovsk\\Anaconda3\\envs\\modin\\lib\\site-packages\\pandas\\core\\internals\\construction.py\", line 355, in _homogenize\nE       val = sanitize_array(\nE     File \"C:\\Users\\alozovsk\\Anaconda3\\envs\\modin\\lib\\site-packages\\pandas\\core\\construction.py\", line 482, in sanitize_array\nE       subarr = maybe_convert_platform(data)\nE     File \"C:\\Users\\alozovsk\\Anaconda3\\envs\\modin\\lib\\site-packages\\pandas\\core\\dtypes\\cast.py\", line 112, in maybe_convert_platform\nE       values = construct_1d_object_array_from_listlike(values)\nE     File \"C:\\Users\\alozovsk\\Anaconda3\\envs\\modin\\lib\\site-packages\\pandas\\core\\dtypes\\cast.py\", line 1639, in construct_1d_object_array_from_listlike\nE       result[:] = values\nE   TypeError: __array__() takes 1 positional argument but 2 were given"
                },
                "teardown": {
                    "name": "teardown",
                    "duration": 0.0005187000000006492,
                    "outcome": "passed"
                },
                "outcome": "failed"
            },
            {
                "name": "modin/pandas/test/dataframe/test_iter.py::test_constructor[int_data]",
                "duration": 3.2328633999999994,
                "run_index": 21,
                "setup": {
                    "name": "setup",
                    "duration": 0.0008598000000006323,
                    "outcome": "passed"
                },
                "call": {
                    "name": "call",
                    "duration": 3.2305960999999996,
                    "outcome": "failed",
                    "longrepr": "modin\\pandas\\test\\dataframe\\test_iter.py:275: in test_constructor\n    df_equals(pandas_df, modin_df)\nmodin\\pandas\\test\\utils.py:527: in df_equals\n    assert_frame_equal(\nE   AssertionError"
                },
                "teardown": {
                    "name": "teardown",
                    "duration": 0.0005476999999984855,
                    "outcome": "passed"
                },
                "outcome": "failed"
            },
            {
                "name": "modin/pandas/test/dataframe/test_iter.py::test_constructor[float_nan_data]",
                "duration": 0.6749766999999878,
                "run_index": 22,
                "setup": {
                    "name": "setup",
                    "duration": 0.0008287999999936346,
                    "outcome": "passed"
                },
                "call": {
                    "name": "call",
                    "duration": 0.6728161999999998,
                    "outcome": "failed",
                    "longrepr": "modin\\pandas\\test\\dataframe\\test_iter.py:274: in test_constructor\n    modin_df = pd.DataFrame(data)\nmodin\\experimental\\cloud\\meta_magic.py:155: in __new__\n    return cls.__real_cls__(*a, **kw)\nmodin\\experimental\\cloud\\rpyc_proxy.py:430: in __init__\n    __remote_end__ = remote_cls(*a, **kw)\nC:\\Users\\alozovsk\\Anaconda3\\envs\\modin\\lib\\site-packages\\rpyc\\core\\netref.py:253: in __call__\n    return syncreq(_self, consts.HANDLE_CALL, args, kwargs)\nC:\\Users\\alozovsk\\Anaconda3\\envs\\modin\\lib\\site-packages\\rpyc\\core\\netref.py:76: in syncreq\n    return conn.sync_request(handler, proxy, *args)\nmodin\\experimental\\cloud\\rpyc_proxy.py:160: in sync_request\n    return super().sync_request(handler, *args)\nC:\\Users\\alozovsk\\Anaconda3\\envs\\modin\\lib\\site-packages\\rpyc\\core\\protocol.py:469: in sync_request\n    return self.async_request(handler, *args, timeout=timeout).value\nC:\\Users\\alozovsk\\Anaconda3\\envs\\modin\\lib\\site-packages\\rpyc\\core\\async_.py:102: in value\n    raise self._obj\nE   _get_exception_class.<locals>.Derived: __array__() takes 1 positional argument but 2 were given\nE   \nE   ========= Remote Traceback (1) =========\nE   Traceback (most recent call last):\nE     File \"C:\\Users\\alozovsk\\Anaconda3\\envs\\modin\\lib\\site-packages\\rpyc\\core\\protocol.py\", line 320, in _dispatch_request\nE       res = self._HANDLERS[handler](self, *args)\nE     File \"C:\\Users\\alozovsk\\Anaconda3\\envs\\modin\\lib\\site-packages\\rpyc\\core\\protocol.py\", line 593, in _handle_call\nE       return obj(*args, **dict(kwargs))\nE     File \"C:\\prog\\modin\\modin\\pandas\\dataframe.py\", line 171, in __init__\nE       pandas_df = pandas.DataFrame(\nE     File \"C:\\Users\\alozovsk\\Anaconda3\\envs\\modin\\lib\\site-packages\\pandas\\core\\frame.py\", line 529, in __init__\nE       mgr = init_dict(data, index, columns, dtype=dtype)\nE     File \"C:\\Users\\alozovsk\\Anaconda3\\envs\\modin\\lib\\site-packages\\pandas\\core\\internals\\construction.py\", line 287, in init_dict\nE       return arrays_to_mgr(arrays, data_names, index, columns, dtype=dtype)\nE     File \"C:\\Users\\alozovsk\\Anaconda3\\envs\\modin\\lib\\site-packages\\pandas\\core\\internals\\construction.py\", line 85, in arrays_to_mgr\nE       arrays = _homogenize(arrays, index, dtype)\nE     File \"C:\\Users\\alozovsk\\Anaconda3\\envs\\modin\\lib\\site-packages\\pandas\\core\\internals\\construction.py\", line 355, in _homogenize\nE       val = sanitize_array(\nE     File \"C:\\Users\\alozovsk\\Anaconda3\\envs\\modin\\lib\\site-packages\\pandas\\core\\construction.py\", line 482, in sanitize_array\nE       subarr = maybe_convert_platform(data)\nE     File \"C:\\Users\\alozovsk\\Anaconda3\\envs\\modin\\lib\\site-packages\\pandas\\core\\dtypes\\cast.py\", line 112, in maybe_convert_platform\nE       values = construct_1d_object_array_from_listlike(values)\nE     File \"C:\\Users\\alozovsk\\Anaconda3\\envs\\modin\\lib\\site-packages\\pandas\\core\\dtypes\\cast.py\", line 1639, in construct_1d_object_array_from_listlike\nE       result[:] = values\nE   TypeError: __array__() takes 1 positional argument but 2 were given"
                },
                "teardown": {
                    "name": "teardown",
                    "duration": 0.00050290000000075,
                    "outcome": "passed"
                },
                "outcome": "failed"
            },
            {
                "name": "modin/pandas/test/dataframe/test_iter.py::test_constructor_dtypes[data0]",
                "duration": 32.1554491,
                "run_index": 23,
                "setup": {
                    "name": "setup",
                    "duration": 0.0010273999999981243,
                    "outcome": "passed"
                },
                "call": {
                    "name": "call",
                    "duration": 32.152742200000006,
                    "outcome": "failed",
                    "longrepr": "modin\\pandas\\test\\dataframe\\test_iter.py:295: in test_constructor_dtypes\n    md_df, pd_df = create_test_dfs(data)\nmodin\\pandas\\test\\utils.py:807: in create_test_dfs\n    post_fn, [pd.DataFrame(*args, **kwargs), pandas.DataFrame(*args, **kwargs)]\nmodin\\experimental\\cloud\\meta_magic.py:155: in __new__\n    return cls.__real_cls__(*a, **kw)\nmodin\\experimental\\cloud\\rpyc_proxy.py:430: in __init__\n    __remote_end__ = remote_cls(*a, **kw)\nC:\\Users\\alozovsk\\Anaconda3\\envs\\modin\\lib\\site-packages\\rpyc\\core\\netref.py:253: in __call__\n    return syncreq(_self, consts.HANDLE_CALL, args, kwargs)\nC:\\Users\\alozovsk\\Anaconda3\\envs\\modin\\lib\\site-packages\\rpyc\\core\\netref.py:76: in syncreq\n    return conn.sync_request(handler, proxy, *args)\nmodin\\experimental\\cloud\\rpyc_proxy.py:160: in sync_request\n    return super().sync_request(handler, *args)\nC:\\Users\\alozovsk\\Anaconda3\\envs\\modin\\lib\\site-packages\\rpyc\\core\\protocol.py:469: in sync_request\n    return self.async_request(handler, *args, timeout=timeout).value\nC:\\Users\\alozovsk\\Anaconda3\\envs\\modin\\lib\\site-packages\\rpyc\\core\\async_.py:102: in value\n    raise self._obj\nE   _get_exception_class.<locals>.Derived: Cannot interpret 'dtype('float32')' as a data type\nE   \nE   ========= Remote Traceback (1) =========\nE   Traceback (most recent call last):\nE     File \"C:\\Users\\alozovsk\\Anaconda3\\envs\\modin\\lib\\site-packages\\rpyc\\core\\protocol.py\", line 320, in _dispatch_request\nE       res = self._HANDLERS[handler](self, *args)\nE     File \"C:\\Users\\alozovsk\\Anaconda3\\envs\\modin\\lib\\site-packages\\rpyc\\core\\protocol.py\", line 593, in _handle_call\nE       return obj(*args, **dict(kwargs))\nE     File \"C:\\prog\\modin\\modin\\pandas\\dataframe.py\", line 158, in __init__\nE       data = np.array(values, dtype=old_dtype)\nE   TypeError: Cannot interpret 'dtype('float32')' as a data type"
                },
                "teardown": {
                    "name": "teardown",
                    "duration": 0.0006520999999963806,
                    "outcome": "passed"
                },
                "outcome": "failed"
            },
            {
                "name": "modin/pandas/test/dataframe/test_iter.py::test_constructor_dtypes[data1]",
                "duration": 0.16217420000002392,
                "run_index": 24,
                "setup": {
                    "name": "setup",
                    "duration": 0.0009990000000072996,
                    "outcome": "passed"
                },
                "call": {
                    "name": "call",
                    "duration": 0.15967670000000567,
                    "outcome": "failed",
                    "longrepr": "modin\\pandas\\test\\dataframe\\test_iter.py:295: in test_constructor_dtypes\n    md_df, pd_df = create_test_dfs(data)\nmodin\\pandas\\test\\utils.py:807: in create_test_dfs\n    post_fn, [pd.DataFrame(*args, **kwargs), pandas.DataFrame(*args, **kwargs)]\nmodin\\experimental\\cloud\\meta_magic.py:155: in __new__\n    return cls.__real_cls__(*a, **kw)\nmodin\\experimental\\cloud\\rpyc_proxy.py:430: in __init__\n    __remote_end__ = remote_cls(*a, **kw)\nC:\\Users\\alozovsk\\Anaconda3\\envs\\modin\\lib\\site-packages\\rpyc\\core\\netref.py:253: in __call__\n    return syncreq(_self, consts.HANDLE_CALL, args, kwargs)\nC:\\Users\\alozovsk\\Anaconda3\\envs\\modin\\lib\\site-packages\\rpyc\\core\\netref.py:76: in syncreq\n    return conn.sync_request(handler, proxy, *args)\nmodin\\experimental\\cloud\\rpyc_proxy.py:160: in sync_request\n    return super().sync_request(handler, *args)\nC:\\Users\\alozovsk\\Anaconda3\\envs\\modin\\lib\\site-packages\\rpyc\\core\\protocol.py:469: in sync_request\n    return self.async_request(handler, *args, timeout=timeout).value\nC:\\Users\\alozovsk\\Anaconda3\\envs\\modin\\lib\\site-packages\\rpyc\\core\\async_.py:102: in value\n    raise self._obj\nE   _get_exception_class.<locals>.Derived: __array__() takes 1 positional argument but 2 were given\nE   \nE   ========= Remote Traceback (1) =========\nE   Traceback (most recent call last):\nE     File \"C:\\Users\\alozovsk\\Anaconda3\\envs\\modin\\lib\\site-packages\\rpyc\\core\\protocol.py\", line 320, in _dispatch_request\nE       res = self._HANDLERS[handler](self, *args)\nE     File \"C:\\Users\\alozovsk\\Anaconda3\\envs\\modin\\lib\\site-packages\\rpyc\\core\\protocol.py\", line 593, in _handle_call\nE       return obj(*args, **dict(kwargs))\nE     File \"C:\\prog\\modin\\modin\\pandas\\dataframe.py\", line 171, in __init__\nE       pandas_df = pandas.DataFrame(\nE     File \"C:\\Users\\alozovsk\\Anaconda3\\envs\\modin\\lib\\site-packages\\pandas\\core\\frame.py\", line 570, in __init__\nE       arrays, columns = to_arrays(data, columns, dtype=dtype)\nE     File \"C:\\Users\\alozovsk\\Anaconda3\\envs\\modin\\lib\\site-packages\\pandas\\core\\internals\\construction.py\", line 534, in to_arrays\nE       return _list_of_series_to_arrays(\nE     File \"C:\\Users\\alozovsk\\Anaconda3\\envs\\modin\\lib\\site-packages\\pandas\\core\\internals\\construction.py\", line 600, in _list_of_series_to_arrays\nE       aligned_values.append(algorithms.take_1d(values, indexer))\nE     File \"C:\\Users\\alozovsk\\Anaconda3\\envs\\modin\\lib\\site-packages\\pandas\\core\\algorithms.py\", line 1708, in take_nd\nE       indexer = ensure_int64(indexer, copy=False)\nE     File \"pandas\\_libs\\algos_common_helper.pxi\", line 93, in pandas._libs.algos.ensure_int64\nE   TypeError: __array__() takes 1 positional argument but 2 were given"
                },
                "teardown": {
                    "name": "teardown",
                    "duration": 0.0004995000000036498,
                    "outcome": "passed"
                },
                "outcome": "failed"
            },
            {
                "name": "modin/pandas/test/dataframe/test_iter.py::test_constructor_dtypes[data2]",
                "duration": 0.071772100000004,
                "run_index": 25,
                "setup": {
                    "name": "setup",
                    "duration": 0.0009928999999999633,
                    "outcome": "passed"
                },
                "call": {
                    "name": "call",
                    "duration": 0.06909149999999897,
                    "outcome": "passed"
                },
                "teardown": {
                    "name": "teardown",
                    "duration": 0.0006948000000051024,
                    "outcome": "passed"
                },
                "outcome": "passed"
            },
            {
                "name": "modin/pandas/test/dataframe/test_iter.py::test_constructor_columns_and_index",
                "duration": 1.5803178000000173,
                "run_index": 26,
                "setup": {
                    "name": "setup",
                    "duration": 0.0005795000000006212,
                    "outcome": "passed"
                },
                "call": {
                    "name": "call",
                    "duration": 1.5757908000000072,
                    "outcome": "failed",
                    "longrepr": "modin\\pandas\\test\\dataframe\\test_iter.py:313: in test_constructor_columns_and_index\n    pd.DataFrame(modin_df, columns=[\"max_speed\", \"health\"]),\nmodin\\experimental\\cloud\\meta_magic.py:155: in __new__\n    return cls.__real_cls__(*a, **kw)\nmodin\\experimental\\cloud\\rpyc_proxy.py:430: in __init__\n    __remote_end__ = remote_cls(*a, **kw)\nC:\\Users\\alozovsk\\Anaconda3\\envs\\modin\\lib\\site-packages\\rpyc\\core\\netref.py:253: in __call__\n    return syncreq(_self, consts.HANDLE_CALL, args, kwargs)\nC:\\Users\\alozovsk\\Anaconda3\\envs\\modin\\lib\\site-packages\\rpyc\\core\\netref.py:76: in syncreq\n    return conn.sync_request(handler, proxy, *args)\nmodin\\experimental\\cloud\\rpyc_proxy.py:160: in sync_request\n    return super().sync_request(handler, *args)\nC:\\Users\\alozovsk\\Anaconda3\\envs\\modin\\lib\\site-packages\\rpyc\\core\\protocol.py:469: in sync_request\n    return self.async_request(handler, *args, timeout=timeout).value\nC:\\Users\\alozovsk\\Anaconda3\\envs\\modin\\lib\\site-packages\\rpyc\\core\\async_.py:102: in value\n    raise self._obj\nE   _get_exception_class.<locals>.Derived: 'list' object is not callable\nE   \nE   ========= Remote Traceback (2) =========\nE   Traceback (most recent call last):\nE     File \"C:\\Users\\alozovsk\\Anaconda3\\envs\\modin\\lib\\site-packages\\rpyc\\core\\protocol.py\", line 320, in _dispatch_request\nE       res = self._HANDLERS[handler](self, *args)\nE     File \"C:\\Users\\alozovsk\\Anaconda3\\envs\\modin\\lib\\site-packages\\rpyc\\core\\protocol.py\", line 593, in _handle_call\nE       return obj(*args, **dict(kwargs))\nE     File \"C:\\prog\\modin\\modin\\pandas\\dataframe.py\", line 140, in __init__\nE       self._query_compiler = data.loc[index, columns]._query_compiler\nE     File \"C:\\prog\\modin\\modin\\pandas\\indexing.py\", line 515, in __getitem__\nE       return self.df.__getitem__(col_loc)\nE     File \"C:\\prog\\modin\\modin\\pandas\\base.py\", line 2847, in __getitem__\nE       return self._getitem(key)\nE     File \"C:\\prog\\modin\\modin\\pandas\\dataframe.py\", line 2891, in _getitem\nE       key = apply_if_callable(key, self)\nE     File \"C:\\Users\\alozovsk\\Anaconda3\\envs\\modin\\lib\\site-packages\\pandas\\core\\common.py\", line 329, in apply_if_callable\nE       return maybe_callable(obj, **kwargs)\nE     File \"C:\\Users\\alozovsk\\Anaconda3\\envs\\modin\\lib\\site-packages\\rpyc\\core\\netref.py\", line 253, in __call__\nE       return syncreq(_self, consts.HANDLE_CALL, args, kwargs)\nE     File \"C:\\Users\\alozovsk\\Anaconda3\\envs\\modin\\lib\\site-packages\\rpyc\\core\\netref.py\", line 76, in syncreq\nE       return conn.sync_request(handler, proxy, *args)\nE     File \"C:\\Users\\alozovsk\\Anaconda3\\envs\\modin\\lib\\site-packages\\rpyc\\core\\protocol.py\", line 469, in sync_request\nE       return self.async_request(handler, *args, timeout=timeout).value\nE     File \"C:\\Users\\alozovsk\\Anaconda3\\envs\\modin\\lib\\site-packages\\rpyc\\core\\async_.py\", line 102, in value\nE       raise self._obj\nE   _get_exception_class.<locals>.Derived: 'list' object is not callable\nE   \nE   ========= Remote Traceback (1) =========\nE   Traceback (most recent call last):\nE     File \"C:\\Users\\alozovsk\\Anaconda3\\envs\\modin\\lib\\site-packages\\rpyc\\core\\protocol.py\", line 320, in _dispatch_request\nE       res = self._HANDLERS[handler](self, *args)\nE     File \"C:\\Users\\alozovsk\\Anaconda3\\envs\\modin\\lib\\site-packages\\rpyc\\core\\protocol.py\", line 593, in _handle_call\nE       return obj(*args, **dict(kwargs))\nE   TypeError: 'list' object is not callable"
                },
                "teardown": {
                    "name": "teardown",
                    "duration": 0.0033680000000089194,
                    "outcome": "passed"
                },
                "outcome": "failed"
            }
        ],
        "summary": {
            "failed": 19,
            "passed": 8,
            "num_tests": 27,
            "duration": 96.05961966514587
        },
        "created_at": "2021-07-28 19:31:02.850256"
    }
}